Workbook
Name _Ref352134769: 'TABELA DE TARIFAS NOVAS'!$A$93

Sheet FIO B
B2: TUSD FIO B
B4: SUBGRUPO | C4: MODALIDADE | D4: CLASSE | E4: SUBCLASSE | F4: POSTO | G4: TARIFAS DE APLICAÇÃO
G5: TUSD FIO B (RTP 2025) | J5: TUSD FIO B (RTA 2026)
G6: R$/kW | H6: R$/MWh | J6: R$/kW | K6: R$/MWh
B7: B1 | C7: BRANCA | D7: RESIDENCIAL | E7: RESIDENCIAL | F7: P | G7: 0 | H7: 591.10909 | J7: 0 | K7: 606.53962
B8: B1 | C8: BRANCA | D8: RESIDENCIAL | E8: RESIDENCIAL | F8: INT | G8: 0 | H8: 354.6655 | J8: 0 | K8: 363.92381
B9: B1 | C9: BRANCA | D9: RESIDENCIAL | E9: RESIDENCIAL | F9: FP | G9: 0 | H9: 118.2218 | J9: 0 | K9: 121.3079
B10: B1 | C10: PRÉ-PAGAMENTO | D10: RESIDENCIAL | E10: RESIDENCIAL | F10: NA | G10: 0 | H10: 203.83072 | J10: 0 | K10: 209.15159
B11: B1 | C11: CONVENCIONAL | D11: RESIDENCIAL | E11: RESIDENCIAL | F11: NA | G11: 0 | H11: 203.83072 | J11: 0 | K11: 209.15159
B12: B1 | C12: PRÉ-PAGAMENTO | D12: RESIDENCIAL | E12: BAIXA RENDA | F12: NA | G12: 0 | H12: 203.83072 | J12: 0 | K12: 209.15159
B13: B1 | C13: CONVENCIONAL | D13: RESIDENCIAL | E13: BAIXA RENDA | F13: NA | G13: 0 | H13: 203.83072 | J13: 0 | K13: 209.15159
B14: B1 | C14: PRÉ-PAGAMENTO | D14: RESIDENCIAL | E14: RESIDENCIAL DESCONTO SOCIAL | F14: NA | G14: 0 | H14: 203.83072 | J14: 0 | K14: 209.15159
B15: B1 | C15: CONVENCIONAL | D15: RESIDENCIAL | E15: RESIDENCIAL DESCONTO SOCIAL | F15: NA | G15: 0 | H15: 203.83072 | J15: 0 | K15: 209.15159
B16: B2 | C16: BRANCA | D16: RURAL | E16: NÃO SE APLICA | F16: P | G16: 0 | H16: 693.02445 | J16: 0 | K16: 711.11541
B17: B2 | C17: BRANCA | D17: RURAL | E17: NÃO SE APLICA | F17: INT | G17: 0 | H17: 415.81471 | J17: 0 | K17: 426.66929
B18: B2 | C18: BRANCA | D18: RURAL | E18: NÃO SE APLICA | F18: FP | G18: 0 | H18: 138.60487 | J18: 0 | K18: 142.22306
... B39: B | C39: GERAÇÃO | D39: TIPO 02 | E39: NA | F39: NA | G39: 0 | H39: 11.690957 | J39: 0 | K39: 11.996142

Sheet TABELA DE TARIFAS ANTIGAS
A1: TABELA 1 – TARIFAS DE APLICAÇÃO E BASE ECONÔMICA PARA O GRUPO A.
A2: SUBGRUPO | B2: MODALIDADE | C2: UC | D2: POSTO | E2: TARIFAS DE APLICAÇÃO | J2: BASE ECONÔMICA | N2: Reajuste | O2: Dia | P2: Mês | Q2: Ano
E3: TUSD | G3: TE | J3: TUSD | L3: TE | N3: De | O3: 07 | P3: 08 | Q3: 2025
E4: R$/kW | F4: R$/MWh | G4: BVD – R$/MWh | H4: BAM – R$/MWh | I4: BVM – R$/MWh | J4: R$/kW | K4: R$/MWh | L4: R$/MWh | N4: Até | O4: 06 | P4: 08 | Q4: 2026
B5: AZUL | C5: NA | D5: P
A6: A1 (230 kV ou mais) | D6: FP
B7: AZUL APE | C7: NA | D7: P
D8: FP
A9: A2 (88 a 138kV) | B9: AZUL | C9: NA | D9: P
D10: FP
B11: AZUL APE | C11: NA | D11: P
D12: FP
B13: DISTRIBUIÇÃO | C13: ELFSM | D13: P
D14: FP
D15: NA
B16: GERAÇÃO | C16: UTE LASA | D16: NA
C17: UTE ALCON | D17: NA
C18: UTE SOL | D18: NA
C19: UHE MASCARENHAS - ENERGEST | D19: NA
C20: UHE SUICA | D20: NA
C21: PCH SAO JOAQUIM | D21: NA
C22: PCH SAO SIMAO | D22: NA
C23: PCH FRANCISCO GROSS | D23: NA
C24: PCH SAO PEDRO | D24: NA
C25: UTE LINHARES | D25: NA
C26: UTE ARCEL | D26: NA
C27: NOVO GERADOR | D27: NA
A28: A3 (69kV) | B28: AZUL | C28: NA | D28: P
D29: FP
B30: AZUL APE | C30: NA | D30: P
D31: FP
B32: DISTRIBUIÇÃO | D32: P
D33: FP
D34: NA
B35: GERAÇÃO | C35: NA | D35: NA
A36: A3a (30 a 44kV) | B36: AZUL | C36: NA | D36: P
D37: FP
B38: AZUL APE | C38: NA | D38: P
D39: FP
B40: VERDE | C40: NA | D40: NA
...

Sheet TABELA DE TARIFAS NOVAS
A1: TABELA 1 – TARIFAS DE APLICAÇÃO E BASE ECONÔMICA PARA O GRUPO A.
A2: SUBGRUPO | B2: MODALIDADE | C2: UC | D2: POSTO | E2: TARIFAS DE APLICAÇÃO | J2: BASE ECONÔMICA | N2: Reajuste | O2: Dia | P2: Mês | Q2: Ano
E3: TUSD | G3: TE | J3: TUSD | L3: TE | N3: De | O3: 07 | P3: 08 | Q3: 2026
E4: R$/kW | F4: R$/MWh | G4: BVD – R$/MWh | H4: BAM – R$/MWh | I4: BVM – R$/MWh | J4: R$/kW | K4: R$/MWh | L4: R$/MWh | N4: Até | O4: 31 | P4: 12 | Q4: 9999
B5: AZUL | C5: NA | D5: P
A6: A1 (230 kV ou mais) | D6: FP
B7: AZUL APE | C7: NA | D7: P
D8: FP
A9: A2 (88 a 138kV) | B9: AZUL | C9: NA | D9: P
D10: FP
B11: AZUL APE | C11: NA | D11: P
D12: FP
B13: DISTRIBUIÇÃO | C13: ELFSM | D13: P
D14: FP
D15: NA
B16: GERAÇÃO | C16: UTE LASA | D16: NA
C17: UTE ALCON | D17: NA
C18: UTE SOL | D18: NA
C19: UHE MASCARENHAS - ENERGEST | D19: NA
C20: UHE SUICA | D20: NA
C21: PCH SAO JOAQUIM | D21: NA
C22: PCH SAO SIMAO | D22: NA
C23: PCH FRANCISCO GROSS | D23: NA
C24: PCH SAO PEDRO | D24: NA
C25: UTE LINHARES | D25: NA
C26: UTE POVOACAO 1 | D26: NA
C27: UTE ARCEL | D27: NA
C28: UTE BIANCOGRES | D28: NA
C29: NOVO GERADOR | D29: NA
A30: A3 (69kV) | B30: AZUL | C30: NA | D30: P
D31: FP
B32: AZUL APE | C32: NA | D32: P
D33: FP
B34: DISTRIBUIÇÃO | D34: P
D35: FP
D36: NA
B37: GERAÇÃO | C37: NA | D37: NA
A38: A3a (30 a 44kV) | B38: AZUL | C38: NA | D38: P
D39: FP
B40: AZUL APE | C40: NA | D40: P
...

Sheet Fatura B1 (GD) OK
B2: B1 Res | E2: Vigência das Tarifas: | F2: 46241 | M2: Bandeira | N2: R$/kWh | O2: ANEEL em 29/06 | Q2: TUSD FIO B
M3: VERDE | N3: 0
B4: TARIFA | C4: TARIFA ANTIGA - REH 3508/2025 | F4: TARIFA NOVA - REH xxxx/2026 | I4: Tarifas Proporcionalizadas | M4: BAM | N4: =[1]BANDEIRA!$D$5 -> 0.01885 | Q4: TARIFA | R4: =C4 -> TARIFA ANTIGA - REH 3508/2025 | U4: =F4 -> TARIFA NOVA - REH xxxx/2026 | X4: Tarifas Proporcionalizadas
C5: Tusd | D5: TE | E5: TUSD + TE | F5: Tusd | G5: TE | H5: TUSD + TE | I5: Tusd | J5: TE | K5: TUSD + TE | M5: BVM1 | N5: =[1]BANDEIRA!$D$6 -> 0.04463 | R5: Tusd (R$/kWh) | U5: Tusd (R$/kWh) | X5: Tusd (R$/kWh)
B6: B1 | C6: ='TABELA DE TARIFAS ANTIGAS'!G71/1000 -> 0.46863 | D6: ='TABELA DE TARIFAS ANTIGAS'!H71/1000 -> 0.32068 | E6: =C6+D6 -> 0.78931 | F6: ='TABELA DE TARIFAS NOVAS'!G73/1000 -> 0.50632 | G6: ='TABELA DE TARIFAS NOVAS'!H73/1000 -> 0.33739 | H6: =F6+G6 -> 0.84371 | I6: =((C6*$C$14)+(F6*$D$14))/($D$14+$C$14) -> 0.49100844 | J6: =((D6*$C$14)+(G6*$D$14))/($D$14+$C$14) -> 0.33060156 | K6: =I6+J6 -> 0.82161 | M6: BVM2 | N6: =[1]BANDEIRA!$D$7 -> 0.07877 | Q6: =B6 -> B1 | R6: ='FIO B'!H11/1000 -> 0.20383072 | U6: ='FIO B'!K11/1000 -> 0.20915159 | X6: =((R6*$C$14)+(U6*$D$14))/($D$14+$C$14) -> 0.20698999
B7: CDE Escassez Hídrica | C7: 0.00018774721 | D7: -0.0044031307 | E7: 0.0036054084 | F7: =T11 -> 0.00018418923 | G7: =U11 -> -0.00053182975 | H7: =F7+G7 -> -0.00034764052 | I7: =((C7*$C$14)+(F7*$D$14))/($D$14+$C$14) -> 0.00018563466 | J7: =((D7*$C$14)+(G7*$D$14))/($D$14+$C$14) -> -0.0021045458 | K7: =I7+J7 -> -0.0019189111 | M7: Escassez Hídrica | N7: 0.142
B8: TE SCEE | G8: =G6*15% -> 0.0506085 | J8: =((D8*$C$14)+(G8*$D$14))/($D$14+$C$14) -> 0.030048797 | P8: CUSTO | R8: Part. TUSD (%) | S8: Part. TE (%) | T8: Tusd (R$/kWh) | U8: TE (R$/kWh)
P9: CDE CONTAS
H10: Fatura | L10: Vigência das Tarifas (troca Bandeira): | M10: =EOMONTH(B14,0)+1 -> 46235 | P10: CDE COVID | U10: 0
B11: INSTALAÇÃO | C11: 73278 | H11: =E14 -> 46259 | K11: Altere a bandeira na célula abaixo | P11: CDE ESCASSEZ HÍDRICA | T11: =0.184189231569235/1000 -> 0.00018418923 | U11: =-0.531829748712515/1000 -> -0.00053182975
K12: BAM | L12: BAM
B13: Leitura Anterior | C13: Nº de dias tarifa Anterior | D13: Nº de dias tarifa Nova | E13: Leitura Atual | J13: Leitura Anterior | K13: Nº de dias tarifa Anterior | L13: Nº de dias tarifa Nova | M13: Leitura Atual
B14: 46227 | C14: =IF((F2-B14-1)<0,0,(F2-B14-1)) -> 13 | D14: =E14-F2+1 -> 19 | E14: 46259 | J14: =B14 -> 46227 | K14: =IF((M10-J14-1)<0,0,(M10-J14-1)) -> 7 | L14: =M14-M10+1 -> 25 | M14: =E14 -> 46259
B17: Perc. de Redução da Energia Injetada | E17: TUSD | F17: 1 | G17: TE | H17: 1 | M17: Documento Impressão | O17: 1025311173
B19: Descrição | C19: Unidade | D19: Quantidade | E19: Preço Unit (R$) com tributos | F19: Valor Total (R$) | G19: PIS/COFINS (R$) | H19: Base de Cálculo ICMS (R$) | I19: Alíquota ICMS (%) | J19: ICMS (R$) | K19: Preço Unit (R$) | L19: Tributos | M19: Base de Cálc (R$) | N19: Alíquota (%) | O19: Valor (R$)
R20: TUSD Fio B | S20: Receita Fio B
B21: TUSD - Consumo | C21: kWh | D21: 324 | E21: =(ROUND(D21*K21,2)+ROUND(G21,2)+ROUND(J21,2))/ROUND(D21,4) -> 0.63049383 | F21: =ROUND(D21*E21,2) -> 204.28 | G21: =((D21*K21)/(1-$N$21-$N$23))*($N$21+$N$23) -> 10.461101 | H21: =((D21*K21)/(1-$N$21-$N$23)/(1-$I$21)) -> 204.2745 | I21: 0.17 | J21: =(H21*$I$21) -> 34.726665 | K21: =IF(AND($B$14<$F$2,$E$14<$F$2),C6,IF($B$14<$F$2,I6,F6)) -> 0.49100844 | L21: PIS | M21: =D71 -> 290.21635 | N21: 0.011 | O21: =ROUND(M21*N21,2) -> 3.19 | R21: =IF(AND($B$14<$F$2,$E$14<$F$2),R6,IF($B$14<$F$2,X6,U6)) -> 0.20698999 | S21: =D21*R21 -> 67.064756 | T21: não está considerando energia injetada
B22: TE - Consumo | C22: kWh | D22: =D21 -> 324 | E22: =(ROUND(D22*K22,2)+ROUND(G22,2)+ROUND(J22,2))/ROUND(D22,4) -> 0.42447531 | F22: =ROUND(D22*E22,2) -> 137.53 | G22: =((D22*K22)/(1-$N$21-$N$23))*($N$21+$N$23) -> 7.0435785 | H22: =ROUND((D22*K22)/(1-$N$21-$N$23)/(1-$I$21),8) -> 137.54034 | J22: =ROUND(H22*$I$21,2) -> 23.38 | K22: =IF(AND($B$14<$F$2,$E$14<$F$2),D6,IF($B$14<$F$2,J6,G6)) -> 0.33060156 | L22: PIS Inj | M22: =D72 -> -245.42257 | N22: =N21 -> 0.011 | O22: =ROUND(M22*N22,2) -> -2.7
B23: Adicional BAM | C23: kWh | D23: =IF($K$12=M4,($D$21*($K$14)/($L$14+$K$14)),0)+IF($L$12=M4,($D$21*($L$14)/($L$14+$K$14)),0) -> 324 | E23: =IFERROR((ROUND(D23*K23,2)+ROUND(G23,2)+ROUND(J23,2))/ROUND(D23,4), 0) -> 0.024197531 | F23: =ROUND(D23*E23,2) -> 7.84 | G23: =((D23*K23)/(1-$N$21-$N$23))*($N$21+$N$23) -> 0.40160565 | H23: =ROUND((D23*K23)/(1-$N$21-$N$23)/(1-$I$21),8) -> 7.8421755 | J23: =ROUND(H23*$I$21,2) -> 1.33 | K23: =N4 -> 0.01885 | L23: COFINS | M23: =M21 -> 290.21635 | N23: 0.0507 | O23: =ROUND(M23*N23,2) -> 14.71
B24: Adicional BVM1 | C24: kWh | D24: =IF($K$12=M5,($D$21*($K$14)/($L$14+$K$14)),0)+IF($L$12=M5,($D$21*($L$14)/($L$14+$K$14)),0) -> 0 | E24: =IFERROR((ROUND(D24*K24,2)+ROUND(G24,2)+ROUND(J24,2))/ROUND(D24,4), 0) -> 0 | F24: =ROUND(D24*E24,2) -> 0 | G24: =((D24*K24)/(1-$N$21-$N$23))*($N$21+$N$23) -> 0 | H24: =ROUND((D24*K24)/(1-$N$21-$N$23)/(1-$I$21),8) -> 0 | J24: =ROUND(H24*$I$21,2) -> 0 | K24: =N5 -> 0.04463 | L24: COFINS Inj | M24: =M22 -> -245.42257 | N24: =N23 -> 0.0507 | O24: =ROUND(M24*N24,2) -> -12.44
B25: Adicional BVM2 | C25: kWh | D25: =IF($K$12=M6,($D$21*($K$14)/($L$14+$K$14)),0)+IF($L$12=M6,($D$21*($L$14)/($L$14+$K$14)),0) -> 0 | E25: =IFERROR((ROUND(D25*K25,2)+ROUND(G25,2)+ROUND(J25,2))/ROUND(D25,4), 0) -> 0 | F25: =ROUND(D25*E25,2) -> 0 | G25: =((D25*K25)/(1-$N$21-$N$23))*($N$21+$N$23) -> 0 | H25: =ROUND((D25*K25)/(1-$N$21-$N$23)/(1-$I$21),8) -> 0 | J25: =ROUND(H25*$I$21,2) -> 0 | K25: =N6 -> 0.07877
B26: Adicional EH | C26: kWh | D26: =IF($K$12=M7,($D$21*($K$14)/($L$14+$K$14)),0)+IF($L$12=M7,($D$21*($L$14)/($L$14+$K$14)),0) -> 0 | E26: =IFERROR((ROUND(D26*K26,2)+ROUND(G26,2)+ROUND(J26,2))/ROUND(D26,4), 0) -> 0 | F26: =ROUND(D26*E26,2) -> 0 | G26: =((D26*K26)/(1-$N$21-$N$23))*($N$21+$N$23) -> 0 | H26: =ROUND((D26*K26)/(1-$N$21-$N$23)/(1-$I$21),8) -> 0 | J26: =ROUND(H26*$I$21,2) -> 0 | K26: =N7 -> 0.142
B28: TUSD - Consumo inj | C28: kWh | D28: -274 | E28: =IFERROR((ROUND(D28*K28,2)+ROUND(G28,2)+ROUND(J28,2))/ROUND(D28,4),0) -> 0.52332117 | F28: =ROUND(D28*E28,2) -> -143.39 | G28: =((D28*K28)/(1-$N$22-$N$24))*($N$22+$N$24) -> -8.8467339 | H28: 0 | I28: 0 | J28: =H28*$I$21 -> 0 | K28: =K21 -> 0.49100844
B29: TE - Consumo inj | C29: kWh | D29: =D28 -> -274 | E29: =IFERROR((ROUND(D29*K29,2)+ROUND(G29,2)+ROUND(J29,2))/ROUND(D29,4),0) -> 0.42448905 | F29: =ROUND(D29*E29,2) -> -116.31 | G29: =((D29*K29)/(1-$N$22-$N$24))*($N$22+$N$24) -> -5.9566065 | H29: =ROUND((D29*K29)/(1-$N$22-$N$24)/(1-$I$21),8) -> -116.31498 | I29: =I21 -> 0.17 | J29: =H29*$I$21 -> -19.773547 | K29: =K22 -> 0.33060156
B30: Adicional BAM inj | C30: kWh | D30: =IF($K$12=M4,($D$28*($K$14)/($K$14+$L$14)),0)+IF($L$12=M4,($D$28*($L$14)/($K$14+$L$14)),0) -> -274 | E30: =IFERROR((ROUND(D30*K30,2)+ROUND(G30,2)+ROUND(J30,2))/ROUND(D30,4),0) -> 0.02419708 | F30: =ROUND(D30*E30,2) -> -6.63 | G30: =((D30*K30)/(1-$N$22-$N$24))*($N$22+$N$24) -> -0.33962947 | H30: =(D30*K30)/(1-$N$22-$N$24)/(1-$I$21) -> -6.6319632 | J30: =H30*$I$21 -> -1.1274337 | K30: =N4 -> 0.01885
B31: Adicional BVM1 inj | C31: kWh | D31: =IF($K$12=M5,($D$28*($K$14)/($K$14+$L$14)),0)+IF($L$12=M5,($D$28*($L$14)/($K$14+$L$14)),0) -> 0 | E31: =IFERROR((ROUND(D31*K31,2)+ROUND(G31,2)+ROUND(J31,2))/ROUND(D31,4),0) -> 0 | F31: =ROUND(D31*E31,2) -> 0 | G31: =((D31*K31)/(1-$N$22-$N$24))*($N$22+$N$24) -> 0 | H31: =(D31*K31)/(1-$N$22-$N$24)/(1-$I$21) -> 0 | J31: =H31*$I$21 -> 0 | K31: =N5 -> 0.04463
B32: Adicional BVM2 inj | C32: kWh | D32: =IF($K$12=M6,($D$28*($K$14)/($K$14+$L$14)),0)+IF($L$12=M6,($D$28*($L$14)/($K$14+$L$14)),0) -> 0 | E32: =IFERROR((ROUND(D32*K32,2)+ROUND(G32,2)+ROUND(J32,2))/ROUND(D32,4),0) -> 0 | F32: =ROUND(D32*E32,2) -> 0 | G32: =((D32*K32)/(1-$N$22-$N$24))*($N$22+$N$24) -> 0 | H32: =(D32*K32)/(1-$N$22-$N$24)/(1-$I$21) -> 0 | J32: =H32*$I$21 -> 0 | K32: =N6 -> 0.07877
B33: Adicional EH inj | C33: kWh | D33: =IF($K$12=M7,($D$28*($K$14)/($K$14+$L$14)),0)+IF($L$12=M7,($D$28*($L$14)/($K$14+$L$14)),0) -> 0 | E33: =IFERROR((ROUND(D33*K33,2)+ROUND(G33,2)+ROUND(J33,2))/ROUND(D33,4),0) -> 0 | F33: =ROUND(D33*E33,2) -> 0 | G33: =((D33*K33)/(1-$N$22-$N$24))*($N$22+$N$24) -> 0 | H33: =(D33*K33)/(1-$N$22-$N$24)/(1-$I$21) -> 0 | J33: =H33*$I$21 -> 0 | K33: =N7 -> 0.142
B35: Multas
B36: Juros
B37: Bônus/Descontos
B38: Doações | F38: -8.29
B39: CIP | F39: 46.36
B42: TOTAL | F42: =SUM(F21:F41) -> 121.39 | G42: =SUM(G21:G41) -> 2.7633157 | H42: =SUM(H21:H41) -> 226.71007 | J42: =SUM(J21:J41) -> 38.535684
B44: Informativo Escassez | C44: =(D21+D28) -> 50 | D44: =IF(AND($B$14<$F$2,$E$14<$F$2),C7,IF($B$14<$F$2,I7,F7)) -> 0.00018563466 | E44: =IF(AND($B$14<$F$2,$E$14<$F$2),D7,IF($B$14<$F$2,J7,G7)) -> -0.0021045458 | F44: =C44*(D44+E44) -> -0.095945556
B46: Fatura B1 Residencial
D47: Qtde | E47: TUSD | F47: TE | G47: TUSD + TE | H47: R$
B48: Fornecimento de Energia Elétrica | H48: =SUM(H50:H66)+SUM(H71:H76) -> 83.335768
B50: Energia Fornecida | D50: =D21 -> 324 | E50: =IF(AND($B$14<$F$2,$E$14<$F$2),C6,IF($B$14<$F$2,I6,F6)) -> 0.49100844 | F50: =IF(AND($B$14<$F$2,$E$14<$F$2),D6,IF($B$14<$F$2,J6,G6)) -> 0.33060156 | G50: =E50+F50 -> 0.82161 | H50: =ROUND((D50*E50),2)+ROUND((D50*F50),2) -> 266.2
B52: Adicional BAM | D52: =IF($K$12=M4,(D50*(K14)/(K14+L14)),0)+IF($L$12=M4,(D50*(L14)/(K14+L14)),0) -> 324 | F52: =N4 -> 0.01885 | H52: =ROUND(D52*(E52+F52),2) -> 6.11
...

Sheet Fatura B1 (GD I)
B2: B1 Res | E2: Vigência das Tarifas: | F2: 45145 | I2: GDI | M2: Bandeira | N2: R$/kWh | O2: ANEEL em 29/06 | Q2: TUSD FIO B
M3: VERDE | N3: 0
B4: TARIFA | C4: TARIFA ANTIGA - REH 3091/2022 | F4: TARIFA NOVA - REH XXXX/2023 | I4: Tarifas Proporcionalizadas | M4: BAM | N4: 0.02989 | Q4: TARIFA | R4: =C4 -> TARIFA ANTIGA - REH 3091/2022 | U4: =F4 -> TARIFA NOVA - REH XXXX/2023 | X4: Tarifas Proporcionalizadas
C5: Tusd | D5: TE | E5: TUSD + TE | F5: Tusd | G5: TE | H5: TUSD + TE | I5: Tusd | J5: TE | K5: TUSD + TE | M5: BVM1 | N5: 0.065 | R5: Tusd (R$/kWh) | U5: Tusd (R$/kWh) | X5: Tusd (R$/kWh)
B6: B1 | C6: 0.39681 | D6: 0.27703 | E6: =C6+D6 -> 0.67384 | F6: 0.39681 | G6: 0.27703 | H6: =F6+G6 -> 0.67384 | I6: =((C6*$C$14)+(F6*$D$14))/($D$14+$C$14) -> 0.39681 | J6: =((D6*$C$14)+(G6*$D$14))/($D$14+$C$14) -> 0.27703 | K6: =I6+J6 -> 0.67384 | M6: BVM2 | N6: 0.09795 | Q6: =B6 -> B1 | R6: ='[2]FIO B'!H11/1000 -> 0.19205 | U6: ='[2]FIO B'!K11/1000 -> 0.17652 | X6: =((R6*$C$14)+(U6*$D$14))/($D$14+$C$14) -> 0.18503645
B7: CDE Escassez Hídrica | F7: =T11 -> 0.00020011 | G7: =U11 -> 0.00402681 | H7: =F7+G7 -> 0.00422692 | I7: =((C7*$C$14)+(F7*$D$14))/($D$14+$C$14) -> 9.0372258e-05 | J7: =((D7*$C$14)+(G7*$D$14))/($D$14+$C$14) -> 0.0018185594 | K7: =I7+J7 -> 0.0019089316
B8: TE SCEE | G8: =G6*15% -> 0.0415545 | J8: =((D8*$C$14)+(G8*$D$14))/($D$14+$C$14) -> 0.018766548 | M8: Escassez Hídrica | N8: 0.142 | P8: CUSTO | T8: Tusd (R$/kWh) | U8: TE (R$/kWh)
P9: CDE CONTAS
H10: Fatura | L10: Vigência das Tarifas (troca Bandeira): | M10: =EOMONTH(B14,0)+1 -> 45139 | P10: CDE COVID
B11: INSTALAÇÃO | C11: 1182321 | H11: =E14 -> 45158 | K11: Altere a bandeira na célula abaixo | P11: CDE ESCASSEZ HÍDRICA | T11: 0.00020011 | U11: 0.00402681
K12: BAM | L12: BVM2
B13: Leitura Anterior | C13: Nº de dias tarifa Anterior | D13: Nº de dias tarifa Nova | E13: Leitura Atual | J13: Leitura Anterior | K13: Nº de dias tarifa Anterior | L13: Nº de dias tarifa Nova | M13: Leitura Atual
B14: 45127 | C14: =IF((F2-B14-1)<0,0,(F2-B14-1)) -> 17 | D14: =E14-F2+1 -> 14 | E14: 45158 | J14: =B14 -> 45127 | K14: =IF((M10-J14-1)<0,0,(M10-J14-1)) -> 11 | L14: =M14-M10+1 -> 20 | M14: =E14 -> 45158
B17: Perc. de Redução da Energia Injetada | E17: TUSD | F17: 1 | G17: TE | H17: 1
B19: Fatura B1 Residencial
D20: Qtde | E20: TUSD | F20: TE | G20: TUSD + TE | H20: R$
B21: Fornecimento de Energia Elétrica | H21: =SUM(H23:H39)+SUM(H44:H49) -> 254.92055
B23: Energia Fornecida | D23: 2000 | E23: =IF(AND($B$14<$F$2,$E$14<$F$2),C6,IF($B$14<$F$2,I6,F6)) -> 0.39681 | F23: =IF(AND($B$14<$F$2,$E$14<$F$2),D6,IF($B$14<$F$2,J6,G6)) -> 0.27703 | G23: =E23+F23 -> 0.67384 | H23: =ROUND((D23*E23),2)+ROUND((D23*F23),2) -> 1347.68
B25: Adicional BAM | D25: =IF($K$12=M4,(D23*(K14)/(K14+L14)),0)+IF($L$12=M4,(D23*(L14)/(K14+L14)),0) -> 709.67742 | F25: =N4 -> 0.02989 | H25: =ROUND(D25*(E25+F25),2) -> 21.21
B26: Adicional BVM 1 | D26: =IF($K$12=M5,(D23*(K14)/(K14+L14)),0)+IF($L$12=M5,(D23*(L14)/(K14+L14)),0) -> 0 | F26: =N5 -> 0.065 | H26: =ROUND(D26*(E26+F26),2) -> 0
B27: Adicional BVM 2 | D27: =IF($K$12=M6,(D23*(K14)/(K14+L14)),0)+IF($L$12=M6,(D23*(L14)/(K14+L14)),0) -> 1290.3226 | F27: =N6 -> 0.09795 | H27: =ROUND(D27*(E27+F27),2) -> 126.39
B28: Adicional Escassez Hídrica | D28: =IF($K$12=M8,(D23*(K14)/(K14+L14)),0)+IF($L$12=M8,(D23*(L14)/(K14+L14)),0) -> 0 | F28: =N8 -> 0.142 | H28: =ROUND(D28*(E28+F28),2) -> 0
B30: Energia Injetada | D30: -1900.0009 | E30: =E23*F17 -> 0.39681 | F30: =F23 -> 0.27703 | G30: =E30+F30 -> 0.67384 | H30: =ROUND((D30*E30),2)+ROUND((D30*F30),2) -> -1280.3
B32: Adicional BAM | D32: =IF($K$12=M4,(D30*(K14)/(K14+L14)),0)+IF($L$12=M4,(D30*(L14)/(K14+L14)),0) -> -674.19385 | F32: =F25 -> 0.02989 | H32: =ROUND(D32*(E32+F32),2) -> -20.15
B33: Adicional BVM 1 | D33: =IF($K$12=M5,(D30*(K14)/(K14+L14)),0)+IF($L$12=M5,(D30*(L14)/(K14+L14)),0) -> 0 | F33: =F26 -> 0.065 | H33: =ROUND(D33*(E33+F33),2) -> 0
B34: Adicional BVM 2 | D34: =IF($K$12=M6,(D30*(K14)/(K14+L14)),0)+IF($L$12=M6,(D30*(L14)/(K14+L14)),0) -> -1225.807 | F34: =F27 -> 0.09795 | H34: =ROUND(D34*(E34+F34),2) -> -120.07
B35: Adicional Escassez Hídrica | D35: =IF($K$12=M8,(D30*(K14)/(K14+L14)),0)+IF($L$12=M8,(D30*(L14)/(K14+L14)),0) -> 0 | F35: =F28 -> 0.142 | H35: =ROUND(D35*(E35+F35),2) -> 0
H41: =SUM(H23:H40) -> 74.76
D43: Base de Cálculo
B44: PIS | D44: =(H23+H25+H26+H27+H28)/(1-E44-E46) -> 1559.0449 | E44: 0.0073 | H44: =D44*E44 -> 11.381028
B45: PIS Eneg Inj | D45: =(H30+H32+H33+H34+H35+H37+H39)/(1-E44-E46) -> -1481.0969 | E45: =E44 -> 0.0073 | H45: =D45*E45 -> -10.812007
B46: COFINS | D46: =D44 -> 1559.0449 | E46: 0.0336 | H46: =D46*E46 -> 52.38391
B47: COFINS Eneg Inj | D47: =D45 -> -1481.0969 | E47: =E46 -> 0.0336 | H47: =D47*E47 -> -49.764855
B48: ICMS | D48: =D44/(1-E48) -> 1878.3674 | E48: 0.17 | H48: =D48*E48 -> 319.32246
B49: ICMS Eneg Inj | D49: =((D30*F30)+(H32+H33+H34+H35)+(D37*F37)+(D39*F39))/(1-E45-E47)/(1-E49) -> -837.35284 | E49: =E48 -> 0.17 | H49: =D49*E49 -> -142.34998
B51: Informativo Escassez Hídrica | D51: =D23+D30 -> 99.999137 | E51: =IF(AND($B$13<$F$2,$E$13<$F$2),C7,IF($B$13<$F$2,I7,F7)) -> 0.00020011 | F51: =IF(AND($B$13<$F$2,$E$13<$F$2),D7,IF($B$13<$F$2,J7,G7)) -> 0.00402681 | H51: =D51*(E51+F51) -> 0.42268835

Sheet Fatura B1CDE (GD) OK
B2: B1 Res | E2: Vigência das Tarifas: | F2: ='Fatura B1 (GD) OK'!F2 -> 46241 | M2: Bandeira | N2: R$/kWh | O2: ANEEL em 29/06 | Q2: TUSD FIO B
M3: VERDE | N3: 0
B4: TARIFA | C4: TARIFA ANTIGA - REH 3508/2025 | F4: TARIFA NOVA - REH xxxx/2026 | I4: Tarifas Proporcionalizadas | M4: BAM | N4: =[1]BANDEIRA!$D$5 -> 0.01885 | Q4: TARIFA | R4: =C4 -> TARIFA ANTIGA - REH 3508/2025 | U4: =F4 -> TARIFA NOVA - REH xxxx/2026 | X4: Tarifas Proporcionalizadas
C5: Tusd | D5: TE | E5: TUSD + TE | F5: Tusd | G5: TE | H5: TUSD + TE | I5: Tusd | J5: TE | K5: TUSD + TE | M5: BVM1 | N5: =[1]BANDEIRA!$D$6 -> 0.04463 | R5: Tusd (R$/kWh) | U5: Tusd (R$/kWh) | X5: Tusd (R$/kWh)
B6: B1 | C6: ='TABELA DE TARIFAS ANTIGAS'!G71/1000 -> 0.46863 | D6: ='TABELA DE TARIFAS ANTIGAS'!H71/1000 -> 0.32068 | E6: =C6+D6 -> 0.78931 | F6: ='TABELA DE TARIFAS NOVAS'!G73/1000 -> 0.50632 | G6: ='TABELA DE TARIFAS NOVAS'!H73/1000 -> 0.33739 | H6: =F6+G6 -> 0.84371 | I6: =((C6*$C$16)+(F6*$D$16))/($D$16+$C$16) -> 0.48621867 | J6: =((D6*$C$16)+(G6*$D$16))/($D$16+$C$16) -> 0.328478 | K6: =I6+J6 -> 0.81469667 | M6: BVM2 | N6: =[1]BANDEIRA!$D$7 -> 0.07877 | Q6: =B6 -> B1 | R6: ='FIO B'!H11/1000 -> 0.20383072 | U6: ='FIO B'!K11/1000 -> 0.20915159 | X6: =((R6*$C$16)+(U6*$D$16))/($D$16+$C$16) -> 0.20631379
B7: B1CDE | C7: ='TABELA DE TARIFAS ANTIGAS'!G73/1000 -> 0.34019 | D7: ='TABELA DE TARIFAS ANTIGAS'!H73/1000 -> 0.29666 | E7: =C7+D7 -> 0.63685 | F7: ='TABELA DE TARIFAS NOVAS'!G75/1000 -> 0.35642 | G7: ='TABELA DE TARIFAS NOVAS'!H75/1000 -> 0.33759 | H7: =F7+G7 -> 0.69401 | I7: =((C7*$C$16)+(F7*$D$16))/($D$16+$C$16) -> 0.347764 | J7: =((D7*$C$16)+(G7*$D$16))/($D$16+$C$16) -> 0.31576067 | K7: =I7+J7 -> 0.66352467 | M7: Escassez Hídrica | N7: 0.142
B8: CDE Escassez Hídrica até 120 kWh | C8: 0 | D8: -0.0044 | E8: =C8+D8 -> -0.0044 | F8: =T12 -> 0 | G8: =U12 -> -0.00053182975 | H8: =F8+G8 -> -0.00053182975 | I8: =((C8*$C$16)+(F8*$D$16))/($D$16+$C$16) -> 0 | J8: =((D8*$C$16)+(G8*$D$16))/($D$16+$C$16) -> -0.0025948539 | K8: =I8+J8 -> -0.0025948539
B9: CDE Escassez Hídrica acima 120 kWh | C9: 0.00018774721 | D9: -0.0044031307 | E9: =C9+D9 -> -0.0042153835 | F9: =T13 -> 0.00018418923 | G9: =U13 -> -0.00053182975 | H9: =F9+G9 -> -0.00034764052 | I9: =((C9*$C$16)+(F9*$D$16))/($D$16+$C$16) -> 0.00018608682 | J9: =((D9*$C$16)+(G9*$D$16))/($D$16+$C$16) -> -0.0025965236 | K9: =I9+J9 -> -0.0024104368
B10: TE SCEE | G10: =G6*15% -> 0.0506085 | J10: =((D10*$C$16)+(G10*$D$16))/($D$16+$C$16) -> 0.0236173 | P10: CUSTO | R10: Part. TUSD (%) | S10: Part. TE (%) | T10: Tusd (R$/kWh) | U10: TE (R$/kWh)
P11: CDE CONTAS
H12: Fatura | L12: Vigência das Tarifas (troca Bandeira): | M12: =EOMONTH(B16,0)+1 -> 46235 | P12: CDE ESCASSEZ HÍDRICA | T12: 0 | U12: =-0.531829748712515/1000 -> -0.00053182975
B13: INSTALAÇÃO | C13: 9858 | H13: =E16 -> 46254 | K13: Altere a bandeira na célula abaixo | P13: CDE ESCASSEZ HÍDRICA | T13: ='Fatura B1 (GD) OK'!T11 -> 0.00018418923 | U13: ='Fatura B1 (GD) OK'!U11 -> -0.00053182975
K14: BAM | L14: BAM
B15: Leitura Anterior | C15: Nº de dias tarifa Anterior | D15: Nº de dias tarifa Nova | E15: Leitura Atual | J15: Leitura Anterior | K15: Nº de dias tarifa Anterior | L15: Nº de dias tarifa Nova | M15: Leitura Atual
B16: 46224 | C16: =IF((F2-B16-1)<0,0,(F2-B16-1)) -> 16 | D16: =E16-F2+1 -> 14 | E16: 46254 | J16: =B16 -> 46224 | K16: =IF((M12-J16-1)<0,0,(M12-J16-1)) -> 10 | L16: =M16-M12+1 -> 20 | M16: =E16 -> 46254
B19: Perc. de Redução da Energia Injetada | E19: TUSD | F19: 1 | G19: TE | H19: 1 | M19: Documento Impressão | O19: 1025311174
B21: Descrição | C21: Unidade | D21: Quantidade | E21: Preço Unit (R$) com tributos | F21: Valor Total (R$) | G21: PIS/COFINS (R$) | H21: Base de Cálculo ICMS (R$) | I21: Alíquota ICMS (%) | J21: ICMS (R$) | K21: Preço Unit (R$) | L21: Tributos | M21: Base de Cálc (R$) | N21: Alíquota (%) | O21: Valor (R$)
R22: TUSD Fio B | S22: Receita Fio B
B23: TUSD - Consumo até 120 KWh | C23: kWh | D23: 120 | E23: =(ROUND(D23*K23,2)+ROUND(G23,2)+ROUND(J23,2))/ROUND(D23,4) -> 0.4465 | F23: =ROUND(D23*E23,2) -> 53.58 | G23: =((D23*K23)/(1-$N$23-$N$25))*($N$23+$N$25) -> 2.7441593 | H23: =((D23*K23)/(1-$N$23-$N$25)/(1-$I$23)) -> 53.585349 | I23: 0.17 | J23: =(H23*$I$23) -> 9.1095093 | K23: =IF(AND($B$16<$F$2,$E$16<$F$2),C7,IF($B$16<$F$2,I7,F7)) -> 0.347764 | L23: PIS | M23: =D81 -> 106.60769 | N23: 0.011 | O23: =ROUND(M23*N23,2) -> 1.17 | R23: =IF(AND($B$16<$F$2,$E$16<$F$2),R6,IF($B$16<$F$2,X6,U6)) -> 0.20631379 | S23: =(D23+D24)*R23 -> 149.37119 | T23: não está considerando energia injetada
B24: TUSD - Consumo acima 120 KWh | C24: kWh | D24: 604 | E24: =(ROUND(D24*K24,2)+ROUND(G24,2)+ROUND(J24,2))/ROUND(D24,4) -> 0.62433775 | F24: =ROUND(D24*E24,2) -> 377.1 | G24: =((D24*K24)/(1-$N$23-$N$25))*($N$23+$N$25) -> 19.311322 | H24: =ROUND((D24*K24)/(1-$N$23-$N$25)/(1-$I$23),8) -> 377.09325 | J24: =ROUND(H24*$I$23,2) -> 64.11 | K24: =IF(AND($B$16<$F$2,$E$16<$F$2),C6,IF($B$16<$F$2,I6,F6)) -> 0.48621867 | L24: PIS Inj | M24: =D8280 -> 0 | N24: =N23 -> 0.011 | O24: =ROUND(M24*N24,2) -> 0
B25: TUSD - Consumo inj até 120kwh | C25: kWh | D25: -20 | E25: =(ROUND(D25*K25,2)+ROUND(G25,2)+ROUND(J25,2))/ROUND(D25,4) -> 0.371 | F25: =ROUND(D25*E25,2) -> -7.42 | G25: =((D25*K25)/(1-$N$24-$N$26))*($N$24+$N$26) -> -0.45735988 | H25: =((D25*K25)/(1-$N$23-$N$25)/(1-$I$23))*0 -> 0 | J25: =(H25*$I$23) -> 0 | K25: =K23 -> 0.347764 | L25: COFINS | M25: =M23 -> 106.60769 | N25: 0.0507 | O25: =ROUND(M25*N25,2) -> 5.41
B26: TUSD - Consumo inj acima 120kwh | C26: kWh | D26: -604 | E26: =(ROUND(D26*K26,2)+ROUND(G26,2)+ROUND(J26,2))/ROUND(D26,4) -> 0.51819536 | F26: =ROUND(D26*E26,2) -> -312.99 | G26: =((D26*K26)/(1-$N$24-$N$26))*($N$24+$N$26) -> -19.311322 | H26: =ROUND((D26*K26)/(1-$N$23-$N$25)/(1-$I$23),8)*0 -> 0 | J26: =ROUND(H26*$I$23,2) -> 0 | K26: =K24 -> 0.48621867 | L26: COFINS Inj | M26: =M24 -> 0 | N26: =N25 -> 0.0507 | O26: =ROUND(M26*N26,2) -> 0
B27: Adicional BAM | C27: kWh | D27: =IF($K$14=M4,(($D$23+$D$24)*($K$16)/($L$16+$K$16)),0)+IF($L$14=M4,(($D$23+$D$24)*($L$16)/($L$16+$K$16)),0) -> 724 | E27: =IFERROR((ROUND(D27*K27,2)+ROUND(G27,2)+ROUND(J27,2))/ROUND(D27,4), 0) -> 0.024212707 | F27: =ROUND(D27*E27,2) -> 17.53 | G27: =((D27*K27)/(1-$N$23-$N$25))*($N$23+$N$25) -> 0.89741509 | H27: =ROUND((D27*K27)/(1-$N$23-$N$25)/(1-$I$23),8) -> 17.523874 | J27: =ROUND(H27*$I$23,2) -> 2.98 | K27: =N4 -> 0.01885
B28: Adicional BVM1 | C28: kWh | D28: =IF($K$14=M5,(($D$23+$D$24)*($K$16)/($L$16+$K$16)),0)+IF($L$14=M5,(($D$23+$D$24)*($L$16)/($L$16+$K$16)),0) -> 0 | E28: =IFERROR((ROUND(D28*K28,2)+ROUND(G28,2)+ROUND(J28,2))/ROUND(D28,4), 0) -> 0 | F28: =ROUND(D28*E28,2) -> 0 | G28: =((D28*K28)/(1-$N$23-$N$25))*($N$23+$N$25) -> 0 | H28: =ROUND((D28*K28)/(1-$N$23-$N$25)/(1-$I$23),8) -> 0 | J28: =ROUND(H28*$I$23,2) -> 0 | K28: =N5 -> 0.04463
B29: Adicional BVM2 | C29: kWh | D29: =IF($K$14=M6,(($D$23+$D$24)*($K$16)/($L$16+$K$16)),0)+IF($L$14=M6,(($D$23+$D$24)*($L$16)/($L$16+$K$16)),0) -> 0 | E29: =IFERROR((ROUND(D29*K29,2)+ROUND(G29,2)+ROUND(J29,2))/ROUND(D29,4), 0) -> 0 | F29: =ROUND(D29*E29,2) -> 0 | G29: =((D29*K29)/(1-$N$23-$N$25))*($N$23+$N$25) -> 0 | H29: =ROUND((D29*K29)/(1-$N$23-$N$25)/(1-$I$23),8) -> 0 | J29: =ROUND(H29*$I$23,2) -> 0 | K29: =N6 -> 0.07877
B30: Adicional EH | C30: kWh | D30: =IF($K$14=M7,(($D$23+$D$24)*($K$16)/($L$16+$K$16)),0)+IF($L$14=M7,(($D$23+$D$24)*($L$16)/($L$16+$K$16)),0) -> 0 | E30: =IFERROR((ROUND(D30*K30,2)+ROUND(G30,2)+ROUND(J30,2))/ROUND(D30,4), 0) -> 0 | F30: =ROUND(D30*E30,2) -> 0 | G30: =((D30*K30)/(1-$N$23-$N$25))*($N$23+$N$25) -> 0 | H30: =ROUND((D30*K30)/(1-$N$23-$N$25)/(1-$I$23),8) -> 0 | J30: =ROUND(H30*$I$23,2) -> 0 | K30: =N7 -> 0.142
B32: TE - Consumo até 120 KWh | C32: kWh | D32: =D23 -> 120 | E32: =IFERROR((ROUND(D32*K32,2)+ROUND(G32,2)+ROUND(J32,2))/ROUND(D32,4),0) -> 0.40541667 | F32: =ROUND(D32*E32,2) -> 48.65 | G32: =((D32*K32)/(1-$N$23-$N$25))*($N$23+$N$25) -> 2.4916253 | H32: =((D32*K32)/(1-$N$23-$N$25)/(1-$I$23)) -> 48.654103 | J32: =H32*$I$23 -> 8.2711975 | K32: =IF(AND($B$16<$F$2,$E$16<$F$2),D7,IF($B$16<$F$2,J7,G7)) -> 0.31576067
B33: TE - Consumo acima 120 KWh | C33: kWh | D33: =D24 -> 604 | E33: =IFERROR((ROUND(D33*K33,2)+ROUND(G33,2)+ROUND(J33,2))/ROUND(D33,4),0) -> 0.42178808 | F33: =ROUND(D33*E33,2) -> 254.76 | G33: =((D33*K33)/(1-$N$23-$N$25))*($N$23+$N$25) -> 13.046279 | H33: =ROUND((D33*K33)/(1-$N$24-$N$26)/(1-$I$23),8) -> 254.75541 | J33: =H33*$I$23 -> 43.30842 | K33: =IF(AND($B$16<$F$2,$E$16<$F$2),D6,IF($B$16<$F$2,J6,G6)) -> 0.328478
B34: TE - Consumo inj até 120kwh | C34: kWh | D34: =D25 -> -20 | E34: =IFERROR((ROUND(D34*K34,2)+ROUND(G34,2)+ROUND(J34,2))/ROUND(D34,4),0) -> 0.406 | F34: =ROUND(D34*E34,2) -> -8.12 | G34: =((D34*K34)/(1-$N$24-$N$26))*($N$24+$N$26) -> -0.41527088 | H34: =((D34*K34)/(1-$N$23-$N$26)/(1-$I$23)) -> -8.1090171 | J34: =H34*$I$23 -> -1.3785329 | K34: =K32 -> 0.31576067
B35: TE - Consumo inj acima 120kwh | C35: kWh | D35: =D26 -> -604 | E35: =IFERROR((ROUND(D35*K35,2)+ROUND(G35,2)+ROUND(J35,2))/ROUND(D35,4),0) -> 0.42178808 | F35: =ROUND(D35*E35,2) -> -254.76 | G35: =((D35*K35)/(1-$N$24-$N$26))*($N$24+$N$26) -> -13.046279 | H35: =ROUND((D35*K35)/(1-$N$24-$N$26)/(1-$I$23),8) -> -254.75541 | J35: =H35*$I$23 -> -43.30842 | K35: =K33 -> 0.328478
B36: Adicional BAM inj | C36: kWh | D36: =IF($K$14=M4,(($D$25+$D$26)*($K$16)/($K$16+$L$16)),0)+IF($L$14=M4,(($D$25+$D$26)*($L$16)/($K$16+$L$16)),0) -> -624 | E36: =IFERROR((ROUND(D36*K36,2)+ROUND(G36,2)+ROUND(J36,2))/ROUND(D36,4),0) -> 0.024198718 | F36: =ROUND(D36*E36,2) -> -15.1 | G36: =((D36*K36)/(1-$N$24-$N$26))*($N$24+$N$26) -> -0.77346273 | H36: =(D36*K36)/(1-$N$24-$N$26)/(1-$I$23) -> -15.103449 | J36: =H36*$I$23 -> -2.5675863 | K36: =N4 -> 0.01885
B37: Adicional BVM1 inj | C37: kWh | D37: =IF($K$14=M5,(($D$25+$D$26)*($K$16)/($K$16+$L$16)),0)+IF($L$14=M5,(($D$25+$D$26)*($L$16)/($K$16+$L$16)),0) -> 0 | E37: =IFERROR((ROUND(D37*K37,2)+ROUND(G37,2)+ROUND(J37,2))/ROUND(D37,4),0) -> 0 | F37: =ROUND(D37*E37,2) -> 0 | G37: =((D37*K37)/(1-$N$24-$N$26))*($N$24+$N$26) -> 0 | H37: =(D37*K37)/(1-$N$24-$N$26)/(1-$I$23) -> 0 | J37: =H37*$I$23 -> 0 | K37: =N5 -> 0.04463
B38: Adicional BVM2 inj | C38: kWh | D38: =IF($K$14=M6,(($D$25+$D$26)*($K$16)/($K$16+$L$16)),0)+IF($L$14=M6,(($D$25+$D$26)*($L$16)/($K$16+$L$16)),0) -> 0 | E38: =IFERROR((ROUND(D38*K38,2)+ROUND(G38,2)+ROUND(J38,2))/ROUND(D38,4),0) -> 0 | F38: =ROUND(D38*E38,2) -> 0 | G38: =((D38*K38)/(1-$N$24-$N$26))*($N$24+$N$26) -> 0 | H38: =(D38*K38)/(1-$N$24-$N$26)/(1-$I$23) -> 0 | J38: =H38*$I$23 -> 0 | K38: =N6 -> 0.07877
B39: Adicional EH inj | C39: kWh | D39: =IF($K$14=M7,(($D$25+$D$26)*($K$16)/($K$16+$L$16)),0)+IF($L$14=M7,(($D$25+$D$26)*($L$16)/($K$16+$L$16)),0) -> 0 | E39: =IFERROR((ROUND(D39*K39,2)+ROUND(G39,2)+ROUND(J39,2))/ROUND(D39,4),0) -> 0 | F39: =ROUND(D39*E39,2) -> 0 | G39: =((D39*K39)/(1-$N$24-$N$26))*($N$24+$N$26) -> 0 | H39: =(D39*K39)/(1-$N$24-$N$26)/(1-$I$23) -> 0 | J39: =H39*$I$23 -> 0 | K39: =N7 -> 0.142
B41: Multas | F41: 0
B42: Juros | F42: 0
B43: Bônus/Descontos | F43: -8.97
B44: Doações | F44: 0
B45: CIP | F45: 0
B48: TOTAL | F48: =SUM(F23:F47) -> 144.26 | G48: =SUM(G23:G47) -> 4.4871061 | H48: =SUM(H23:H47) -> 473.64411 | J48: =SUM(J23:J47) -> 80.524587
...

Sheet Fatura B3 (GD) OK
B2: B3 | E2: Vigência das Tarifas: | F2: ='Fatura B1 (GD) OK'!F2 -> 46241 | M2: Bandeira | N2: R$/kWh | O2: ANEEL em 29/06 | Q2: TUSD FIO B
M3: VERDE | N3: 0
B4: TARIFA | C4: ='Fatura B1 (GD) OK'!C4:E4 -> TARIFA ANTIGA - REH 3508/2025 | F4: ='Fatura B1 (GD) OK'!F4 -> TARIFA NOVA - REH xxxx/2026 | I4: Tarifas Proporcionalizadas | M4: BAM | N4: =[1]BANDEIRA!$D$5 -> 0.01885 | Q4: TARIFA | R4: =C4 -> TARIFA ANTIGA - REH 3508/2025 | U4: =F4 -> TARIFA NOVA - REH xxxx/2026 | X4: Tarifas Proporcionalizadas
C5: Tusd | D5: TE | E5: TUSD + TE | F5: Tusd | G5: TE | H5: TUSD + TE | I5: Tusd | J5: TE | K5: TUSD + TE | M5: BVM1 | N5: =[1]BANDEIRA!$D$6 -> 0.04463 | R5: Tusd (R$/kWh) | U5: Tusd (R$/kWh) | X5: Tusd (R$/kWh)
B6: B3 | C6: ='TABELA DE TARIFAS ANTIGAS'!G89/1000 -> 0.46863 | D6: ='TABELA DE TARIFAS ANTIGAS'!H89/1000 -> 0.32068 | E6: =C6+D6 -> 0.78931 | F6: ='TABELA DE TARIFAS NOVAS'!G91/1000 -> 0.50632 | G6: ='TABELA DE TARIFAS NOVAS'!H91/1000 -> 0.33739 | H6: =F6+G6 -> 0.84371 | I6: =((C6*$C$14)+(F6*$D$14))/($D$14+$C$14) -> 0.502551 | J6: =((D6*$C$14)+(G6*$D$14))/($D$14+$C$14) -> 0.335719 | K6: =I6+J6 -> 0.83827 | M6: BVM2 | N6: =[1]BANDEIRA!$D$7 -> 0.07877 | Q6: =B6 -> B3 | R6: ='FIO B'!H35/1000 -> 0.20383072 | U6: ='FIO B'!K35/1000 -> 0.20915159 | X6: =((R6*$C$14)+(U6*$D$14))/($D$14+$C$14) -> 0.20861951
B7: CDE Escassez Hídrica | C7: 0.00018774721 | D7: -0.0044031307 | E7: 0.0036054084 | F7: =T11 -> 0.00018418923 | G7: =U11 -> -0.00053182975 | H7: =F7+G7 -> -0.00034764052 | I7: =((C7*$C$14)+(F7*$D$14))/($D$14+$C$14) -> 0.00018454503 | J7: =((D7*$C$14)+(G7*$D$14))/($D$14+$C$14) -> -0.00091895985 | K7: =I7+J7 -> -0.00073441482 | M7: Escassez Hídrica | N7: 0.142
B8: TE SCEE | G8: =G6*15% -> 0.0506085 | J8: =((D8*$C$14)+(G8*$D$14))/($D$14+$C$14) -> 0.04554765 | P8: CUSTO | R8: Part. TUSD (%) | S8: Part. TE (%) | T8: Tusd (R$/kWh) | U8: TE (R$/kWh)
P9: CDE CONTAS
H10: Fatura | L10: Vigência das Tarifas (troca Bandeira): | M10: =EOMONTH(B14,0)+1 -> 46266 | P10: CDE COVID | U10: 0
B11: INSTALAÇÃO | C11: 945467 | H11: =E14 -> 46267 | K11: Altere a bandeira na célula abaixo | P11: CDE ESCASSEZ HÍDRICA | T11: ='Fatura B1 (GD) OK'!T11 -> 0.00018418923 | U11: ='Fatura B1 (GD) OK'!U11 -> -0.00053182975
K12: BAM | L12: BAM
B13: Leitura Anterior | C13: Nº de dias tarifa Anterior | D13: Nº de dias tarifa Nova | E13: Leitura Atual | J13: Leitura Anterior | K13: Nº de dias tarifa Anterior | L13: Nº de dias tarifa Nova | M13: Leitura Atual
B14: 46237 | C14: =IF((F2-B14-1)<0,0,(F2-B14-1)) -> 3 | D14: =E14-F2+1 -> 27 | E14: 46267 | J14: =B14 -> 46237 | K14: =IF((M10-J14-1)<0,0,(M10-J14-1)) -> 28 | L14: =M14-M10+1 -> 2 | M14: =E14 -> 46267
B17: Perc. de Redução da Energia Injetada | E17: TUSD | F17: 1 | G17: TE | H17: 1 | M17: Documento Impressão | O17: 1025311205
B19: Descrição | C19: Unidade | D19: Quantidade | E19: Preço Unit (R$) com tributos | F19: Valor Total (R$) | G19: PIS/COFINS (R$) | H19: Base de Cálculo ICMS (R$) | I19: Alíquota ICMS (%) | J19: ICMS (R$) | K19: Preço Unit (R$) | L19: Tributos | M19: Base de Cálc (R$) | N19: Alíquota (%) | O19: Valor (R$)
R20: TUSD Fio B | S20: Receita Fio B
B21: TUSD - Consumo | C21: kWh | D21: 2282 | E21: =(ROUND(D21*K21,2)+ROUND(G21,2)+ROUND(J21,2))/ROUND(D21,4) -> 0.64529798 | F21: =ROUND(D21*E21,2) -> 1472.57 | G21: =((D21*K21)/(1-$N$21-$N$23))*($N$21+$N$23) -> 75.411786 | H21: =((D21*K21)/(1-$N$21-$N$23)/(1-$I$21)) -> 1472.5701 | I21: 0.17 | J21: =(H21*$I$21) -> 250.33691 | K21: =IF(AND($B$14<$F$2,$E$14<$F$2),C6,IF($B$14<$F$2,I6,F6)) -> 0.502551 | L21: PIS | M21: =D70 -> 2084.5678 | N21: 0.011 | O21: =ROUND(M21*N21,2) -> 22.93 | R21: =IF(AND($B$14<$F$2,$E$14<$F$2),R6,IF($B$14<$F$2,X6,U6)) -> 0.20861951 | S21: =D21*R21 -> 476.06971 | T21: não está considerando energia injetada
B22: TE - Consumo | C22: kWh | D22: =D21 -> 2282 | E22: =(ROUND(D22*K22,2)+ROUND(G22,2)+ROUND(J22,2))/ROUND(D22,4) -> 0.431078 | F22: =ROUND(D22*E22,2) -> 983.72 | G22: =((D22*K22)/(1-$N$21-$N$23))*($N$21+$N$23) -> 50.377314 | H22: =ROUND((D22*K22)/(1-$N$21-$N$23)/(1-$I$21),8) -> 983.72057 | J22: =ROUND(H22*$I$21,2) -> 167.23 | K22: =IF(AND($B$14<$F$2,$E$14<$F$2),D6,IF($B$14<$F$2,J6,G6)) -> 0.335719 | L22: PIS Inj | M22: =D71 -> -357.17787 | N22: =N21 -> 0.011 | O22: =ROUND(M22*N22,2) -> -3.93
B23: Adicional BAM | C23: kWh | D23: =IF($K$12=M4,($D$21*($K$14)/($K$14+$L$14)),0)+IF($L$12=M4,($D$21*($L$14)/($K$14+$L$14)),0) -> 2282 | E23: =IFERROR((ROUND(D23*K23,2)+ROUND(G23,2)+ROUND(J23,2))/ROUND(D23,4), 0) -> 0.024206836 | F23: =ROUND(D23*E23,2) -> 55.24 | G23: =((D23*K23)/(1-$N$21-$N$23))*($N$21+$N$23) -> 2.8285929 | H23: =ROUND((D23*K23)/(1-$N$21-$N$23)/(1-$I$21),8) -> 55.234088 | J23: =ROUND(H23*$I$21,2) -> 9.39 | K23: =N4 -> 0.01885 | L23: COFINS | M23: =M21 -> 2084.5678 | N23: 0.0507 | O23: =ROUND(M23*N23,2) -> 105.69
B24: Adicional BVM1 | C24: kWh | D24: =IF($K$12=M5,($D$21*($K$14)/($K$14+$L$14)),0)+IF($L$12=M5,($D$21*($L$14)/($K$14+$L$14)),0) -> 0 | E24: =IFERROR((ROUND(D24*K24,2)+ROUND(G24,2)+ROUND(J24,2))/ROUND(D24,4), 0) -> 0 | F24: =ROUND(D24*E24,2) -> 0 | G24: =((D24*K24)/(1-$N$21-$N$23))*($N$21+$N$23) -> 0 | H24: =ROUND((D24*K24)/(1-$N$21-$N$23)/(1-$I$21),8) -> 0 | J24: =ROUND(H24*$I$21,2) -> 0 | K24: =N5 -> 0.04463 | L24: COFINS Inj | M24: =M22 -> -357.17787 | N24: =N23 -> 0.0507 | O24: =ROUND(M24*N24,2) -> -18.11
B25: Adicional BVM2 | C25: kWh | D25: =IF($K$12=M6,($D$21*($K$14)/($K$14+$L$14)),0)+IF($L$12=M6,($D$21*($L$14)/($K$14+$L$14)),0) -> 0 | E25: =IFERROR((ROUND(D25*K25,2)+ROUND(G25,2)+ROUND(J25,2))/ROUND(D25,4), 0) -> 0 | F25: =ROUND(D25*E25,2) -> 0 | G25: =((D25*K25)/(1-$N$21-$N$23))*($N$21+$N$23) -> 0 | H25: =ROUND((D25*K25)/(1-$N$21-$N$23)/(1-$I$21),8) -> 0 | J25: =ROUND(H25*$I$21,2) -> 0 | K25: =N6 -> 0.07877
B26: Adicional EH | C26: kWh | D26: =IF($K$12=M7,($D$21*($K$14)/($K$14+$L$14)),0)+IF($L$12=M7,($D$21*($L$14)/($K$14+$L$14)),0) -> 0 | E26: =IFERROR((ROUND(D26*K26,2)+ROUND(G26,2)+ROUND(J26,2))/ROUND(D26,4), 0) -> 0 | F26: =ROUND(D26*E26,2) -> 0 | G26: =((D26*K26)/(1-$N$21-$N$23))*($N$21+$N$23) -> 0 | H26: =ROUND((D26*K26)/(1-$N$21-$N$23)/(1-$I$21),8) -> 0 | J26: =ROUND(H26*$I$21,2) -> 0 | K26: =N7 -> 0.142
B28: TUSD - Consumo inj | C28: kWh | D28: -391 | E28: =IFERROR((ROUND(D28*K28,2)+ROUND(G28,2)+ROUND(J28,2))/ROUND(D28,4),0) -> 0.53560102 | F28: =ROUND(D28*E28,2) -> -209.42 | G28: =((D28*K28)/(1-$N$22-$N$24))*($N$22+$N$24) -> -12.921126 | H28: 0 | I28: 0.12 | J28: =H28*$I$21 -> 0 | K28: =K21 -> 0.502551
B29: TE - Consumo inj | C29: kWh | D29: =D28 -> -391 | E29: =IFERROR((ROUND(D29*K29,2)+ROUND(G29,2)+ROUND(J29,2))/ROUND(D29,4),0) -> 0.43107417 | F29: =ROUND(D29*E29,2) -> -168.55 | G29: =((D29*K29)/(1-$N$22-$N$24))*($N$22+$N$24) -> -8.6316958 | H29: =ROUND((D29*K29)/(1-$N$22-$N$24)/(1-$I$21),8) -> -168.5516 | I29: =I21 -> 0.17 | J29: =H29*$I$21 -> -28.653771 | K29: =K22 -> 0.335719
B30: Adicional BAM inj | C30: kWh | D30: =IF($K$12=M4,($D$28*($K$14)/($K$14+$L$14)),0)+IF($L$12=M4,($D$28*($L$14)/($K$14+$L$14)),0) -> -391 | E30: =IFERROR((ROUND(D30*K30,2)+ROUND(G30,2)+ROUND(J30,2))/ROUND(D30,4),0) -> 0.024194373 | F30: =ROUND(D30*E30,2) -> -9.46 | G30: =((D30*K30)/(1-$N$22-$N$24))*($N$22+$N$24) -> -0.48465373 | H30: =(D30*K30)/(1-$N$22-$N$24)/(1-$I$21) -> -9.4638599 | J30: =H30*$I$21 -> -1.6088562 | K30: =N4 -> 0.01885
B31: Adicional BVM1 inj | C31: kWh | D31: =IF($K$12=M5,($D$28*($K$14)/($K$14+$L$14)),0)+IF($L$12=M5,($D$28*($L$14)/($K$14+$L$14)),0) -> 0 | E31: =IFERROR((ROUND(D31*K31,2)+ROUND(G31,2)+ROUND(J31,2))/ROUND(D31,4),0) -> 0 | F31: =ROUND(D31*E31,2) -> 0 | G31: =((D31*K31)/(1-$N$22-$N$24))*($N$22+$N$24) -> 0 | H31: =(D31*K31)/(1-$N$22-$N$24)/(1-$I$21) -> 0 | J31: =H31*$I$21 -> 0 | K31: =N5 -> 0.04463
B32: Adicional BVM2 inj | C32: kWh | D32: =IF($K$12=M6,($D$28*($K$14)/($K$14+$L$14)),0)+IF($L$12=M6,($D$28*($L$14)/($K$14+$L$14)),0) -> 0 | E32: =IFERROR((ROUND(D32*K32,2)+ROUND(G32,2)+ROUND(J32,2))/ROUND(D32,4),0) -> 0 | F32: =ROUND(D32*E32,2) -> 0 | G32: =((D32*K32)/(1-$N$22-$N$24))*($N$22+$N$24) -> 0 | H32: =(D32*K32)/(1-$N$22-$N$24)/(1-$I$21) -> 0 | J32: =H32*$I$21 -> 0 | K32: =N6 -> 0.07877
B33: Adicional EH inj | C33: kWh | D33: =IF($K$12=M7,($D$28*($K$14)/($K$14+$L$14)),0)+IF($L$12=M7,($D$28*($L$14)/($K$14+$L$14)),0) -> 0 | E33: =IFERROR((ROUND(D33*K33,2)+ROUND(G33,2)+ROUND(J33,2))/ROUND(D33,4),0) -> 0 | F33: =ROUND(D33*E33,2) -> 0 | G33: =((D33*K33)/(1-$N$22-$N$24))*($N$22+$N$24) -> 0 | H33: =(D33*K33)/(1-$N$22-$N$24)/(1-$I$21) -> 0 | J33: =H33*$I$21 -> 0 | K33: =N7 -> 0.142
B35: Multas
B36: Juros
B37: Doações
B38: CIP | F38: 61.73
B41: TOTAL | F41: =SUM(F21:F40) -> 2185.83 | G41: =SUM(G21:G40) -> 106.58022 | H41: =SUM(H21:H40) -> 2333.5093 | J41: =SUM(J21:J40) -> 396.69429
B43: Informativo Escassez Hídrica | D43: 50 | E43: 0.00018418923 | F43: -0.00053182975 | H43: -0.017382026
B45: Fatura B1 Residencial
D46: Qtde | E46: TUSD | F46: TE | G46: TUSD + TE | H46: R$
B47: Fornecimento de Energia Elétrica | H47: =SUM(H49:H65)+SUM(H70:H75) -> 2124.0871
B49: Energia Fornecida | D49: =D21 -> 2282 | E49: =IF(AND($B$14<$F$2,$E$14<$F$2),C6,IF($B$14<$F$2,I6,F6)) -> 0.502551 | F49: =IF(AND($B$14<$F$2,$E$14<$F$2),D6,IF($B$14<$F$2,J6,G6)) -> 0.335719 | G49: =E49+F49 -> 0.83827 | H49: =ROUND((D49*E49),2)+ROUND((D49*F49),2) -> 1912.93
B51: Adicional BAM | D51: =IF($K$12=M4,(D49*(K14)/(K14+L14)),0)+IF($L$12=M4,(D49*(L14)/(K14+L14)),0) -> 2282 | F51: =N4 -> 0.01885 | H51: =ROUND(D51*(E51+F51),2) -> 43.02
B52: Adicional BVM 1 | D52: =IF($K$12=M5,(D49*(K14)/(K14+L14)),0)+IF($L$12=M5,(D49*(L14)/(K14+L14)),0) -> 0 | F52: =N5 -> 0.04463 | H52: =ROUND(D52*(E52+F52),2) -> 0
...

Sheet Fatura B2 (GD) OK
B2: B2 | E2: Vigência das Tarifas: | F2: ='Fatura B1 (GD) OK'!F2 -> 46241 | M2: Bandeira | N2: R$/kWh | O2: ANEEL em 29/06 | Q2: TUSD FIO B
M3: VERDE | N3: 0
B4: TARIFA | C4: ='Fatura B1 (GD) OK'!C4:E4 -> TARIFA ANTIGA - REH 3508/2025 | F4: ='Fatura B1 (GD) OK'!F4 -> TARIFA NOVA - REH xxxx/2026 | I4: Tarifas Proporcionalizadas | M4: BAM | N4: ='[3]Fatura B1 (Res) OK'!$N$4 -> 0.01885 | Q4: TARIFA | R4: =C4 -> TARIFA ANTIGA - REH 3508/2025 | U4: =F4 -> TARIFA NOVA - REH xxxx/2026 | X4: Tarifas Proporcionalizadas
C5: Tusd | D5: TE | E5: TUSD + TE | F5: Tusd | G5: TE | H5: TUSD + TE | I5: Tusd | J5: TE | K5: TUSD + TE | M5: BVM1 | N5: ='[3]Fatura B1 (Res) OK'!$N$5 -> 0.04463 | R5: Tusd (R$/kWh) | U5: Tusd (R$/kWh) | X5: Tusd (R$/kWh)
B6: B2 | C6: ='TABELA DE TARIFAS ANTIGAS'!G77/1000 -> 0.46863 | D6: ='TABELA DE TARIFAS ANTIGAS'!H77/1000 -> 0.32068 | E6: =C6+D6 -> 0.78931 | F6: ='TABELA DE TARIFAS NOVAS'!G79/1000 -> 0.50632 | G6: ='TABELA DE TARIFAS NOVAS'!H79/1000 -> 0.33739 | H6: =F6+G6 -> 0.84371 | I6: =((C6*$C$14)+(F6*$D$14))/($D$14+$C$14) -> 0.48621867 | J6: =((D6*$C$14)+(G6*$D$14))/($D$14+$C$14) -> 0.328478 | K6: =I6+J6 -> 0.81469667 | M6: BVM2 | N6: ='[3]Fatura B1 (Res) OK'!$N$6 -> 0.07877 | Q6: =B6 -> B2 | R6: ='FIO B'!H20/1000 -> 0.20383072 | U6: ='FIO B'!K20/1000 -> 0.20915159 | X6: =((R6*$C$14)+(U6*$D$14))/($D$14+$C$14) -> 0.20631379
B7: CDE Escassez Hídrica | C7: 0.00018774721 | D7: -0.0044031307 | E7: 0.0036054084 | F7: =T11 -> 0.00018418923 | G7: =U11 -> -0.00053182975 | H7: =F7+G7 -> -0.00034764052 | I7: =((C7*$C$14)+(F7*$D$14))/($D$14+$C$14) -> 0.00018608682 | J7: =((D7*$C$14)+(G7*$D$14))/($D$14+$C$14) -> -0.0025965236 | K7: =I7+J7 -> -0.0024104368 | M7: Escassez Hídrica | N7: 0.142
B8: TE SCEE | G8: =G6*15% -> 0.0506085 | J8: =((D8*$C$14)+(G8*$D$14))/($D$14+$C$14) -> 0.0236173 | P8: CUSTO | R8: Part. TUSD (%) | S8: Part. TE (%) | T8: Tusd (R$/kWh) | U8: TE (R$/kWh)
P9: CDE CONTAS
H10: Fatura | L10: Vigência das Tarifas (troca Bandeira): | M10: =EOMONTH(B14,0)+1 -> 46235 | P10: CDE COVID | U10: 0
B11: INSTALAÇÃO | C11: 1321770 | H11: =E14 -> 46254 | K11: Altere a bandeira na célula abaixo | P11: CDE ESCASSEZ HÍDRICA | T11: ='Fatura B1 (GD) OK'!T11 -> 0.00018418923 | U11: ='Fatura B1 (GD) OK'!U11 -> -0.00053182975
K12: ='Fatura B1 (GD) OK'!K12 -> BAM | L12: ='Fatura B1 (GD) OK'!L12 -> BAM
B13: Leitura Anterior | C13: Nº de dias tarifa Anterior | D13: Nº de dias tarifa Nova | E13: Leitura Atual | J13: Leitura Anterior | K13: Nº de dias tarifa Anterior | L13: Nº de dias tarifa Nova | M13: Leitura Atual
B14: 46224 | C14: =IF((F2-B14-1)<0,0,(F2-B14-1)) -> 16 | D14: =E14-F2+1 -> 14 | E14: 46254 | J14: =B14 -> 46224 | K14: =IF((M10-J14-1)<0,0,(M10-J14-1)) -> 10 | L14: =M14-M10+1 -> 20 | M14: =E14 -> 46254
B17: Perc. de Redução da Energia Injetada | E17: TUSD | F17: 1 | G17: TE | H17: 1 | M17: Documento Impressão | O17: 1025311193
B19: Descrição | C19: Unidade | D19: Quantidade | E19: Preço Unit (R$) com tributos | F19: Valor Total (R$) | G19: PIS/COFINS (R$) | H19: Base de Cálculo ICMS (R$) | I19: Alíquota ICMS (%) | J19: ICMS (R$) | K19: Preço Unit (R$) | L19: Tributos | M19: Base de Cálc (R$) | N19: Alíquota (%) | O19: Valor (R$)
R20: TUSD Fio B | S20: Receita Fio B
B21: TUSD - Consumo | C21: kWh | D21: 715 | E21: =(ROUND(D21*K21,2)+ROUND(G21,2)+ROUND(J21,2))/ROUND(D21,4) -> 0.62433566 | F21: =ROUND(D21*E21,2) -> 446.4 | G21: =((D21*K21)/(1-$N$21-$N$23))*($N$21+$N$23) -> 22.860257 | H21: =(IF($I$21=12%,(D21*K21)/(1-$N$21-$N$23)/(1-$C$50)/$F$50*$C$50,(D21*K21)/(1-$N$21-$N$23)/(1-$I$21))) -> 446.3935 | I21: 0.17 | J21: =(H21*$I$21) -> 75.886895 | K21: =IF(AND($B$14<$F$2,$E$14<$F$2),C6,IF($B$14<$F$2,I6,F6)) -> 0.48621867 | L21: PIS | M21: =D82 -> 635.18065 | N21: ='Fatura B1 (GD) OK'!N21 -> 0.011 | O21: =ROUND(M21*N21,2) -> 6.99 | R21: =IF(AND($B$14<$F$2,$E$14<$F$2),R6,IF($B$14<$F$2,X6,U6)) -> 0.20631379 | S21: =D21*R21 -> 147.51436 | T21: não está considerando energia injetada
B22: TE - Consumo | C22: kWh | D22: =D21 -> 715 | E22: =(ROUND(D22*K22,2)+ROUND(G22,2)+ROUND(J22,2))/ROUND(D22,4) -> 0.42177622 | F22: =ROUND(D22*E22,2) -> 301.57 | G22: =((D22*K22)/(1-$N$21-$N$23))*($N$21+$N$23) -> 15.443857 | H22: =(IF($I$21=12%,(D22*K22)/(1-$N$21-$N$23)/(1-$C$50)/$F$50*$C$50,(D22*K22)/(1-$N$21-$N$23)/(1-$I$21))) -> 301.57304 | J22: =ROUND(H22*$I$21,2) -> 51.27 | K22: =IF(AND($B$14<$F$2,$E$14<$F$2),D6,IF($B$14<$F$2,J6,G6)) -> 0.328478 | L22: PIS Inj | M22: =D83 -> -162.57061 | N22: =N21 -> 0.011 | O22: =ROUND(M22*N22,2) -> -1.79
B23: Adicional BAM | C23: kWh | D23: =IF($K$12=M4,($D$21*($K$14)/($K$14+$L$14)),0)+IF($L$12=M4,($D$21*($L$14)/($K$14+$L$14)),0) -> 715 | E23: =IFERROR((ROUND(D23*K23,2)+ROUND(G23,2)+ROUND(J23,2))/ROUND(D23,4), 0) -> 0.02420979 | F23: =ROUND(D23*E23,2) -> 17.31 | G23: =((D23*K23)/(1-$N$21-$N$23))*($N$21+$N$23) -> 0.88625938 | H23: =(IF($I$21=12%,(D23*K23)/(1-$N$21-$N$23)/(1-$C$50)/$F$50*$C$50,(D23*K23)/(1-$N$21-$N$23)/(1-$I$21))) -> 17.306035 | J23: =ROUND(H23*$I$21,2) -> 2.94 | K23: =N4 -> 0.01885 | L23: COFINS | M23: =M21 -> 635.18065 | N23: ='Fatura B1 (GD) OK'!N23 -> 0.0507 | O23: =ROUND(M23*N23,2) -> 32.2
B24: Adicional BVM1 | C24: kWh | D24: =IF($K$12=M5,($D$21*($K$14)/($K$14+$L$14)),0)+IF($L$12=M5,($D$21*($L$14)/($K$14+$L$14)),0) -> 0 | E24: =IFERROR((ROUND(D24*K24,2)+ROUND(G24,2)+ROUND(J24,2))/ROUND(D24,4), 0) -> 0 | F24: =ROUND(D24*E24,2) -> 0 | G24: =((D24*K24)/(1-$N$21-$N$23))*($N$21+$N$23) -> 0 | H24: =(IF($I$21=12%,(D24*K24)/(1-$N$21-$N$23)/(1-$C$50)/$F$50*$C$50,(D24*K24)/(1-$N$21-$N$23)/(1-$I$21))) -> 0 | J24: =ROUND(H24*$I$21,2) -> 0 | K24: =N5 -> 0.04463 | L24: COFINS Inj | M24: =M22 -> -162.57061 | N24: =N23 -> 0.0507 | O24: =ROUND(M24*N24,2) -> -8.24
B25: Adicional BVM2 | C25: kWh | D25: =IF($K$12=M6,($D$21*($K$14)/($K$14+$L$14)),0)+IF($L$12=M6,($D$21*($L$14)/($K$14+$L$14)),0) -> 0 | E25: =IFERROR((ROUND(D25*K25,2)+ROUND(G25,2)+ROUND(J25,2))/ROUND(D25,4), 0) -> 0 | F25: =ROUND(D25*E25,2) -> 0 | G25: =((D25*K25)/(1-$N$21-$N$23))*($N$21+$N$23) -> 0 | H25: =(IF($I$21=12%,(D25*K25)/(1-$N$21-$N$23)/(1-$C$50)/$F$50*$C$50,(D25*K25)/(1-$N$21-$N$23)/(1-$I$21))) -> 0 | J25: =ROUND(H25*$I$21,2) -> 0 | K25: =N6 -> 0.07877
B26: Adicional EH | C26: kWh | D26: =IF($K$12=M7,($D$21*($K$14)/($K$14+$L$14)),0)+IF($L$12=M7,($D$21*($L$14)/($K$14+$L$14)),0) -> 0 | E26: =IFERROR((ROUND(D26*K26,2)+ROUND(G26,2)+ROUND(J26,2))/ROUND(D26,4), 0) -> 0 | F26: =ROUND(D26*E26,2) -> 0 | G26: =((D26*K26)/(1-$N$21-$N$23))*($N$21+$N$23) -> 0 | H26: =(IF($I$21=12%,(D26*K26)/(1-$N$21-$N$23)/(1-$C$50)/$F$50*$C$50,(D26*K26)/(1-$N$21-$N$23)/(1-$I$21))) -> 0 | J26: =ROUND(H26*$I$21,2) -> 0 | K26: =N7 -> 0.142
B28: TUSD - Consumo inj | C28: kWh | D28: -183 | E28: =IFERROR((ROUND(D28*K28,2)+ROUND(G28,2)+ROUND(J28,2))/ROUND(D28,4), 0) -> 0.51819672 | F28: =ROUND(D28*E28,2) -> -94.83 | G28: =((D28*K28)/(1-$N$22-$N$24))*($N$22+$N$24) -> -5.850947 | H28: 0 | I28: 0 | J28: =H28*$I$21 -> 0 | K28: =K21 -> 0.48621867
B29: TE - Consumo inj | C29: kWh | D29: =D28 -> -183 | E29: =IFERROR((ROUND(D29*K29,2)+ROUND(G29,2)+ROUND(J29,2))/ROUND(D29,4), 0) -> 0.42174863 | F29: =ROUND(D29*E29,2) -> -77.18 | G29: =((D29*K29)/(1-$N$22-$N$24))*($N$22+$N$24) -> -3.9527635 | H29: =(IF($I$29=12%,(D29*K29)/(1-$N$22-$N$24)/(1-$C$50)/$F$50*$C$50,(D29*K29)/(1-$N$22-$N$24)/(1-$I$29))) -> -77.185828 | I29: =I21 -> 0.17 | J29: =H29*$I$21 -> -13.121591 | K29: =K22 -> 0.328478
B30: Adicional BAM Inj | C30: kWh | D30: =IF($K$12=M4,($D$28*($K$14)/($K$14+$L$14)),0)+IF($L$12=M4,($D$28*($L$14)/($K$14+$L$14)),0) -> -183 | E30: =IFERROR((ROUND(D30*K30,2)+ROUND(G30,2)+ROUND(J30,2))/ROUND(D30,4), 0) -> 0.02420765 | F30: =ROUND(D30*E30,2) -> -4.43 | G30: =((D30*K30)/(1-$N$22-$N$24))*($N$22+$N$24) -> -0.22683282 | H30: =(IF($I$29=12%,(D30*K30)/(1-$N$22-$N$24)/(1-$C$50)/$F$50*$C$50,(D30*K30)/(1-$N$22-$N$24)/(1-$I$29))) -> -4.4293769 | J30: =H30*$I$21 -> -0.75299407 | K30: =N4 -> 0.01885
B31: Adicional BVM1 Inj | C31: kWh | D31: =IF($K$12=M5,($D$28*($K$14)/($K$14+$L$14)),0)+IF($L$12=M5,($D$28*($L$14)/($K$14+$L$14)),0) -> 0 | E31: =IFERROR((ROUND(D31*K31,2)+ROUND(G31,2)+ROUND(J31,2))/ROUND(D31,4), 0) -> 0 | F31: =ROUND(D31*E31,2) -> 0 | G31: =((D31*K31)/(1-$N$22-$N$24))*($N$22+$N$24) -> 0 | H31: =(IF($I$29=12%,(D31*K31)/(1-$N$22-$N$24)/(1-$C$50)/$F$50*$C$50,(D31*K31)/(1-$N$22-$N$24)/(1-$I$29))) -> 0 | J31: =H31*$I$21 -> 0 | K31: =N5 -> 0.04463
B32: Adicional BVM2 Inj | C32: kWh | D32: =IF($K$12=M6,($D$28*($K$14)/($K$14+$L$14)),0)+IF($L$12=M6,($D$28*($L$14)/($K$14+$L$14)),0) -> 0 | E32: =IFERROR((ROUND(D32*K32,2)+ROUND(G32,2)+ROUND(J32,2))/ROUND(D32,4), 0) -> 0 | F32: =ROUND(D32*E32,2) -> 0 | G32: =((D32*K32)/(1-$N$22-$N$24))*($N$22+$N$24) -> 0 | H32: =(IF($I$29=12%,(D32*K32)/(1-$N$22-$N$24)/(1-$C$50)/$F$50*$C$50,(D32*K32)/(1-$N$22-$N$24)/(1-$I$29))) -> 0 | J32: =H32*$I$21 -> 0 | K32: =N6 -> 0.07877
B33: Adicional EH Inj | C33: kWh | D33: =IF($K$12=M7,($D$28*($K$14)/($K$14+$L$14)),0)+IF($L$12=M7,($D$28*($L$14)/($K$14+$L$14)),0) -> 0 | E33: =IFERROR((ROUND(D33*K33,2)+ROUND(G33,2)+ROUND(J33,2))/ROUND(D33,4), 0) -> 0 | F33: =ROUND(D33*E33,2) -> 0 | G33: =((D33*K33)/(1-$N$22-$N$24))*($N$22+$N$24) -> 0 | H33: =(IF($I$29=12%,(D33*K33)/(1-$N$22-$N$24)/(1-$C$50)/$F$50*$C$50,(D33*K33)/(1-$N$22-$N$24)/(1-$I$29))) -> 0 | J33: =H33*$I$21 -> 0 | K33: =N7 -> 0.142
B35: Juros
B36: Multas
B37: Doações | F37: -6.69
B38: CIP
B42: TOTAL | F42: =SUM(F21:F41) -> 582.15 | G42: =SUM(G21:G41) -> 29.159831 | H42: =SUM(H21:H41) -> 683.65737 | J42: =SUM(J21:J41) -> 116.22231
B44: Informativo Escassez | C44: =D21+D28 -> 532 | D44: =IF(AND($B$14<$F$2,$E$14<$F$2),C7,IF($B$14<$F$2,I7,F7)) -> 0.00018608682 | E44: =IF(AND($B$14<$F$2,$E$14<$F$2),D7,IF($B$14<$F$2,J7,G7)) -> -0.0025965236 | F44: =C44*(D44+E44) -> -1.2823524
B46: Se for base reduzida: (célula I18 = 12%)
D47: Com tributos
B48: PIS | C48: =N21 -> 0.011 | D48: =((D21*K21)+(D22*K22)+(D23*K23)+(D24*K24)+(D25*K25)+(D26*K26))/(1-$N$21-$N$23) -> 635.17624 | E48: x | F48: =C48 -> 0.011 | G48: =D48*F48 -> 6.9869386
B49: COFINS | C49: =N23 -> 0.0507 | D49: =D48 -> 635.17624 | E49: x | F49: =C49 -> 0.0507 | G49: =D49*F49 -> 32.203435
A50: Rural c/ incrição | B50: ICMS | C50: 0.04 | D50: =H50/F50*C50 -> 220.54731 | E50: x | F50: 0.12 | G50: =D50*F50 -> 26.465677 | H50: =((D21*K21)+(D22*K22)+(D23*K23)+(D24*K24)+(D25*K25)+(D26*K26))/(1-F48-F49)/(1-(C50)) -> 661.64192
E51: =(O40)/(1-C48-C49-C50) -> 0
...

Sheet Fatura B2 IRRIG (GD) OK
B2: B2 | E2: Vigência das Tarifas: | F2: ='Fatura B1 (GD) OK'!F2 -> 46241 | M2: Bandeira | N2: R$/kWh | O2: ANEEL em 29/06 | Q2: TUSD FIO B
M3: VERDE | N3: 0
B4: TARIFA | C4: ='Fatura B1 (GD) OK'!C4:E4 -> TARIFA ANTIGA - REH 3508/2025 | F4: ='Fatura B1 (GD) OK'!F4 -> TARIFA NOVA - REH xxxx/2026 | I4: Tarifas Proporcionalizadas | M4: BAM | N4: 0.01885 | Q4: TARIFA | R4: =C4 -> TARIFA ANTIGA - REH 3508/2025 | U4: =F4 -> TARIFA NOVA - REH xxxx/2026 | X4: Tarifas Proporcionalizadas
C5: Tusd | D5: TE | E5: TUSD + TE | F5: Tusd | G5: TE | H5: TUSD + TE | I5: Tusd | J5: TE | K5: TUSD + TE | M5: BVM1 | N5: 0.04463 | R5: Tusd (R$/kWh) | U5: Tusd (R$/kWh) | X5: Tusd (R$/kWh)
B6: B2 | C6: ='TABELA DE TARIFAS ANTIGAS'!G77/1000 -> 0.46863 | D6: ='TABELA DE TARIFAS ANTIGAS'!H77/1000 -> 0.32068 | E6: =C6+D6 -> 0.78931 | F6: ='TABELA DE TARIFAS NOVAS'!G79/1000 -> 0.50632 | G6: ='TABELA DE TARIFAS NOVAS'!H79/1000 -> 0.33739 | H6: =F6+G6 -> 0.84371 | I6: =((C6*$C$14)+(F6*$D$14))/($D$14+$C$14) -> 0.50380733 | J6: =((D6*$C$14)+(G6*$D$14))/($D$14+$C$14) -> 0.336276 | K6: =I6+J6 -> 0.84008333 | M6: BVM2 | N6: 0.07877 | Q6: =B6 -> B2 | R6: ='FIO B'!H30/1000 -> 0.20383072 | U6: ='FIO B'!K30/1000 -> 0.20915159 | X6: =((R6*$C$14)+(U6*$D$14))/($D$14+$C$14) -> 0.20879687
B7: CDE Escassez Hídrica | C7: 0.00018774721 | D7: -0.0044031307 | E7: 0.0036054084 | F7: =T11 -> 0.00018418923 | G7: =U11 -> -0.00053182975 | H7: =F7+G7 -> -0.00034764052 | I7: =((C7*$C$14)+(F7*$D$14))/($D$14+$C$14) -> 0.00018442643 | J7: =((D7*$C$14)+(G7*$D$14))/($D$14+$C$14) -> -0.00078991648 | K7: =I7+J7 -> -0.00060549005
B8: TE SCEE | G8: =G6*15% -> 0.0506085 | J8: =((D8*$C$14)+(G8*$D$14))/($D$14+$C$14) -> 0.0472346 | M8: Escassez Hídrica | N8: 0.142 | P8: CUSTO | R8: Part. TUSD (%) | S8: Part. TE (%) | T8: Tusd (R$/kWh) | U8: TE (R$/kWh)
P9: CDE CONTAS
H10: Fatura | L10: Vigência das Tarifas (troca Bandeira): | M10: =EOMONTH(B14,0)+1 -> 46266 | P10: CDE COVID | U10: 0
B11: INSTALAÇÃO | C11: 160489097 | H11: =E14 -> 46268 | K11: Altere a bandeira na célula abaixo | P11: CDE ESCASSEZ HÍDRICA | T11: ='Fatura B1 (GD) OK'!T11 -> 0.00018418923 | U11: ='Fatura B1 (GD) OK'!U11 -> -0.00053182975
K12: BAM | L12: BAM
B13: Leitura Anterior | C13: Nº de dias tarifa Anterior | D13: Nº de dias tarifa Nova | E13: Leitura Atual | J13: Leitura Anterior | K13: Nº de dias tarifa Anterior | L13: Nº de dias tarifa Nova | M13: Leitura Atual
B14: 46238 | C14: =IF((F2-B14-1)<0,0,(F2-B14-1)) -> 2 | D14: =E14-F2+1 -> 28 | E14: 46268 | J14: =B14 -> 46238 | K14: =IF((M10-J14-1)<0,0,(M10-J14-1)) -> 27 | L14: =M14-M10+1 -> 3 | M14: =E14 -> 46268
B17: Perc. de Redução da Energia Injetada | E17: TUSD | F17: 1 | G17: TE | H17: 1 | M17: Documento Impressão | O17: 1025311195
R18: ERRO EM PRD QUANDO O CONSUMO É ABAIXO DO MÍNIMO NA UTILIZAÇÃO DA INJETADA
B19: Descrição | C19: Unidade | D19: Quantidade | E19: Preço Unit (R$) com tributos | F19: Valor Total (R$) | G19: PIS/COFINS (R$) | H19: Base de Cálculo ICMS (R$) | I19: Alíquota ICMS (%) | J19: ICMS (R$) | K19: Preço Unit (R$) | L19: Tributos | M19: Base de Cálc (R$) | N19: Alíquota (%) | O19: Valor (R$)
R20: TUSD Fio B | S20: Receita Fio B | T20: não está considerando energia injetada
B21: TUSD - Ativo | C21: kWh | D21: 1036 | E21: =IFERROR((ROUND(D21*K21,2)+ROUND(G21,2)+ROUND(J21,2))/ROUND(D21,4), 0) -> 0.55930502 | F21: =ROUND(D21*E21,2) -> 579.44 | G21: =((D21*K21)/(1-$N$21-$N$23))*($N$21+$N$23) -> 34.321613 | H21: =(IF($I$21=12%,(D21*K21)/(1-$N$21-$N$23)/(1-$C$122)/$F$122*$C$122,(D21*K21)/(1-$N$21-$N$23)/(1-$I$21))) -> 579.44376 | I21: 0.04 | J21: =(H21*$I$21) -> 23.17775 | K21: =IF(AND($B$14<$F$2,$E$14<$F$2),C6,IF($B$14<$F$2,I6,F6)) -> 0.50380733 | L21: PIS | M21: =D109 -> 948.36406 | N21: ='Fatura B1 (GD) OK'!N21 -> 0.011 | O21: =ROUND(M21*N21,2) -> 10.43 | R21: =IF(AND($B$14<$F$2,$E$14<$F$2),R6,IF($B$14<$F$2,X6,U6)) -> 0.20879687 | S21: =D21*R21 -> 216.31355 | T21: =SUM(S21:S23) -> 216.31355
B22: TUSD - Consumo Reservado | C22: kWh | D22: 0 | E22: =IFERROR((ROUND(D22*K22,2)+ROUND(G22,2)+ROUND(J22,2))/ROUND(D22,4), 0) -> 0 | F22: =ROUND(D22*E22,2) -> 0 | G22: =((D22*K22)/(1-$N$21-$N$23))*($N$21+$N$23) -> 0 | H22: =(IF($I$21=12%,(D22*K22)/(1-$N$21-$N$23)/(1-$C$122)/$F$122*$C$122,(D22*K22)/(1-$N$21-$N$23)/(1-$I$21))) -> 0 | I22: =I21 -> 0.04 | J22: =(H22*$I$21) -> 0 | K22: =(K21+(K21*(-$H$55))) -> 0.20152293 | L22: PIS Inj | M22: =D110 -> -920.8995 | N22: =N21 -> 0.011 | O22: =ROUND(M22*N22,2) -> -10.13 | R22: =IF(AND($B$14<$F$2,$E$14<$F$2),R6,IF($B$14<$F$2,X6,U6)) -> 0.20879687 | S22: =D22*R22 -> 0
B23: TE - Consumo | C23: kWh | D23: =D21 -> 1036 | E23: =IFERROR((ROUND(D23*K23,2)+ROUND(G23,2)+ROUND(J23,2))/ROUND(D23,4), 0) -> 0.37332046 | F23: =ROUND(D23*E23,2) -> 386.76 | G23: =((D23*K23)/(1-$N$21-$N$23))*($N$21+$N$23) -> 22.908628 | H23: =(IF($I$21=12%,(D23*K23)/(1-$N$21-$N$23)/(1-$C$122)/$F$122*$C$122,(D23*K23)/(1-$N$21-$N$23)/(1-$I$21))) -> 386.761 | J23: =ROUND(H23*$I$21,2) -> 15.47 | K23: =IF(AND($B$14<$F$2,$E$14<$F$2),D6,IF($B$14<$F$2,J6,G6)) -> 0.336276 | L23: COFINS | M23: =M21 -> 948.36406 | N23: ='Fatura B1 (GD) OK'!N23 -> 0.0507 | O23: =ROUND(M23*N23,2) -> 48.08 | S23: =-S22*$H$55 -> 0 | T23: NÃO ESTÁ CONSIDERANDO O DESCONTO DO RESERVADO DA CONSUMIDA
B24: TE - Consumo Reservado | C24: kWh | D24: =D22 -> 0 | E24: =IFERROR((ROUND(D24*K24,2)+ROUND(G24,2)+ROUND(J24,2))/ROUND(D24,4), 0) -> 0 | F24: =ROUND(D24*E24,2) -> 0 | G24: =((D24*K24)/(1-$N$21-$N$23))*($N$21+$N$23) -> 0 | H24: =(IF($I$21=12%,(D24*K24)/(1-$N$21-$N$23)/(1-$C$122)/$F$122*$C$122,(D24*K24)/(1-$N$21-$N$23)/(1-$I$21))) -> 0 | J24: =ROUND(H24*$I$21,2) -> 0 | K24: =ROUND(K23+(K23*(-$H$55)),8) -> 0.1345104 | L24: COFINS Inj | M24: =M22 -> -920.8995 | N24: =N23 -> 0.0507 | O24: =ROUND(M24*N24,2) -> -46.69
B25: Adicional BAM | C25: kWh | D25: =IF($K$12=M4,($D$21*($K$14)/($K$14+$L$14)),0)+IF($L$12=M4,($D$21*($L$14)/($K$14+$L$14)),0)+IF($K$12=M4,($D$22*($K$14)/($K$14+$L$14)),0)+IF($L$12=M4,(D22*($L$14)/($K$14+$L$14)),0) -> 1036 | E25: =IFERROR((ROUND(D25*K25,2)+ROUND(G25,2)+ROUND(J25,2))/ROUND(D25,4), 0) -> 0.020926641 | F25: =ROUND(D25*E25,2) -> 21.68 | G25: =((D25*K25)/(1-$N$21-$N$23))*($N$21+$N$23) -> 1.2841465 | H25: =(IF($I$21=12%,(D25*K25)/(1-$N$21-$N$23)/(1-$C$122)/$F$122*$C$122,(D25*K25)/(1-$N$21-$N$23)/(1-$I$21))) -> 21.679944 | J25: =ROUND(H25*$I$21,2) -> 0.87 | K25: =J65 -> 0.01885
B26: Adicional BVM1 | C26: kWh | D26: =IF($K$12=M5,((D21+D22)*($K$14)/($K$14+$L$14)),0)+IF($L$12=M5,((D21+D22)*($L$14)/($K$14+$L$14)),0) -> 0 | E26: =IFERROR((ROUND(D26*K26,2)+ROUND(G26,2)+ROUND(J26,2))/ROUND(D26,4), 0) -> 0 | F26: =ROUND(D26*E26,2) -> 0 | G26: =((D26*K26)/(1-$N$21-$N$23))*($N$21+$N$23) -> 0 | H26: =(IF($I$21=12%,(D26*K26)/(1-$N$21-$N$23)/(1-$C$122)/$F$122*$C$122,(D26*K26)/(1-$N$21-$N$23)/(1-$I$21))) -> 0 | J26: =ROUND(H26*$I$21,2) -> 0 | K26: =J66 -> 0
B27: Adicional BVM2 | C27: kWh | D27: =IF($K$12=M6,((D22+D23)*($K$14)/($K$14+$L$14)),0)+IF($L$12=M6,((D22+D23)*($L$14)/($K$14+$L$14)),0) -> 0 | E27: =IFERROR((ROUND(D27*K27,2)+ROUND(G27,2)+ROUND(J27,2))/ROUND(D27,4), 0) -> 0 | F27: =ROUND(D27*E27,2) -> 0 | G27: =((D27*K27)/(1-$N$21-$N$23))*($N$21+$N$23) -> 0 | H27: =(IF($I$21=12%,(D27*K27)/(1-$N$21-$N$23)/(1-$C$122)/$F$122*$C$122,(D27*K27)/(1-$N$21-$N$23)/(1-$I$21))) -> 0 | J27: =ROUND(H27*$I$21,2) -> 0 | K27: =J67 -> 0
B28: Adicional EH | C28: kWh | D28: =IF($K$12=M7,((D23+D24)*($K$14)/($K$14+$L$14)),0)+IF($L$12=M7,((D23+D24)*($L$14)/($K$14+$L$14)),0) -> 0 | E28: =IFERROR((ROUND(D28*K28,2)+ROUND(G28,2)+ROUND(J28,2))/ROUND(D28,4), 0) -> 0 | F28: =ROUND(D28*E28,2) -> 0 | G28: =((D28*K28)/(1-$N$21-$N$23))*($N$21+$N$23) -> 0 | H28: =(IF($I$21=12%,(D28*K28)/(1-$N$21-$N$23)/(1-$C$122)/$F$122*$C$122,(D28*K28)/(1-$N$21-$N$23)/(1-$I$21))) -> 0 | J28: =ROUND(H28*$I$21,2) -> 0 | K28: =J68 -> 0
B30: TUSD - Consumo inj Reservado | C30: kWh | D30: 0 | E30: =IFERROR((ROUND(D30*K30,2)+ROUND(G30,2)+ROUND(J30,2))/ROUND(D30,4), 0) -> 0 | F30: =ROUND(D30*E30,2) -> 0 | G30: =((D30*K30)/(1-$N$22-$N$24))*($N$22+$N$24) -> 0 | H30: 0 | I30: 0 | J30: =H30*$I$21 -> 0 | K30: =K22 -> 0.20152293
B31: TUSD - Consumo inj | C31: kWh | D31: -1006 | E31: =IFERROR((ROUND(D31*K31,2)+ROUND(G31,2)+ROUND(J31,2))/ROUND(D31,4), 0) -> 0.53693837 | F31: =ROUND(D31*E31,2) -> -540.16 | G31: =((D31*K31)/(1-$N$22-$N$24))*($N$22+$N$24) -> -33.327744 | H31: 0 | I31: 0 | J31: =H31*$I$21 -> 0 | K31: =K21 -> 0.50380733
B32: TUSD - Consumo inj 11/2025 | C32: kWh | D32: 0 | E32: =IFERROR((ROUND(D32*K32,2)+ROUND(G32,2)+ROUND(J32,2))/ROUND(D32,4), 0) -> 0 | F32: =ROUND(D32*E32,2) -> 0 | G32: =((D32*K32)/(1-$N$22-$N$24))*($N$22+$N$24) -> 0 | I32: 0 | J32: =H32*$I$21 -> 0 | K32: =K22 -> 0.20152293
B33: TE - Consumo inj Reservado | C33: kWh | D33: =D30 -> 0 | E33: =IFERROR((ROUND(D33*K33,2)+ROUND(G33,2)+ROUND(J33,2))/ROUND(D33,4), 0) -> 0 | F33: =ROUND(D33*E33,2) -> 0 | G33: =((D33*K33)/(1-$N$22-$N$24))*($N$22+$N$24) -> 0 | H33: =(IF($I$33=12%,(D33*K33)/(1-$N$22-$N$24)/(1-$C$128)/$F$128*$C$128,(D33*K33)/(1-$N$22-$N$24)/(1-$I$33))) -> 0 | I33: =I21 -> 0.04 | J33: =H33*$I$21 -> 0 | K33: =K24 -> 0.1345104
