Workbook
Name _Ref352134769: 'TABELA DE TARIFAS ANTIGAS'!$A$91
Name _Ref352134769: 'TABELA DE TARIFAS NOVAS'!$A$93

Sheet TABELA DE TARIFAS ANTIGAS
A1: TABELA 1 – TARIFAS DE APLICAÇÃO E BASE ECONÔMICA PARA O GRUPO A.
A2: SUBGRUPO | B2: MODALIDADE | C2: UC | D2: POSTO | E2: TARIFAS DE APLICAÇÃO | J2: BASE ECONÔMICA | N2: Reajuste | O2: Dia | P2: Mês | Q2: Ano
E3: TUSD | G3: TE | J3: TUSD | L3: TE | N3: De | O3: 07 | P3: 08 | Q3: 2025
E4: R$/kW | F4: R$/MWh | G4: BVD – R$/MWh | H4: BAM – R$/MWh | I4: BVM – R$/MWh | J4: R$/kW | K4: R$/MWh | L4: R$/MWh | N4: Até | O4: 06 | P4: 08 | Q4: 2026
B5: AZUL | C5: NA | D5: P
A6: A1 (230 kV ou mais) | D6: FP
B7: AZUL APE | C7: NA | D7: P
D8: FP
A9: A2 (88 a 138kV) | B9: AZUL | C9: NA | D9: P
D10: FP
B11: AZUL APE | C11: NA | D11: P
D12: FP
B13: DISTRIBUIÇÃO | C13: ELFSM | D13: P
D14: FP
D15: NA
B16: GERAÇÃO | C16: UTE LASA | D16: NA
C17: UTE ALCON | D17: NA
C18: UTE SOL | D18: NA
C19: UHE MASCARENHAS - ENERGEST | D19: NA
C20: UHE SUICA | D20: NA
C21: PCH SAO JOAQUIM | D21: NA
C22: PCH SAO SIMAO | D22: NA
C23: PCH FRANCISCO GROSS | D23: NA
C24: PCH SAO PEDRO | D24: NA
C25: UTE LINHARES | D25: NA
C26: UTE ARCEL | D26: NA
C27: NOVO GERADOR | D27: NA
A28: A3 (69kV) | B28: AZUL | C28: NA | D28: P
D29: FP
B30: AZUL APE | C30: NA | D30: P
D31: FP
B32: DISTRIBUIÇÃO | D32: P
D33: FP
D34: NA
B35: GERAÇÃO | C35: NA | D35: NA
A36: A3a (30 a 44kV) | B36: AZUL | C36: NA | D36: P
D37: FP
B38: AZUL APE | C38: NA | D38: P
D39: FP
B40: VERDE | C40: NA | D40: NA
...

Sheet TABELA DE TARIFAS NOVAS
A1: TABELA 1 – TARIFAS DE APLICAÇÃO E BASE ECONÔMICA PARA O GRUPO A.
A2: SUBGRUPO | B2: MODALIDADE | C2: UC | D2: POSTO | E2: TARIFAS DE APLICAÇÃO | J2: BASE ECONÔMICA | N2: Reajuste | O2: Dia | P2: Mês | Q2: Ano
E3: TUSD | G3: TE | J3: TUSD | L3: TE | N3: De | O3: 07 | P3: 08 | Q3: 2026
E4: R$/kW | F4: R$/MWh | G4: BVD – R$/MWh | H4: BAM – R$/MWh | I4: BVM – R$/MWh | J4: R$/kW | K4: R$/MWh | L4: R$/MWh | N4: Até | O4: 31 | P4: 12 | Q4: 9999
B5: AZUL | C5: NA | D5: P
A6: A1 (230 kV ou mais) | D6: FP
B7: AZUL APE | C7: NA | D7: P
D8: FP
A9: A2 (88 a 138kV) | B9: AZUL | C9: NA | D9: P
D10: FP
B11: AZUL APE | C11: NA | D11: P
D12: FP
B13: DISTRIBUIÇÃO | C13: ELFSM | D13: P
D14: FP
D15: NA
B16: GERAÇÃO | C16: UTE LASA | D16: NA
C17: UTE ALCON | D17: NA
C18: UTE SOL | D18: NA
C19: UHE MASCARENHAS - ENERGEST | D19: NA
C20: UHE SUICA | D20: NA
C21: PCH SAO JOAQUIM | D21: NA
C22: PCH SAO SIMAO | D22: NA
C23: PCH FRANCISCO GROSS | D23: NA
C24: PCH SAO PEDRO | D24: NA
C25: UTE LINHARES | D25: NA
C26: UTE POVOACAO 1 | D26: NA
C27: UTE ARCEL | D27: NA
C28: UTE BIANCOGRES | D28: NA
C29: NOVO GERADOR | D29: NA
A30: A3 (69kV) | B30: AZUL | C30: NA | D30: P
D31: FP
B32: AZUL APE | C32: NA | D32: P
D33: FP
B34: DISTRIBUIÇÃO | D34: P
D35: FP
D36: NA
B37: GERAÇÃO | C37: NA | D37: NA
A38: A3a (30 a 44kV) | B38: AZUL | C38: NA | D38: P
D39: FP
B40: AZUL APE | C40: NA | D40: P
...

Sheet B1 (Res) Branca OK
B2: B1 Res | E2: Vigência das Tarifas: | F2: 46241 | H2: TARIFA BRANCA | M2: Bandeira | N2: R$/kWh | Q2: TUSD FIO B
M3: VERDE | N3: 0
B4: TARIFA | C4: TARIFA ANTIGA - REH 3370/2024 | F4: TARIFA NOVA - REH xxxx/2025 | I4: Tarifas Proporcionalizadas | M4: BAM | N4: 0.01885 | Q4: TARIFA | R4: =C4 -> TARIFA ANTIGA - REH 3370/2024 | U4: =F4 -> TARIFA NOVA - REH xxxx/2025 | X4: Tarifas Proporcionalizadas
C5: Tusd | D5: TE | E5: TUSD + TE | F5: Tusd | G5: TE | H5: TUSD + TE | I5: Tusd | J5: TE | K5: TUSD + TE | M5: BVM1 | N5: 0.04463 | R5: Tusd (R$/kWh) | U5: Tusd (R$/kWh) | X5: Tusd (R$/kWh)
B6: B1 Ponta | C6: ='TABELA DE TARIFAS ANTIGAS'!G68/1000 -> 0.93761 | D6: ='TABELA DE TARIFAS ANTIGAS'!H68/1000 -> 0.48448 | E6: =C6+D6 -> 1.42209 | F6: ='TABELA DE TARIFAS NOVAS'!G70/1000 -> 0.99902 | G6: ='TABELA DE TARIFAS NOVAS'!H70/1000 -> 0.51691 | H6: =F6+G6 -> 1.51593 | I6: =((C6*$C$15)+(F6*$D$15))/($D$15+$C$15) -> 0.966268 | J6: =((D6*$C$15)+(G6*$D$15))/($D$15+$C$15) -> 0.499614 | K6: =I6+J6 -> 1.465882 | M6: BVM2 | N6: 0.07877 | Q6: =B6 -> B1 Ponta | R6: ='FIO B'!H7/1000 -> 0.59110909 | U6: ='FIO B'!K7/1000 -> 0.60653962 | X6: =((R6*$C$15)+(U6*$D$15))/($D$15+$C$15) -> 0.59831
B7: B1 Fora Ponta | C7: ='TABELA DE TARIFAS ANTIGAS'!G70/1000 -> 0.36496 | D7: ='TABELA DE TARIFAS ANTIGAS'!H70/1000 -> 0.30579 | E7: =C7+D7 -> 0.67075 | F7: ='TABELA DE TARIFAS NOVAS'!G72/1000 -> 0.39741 | G7: ='TABELA DE TARIFAS NOVAS'!H72/1000 -> 0.32107 | H7: =F7+G7 -> 0.71848 | I7: =((C7*$C$15)+(F7*$D$15))/($D$15+$C$15) -> 0.38010333 | J7: =((D7*$C$15)+(G7*$D$15))/($D$15+$C$15) -> 0.31292067 | K7: =I7+J7 -> 0.693024 | M7: Escassez Hídrica | N7: 0.142 | Q7: =B7 -> B1 Fora Ponta | R7: ='FIO B'!H9/1000 -> 0.1182218 | U7: ='FIO B'!K9/1000 -> 0.1213079 | X7: =((R7*$C$15)+(U7*$D$15))/($D$15+$C$15) -> 0.11966198
B8: B1 Interm. | C8: ='TABELA DE TARIFAS ANTIGAS'!G69/1000 -> 0.65129 | D8: ='TABELA DE TARIFAS ANTIGAS'!H69/1000 -> 0.30579 | E8: =C8+D8 -> 0.95708 | F8: ='TABELA DE TARIFAS NOVAS'!G71/1000 -> 0.69821 | G8: ='TABELA DE TARIFAS NOVAS'!H71/1000 -> 0.32107 | H8: =F8+G8 -> 1.01928 | I8: =((C8*$C$15)+(F8*$D$15))/($D$15+$C$15) -> 0.673186 | J8: =((D8*$C$15)+(G8*$D$15))/($D$15+$C$15) -> 0.31292067 | K8: =I8+J8 -> 0.98610667 | Q8: =B8 -> B1 Interm. | R8: ='FIO B'!H8/1000 -> 0.3546655 | U8: ='FIO B'!K8/1000 -> 0.36392381 | X8: =((R8*$C$15)+(U8*$D$15))/($D$15+$C$15) -> 0.35898604
B9: CDE Escassez Hídrica | C9: 0.00018774721 | D9: -0.0044031307 | E9: 0.0036054084 | F9: =T13 -> 0.00018418923 | G9: =U13 -> -0.00053182975 | H9: =F9+G9 -> -0.00034764052 | I9: =((C9*$C$15)+(F9*$D$15))/($D$15+$C$15) -> 0.00018608682 | J9: =((D9*$C$15)+(G9*$D$15))/($D$15+$C$15) -> -0.0025965236 | K9: =I9+J9 -> -0.0024104368
P10: CUSTO | R10: Part. TUSD (%) | S10: Part. TE (%) | T10: Tusd (R$/kWh) | U10: TE (R$/kWh)
H11: Fatura | L11: Vigência das Tarifas (troca Bandeira): | M11: =EOMONTH(B15,0)+1 -> 46235 | P11: CDE CONTAS
B12: INSTALAÇÃO | C12: 99019 | H12: =E15 -> 46254 | K12: Altere a bandeira na célula abaixo | P12: CDE COVID | U12: 0
K13: BAM | L13: BAM | P13: CDE ESCASSEZ HÍDRICA | T13: =0.184189231569235/1000 -> 0.00018418923 | U13: =-0.531829748712515/1000 -> -0.00053182975
B14: Leitura Anterior | C14: Nº de dias tarifa Anterior | D14: Nº de dias tarifa Nova | E14: Leitura Atual | J14: Leitura Anterior | K14: Nº de dias tarifa Anterior | L14: Nº de dias tarifa Nova | M14: Leitura Atual
B15: 46224 | C15: =IF((F2-B15-1)<0,0,(F2-B15-1)) -> 16 | D15: =E15-F2+1 -> 14 | E15: 46254 | J15: =B15 -> 46224 | K15: =IF((M11-J15-1)<0,0,(M11-J15-1)) -> 10 | L15: =M15-M11+1 -> 20 | M15: =E15 -> 46254 | O15: Documento impressão: | Q15: 1025310387
B17: Descrição | C17: Unidade | D17: Quantidade | E17: Preço Unit (R$) com tributos | F17: Valor Total (R$) | G17: PIS/COFINS (R$) | H17: Base de Cálculo ICMS (R$) | I17: Alíquota ICMS (%) | J17: ICMS (R$) | K17: Preço Unit (R$) | L17: Tributos | M17: Base de Cálc (R$) | N17: Alíquota (%) | O17: Valor (R$)
B19: TUSD - Consumo Ponta | C19: kWh | D19: 15 | E19: =IFERROR((ROUND(D19*K19,2)+ROUND(G19,2)+ROUND(J19,2))/ROUND(D19,4),0) -> 1.24 | F19: =ROUND(D19*E19,2) -> 18.6 | G19: =((D19*K19)/(1-$N$19-$N$20))*($N$19+$N$20) -> 0.95308647 | H19: =ROUND((D19*K19)/(1-$N$19-$N$20)/(1-$I$19),8) -> 18.610972 | I19: 0.17 | J19: =H19*$I$19 -> 3.1638652 | K19: =IF(AND($B$15<$F$2,$E$15<$F$2),C6,IF($B$15<$F$2,I6,F6)) -> 0.966268 | L19: PIS | M19: =D61 -> 173.59054 | N19: 0.011 | O19: =ROUND(M19*N19,2) -> 1.91
B20: TUSD - Consumo Intermediário | C20: kWh | D20: 11 | E20: =IFERROR((ROUND(D20*K20,2)+ROUND(G20,2)+ROUND(J20,2))/ROUND(D20,4),0) -> 0.86545455 | F20: =ROUND(D20*E20,2) -> 9.52 | G20: =((D20*K20)/(1-$N$19-$N$20))*($N$19+$N$20) -> 0.48693524 | H20: =ROUND((D20*K20)/(1-$N$19-$N$20)/(1-$I$19),8) -> 9.5084111 | I20: =I19 -> 0.17 | J20: =H20*$I$19 -> 1.6164299 | K20: =IF(AND($B$15<$F$2,$E$15<$F$2),C8,IF($B$15<$F$2,I8,F8)) -> 0.673186 | L20: COFINS | M20: =M19 -> 173.59054 | N20: 0.0507 | O20: =ROUND(M20*N20,2) -> 8.8
B21: TUSD - Consumo Fora Ponta | C21: kWh | D21: 182 | E21: =IFERROR((ROUND(D21*K21,2)+ROUND(G21,2)+ROUND(J21,2))/ROUND(D21,4),0) -> 0.48807692 | F21: =ROUND(D21*E21,2) -> 88.83 | G21: =((D21*K21)/(1-$N$19-$N$20))*($N$19+$N$20) -> 4.549006 | H21: =ROUND((D21*K21)/(1-$N$19-$N$20)/(1-$I$19),8) -> 88.82869 | I21: =I19 -> 0.17 | J21: =H21*$I$19 -> 15.100877 | K21: =IF(AND($B$15<$F$2,$E$15<$F$2),C7,IF($B$15<$F$2,I7,F7)) -> 0.38010333
B22: TE - Consumo Ponta | C22: kWh | D22: =D19 -> 15 | E22: =IFERROR((ROUND(D22*K22,2)+ROUND(G22,2)+ROUND(J22,2))/ROUND(D22,4),0) -> 0.64133333 | F22: =ROUND(D22*E22,2) -> 9.62 | G22: =((D22*K22)/(1-$N$19-$N$20))*($N$19+$N$20) -> 0.49279842 | H22: =(D22*K22)/(1-$N$19-$N$20)/(1-$I$19) -> 9.6229017 | J22: =H22*$I$19 -> 1.6358933 | K22: =IF(AND($B$15<$F$2,$E$15<$F$2),D6,IF($B$15<$F$2,J6,G6)) -> 0.499614 | R22: TUSD Fio B | S22: Receita Fio B
B23: TE - Consumo Intermediário | C23: kWh | D23: =D20 -> 11 | E23: =IFERROR((ROUND(D23*K23,2)+ROUND(G23,2)+ROUND(J23,2))/ROUND(D23,4),0) -> 0.40181818 | F23: =ROUND(D23*E23,2) -> 4.42 | G23: =((D23*K23)/(1-$N$19-$N$20))*($N$19+$N$20) -> 0.22634473 | H23: =(D23*K23)/(1-$N$19-$N$20)/(1-$I$19) -> 4.4198459 | J23: =H23*$I$19 -> 0.7513738 | K23: =IF(AND($B$15<$F$2,$E$15<$F$2),D8,IF($B$15<$F$2,J8,G8)) -> 0.31292067 | R23: =IF(AND($B$15<$F$2,$E$15<$F$2),R6,IF($B$15<$F$2,X6,U6)) -> 0.59831 | S23: =D47*R23 -> 8.9746501
B24: TE - Consumo Fora Ponta | C24: kWh | D24: =D21 -> 182 | E24: =IFERROR((ROUND(D24*K24,2)+ROUND(G24,2)+ROUND(J24,2))/ROUND(D24,4),0) -> 0.40175824 | F24: =ROUND(D24*E24,2) -> 73.12 | G24: =((D24*K24)/(1-$N$19-$N$20))*($N$19+$N$20) -> 3.7449764 | H24: =(D24*K24)/(1-$N$19-$N$20)/(1-$I$19) -> 73.128359 | J24: =H24*$I$19 -> 12.431821 | K24: =IF(AND($B$15<$F$2,$E$15<$F$2),D7,IF($B$15<$F$2,J7,G7)) -> 0.31292067 | R24: =IF(AND($B$15<$F$2,$E$15<$F$2),R7,IF($B$15<$F$2,X7,U7)) -> 0.11966198 | S24: =D48*R24 -> 21.77848
B25: Adicional BAM | C25: kWh | D25: =IF($K$13=M4,(($D$19+$D$20+$D$21)*($K$15)/($K$15+$L$15)),0)+IF($L$13=M4,(($D$19+$D$20+$D$21)*($L$15)/($K$15+$L$15)),0) -> 208 | E25: =IFERROR( (ROUND(D25*K25,2)+ROUND(G25,2)+ROUND(J25,2))/ROUND(D25,4), N4) -> 0.024230769 | F25: =ROUND(D25*E25,2) -> 5.04 | G25: =((D25*K25)/(1-$N$19-$N$20))*($N$19+$N$20) -> 0.25782091 | H25: =(D25*K25)/(1-$N$19-$N$20)/(1-$I$19) -> 5.034483 | J25: =H25*$I$19 -> 0.85586211 | K25: =N4 -> 0.01885 | R25: =IF(AND($B$15<$F$2,$E$15<$F$2),R8,IF($B$15<$F$2,X8,U8)) -> 0.35898604 | S25: =D49*R25 -> 3.9488465
B26: Adicional BVM 1 | C26: kWh | D26: =IF($K$13=M5,(($D$19+$D$20+$D$21)*($K$15)/($K$15+$L$15)),0)+IF($L$13=M5,(($D$19+$D$20+$D$21)*($L$15)/($K$15+$L$15)),0) -> 0 | E26: =K26/(1-$N$19-$N$20)/(1-$I$19) -> 0.057306921 | F26: =ROUND(D26*E26,2) -> 0 | G26: =((D26*K26)/(1-$N$19-$N$20))*($N$19+$N$20) -> 0 | H26: =(D26*K26)/(1-$N$19-$N$20)/(1-$I$19) -> 0 | J26: =H26*$I$19 -> 0 | K26: =N5 -> 0.04463 | S26: =SUM(S23:S25) -> 34.701977
B27: Adicional BVM 2 | C27: kWh | D27: =IF($K$13=M6,(($D$19+$D$20+$D$21)*($K$15)/($K$15+$L$15)),0)+IF($L$13=M6,(($D$19+$D$20+$D$21)*($L$15)/($K$15+$L$15)),0) -> 0 | E27: =K27/(1-$N$19-$N$20)/(1-$I$19) -> 0.10114421 | F27: =ROUND(D27*E27,2) -> 0 | G27: =((D27*K27)/(1-$N$19-$N$20))*($N$19+$N$20) -> 0 | H27: =(D27*K27)/(1-$N$19-$N$20)/(1-$I$19) -> 0 | J27: =H27*$I$19 -> 0 | K27: =N6 -> 0.07877
B28: Adicional Escassez | C28: kWh | D28: =IF($K$13=M7,(($D$19+$D$20+$D$21)*($K$15)/($K$15+$L$15)),0)+IF($L$13=M7,(($D$19+$D$20+$D$21)*($L$15)/($K$15+$L$15)),0) -> 0 | E28: =K28/(1-$N$19-$N$20)/(1-$I$19) -> 0.18233437 | F28: =ROUND(D28*E28,2) -> 0 | G28: =((D28*K28)/(1-$N$19-$N$20))*($N$19+$N$20) -> 0 | H28: =(D28*K28)/(1-$N$19-$N$20)/(1-$I$19) -> 0 | J28: =H28*$I$19 -> 0 | K28: =N7 -> 0.142
B29: Multas | F29: 4.54
B30: Juros | F30: 0.49
B31: Bônus/Descontos | F31: 3.38
B32: Doações | F32: 0.31
B33: CIP | F33: 45.66
B36: TOTAL | F36: =SUM(F19:F35) -> 263.53 | G36: =SUM(G19:G35) -> 10.710968 | H36: =SUM(H19:H35) -> 209.15366 | J36: =SUM(J19:J35) -> 35.556123
B38: Informativo Escassez | C38: =D19+D20+D21 -> 208 | D38: =IF(AND($B$15<$F$2,$E$15<$F$2),C9,IF($B$15<$F$2,I9,F9)) -> 0.00018608682 | E38: =IF(AND($B$15<$F$2,$E$15<$F$2),D9,IF($B$15<$F$2,J9,G9)) -> -0.0025965236 | F38: =C38*(D38+E38) -> -0.50137085
B43: Fatura B1 Residencial TB
D44: Qtde | E44: TUSD | F44: TE | G44: TUSD + TE | H44: R$ | J44: Documento impressão: | L44: =Q15 -> 1025310387
B45: Fornecimento de Energia Elétrica | H45: =SUM(H47:H55)+SUM(H61:H63) -> 209.14522
B47: Consumo Ponta | D47: =D19 -> 15 | E47: =IF(AND($B$15<$F$2,$E$15<$F$2),C6,IF($B$15<$F$2,I6,F6)) -> 0.966268 | F47: =IF(AND($B$15<$F$2,$E$15<$F$2),D6,IF($B$15<$F$2,J6,G6)) -> 0.499614 | G47: =E47+F47 -> 1.465882 | H47: =ROUND((D47*E47),2)+ROUND((D47*F47),2) -> 21.98 | U47: =D47*E47 -> 14.49402
B48: Consumo Fora Ponta | D48: =D21 -> 182 | E48: =IF(AND($B$15<$F$2,$E$15<$F$2),C7,IF($B$15<$F$2,I7,F7)) -> 0.38010333 | F48: =IF(AND($B$15<$F$2,$E$15<$F$2),D7,IF($B$15<$F$2,J7,G7)) -> 0.31292067 | G48: =E48+F48 -> 0.693024 | H48: =ROUND((D48*E48),2)+ROUND((D48*F48),2) -> 126.13 | U48: =D48*E48 -> 69.178807
B49: Consumo Intemediário | D49: =D20 -> 11 | E49: =IF(AND($B$15<$F$2,$E$15<$F$2),C8,IF($B$15<$F$2,I8,F8)) -> 0.673186 | F49: =IF(AND($B$15<$F$2,$E$15<$F$2),D8,IF($B$15<$F$2,J8,G8)) -> 0.31292067 | G49: =E49+F49 -> 0.98610667 | H49: =ROUND((D49*E49),2)+ROUND((D49*F49),2) -> 10.85 | U49: =D49*E49 -> 7.405046
U50: =SUM(U47:U49) -> 91.077873
B52: Adicional BAM | D52: =IF($K$13=M4,((D47+D48+D49)*(K15)/(K15+L15)),0)+IF($L$13=M4,((D47+D48+D49)*(L15)/(K15+L15)),0) -> 208 | F52: =N4 -> 0.01885 | H52: =ROUND(D52*(E52+F52),2) -> 3.92
...

Sheet B2 (Rural) Branca OK
B2: B2 Rural | E2: Vigência das Tarifas: | F2: ='B1 (Res) Branca OK'!F2 -> 46241 | H2: TARIFA BRANCA | M2: Bandeira | N2: R$/kWh | Q2: TUSD FIO B
M3: VERDE | N3: ='B1 (Res) Branca OK'!N3 -> 0
B4: TARIFA | C4: ='B1 (Res) Branca OK'!C4 -> TARIFA ANTIGA - REH 3370/2024 | F4: ='B1 (Res) Branca OK'!F4 -> TARIFA NOVA - REH xxxx/2025 | I4: Tarifas Proporcionalizadas | M4: BAM | N4: ='B1 (Res) Branca OK'!N4 -> 0.01885 | Q4: TARIFA | R4: =C4 -> TARIFA ANTIGA - REH 3370/2024 | U4: =F4 -> TARIFA NOVA - REH xxxx/2025
C5: Tusd | D5: TE | E5: TUSD + TE | F5: Tusd | G5: TE | H5: TUSD + TE | I5: Tusd | J5: TE | K5: TUSD + TE | M5: BVM1 | N5: ='B1 (Res) Branca OK'!N5 -> 0.04463 | R5: Tusd (R$/kWh) | U5: Tusd (R$/kWh) | X5: Tusd (R$/kWh)
B6: B2 Ponta | C6: ='TABELA DE TARIFAS ANTIGAS'!G74/1000 -> 1.06103 | D6: ='TABELA DE TARIFAS ANTIGAS'!H74/1000 -> 0.48448 | E6: =C6+D6 -> 1.54551 | F6: ='TABELA DE TARIFAS NOVAS'!G76/1000 -> 1.12867 | G6: ='TABELA DE TARIFAS NOVAS'!H76/1000 -> 0.51691 | H6: =F6+G6 -> 1.64558 | I6: =((C6*$C$15)+(F6*$D$15))/($D$15+$C$15) -> 1.1061233 | J6: =((D6*$C$15)+(G6*$D$15))/($D$15+$C$15) -> 0.5061 | K6: =I6+J6 -> 1.6122233 | M6: BVM2 | N6: ='B1 (Res) Branca OK'!N6 -> 0.07877 | Q6: =B6 -> B2 Ponta | R6: ='FIO B'!H16/1000 -> 0.69302445 | U6: ='FIO B'!K16/1000 -> 0.71111541 | X6: =((R6*$C$15)+(U6*$D$15))/($D$15+$C$15) -> 0.70508509
B7: B2 Fora Ponta | C7: ='TABELA DE TARIFAS ANTIGAS'!G76/1000 -> 0.38965 | D7: ='TABELA DE TARIFAS ANTIGAS'!H76/1000 -> 0.30579 | E7: =C7+D7 -> 0.69544 | F7: ='TABELA DE TARIFAS NOVAS'!G78/1000 -> 0.42334 | G7: ='TABELA DE TARIFAS NOVAS'!H78/1000 -> 0.32107 | H7: =F7+G7 -> 0.74441 | I7: =((C7*$C$15)+(F7*$D$15))/($D$15+$C$15) -> 0.41211 | J7: =((D7*$C$15)+(G7*$D$15))/($D$15+$C$15) -> 0.31597667 | K7: =I7+J7 -> 0.72808667 | M7: Escassez Hídrica | N7: ='B1 (Res) Branca OK'!N7 -> 0.142 | Q7: =B7 -> B2 Fora Ponta | R7: ='FIO B'!H18/1000 -> 0.13860487 | U7: ='FIO B'!K18/1000 -> 0.14222306 | X7: =((R7*$C$15)+(U7*$D$15))/($D$15+$C$15) -> 0.141017
B8: B2 Interm. | C8: ='TABELA DE TARIFAS ANTIGAS'!G75/1000 -> 0.72534 | D8: ='TABELA DE TARIFAS ANTIGAS'!H75/1000 -> 0.30579 | E8: =C8+D8 -> 1.03113 | F8: ='TABELA DE TARIFAS NOVAS'!G77/1000 -> 0.77601 | G8: ='TABELA DE TARIFAS NOVAS'!H77/1000 -> 0.32107 | H8: =F8+G8 -> 1.09708 | I8: =((C8*$C$15)+(F8*$D$15))/($D$15+$C$15) -> 0.75912 | J8: =((D8*$C$15)+(G8*$D$15))/($D$15+$C$15) -> 0.31597667 | K8: =I8+J8 -> 1.0750967 | Q8: =B8 -> B2 Interm. | R8: ='FIO B'!H17/1000 -> 0.41581471 | U8: ='FIO B'!K17/1000 -> 0.42666929 | X8: =((R8*$C$15)+(U8*$D$15))/($D$15+$C$15) -> 0.4230511
B9: CDE Escassez Hídrica | C9: ='B1 (Res) Branca OK'!C9 -> 0.00018774721 | D9: ='B1 (Res) Branca OK'!D9 -> -0.0044031307 | E9: =SUM(C9+D9) -> -0.0042153835 | F9: =T13 -> 0.00018418923 | G9: =U13 -> -0.00053182975 | H9: =F9+G9 -> -0.00034764052 | I9: =((C9*$C$15)+(F9*$D$15))/($D$15+$C$15) -> 0.00018537523 | J9: =((D9*$C$15)+(G9*$D$15))/($D$15+$C$15) -> -0.0018222634 | K9: =I9+J9 -> -0.0016368882
P10: CUSTO | R10: Part. TUSD (%) | S10: Part. TE (%) | T10: Tusd (R$/kWh) | U10: TE (R$/kWh)
H11: Fatura | L11: Vigência das Tarifas (troca Bandeira): | M11: =EOMONTH(B15,0)+1 -> 46235 | P11: CDE CONTAS
B12: INSTALAÇÃO | C12: 160451628 | H12: =E15 -> 46260 | K12: Altere a bandeira na célula abaixo | P12: CDE COVID | U12: 0
K13: BAM | L13: ='B1 (Res) Branca OK'!L13 -> BAM | P13: CDE ESCASSEZ HÍDRICA | T13: ='B1 (Res) Branca OK'!T13 -> 0.00018418923 | U13: ='B1 (Res) Branca OK'!U13 -> -0.00053182975
B14: Leitura Anterior | C14: Nº de dias tarifa Anterior | D14: Nº de dias tarifa Nova | E14: Leitura Atual | J14: Leitura Anterior | K14: Nº de dias tarifa Anterior | L14: Nº de dias tarifa Nova | M14: Leitura Atual
B15: 46230 | C15: =IF((F2-B15-1)<0,0,(F2-B15-1)) -> 10 | D15: =E15-F2+1 -> 20 | E15: 46260 | J15: =B15 -> 46230 | K15: =IF((M11-J15-1)<0,0,(M11-J15-1)) -> 4 | L15: =M15-M11+1 -> 26 | M15: =E15 -> 46260 | O15: Documento impressão: | Q15: 1025310389
B17: Descrição | C17: Unidade | D17: Quantidade | E17: Preço Unit (R$) com tributos | F17: Valor Total (R$) | G17: PIS/COFINS (R$) | H17: Base de Cálculo ICMS (R$) | I17: Alíquota ICMS (%) | J17: ICMS (R$) | K17: Preço Unit (R$) | L17: Tributos | M17: Base de Cálc (R$) | N17: Alíquota (%) | O17: Valor (R$)
B19: TUSD - Consumo Ponta | C19: kWh | D19: 27 | E19: =IFERROR((ROUND(D19*K19,2)+ROUND(G19,2)+ROUND(J19,2))/ROUND(D19,4), 0) -> 1.4203704 | F19: =ROUND(D19*E19,2) -> 38.35 | G19: =((D19*K19)/(1-$N$19-$N$20))*($N$19+$N$20) -> 1.9638611 | H19: =(IF($I$19=12%,(D19*K19)/(1-$N$19-$N$20)/(1-$C$72)/$F$72*$C$72,(D19*K19)/(1-$N$19-$N$20)/(1-$I$19))) -> 38.348423 | I19: 0.17 | J19: =H19*$I$19 -> 6.5192319 | K19: =IF(AND($B$15<$F$2,$E$15<$F$2),C6,IF($B$15<$F$2,I6,F6)) -> 1.1061233 | L19: PIS | M19: =D60 -> 209.55984 | N19: ='B1 (Res) Branca OK'!N19 -> 0.011 | O19: =ROUND(M19*N19,2) -> 2.31 | Q19: TUSD Fio B | R19: Receita Fio B
B20: TUSD - Consumo Intermediário | C20: kWh | D20: 20 | E20: =IFERROR((ROUND(D20*K20,2)+ROUND(G20,2)+ROUND(J20,2))/ROUND(D20,4), 0) -> 0.9745 | F20: =ROUND(D20*E20,2) -> 19.49 | G20: =((D20*K20)/(1-$N$19-$N$20))*($N$19+$N$20) -> 0.99835242 | H20: =(IF($I$19=12%,(D20*K20)/(1-$N$19-$N$20)/(1-$C$72)/$F$72*$C$72,(D20*K20)/(1-$N$19-$N$20)/(1-$I$19))) -> 19.494882 | I20: =I19 -> 0.17 | J20: =H20*$I$19 -> 3.31413 | K20: =IF(AND($B$15<$F$2,$E$15<$F$2),C8,IF($B$15<$F$2,I8,F8)) -> 0.75912 | L20: COFINS | M20: =D61 -> 209.55984 | N20: ='B1 (Res) Branca OK'!N20 -> 0.0507 | O20: =ROUND(M20*N20,2) -> 10.62 | Q20: =IF(AND($B$15<$F$2,$E$15<$F$2),R6,IF($B$15<$F$2,X6,U6)) -> 0.70508509 | R20: =D46*Q20 -> 19.037298
B21: TUSD - Consumo Fora Ponta | C21: kWh | D21: 175 | E21: =IFERROR((ROUND(D21*K21,2)+ROUND(G21,2)+ROUND(J21,2))/ROUND(D21,4), 0) -> 0.52914286 | F21: =ROUND(D21*E21,2) -> 92.6 | G21: =((D21*K21)/(1-$N$19-$N$20))*($N$19+$N$20) -> 4.7423614 | H21: =(IF($I$19=12%,(D21*K21)/(1-$N$19-$N$20)/(1-$C$72)/$F$72*$C$72,(D21*K21)/(1-$N$19-$N$20)/(1-$I$19))) -> 92.604351 | I21: =I19 -> 0.17 | J21: =H21*$I$19 -> 15.74274 | K21: =IF(AND($B$15<$F$2,$E$15<$F$2),C7,IF($B$15<$F$2,I7,F7)) -> 0.41211 | Q21: =IF(AND($B$15<$F$2,$E$15<$F$2),R7,IF($B$15<$F$2,X7,U7)) -> 0.141017 | R21: =D47*Q21 -> 24.677975
B22: TE - Consumo Ponta | C22: kWh | D22: =D19 -> 27 | E22: =IFERROR((ROUND(D22*K22,2)+ROUND(G22,2)+ROUND(J22,2))/ROUND(D22,4), 0) -> 0.64962963 | F22: =ROUND(D22*E22,2) -> 17.54 | G22: =((D22*K22)/(1-$N$19-$N$20))*($N$19+$N$20) -> 0.89855269 | H22: =(IF($I$19=12%,(D22*K22)/(1-$N$19-$N$20)/(1-$C$72)/$F$72*$C$72,(D22*K22)/(1-$N$19-$N$20)/(1-$I$19))) -> 17.546088 | J22: =H22*$I$19 -> 2.9828349 | K22: =IF(AND($B$15<$F$2,$E$15<$F$2),D6,IF($B$15<$F$2,J6,G6)) -> 0.5061 | Q22: =IF(AND($B$15<$F$2,$E$15<$F$2),R8,IF($B$15<$F$2,X8,U8)) -> 0.4230511 | R22: =D48*Q22 -> 8.4610219
B23: TE - Consumo Intermediário | C23: kWh | D23: =D20 -> 20 | E23: =IFERROR((ROUND(D23*K23,2)+ROUND(G23,2)+ROUND(J23,2))/ROUND(D23,4), 0) -> 0.406 | F23: =ROUND(D23*E23,2) -> 8.12 | G23: =((D23*K23)/(1-$N$19-$N$20))*($N$19+$N$20) -> 0.41555495 | H23: =(IF($I$19=12%,(D23*K23)/(1-$N$19-$N$20)/(1-$C$72)/$F$72*$C$72,(D23*K23)/(1-$N$19-$N$20)/(1-$I$19))) -> 8.1145642 | J23: =H23*$I$19 -> 1.3794759 | K23: =IF(AND($B$15<$F$2,$E$15<$F$2),D8,IF($B$15<$F$2,J8,G8)) -> 0.31597667 | R23: =SUM(R20:R22) -> 52.176294
B24: TE - Consumo Fora Ponta | C24: kWh | D24: =D21 -> 175 | E24: =IFERROR((ROUND(D24*K24,2)+ROUND(G24,2)+ROUND(J24,2))/ROUND(D24,4), 0) -> 0.40577143 | F24: =ROUND(D24*E24,2) -> 71.01 | G24: =((D24*K24)/(1-$N$19-$N$20))*($N$19+$N$20) -> 3.6361058 | H24: =(IF($I$19=12%,(D24*K24)/(1-$N$19-$N$20)/(1-$C$72)/$F$72*$C$72,(D24*K24)/(1-$N$19-$N$20)/(1-$I$19))) -> 71.002437 | J24: =H24*$I$19 -> 12.070414 | K24: =IF(AND($B$15<$F$2,$E$15<$F$2),D7,IF($B$15<$F$2,J7,G7)) -> 0.31597667
B25: Adicional BAM | C25: kWh | D25: =IF($K$13=M4,(($D$19+$D$20+$D$21)*($K$15)/($K$15+$L$15)),0)+IF($L$13=M4,(($D$19+$D$20+$D$21)*($L$15)/($K$15+$L$15)),0) -> 222 | E25: =IFERROR((ROUND(D25*K25,2)+ROUND(G25,2)+ROUND(J25,2))/ROUND(D25,4), 0) -> 0.024189189 | F25: =ROUND(D25*E25,2) -> 5.37 | G25: =((D25*K25)/(1-$N$19-$N$20))*($N$19+$N$20) -> 0.27517424 | H25: =(IF($I$19=12%,(D25*K25)/(1-$N$19-$N$20)/(1-$C$72)/$F$72*$C$72,(D25*K25)/(1-$N$19-$N$20)/(1-$I$19))) -> 5.3733425 | J25: =H25*$I$19 -> 0.91346822 | K25: =N4 -> 0.01885
B26: Adicional BVM 1 | C26: kWh | D26: =IF($K$13=M5,(($D$19+$D$20+$D$21)*($K$15)/($K$15+$L$15)),0)+IF($L$13=M5,(($D$19+$D$20+$D$21)*($L$15)/($K$15+$L$15)),0) -> 0 | E26: =IFERROR((ROUND(D26*K26,2)+ROUND(G26,2)+ROUND(J26,2))/ROUND(D26,4), 0) -> 0 | F26: =ROUND(D26*E26,2) -> 0 | G26: =((D26*K26)/(1-$N$19-$N$20))*($N$19+$N$20) -> 0 | H26: =(IF($I$19=12%,(D26*K26)/(1-$N$19-$N$20)/(1-$C$72)/$F$72*$C$72,(D26*K26)/(1-$N$19-$N$20)/(1-$I$19))) -> 0 | J26: =H26*$I$19 -> 0 | K26: =N5 -> 0.04463
B27: Adicional BVM 2 | C27: kWh | D27: =IF($K$13=M6,(($D$19+$D$20+$D$21)*($K$15)/($K$15+$L$15)),0)+IF($L$13=M6,(($D$19+$D$20+$D$21)*($L$15)/($K$15+$L$15)),0) -> 0 | E27: =IFERROR((ROUND(D27*K27,2)+ROUND(G27,2)+ROUND(J27,2))/ROUND(D27,4), 0) -> 0 | F27: =ROUND(D27*E27,2) -> 0 | G27: =((D27*K27)/(1-$N$19-$N$20))*($N$19+$N$20) -> 0 | H27: =(IF($I$19=12%,(D27*K27)/(1-$N$19-$N$20)/(1-$C$72)/$F$72*$C$72,(D27*K27)/(1-$N$19-$N$20)/(1-$I$19))) -> 0 | J27: =H27*$I$19 -> 0 | K27: =N6 -> 0.07877
B28: Adicional Escassez | C28: kWh | D28: =IF($K$13=M7,(($D$19+$D$20+$D$21)*($K$15)/($K$15+$L$15)),0)+IF($L$13=M7,(($D$19+$D$20+$D$21)*($L$15)/($K$15+$L$15)),0) -> 0 | E28: =IFERROR((ROUND(D28*K28,2)+ROUND(G28,2)+ROUND(J28,2))/ROUND(D28,4), 0) -> 0 | F28: =ROUND(D28*E28,2) -> 0 | G28: =((D28*K28)/(1-$N$19-$N$20))*($N$19+$N$20) -> 0 | H28: =(IF($I$19=12%,(D28*K28)/(1-$N$19-$N$20)/(1-$C$72)/$F$72*$C$72,(D28*K28)/(1-$N$19-$N$20)/(1-$I$19))) -> 0 | J28: =H28*$I$19 -> 0 | K28: =N7 -> 0.142
B29: Multas
B30: Juros | Q30: 200
B31: Doações | F31: -6.91 | Q31: 18700
B32: CIP | Q32: 600
B35: TOTAL | F35: =SUM(F19:F34) -> 245.57 | G35: =SUM(G19:G34) -> 12.929963 | H35: =SUM(H19:H34) -> 252.48409 | J35: =SUM(J19:J34) -> 42.922295
B37: Informativo Escassez | C37: =D19+D20+D21 -> 222 | D37: =IF(AND($B$15<$F$2,$E$15<$F$2),C9,IF($B$15<$F$2,I9,F9)) -> 0.00018537523 | E37: =IF(AND($B$15<$F$2,$E$15<$F$2),D9,IF($B$15<$F$2,J9,G9)) -> -0.0018222634 | F37: =C37*(D37+E37) -> -0.36338918
B42: Fatura B2 Rural TB
D43: Qtde | E43: TUSD | F43: TE | G43: TUSD + TE | H43: R$
B44: Fornecimento de Energia Elétrica | H44: =SUM(H46:H54)+SUM(H60:H62) -> 218.2915 | J44: B1 Residencial | L44: Diferença
J45: TUSD + TE | K45: R$
B46: Consumo Ponta | D46: =D19 -> 27 | E46: =IF(AND($B$15<$F$2,$E$15<$F$2),C6,IF($B$15<$F$2,I6,F6)) -> 1.1061233 | F46: =IF(AND($B$15<$F$2,$E$15<$F$2),D6,IF($B$15<$F$2,J6,G6)) -> 0.5061 | G46: =E46+F46 -> 1.6122233 | H46: =ROUND((D46*E46),2)+ROUND((D46*F46),2) -> 43.53 | J46: =IF(AND($B$15<$F$2,$E$15<$F$2),E132,IF($B$15<$F$2,K132,H132)) -> 1.465882 | K46: =D46*J46 -> 39.578814 | L46: =K46-H46 -> -3.951186
B47: Consumo Fora Ponta | D47: =D21 -> 175 | E47: =IF(AND($B$15<$F$2,$E$15<$F$2),C7,IF($B$15<$F$2,I7,F7)) -> 0.41211 | F47: =IF(AND($B$15<$F$2,$E$15<$F$2),D7,IF($B$15<$F$2,J7,G7)) -> 0.31597667 | G47: =E47+F47 -> 0.72808667 | H47: =ROUND((D47*E47),2)+ROUND((D47*F47),2) -> 127.42 | J47: =IF(AND($B$15<$F$2,$E$15<$F$2),E133,IF($B$15<$F$2,K133,H133)) -> 0.693024 | K47: =D47*J47 -> 121.2792 | L47: =K47-H47 -> -6.1408
B48: Consumo Intemediário | D48: =D20 -> 20 | E48: =IF(AND($B$15<$F$2,$E$15<$F$2),C8,IF($B$15<$F$2,I8,F8)) -> 0.75912 | F48: =IF(AND($B$15<$F$2,$E$15<$F$2),D8,IF($B$15<$F$2,J8,G8)) -> 0.31597667 | G48: =E48+F48 -> 1.0750967 | H48: =ROUND((D48*E48),2)+ROUND((D48*F48),2) -> 21.5 | J48: =IF(AND($B$15<$F$2,$E$15<$F$2),E134,IF($B$15<$F$2,K134,H134)) -> 0.98610667 | K48: =D48*J48 -> 19.722133 | L48: =K48-H48 -> -1.7778667
L50: =SUM(L46:L48) -> -11.869853
B51: Adicional BAM | D51: =IF($K$13=M4,((D46+D47+D48)*(K15)/(K15+L15)),0)+IF($L$13=M4,((D46+D47+D48)*(L15)/(K15+L15)),0) -> 222 | F51: =N4 -> 0.01885 | H51: =ROUND(D51*(E51+F51),2) -> 4.18
...

Sheet FIO B
B2: TUSD FIO B
B4: SUBGRUPO | C4: MODALIDADE | D4: CLASSE | E4: SUBCLASSE | F4: POSTO | G4: TARIFAS DE APLICAÇÃO
G5: TUSD FIO B (RTP 2025) | J5: TUSD FIO B (RTA 2026)
G6: R$/kW | H6: R$/MWh | J6: R$/kW | K6: R$/MWh
B7: B1 | C7: BRANCA | D7: RESIDENCIAL | E7: RESIDENCIAL | F7: P | G7: 0 | H7: 591.10909 | J7: 0 | K7: 606.53962
B8: B1 | C8: BRANCA | D8: RESIDENCIAL | E8: RESIDENCIAL | F8: INT | G8: 0 | H8: 354.6655 | J8: 0 | K8: 363.92381
B9: B1 | C9: BRANCA | D9: RESIDENCIAL | E9: RESIDENCIAL | F9: FP | G9: 0 | H9: 118.2218 | J9: 0 | K9: 121.3079
B10: B1 | C10: PRÉ-PAGAMENTO | D10: RESIDENCIAL | E10: RESIDENCIAL | F10: NA | G10: 0 | H10: 203.83072 | J10: 0 | K10: 209.15159
B11: B1 | C11: CONVENCIONAL | D11: RESIDENCIAL | E11: RESIDENCIAL | F11: NA | G11: 0 | H11: 203.83072 | J11: 0 | K11: 209.15159
B12: B1 | C12: PRÉ-PAGAMENTO | D12: RESIDENCIAL | E12: BAIXA RENDA | F12: NA | G12: 0 | H12: 203.83072 | J12: 0 | K12: 209.15159
B13: B1 | C13: CONVENCIONAL | D13: RESIDENCIAL | E13: BAIXA RENDA | F13: NA | G13: 0 | H13: 203.83072 | J13: 0 | K13: 209.15159
B14: B1 | C14: PRÉ-PAGAMENTO | D14: RESIDENCIAL | E14: RESIDENCIAL DESCONTO SOCIAL | F14: NA | G14: 0 | H14: 203.83072 | J14: 0 | K14: 209.15159
B15: B1 | C15: CONVENCIONAL | D15: RESIDENCIAL | E15: RESIDENCIAL DESCONTO SOCIAL | F15: NA | G15: 0 | H15: 203.83072 | J15: 0 | K15: 209.15159
B16: B2 | C16: BRANCA | D16: RURAL | E16: NÃO SE APLICA | F16: P | G16: 0 | H16: 693.02445 | J16: 0 | K16: 711.11541
B17: B2 | C17: BRANCA | D17: RURAL | E17: NÃO SE APLICA | F17: INT | G17: 0 | H17: 415.81471 | J17: 0 | K17: 426.66929
B18: B2 | C18: BRANCA | D18: RURAL | E18: NÃO SE APLICA | F18: FP | G18: 0 | H18: 138.60487 | J18: 0 | K18: 142.22306
... B39: B | C39: GERAÇÃO | D39: TIPO 02 | E39: NA | F39: NA | G39: 0 | H39: 11.690957 | J39: 0 | K39: 11.996142

Sheet B2 (Rural Irrig) Branca OK
B2: B2 Rural | E2: Vigência das Tarifas: | F2: ='B1 (Res) Branca OK'!F2 -> 46241 | H2: TARIFA BRANCA | M2: Bandeira | N2: R$/kWh | Q2: TUSD FIO B
M3: VERDE | N3: ='B1 (Res) Branca OK'!N3 -> 0
B4: TARIFA | C4: ='B1 (Res) Branca OK'!C4 -> TARIFA ANTIGA - REH 3370/2024 | F4: ='B1 (Res) Branca OK'!F4 -> TARIFA NOVA - REH xxxx/2025 | I4: Tarifas Proporcionalizadas | M4: BAM | N4: ='B1 (Res) Branca OK'!N4 -> 0.01885 | Q4: TARIFA | R4: =C4 -> TARIFA ANTIGA - REH 3370/2024 | U4: =F4 -> TARIFA NOVA - REH xxxx/2025
C5: Tusd | D5: TE | E5: TUSD + TE | F5: Tusd | G5: TE | H5: TUSD + TE | I5: Tusd | J5: TE | K5: TUSD + TE | M5: BVM1 | N5: ='B1 (Res) Branca OK'!N5 -> 0.04463 | R5: Tusd (R$/kWh) | U5: Tusd (R$/kWh) | X5: Tusd (R$/kWh)
B6: B2 Ponta | C6: ='TABELA DE TARIFAS ANTIGAS'!G74/1000 -> 1.06103 | D6: ='TABELA DE TARIFAS ANTIGAS'!H74/1000 -> 0.48448 | E6: =C6+D6 -> 1.54551 | F6: ='TABELA DE TARIFAS NOVAS'!G76/1000 -> 1.12867 | G6: ='TABELA DE TARIFAS NOVAS'!H76/1000 -> 0.51691 | H6: =F6+G6 -> 1.64558 | I6: =((C6*$C$15)+(F6*$D$15))/($D$15+$C$15) -> 1.0903407 | J6: =((D6*$C$15)+(G6*$D$15))/($D$15+$C$15) -> 0.498533 | K6: =I6+J6 -> 1.5888737 | M6: BVM2 | N6: ='B1 (Res) Branca OK'!N6 -> 0.07877 | Q6: =B6 -> B2 Ponta | R6: ='FIO B'!H16/1000 -> 0.69302445 | U6: ='FIO B'!K16/1000 -> 0.71111541 | X6: =((R6*$C$15)+(U6*$D$15))/($D$15+$C$15) -> 0.70086387
B7: B2 Fora Ponta | C7: ='TABELA DE TARIFAS ANTIGAS'!G76/1000 -> 0.38965 | D7: ='TABELA DE TARIFAS ANTIGAS'!H76/1000 -> 0.30579 | E7: =C7+D7 -> 0.69544 | F7: ='TABELA DE TARIFAS NOVAS'!G78/1000 -> 0.42334 | G7: ='TABELA DE TARIFAS NOVAS'!H78/1000 -> 0.32107 | H7: =F7+G7 -> 0.74441 | I7: =((C7*$C$15)+(F7*$D$15))/($D$15+$C$15) -> 0.404249 | J7: =((D7*$C$15)+(G7*$D$15))/($D$15+$C$15) -> 0.31241133 | K7: =I7+J7 -> 0.71666033 | M7: Escassez Hídrica | N7: ='B1 (Res) Branca OK'!N7 -> 0.142 | Q7: =B7 -> B2 Fora Ponta | R7: ='FIO B'!H18/1000 -> 0.13860487 | U7: ='FIO B'!K18/1000 -> 0.14222306 | X7: =((R7*$C$15)+(U7*$D$15))/($D$15+$C$15) -> 0.14017275
B8: B2 Interm. | C8: ='TABELA DE TARIFAS ANTIGAS'!G75/1000 -> 0.72534 | D8: ='TABELA DE TARIFAS ANTIGAS'!H75/1000 -> 0.30579 | E8: =C8+D8 -> 1.03113 | F8: ='TABELA DE TARIFAS NOVAS'!G77/1000 -> 0.77601 | G8: ='TABELA DE TARIFAS NOVAS'!H77/1000 -> 0.32107 | H8: =F8+G8 -> 1.09708 | I8: =((C8*$C$15)+(F8*$D$15))/($D$15+$C$15) -> 0.747297 | J8: =((D8*$C$15)+(G8*$D$15))/($D$15+$C$15) -> 0.31241133 | K8: =I8+J8 -> 1.0597083 | Q8: =B8 -> B2 Interm. | R8: ='FIO B'!H17/1000 -> 0.41581471 | U8: ='FIO B'!K17/1000 -> 0.42666929 | X8: =((R8*$C$15)+(U8*$D$15))/($D$15+$C$15) -> 0.42051836
B9: CDE Escassez Hídrica | C9: ='B1 (Res) Branca OK'!C9 -> 0.00018774721 | D9: ='B1 (Res) Branca OK'!D9 -> -0.0044031307 | E9: =SUM(C9+D9) -> -0.0042153835 | F9: =T13 -> 0.00018418923 | G9: =U13 -> -0.00053182975 | H9: =F9+G9 -> -0.00034764052 | I9: =((C9*$C$15)+(F9*$D$15))/($D$15+$C$15) -> 0.00018620542 | J9: =((D9*$C$15)+(G9*$D$15))/($D$15+$C$15) -> -0.002725567 | K9: =I9+J9 -> -0.0025393616
P10: CUSTO | R10: Part. TUSD (%) | S10: Part. TE (%) | T10: Tusd (R$/kWh) | U10: TE (R$/kWh)
H11: Fatura | L11: Vigência das Tarifas (troca Bandeira): | M11: 45968 | P11: CDE CONTAS
B12: INSTALAÇÃO | C12: 1831902 | H12: =E15 -> 46253 | K12: Altere a bandeira na célula abaixo | P12: CDE COVID | U12: 0
K13: ='B1 (Res) Branca OK'!K13 -> BAM | L13: ='B1 (Res) Branca OK'!L13 -> BAM | P13: CDE ESCASSEZ HÍDRICA | T13: ='B1 (Res) Branca OK'!T13 -> 0.00018418923 | U13: ='B1 (Res) Branca OK'!U13 -> -0.00053182975
B14: Leitura Anterior | C14: Nº de dias tarifa Anterior | D14: Nº de dias tarifa Nova | E14: Leitura Atual | J14: Leitura Anterior | K14: Nº de dias tarifa Anterior | L14: Nº de dias tarifa Nova | M14: Leitura Atual
B15: 46223 | C15: =IF((F2-B15-1)<0,0,(F2-B15-1)) -> 17 | D15: =E15-F2+1 -> 13 | E15: 46253 | J15: =B15 -> 46223 | K15: =IF((M11-J15-1)<0,0,(M11-J15-1)) -> 0 | L15: =M15-M11+1 -> 286 | M15: =E15 -> 46253 | O15: Documento impressão: | Q15: 1025310390
B17: Descrição | C17: Unidade | D17: Quantidade | E17: Preço Unit (R$) com tributos | F17: Valor Total (R$) | G17: PIS/COFINS (R$) | H17: Base de Cálculo ICMS (R$) | I17: Alíquota ICMS (%) | J17: ICMS (R$) | K17: Preço Unit (R$) | L17: Tributos | M17: Base de Cálc (R$) | N17: Alíquota (%) | O17: Valor (R$)
B19: TUSD - Consumo Ponta | C19: kWh | D19: 0 | E19: =IFERROR((ROUND(D19*K19,2)+ROUND(G19,2)+ROUND(J19,2))/ROUND(D19,4), 0) -> 0 | F19: =ROUND(D19*E19,2) -> 0 | G19: =((D19*K19)/(1-$N$19-$N$20))*($N$19+$N$20) -> 0 | H19: =(IF($I$19=12%,(D19*K19)/(1-$N$19-$N$20)/(1-$C$85)/$F$85*$C$85,(D19*K19)/(1-$N$19-$N$20)/(1-$I$19))) -> 0 | I19: 0.12 | J19: =H19*$I$19 -> 0 | K19: =IF(AND($B$15<$F$2,$E$15<$F$2),C6,IF($B$15<$F$2,I6,F6)) -> 1.0903407 | L19: PIS | M19: =D52 -> 265 | N19: ='B1 (Res) Branca OK'!N19 -> 0.011 | O19: =ROUND(M19*N19,2) -> 2.92
B20: TUSD - Consumo Intermediário | C20: kWh | D20: 2 | E20: =IFERROR((ROUND(D20*K20,2)+ROUND(G20,2)+ROUND(J20,2))/ROUND(D20,4), 0) -> 0.83 | F20: =ROUND(D20*E20,2) -> 1.66 | G20: =((D20*K20)/(1-$N$19-$N$20))*($N$19+$N$20) -> 0.098280347 | H20: =(IF($I$19=12%,(D20*K20)/(1-$N$19-$N$20)/(1-$C$85)/$F$85*$C$85,(D20*K20)/(1-$N$19-$N$20)/(1-$I$19))) -> 0.55308137 | I20: =I19 -> 0.12 | J20: =H20*$I$19 -> 0.066369764 | K20: =IF(AND($B$15<$F$2,$E$15<$F$2),C8,IF($B$15<$F$2,I8,F8)) -> 0.747297 | L20: COFINS | M20: =M19 -> 265 | N20: ='B1 (Res) Branca OK'!N20 -> 0.0507 | O20: =ROUND(M20*N20,2) -> 13.44 | Q20: TUSD Fio B | R20: Receita Fio B
B21: TUSD - Consumo Fora Ponta | C21: kWh | D21: 265 | E21: =IFERROR((ROUND(D21*K21,2)+ROUND(G21,2)+ROUND(J21,2))/ROUND(D21,4), 0) -> 0.44879245 | F21: =ROUND(D21*E21,2) -> 118.93 | G21: =((D21*K21)/(1-$N$19-$N$20))*($N$19+$N$20) -> 7.044307 | H21: =(IF($I$19=12%,(D21*K21)/(1-$N$19-$N$20)/(1-$C$85)/$F$85*$C$85,(D21*K21)/(1-$N$19-$N$20)/(1-$I$19))) -> 39.642463 | I21: =I19 -> 0.12 | J21: =H21*$I$19 -> 4.7570955 | K21: =IF(AND($B$15<$F$2,$E$15<$F$2),C7,IF($B$15<$F$2,I7,F7)) -> 0.404249 | Q21: =IF(AND($B$15<$F$2,$E$15<$F$2),R6,IF($B$15<$F$2,X6,U6)) -> 0.70086387 | R21: =D51*Q21 -> 0
B22: TUSD - Consumo Reservado | C22: kWh | D22: 586 | E22: =IFERROR((ROUND(D22*K22,2)+ROUND(G22,2)+ROUND(J22,2))/ROUND(D22,4), 0) -> 0.17952218 | F22: =ROUND(D22*E22,2) -> 105.2 | G22: =((D22*K22)/(1-$N$19-$N$20))*($N$19+$N$20) -> 6.2308889 | H22: =(IF($I$19=12%,(D22*K22)/(1-$N$19-$N$20)/(1-$C$85)/$F$85*$C$85,(D22*K22)/(1-$N$19-$N$20)/(1-$I$19))) -> 35.06488 | I22: =I20 -> 0.12 | J22: =H22*$I$19 -> 4.2077856 | K22: =ROUND(K21+(K21*(-$H$46)),8) -> 0.1616996 | Q22: =IF(AND($B$15<$F$2,$E$15<$F$2),R7,IF($B$15<$F$2,X7,U7)) -> 0.14017275 | R22: =D52*Q22 -> 37.14578
Q23: =IF(AND($B$15<$F$2,$E$15<$F$2),R8,IF($B$15<$F$2,X8,U8)) -> 0.42051836 | R23: =D53*Q23 -> 0.84103673
B24: TE - Consumo Ponta | C24: kWh | D24: =D19 -> 0 | E24: =IFERROR((ROUND(D24*K24,2)+ROUND(G24,2)+ROUND(J24,2))/ROUND(D24,4), 0) -> 0 | F24: =ROUND(D24*E24,2) -> 0 | G24: =((D24*K24)/(1-$N$19-$N$20))*($N$19+$N$20) -> 0 | H24: =(IF($I$19=12%,(D24*K24)/(1-$N$19-$N$20)/(1-$C$85)/$F$85*$C$85,(D24*K24)/(1-$N$19-$N$20)/(1-$I$19))) -> 0 | J24: =H24*$I$19 -> 0 | K24: =IF(AND($B$15<$F$2,$E$15<$F$2),D6,IF($B$15<$F$2,J6,G6)) -> 0.498533 | Q24: =IF(AND($B$15<$F$2,$E$15<$F$2),R7,IF($B$15<$F$2,(X7-(X7*H46)),U7)) -> 0.056069101 | R24: =D54*Q24 -> 32.856493
B25: TE - Consumo Intermediário | C25: kWh | D25: =D20 -> 2 | E25: =IFERROR((ROUND(D25*K25,2)+ROUND(G25,2)+ROUND(J25,2))/ROUND(D25,4), 0) -> 0.345 | F25: =ROUND(D25*E25,2) -> 0.69 | G25: =((D25*K25)/(1-$N$19-$N$20))*($N$19+$N$20) -> 0.041086602 | H25: =(IF($I$19=12%,(D25*K25)/(1-$N$19-$N$20)/(1-$C$85)/$F$85*$C$85,(D25*K25)/(1-$N$19-$N$20)/(1-$I$19))) -> 0.2312185 | J25: =H25*$I$19 -> 0.02774622 | K25: =IF(AND($B$15<$F$2,$E$15<$F$2),D8,IF($B$15<$F$2,J8,G8)) -> 0.31241133 | R25: =-R24*H46 -> -19.713896 | S25: Não esta considerando o desconto do reservado.
B26: TE - Consumo Fora Ponta | C26: kWh | D26: =D21 -> 265 | E26: =IFERROR((ROUND(D26*K26,2)+ROUND(G26,2)+ROUND(J26,2))/ROUND(D26,4), 0) -> 0.34683019 | F26: =ROUND(D26*E26,2) -> 91.91 | G26: =((D26*K26)/(1-$N$19-$N$20))*($N$19+$N$20) -> 5.4439747 | H26: =(IF($I$19=12%,(D26*K26)/(1-$N$19-$N$20)/(1-$C$85)/$F$85*$C$85,(D26*K26)/(1-$N$19-$N$20)/(1-$I$19))) -> 30.636451 | J26: =H26*$I$19 -> 3.6763741 | K26: =IF(AND($B$15<$F$2,$E$15<$F$2),D7,IF($B$15<$F$2,J7,G7)) -> 0.31241133 | R26: =SUM(R21:R25) -> 51.129414
B27: TE - Consumo Reservado | C27: kWh | D27: =D22 -> 586 | E27: =IFERROR((ROUND(D27*K27,2)+ROUND(G27,2)+ROUND(J27,2))/ROUND(D27,4), 0) -> 0.1387372 | F27: =ROUND(D27*E27,2) -> 81.3 | G27: =((D27*K27)/(1-$N$19-$N$20))*($N$19+$N$20) -> 4.8153496 | H27: =(IF($I$19=12%,(D27*K27)/(1-$N$19-$N$20)/(1-$C$85)/$F$85*$C$85,(D27*K27)/(1-$N$19-$N$20)/(1-$I$19))) -> 27.098807 | J27: =H27*$I$19 -> 3.2518568 | K27: =ROUND(K26+(K26*(-$H$46)),8) -> 0.12496453
B29: Adicional BAM | C29: kWh | D29: =IF($K$13=M4,(($D$19+$D$20+$D$21+$D$22)*($K$15)/($K$15+$L$15)),0)+IF($L$13=M4,(($D$19+$D$20+$D$21+$D$22)*($L$15)/($K$15+$L$15)),0) -> 853 | E29: =IFERROR((ROUND(D29*K29,2)+ROUND(G29,2)+ROUND(J29,2))/ROUND(D29,4), 0) -> 0.012297773 | F29: =ROUND(D29*E29,2) -> 10.49 | G29: =((D29*K29)/(1-$N$19-$N$20))*($N$19+$N$20) -> 0.62149714 | H29: =(IF($I$19=12%,(D29*K29)/(1-$N$19-$N$20)/(1-$C$85)/$F$85*$C$85,(D29*K29)/(1-$N$19-$N$20)/(1-$I$19))) -> 3.4975303 | J29: =H29*$I$19 -> 0.41970363 | K29: =J62 -> 0.011080176
B30: Adicional BVM 1 | C30: kWh | D30: =IF($K$13=M5,(($D$19+$D$20+$D$21+$D$22)*($K$15)/($K$15+$L$15)),0)+IF($L$13=M5,(($D$19+$D$20+$D$21+$D$22)*($L$15)/($K$15+$L$15)),0) -> 0 | E30: =IFERROR((ROUND(D30*K30,2)+ROUND(G30,2)+ROUND(J30,2))/ROUND(D30,4), 0) -> 0 | F30: =ROUND(D30*E30,2) -> 0 | G30: =((D30*K30)/(1-$N$19-$N$20))*($N$19+$N$20) -> 0 | H30: =(IF($I$19=12%,(D30*K30)/(1-$N$19-$N$20)/(1-$C$85)/$F$85*$C$85,(D30*K30)/(1-$N$19-$N$20)/(1-$I$19))) -> 0 | J30: =H30*$I$19 -> 0 | K30: =J63 -> 0.04463
B31: Adicional BVM 2 | C31: kWh | D31: =IF($K$13=M6,(($D$19+$D$20+$D$21+$D$22)*($K$15)/($K$15+$L$15)),0)+IF($L$13=M6,(($D$19+$D$20+$D$21+$D$22)*($L$15)/($K$15+$L$15)),0) -> 0 | E31: =IFERROR((ROUND(D31*K31,2)+ROUND(G31,2)+ROUND(J31,2))/ROUND(D31,4), 0) -> 0 | F31: =ROUND(D31*E31,2) -> 0 | G31: =((D31*K31)/(1-$N$19-$N$20))*($N$19+$N$20) -> 0 | H31: =(IF($I$19=12%,(D31*K31)/(1-$N$19-$N$20)/(1-$C$85)/$F$85*$C$85,(D31*K31)/(1-$N$19-$N$20)/(1-$I$19))) -> 0 | J31: =H31*$I$19 -> 0 | K31: =J64 -> 0.07877 | AG31: =(D22*K30)/(1-$N$19-$N$20)/(1-$I$19) -> 31.673796
B32: Adicional Escassez | C32: kWh | D32: =IF($K$13=M7,(($D$19+$D$20+$D$21+$D$22)*($K$15)/($K$15+$L$15)),0)+IF($L$13=M7,(($D$19+$D$20+$D$21+$D$22)*($L$15)/($K$15+$L$15)),0) -> 0 | E32: =IFERROR((ROUND(D32*K32,2)+ROUND(G32,2)+ROUND(J32,2))/ROUND(D32,4), 0) -> 0 | F32: =ROUND(D32*E32,2) -> 0 | G32: =((D32*K32)/(1-$N$19-$N$20))*($N$19+$N$20) -> 0 | H32: =(IF($I$19=12%,(D32*K32)/(1-$N$19-$N$20)/(1-$C$85)/$F$85*$C$85,(D32*K32)/(1-$N$19-$N$20)/(1-$I$19))) -> 0 | J32: =H32*$I$19 -> 0 | K32: =J65 -> 0.142
B34: Multas
B35: Juros
B36: Doações
B37: CIP
B40: TOTAL | F40: =SUM(F19:F39) -> 410.18 | G40: =SUM(G19:G39) -> 24.295384 | H40: =SUM(H19:H39) -> 136.72443 | J40: =SUM(J19:J39) -> 16.406932
B42: Informativo Escassez | C42: =D19+D20+D21+D22 -> 853 | D42: =IF(AND($B$15<$F$2,$E$15<$F$2),C9,IF($B$15<$F$2,I9,F9)) -> 0.00018620542 | E42: =IF(AND($B$15<$F$2,$E$15<$F$2),D9,IF($B$15<$F$2,J9,G9)) -> -0.002725567 | F42: =C42*(D42+E42)+((D22*(D42+E42))*(-$H$46)) -> -1.2732359
B44: Desconto Rural Irrigante | F44: =SUM(H55+H68+H69+H70+H71) -> -258.606
G46: desconto: | H46: 0.6
B47: Fatura B2 Rural TB
D48: Qtde | E48: TUSD | F48: TE | G48: TUSD + TE | H48: R$
B49: Fornecimento de Energia Elétrica | H49: =SUM(H51:H60)+SUM(H73:H75) -> 469.98834
B51: Consumo Ponta | D51: =D19 -> 0 | E51: =IF(AND($B$15<$F$2,$E$15<$F$2),C6,IF($B$15<$F$2,I6,F6)) -> 1.0903407 | F51: =IF(AND($B$15<$F$2,$E$15<$F$2),D6,IF($B$15<$F$2,J6,G6)) -> 0.498533 | G51: =E51+F51 -> 1.5888737 | H51: =ROUND((D51*E51),2)+ROUND((D51*F51),2) -> 0
...

Sheet B3 Branca OK
B2: B3 | E2: Vigência das Tarifas: | F2: ='B1 (Res) Branca OK'!F2 -> 46241 | H2: TARIFA BRANCA | M2: Bandeira | N2: R$/kWh | Q2: TUSD FIO B
M3: VERDE | N3: ='B1 (Res) Branca OK'!N3 -> 0
B4: TARIFA | C4: ='B1 (Res) Branca OK'!C4 -> TARIFA ANTIGA - REH 3370/2024 | F4: ='B1 (Res) Branca OK'!F4 -> TARIFA NOVA - REH xxxx/2025 | I4: Tarifas Proporcionalizadas | M4: BAM | N4: ='B1 (Res) Branca OK'!N4 -> 0.01885 | Q4: TARIFA | R4: =C4 -> TARIFA ANTIGA - REH 3370/2024 | U4: =F4 -> TARIFA NOVA - REH xxxx/2025 | X4: Tarifas Proporcionalizadas
C5: Tusd | D5: TE | E5: TUSD + TE | F5: Tusd | G5: TE | H5: TUSD + TE | I5: Tusd | J5: TE | K5: TUSD + TE | M5: BVM1 | N5: ='B1 (Res) Branca OK'!N5 -> 0.04463 | R5: Tusd (R$/kWh) | U5: Tusd (R$/kWh) | X5: Tusd (R$/kWh)
B6: B3 Ponta | C6: ='TABELA DE TARIFAS ANTIGAS'!G86/1000 -> 1.06103 | D6: ='TABELA DE TARIFAS ANTIGAS'!H86/1000 -> 0.48448 | E6: =C6+D6 -> 1.54551 | F6: ='TABELA DE TARIFAS NOVAS'!G88/1000 -> 1.12867 | G6: ='TABELA DE TARIFAS NOVAS'!H88/1000 -> 0.51691 | H6: =F6+G6 -> 1.64558 | I6: =((C6*$C$15)+(F6*$D$15))/($D$15+$C$15) -> 1.0925953 | J6: =((D6*$C$15)+(G6*$D$15))/($D$15+$C$15) -> 0.499614 | K6: =I6+J6 -> 1.5922093 | M6: BVM2 | N6: ='B1 (Res) Branca OK'!N6 -> 0.07877 | Q6: =B6 -> B3 Ponta | R6: ='FIO B'!H31/1000 -> 0.69302445 | U6: ='FIO B'!K31/1000 -> 0.71111541 | X6: =((R6*$C$46)+(U6*$D$46))/($D$46+$C$46) -> 0.7014669
B7: B3 Fora Ponta | C7: ='TABELA DE TARIFAS ANTIGAS'!G88/1000 -> 0.38965 | D7: ='TABELA DE TARIFAS ANTIGAS'!H88/1000 -> 0.30579 | E7: =C7+D7 -> 0.69544 | F7: ='TABELA DE TARIFAS NOVAS'!G90/1000 -> 0.42334 | G7: ='TABELA DE TARIFAS NOVAS'!H90/1000 -> 0.32107 | H7: =F7+G7 -> 0.74441 | I7: =((C7*$C$15)+(F7*$D$15))/($D$15+$C$15) -> 0.405372 | J7: =((D7*$C$15)+(G7*$D$15))/($D$15+$C$15) -> 0.31292067 | K7: =I7+J7 -> 0.71829267 | M7: Escassez Hídrica | N7: ='B1 (Res) Branca OK'!N7 -> 0.142 | Q7: =B7 -> B3 Fora Ponta | R7: ='FIO B'!H33/1000 -> 0.13860487 | U7: ='FIO B'!K33/1000 -> 0.14222306 | X7: =((R7*$C$46)+(U7*$D$46))/($D$46+$C$46) -> 0.14029336
B8: B3 Interm. | C8: ='TABELA DE TARIFAS ANTIGAS'!G87/1000 -> 0.72534 | D8: ='TABELA DE TARIFAS ANTIGAS'!H87/1000 -> 0.30579 | E8: =C8+D8 -> 1.03113 | F8: ='TABELA DE TARIFAS NOVAS'!G89/1000 -> 0.77601 | G8: ='TABELA DE TARIFAS NOVAS'!H89/1000 -> 0.32107 | H8: =F8+G8 -> 1.09708 | I8: =((C8*$C$15)+(F8*$D$15))/($D$15+$C$15) -> 0.748986 | J8: =((D8*$C$15)+(G8*$D$15))/($D$15+$C$15) -> 0.31292067 | K8: =I8+J8 -> 1.0619067 | Q8: =B8 -> B3 Interm. | R8: ='FIO B'!H32/1000 -> 0.41581471 | U8: ='FIO B'!K32/1000 -> 0.42666929 | X8: =((R8*$C$46)+(U8*$D$46))/($D$46+$C$46) -> 0.42088018
B9: CDE Escassez Hídrica | C9: ='B1 (Res) Branca OK'!C9 -> 0.00018774721 | D9: ='B1 (Res) Branca OK'!D9 -> -0.0044031307 | E9: =SUM(C9+D9) -> -0.0042153835 | F9: =T13 -> 0.00018418923 | G9: =U13 -> -0.00053182975 | H9: =F9+G9 -> -0.00034764052 | I9: =((C9*$C$15)+(F9*$D$15))/($D$15+$C$15) -> 0.00018608682 | J9: =((D9*$C$15)+(G9*$D$15))/($D$15+$C$15) -> -0.0025965236 | K9: =I9+J9 -> -0.0024104368
P10: CUSTO | R10: Part. TUSD (%) | S10: Part. TE (%) | T10: Tusd (R$/kWh) | U10: TE (R$/kWh)
H11: Fatura | L11: Vigência das Tarifas (troca Bandeira): | M11: =EOMONTH(B15,0)+1 -> 46235 | P11: CDE CONTAS
B12: INSTALAÇÃO | C12: 160008463 | H12: =E15 -> 46254 | K12: Altere a bandeira na célula abaixo | P12: CDE COVID | U12: 0
K13: ='B1 (Res) Branca OK'!K13 -> BAM | L13: ='B1 (Res) Branca OK'!L13 -> BAM | P13: CDE ESCASSEZ HÍDRICA | T13: ='B1 (Res) Branca OK'!T13 -> 0.00018418923 | U13: ='B1 (Res) Branca OK'!U13 -> -0.00053182975
B14: Leitura Anterior | C14: Nº de dias tarifa Anterior | D14: Nº de dias tarifa Nova | E14: Leitura Atual | J14: Leitura Anterior | K14: Nº de dias tarifa Anterior | L14: Nº de dias tarifa Nova | M14: Leitura Atual
B15: 46224 | C15: =IF((F2-B15-1)<0,0,(F2-B15-1)) -> 16 | D15: =E15-F2+1 -> 14 | E15: 46254 | J15: =B15 -> 46224 | K15: =IF((M11-J15-1)<0,0,(M11-J15-1)) -> 10 | L15: =M15-M11+1 -> 20 | M15: =E15 -> 46254 | O15: Documento impressão: | Q15: 1025310394
B17: Descrição | C17: Unidade | D17: Quantidade | E17: Preço Unit (R$) com tributos | F17: Valor Total (R$) | G17: PIS/COFINS (R$) | H17: Base de Cálculo ICMS (R$) | I17: Alíquota ICMS (%) | J17: ICMS (R$) | K17: Preço Unit (R$) | L17: Tributos | M17: Base de Cálc (R$) | N17: Alíquota (%) | O17: Valor (R$)
B19: TUSD - Consumo Ponta | C19: kWh | D19: 19 | E19: =IFERROR((ROUND(D19*K19,2)+ROUND(G19,2)+ROUND(J19,2))/ROUND(D19,4), 0) -> 1.4031579 | F19: =ROUND(D19*E19,2) -> 26.66 | G19: =((D19*K19)/(1-$N$19-$N$20))*($N$19+$N$20) -> 1.3650746 | H19: =ROUND((D19*K19)/(1-$N$19-$N$20)/(1-$I$19),8) -> 26.655887 | I19: 0.17 | J19: =H19*$I$19 -> 4.5315007 | K19: =IF(AND($B$15<$F$2,$E$15<$F$2),C6,IF($B$15<$F$2,I6,F6)) -> 1.0925953 | L19: PIS | M19: =D66 -> 289.87531 | N19: ='B1 (Res) Branca OK'!N19 -> 0.011 | O19: =ROUND(M19*N19,2) -> 3.19 | R19: TUSD Fio B | S19: Receita Fio B
B20: TUSD - Consumo Intermediário | C20: kWh | D20: 16 | E20: =IFERROR((ROUND(D20*K20,2)+ROUND(G20,2)+ROUND(J20,2))/ROUND(D20,4), 0) -> 0.961875 | F20: =ROUND(D20*E20,2) -> 15.39 | G20: =((D20*K20)/(1-$N$19-$N$20))*($N$19+$N$20) -> 0.7880198 | H20: =ROUND((D20*K20)/(1-$N$19-$N$20)/(1-$I$19),8) -> 15.387706 | I20: =I19 -> 0.17 | J20: =H20*$I$19 -> 2.61591 | K20: =IF(AND($B$15<$F$2,$E$15<$F$2),C8,IF($B$15<$F$2,I8,F8)) -> 0.748986 | L20: COFINS | M20: =M19 -> 289.87531 | N20: ='B1 (Res) Branca OK'!N20 -> 0.0507 | O20: =ROUND(M20*N20,2) -> 14.7 | R20: =IF(AND($B$46<$F$2,$E$46<$F$2),R6,IF($B$46<$F$2,X6,U6)) -> 0.7014669 | S20: =D52*R20 -> 13.327871
B21: TUSD - Consumo Fora Ponta | C21: kWh | D21: 304 | E21: =IFERROR((ROUND(D21*K21,2)+ROUND(G21,2)+ROUND(J21,2))/ROUND(D21,4), 0) -> 0.52049342 | F21: =ROUND(D21*E21,2) -> 158.23 | G21: =((D21*K21)/(1-$N$19-$N$20))*($N$19+$N$20) -> 8.1034653 | H21: =ROUND((D21*K21)/(1-$N$19-$N$20)/(1-$I$19),8) -> 158.23681 | I21: =I19 -> 0.17 | J21: =H21*$I$19 -> 26.900258 | K21: =IF(AND($B$15<$F$2,$E$15<$F$2),C7,IF($B$15<$F$2,I7,F7)) -> 0.405372 | R21: =IF(AND($B$46<$F$2,$E$46<$F$2),R7,IF($B$46<$F$2,X7,U7)) -> 0.14029336 | S21: =D53*R21 -> 42.649181
B22: TE - Consumo Ponta | C22: kWh | D22: =D19 -> 19 | E22: =IFERROR((ROUND(D22*K22,2)+ROUND(G22,2)+ROUND(J22,2))/ROUND(D22,4), 0) -> 0.64105263 | F22: =ROUND(D22*E22,2) -> 12.18 | G22: =((D22*K22)/(1-$N$19-$N$20))*($N$19+$N$20) -> 0.62421133 | H22: =(D22*K22)/(1-$N$19-$N$20)/(1-$I$19) -> 12.189009 | J22: =H22*$I$19 -> 2.0721315 | K22: =IF(AND($B$15<$F$2,$E$15<$F$2),D6,IF($B$15<$F$2,J6,G6)) -> 0.499614 | R22: =IF(AND($B$46<$F$2,$E$46<$F$2),R8,IF($B$46<$F$2,X8,U8)) -> 0.42088018 | S22: =D54*R22 -> 6.7340829
B23: TE - Consumo Intermediário | C23: kWh | D23: =D20 -> 16 | E23: =IFERROR((ROUND(D23*K23,2)+ROUND(G23,2)+ROUND(J23,2))/ROUND(D23,4), 0) -> 0.401875 | F23: =ROUND(D23*E23,2) -> 6.43 | G23: =((D23*K23)/(1-$N$19-$N$20))*($N$19+$N$20) -> 0.32922869 | H23: =(D23*K23)/(1-$N$19-$N$20)/(1-$I$19) -> 6.4288667 | J23: =H23*$I$19 -> 1.0929073 | K23: =IF(AND($B$15<$F$2,$E$15<$F$2),D8,IF($B$15<$F$2,J8,G8)) -> 0.31292067 | S23: =SUM(S20:S22) -> 62.711136
B24: TE - Consumo Fora Ponta | C24: kWh | D24: =D21 -> 304 | E24: =IFERROR((ROUND(D24*K24,2)+ROUND(G24,2)+ROUND(J24,2))/ROUND(D24,4), 0) -> 0.40184211 | F24: =ROUND(D24*E24,2) -> 122.16 | G24: =((D24*K24)/(1-$N$19-$N$20))*($N$19+$N$20) -> 6.2553452 | H24: =(D24*K24)/(1-$N$19-$N$20)/(1-$I$19) -> 122.14847 | J24: =H24*$I$19 -> 20.765239 | K24: =IF(AND($B$15<$F$2,$E$15<$F$2),D7,IF($B$15<$F$2,J7,G7)) -> 0.31292067
B25: Adicional BAM | C25: kWh | D25: =IF($K$13=M4,(($D$19+$D$20+$D$21)*($K$15)/($K$15+$L$15)),0)+IF($L$13=M4,(($D$19+$D$20+$D$21)*($L$15)/($K$15+$L$15)),0) -> 339 | E25: =IFERROR((ROUND(D25*K25,2)+ROUND(G25,2)+ROUND(J25,2))/ROUND(D25,4), 0) -> 0.024188791 | F25: =ROUND(D25*E25,2) -> 8.2 | G25: =((D25*K25)/(1-$N$19-$N$20))*($N$19+$N$20) -> 0.4201985 | H25: =(D25*K25)/(1-$N$19-$N$20)/(1-$I$19) -> 8.2052392 | J25: =H25*$I$19 -> 1.3948907 | K25: =N4 -> 0.01885
B26: Adicional BVM 1 | C26: kWh | D26: =IF($K$13=M5,(($D$19+$D$20+$D$21)*($K$15)/($K$15+$L$15)),0)+IF($L$13=M5,(($D$19+$D$20+$D$21)*($L$15)/($K$15+$L$15)),0) -> 0 | E26: =K26/(1-$N$19-$N$20)/(1-$I$19) -> 0.057306921 | F26: =ROUND(D26*E26,2) -> 0 | G26: =((D26*K26)/(1-$N$19-$N$20))*($N$19+$N$20) -> 0 | H26: =(D26*K26)/(1-$N$19-$N$20)/(1-$I$19) -> 0 | J26: =H26*$I$19 -> 0 | K26: =N5 -> 0.04463
B27: Adicional BVM 2 | C27: kWh | D27: =IF($K$13=M6,(($D$19+$D$20+$D$21)*($K$15)/($K$15+$L$15)),0)+IF($L$13=M6,(($D$19+$D$20+$D$21)*($L$15)/($K$15+$L$15)),0) -> 0 | E27: =K27/(1-$N$19-$N$20)/(1-$I$19) -> 0.10114421 | F27: =ROUND(D27*E27,2) -> 0 | G27: =((D27*K27)/(1-$N$19-$N$20))*($N$19+$N$20) -> 0 | H27: =(D27*K27)/(1-$N$19-$N$20)/(1-$I$19) -> 0 | J27: =H27*$I$19 -> 0 | K27: =N6 -> 0.07877
B28: Adicional Escassez | C28: kWh | D28: =IF($K$13=M7,(($D$19+$D$20+$D$21)*($K$15)/($K$15+$L$15)),0)+IF($L$13=M7,(($D$19+$D$20+$D$21)*($L$15)/($K$15+$L$15)),0) -> 0 | E28: =K28/(1-$N$19-$N$20)/(1-$I$19) -> 0.18233437 | F28: =ROUND(D28*E28,2) -> 0 | G28: =((D28*K28)/(1-$N$19-$N$20))*($N$19+$N$20) -> 0 | H28: =(D28*K28)/(1-$N$19-$N$20)/(1-$I$19) -> 0 | J28: =H28*$I$19 -> 0 | K28: =N7 -> 0.142
B29: Multas
B30: Juros
B31: Doações
B32: CIP | F32: 61.03
B35: TOTAL | F35: =SUM(F19:F34) -> 410.28 | G35: =SUM(G19:G34) -> 17.885543 | H35: =SUM(H19:H34) -> 349.25199 | J35: =SUM(J19:J34) -> 59.372838
B37: Informativo Escassez | C37: =D19+D20+D21 -> 339 | D37: =IF(AND($B$15<$F$2,$E$15<$F$2),C9,IF($B$15<$F$2,I9,F9)) -> 0.00018608682 | E37: =IF(AND($B$15<$F$2,$E$15<$F$2),D9,IF($B$15<$F$2,J9,G9)) -> -0.0025965236 | F37: =C37*(D37+E37) -> -0.81713807
H42: Fatura | L42: Vigência das Tarifas (troca Bandeira): | M42: =EOMONTH(B46,0)+1 -> 46235
B43: INSTALAÇÃO | C43: =C12 -> 160008463 | H43: =E46 -> 46254 | K43: Altere a bandeira na célula abaixo
K44: =K13 -> BAM | L44: =L13 -> BAM
B45: Leitura Anterior | C45: Nº de dias tarifa Anterior | D45: Nº de dias tarifa Nova | E45: Leitura Atual | J45: Leitura Anterior | K45: Nº de dias tarifa Anterior | L45: Nº de dias tarifa Nova | M45: Leitura Atual
B46: =B15 -> 46224 | C46: =IF((F2-B46-1)<0,0,(F2-B46-1)) -> 16 | D46: =E46-F2+1 -> 14 | E46: =E15 -> 46254 | J46: =B46 -> 46224 | K46: =IF((M42-J46-1)<0,0,(M42-J46-1)) -> 10 | L46: =M46-M42+1 -> 20 | M46: =E46 -> 46254
B48: Fatura B3 - TB
D49: Qtde | E49: TUSD | F49: TE | G49: TUSD + TE | H49: R$
B50: Fornecimento de Energia Elétrica | H50: =SUM(H52:H60)+SUM(H66:H68) -> 349.24736
B52: Consumo Ponta | D52: =D19 -> 19 | E52: =IF(AND($B$46<$F$2,$E$46<$F$2),C6,IF($B$46<$F$2,I6,F6)) -> 1.0925953 | F52: =IF(AND($B$46<$F$2,$E$46<$F$2),D6,IF($B$46<$F$2,J6,G6)) -> 0.499614 | G52: 1.325 | H52: =ROUND((D52*E52),2)+ROUND((D52*F52),2) -> 30.25
...

Sheet B3 PPF Branca OK
B2: B3 | E2: Vigência das Tarifas: | F2: ='B1 (Res) Branca OK'!F2 -> 46241 | H2: TARIFA BRANCA | M2: Bandeira | N2: R$/kWh | Q2: TUSD FIO B
M3: VERDE | N3: ='B1 (Res) Branca OK'!N3 -> 0
B4: TARIFA | C4: ='B1 (Res) Branca OK'!C4 -> TARIFA ANTIGA - REH 3370/2024 | F4: ='B1 (Res) Branca OK'!F4 -> TARIFA NOVA - REH xxxx/2025 | I4: Tarifas Proporcionalizadas | M4: BAM | N4: ='B1 (Res) Branca OK'!N4 -> 0.01885 | Q4: TARIFA | R4: =C4 -> TARIFA ANTIGA - REH 3370/2024 | U4: =F4 -> TARIFA NOVA - REH xxxx/2025 | X4: Tarifas Proporcionalizadas
C5: Tusd | D5: TE | E5: TUSD + TE | F5: Tusd | G5: TE | H5: TUSD + TE | I5: Tusd | J5: TE | K5: TUSD + TE | M5: BVM1 | N5: ='B1 (Res) Branca OK'!N5 -> 0.04463 | R5: Tusd (R$/kWh) | U5: Tusd (R$/kWh) | X5: Tusd (R$/kWh)
B6: B3 Ponta | C6: ='TABELA DE TARIFAS ANTIGAS'!G86/1000 -> 1.06103 | D6: ='TABELA DE TARIFAS ANTIGAS'!H86/1000 -> 0.48448 | E6: =C6+D6 -> 1.54551 | F6: ='TABELA DE TARIFAS NOVAS'!G88/1000 -> 1.12867 | G6: ='TABELA DE TARIFAS NOVAS'!H88/1000 -> 0.51691 | H6: =F6+G6 -> 1.64558 | I6: =((C6*$C$50)+(F6*$D$50))/($D$50+$C$50) -> 1.0903407 | J6: =((D6*$C$50)+(G6*$D$50))/($D$50+$C$50) -> 0.498533 | K6: =I6+J6 -> 1.5888737 | M6: BVM2 | N6: ='B1 (Res) Branca OK'!N6 -> 0.07877 | Q6: =B6 -> B3 Ponta | R6: ='FIO B'!H31/1000 -> 0.69302445 | U6: ='FIO B'!K31/1000 -> 0.71111541 | X6: =((R6*$C$50)+(U6*$D$50))/($D$50+$C$50) -> 0.70086387
B7: B3 Fora Ponta | C7: ='TABELA DE TARIFAS ANTIGAS'!G88/1000 -> 0.38965 | D7: ='TABELA DE TARIFAS ANTIGAS'!H88/1000 -> 0.30579 | E7: =C7+D7 -> 0.69544 | F7: ='TABELA DE TARIFAS NOVAS'!G90/1000 -> 0.42334 | G7: ='TABELA DE TARIFAS NOVAS'!H90/1000 -> 0.32107 | H7: =F7+G7 -> 0.74441 | I7: =((C7*$C$50)+(F7*$D$50))/($D$50+$C$50) -> 0.404249 | J7: =((D7*$C$50)+(G7*$D$50))/($D$50+$C$50) -> 0.31241133 | K7: =I7+J7 -> 0.71666033 | M7: Escassez Hídrica | N7: ='B1 (Res) Branca OK'!N7 -> 0.142 | Q7: =B7 -> B3 Fora Ponta | R7: ='FIO B'!H33/1000 -> 0.13860487 | U7: ='FIO B'!K33/1000 -> 0.14222306 | X7: =((R7*$C$50)+(U7*$D$50))/($D$50+$C$50) -> 0.14017275
B8: B3 Interm. | C8: ='TABELA DE TARIFAS ANTIGAS'!G87/1000 -> 0.72534 | D8: ='TABELA DE TARIFAS ANTIGAS'!H87/1000 -> 0.30579 | E8: =C8+D8 -> 1.03113 | F8: ='TABELA DE TARIFAS NOVAS'!G89/1000 -> 0.77601 | G8: ='TABELA DE TARIFAS NOVAS'!H89/1000 -> 0.32107 | H8: =F8+G8 -> 1.09708 | I8: =((C8*$C$50)+(F8*$D$50))/($D$50+$C$50) -> 0.747297 | J8: =((D8*$C$50)+(G8*$D$50))/($D$50+$C$50) -> 0.31241133 | K8: =I8+J8 -> 1.0597083 | Q8: =B8 -> B3 Interm. | R8: ='FIO B'!H32/1000 -> 0.41581471 | U8: ='FIO B'!K32/1000 -> 0.42666929 | X8: =((R8*$C$50)+(U8*$D$50))/($D$50+$C$50) -> 0.42051836
B9: CDE Escassez Hídrica | C9: ='B1 (Res) Branca OK'!C9 -> 0.00018774721 | D9: ='B1 (Res) Branca OK'!D9 -> -0.0044031307 | E9: =SUM(C9+D9) -> -0.0042153835 | F9: =T13 -> 0.00018418923 | G9: =U13 -> -0.00053182975 | H9: =F9+G9 -> -0.00034764052 | I9: =((C9*$C$50)+(F9*$D$50))/($D$50+$C$50) -> 0.00018620542 | J9: =((D9*$C$50)+(G9*$D$50))/($D$50+$C$50) -> -0.002725567 | K9: =I9+J9 -> -0.0025393616
P10: CUSTO | R10: Part. TUSD (%) | S10: Part. TE (%) | T10: Tusd (R$/kWh) | U10: TE (R$/kWh)
H11: Fatura | L11: Vigência das Tarifas (troca Bandeira): | M11: =EOMONTH(B15,0)+1 -> 46235 | P11: CDE CONTAS
B12: INSTALAÇÃO | C12: 475728 | H12: =E15 -> 46253 | K12: Altere a bandeira na célula abaixo | P12: CDE COVID | U12: 0
K13: ='B2 (Rural) Branca OK'!K13 -> BAM | L13: ='B1 (Res) Branca OK'!L13 -> BAM | P13: CDE ESCASSEZ HÍDRICA | T13: ='B1 (Res) Branca OK'!T13 -> 0.00018418923 | U13: ='B1 (Res) Branca OK'!U13 -> -0.00053182975
B14: Leitura Anterior | C14: Nº de dias tarifa Anterior | D14: Nº de dias tarifa Nova | E14: Leitura Atual | J14: Leitura Anterior | K14: Nº de dias tarifa Anterior | L14: Nº de dias tarifa Nova | M14: Leitura Atual
B15: 46223 | C15: =IF((F2-B15-1)<0,0,(F2-B15-1)) -> 17 | D15: =E15-F2+1 -> 13 | E15: 46253 | J15: =B15 -> 46223 | K15: =IF((M11-J15-1)<0,0,(M11-J15-1)) -> 11 | L15: =M15-M11+1 -> 19 | M15: =E15 -> 46253
P16: Documento simulado: | R16: 1025310395
B17: Descrição | C17: Unidade | D17: Quantidade | E17: Preço Unit (R$) com tributos | F17: Valor Total (R$) | G17: PIS/COFINS (R$) | H17: Base de Cálculo ICMS (R$) | I17: Alíquota ICMS (%) | J17: ICMS (R$) | K17: Preço Unit (R$) | L17: Tributos | M17: Base de Cálc (R$) | N17: Alíquota (%) | O17: Valor (R$)
B19: TUSD - Consumo Ponta | C19: kWh | D19: 33 | E19: =IFERROR((ROUND(D19*K19,2)+ROUND(G19,2)+ROUND(J19,2))/ROUND(D19,4), 0) -> 1.4 | F19: =ROUND(D19*E19,2) -> 46.2 | G19: =((D19*K19)/(1-$N$19-$N$20))*($N$19+$N$20) -> 2.3660265 | H19: =ROUND((D19*K19)/(1-$N$19-$N$20)/(1-$I$19),8) -> 46.201528 | I19: 0.17 | J19: =H19*$I$19 -> 7.8542598 | K19: =IF(AND($B$15<$F$2,$E$15<$F$2),C6,IF($B$15<$F$2,I6,F6)) -> 1.0903407 | L19: PIS | M19: =D70 -> 228.62624 | N19: ='B1 (Res) Branca OK'!N19 -> 0.011 | O19: =ROUND(M19*N19,2) -> 2.51 | R19: TUSD Fio B | S19: Receita Fio B
B20: TUSD - Consumo Intermediário | C20: kWh | D20: 14 | E20: =IFERROR((ROUND(D20*K20,2)+ROUND(G20,2)+ROUND(J20,2))/ROUND(D20,4), 0) -> 0.95928571 | F20: =ROUND(D20*E20,2) -> 13.43 | G20: =((D20*K20)/(1-$N$19-$N$20))*($N$19+$N$20) -> 0.68796243 | H20: =ROUND((D20*K20)/(1-$N$19-$N$20)/(1-$I$19),8) -> 13.43388 | I20: =I19 -> 0.17 | J20: =H20*$I$19 -> 2.2837596 | K20: =IF(AND($B$15<$F$2,$E$15<$F$2),C8,IF($B$15<$F$2,I8,F8)) -> 0.747297 | L20: COFINS | M20: =M19 -> 228.62624 | N20: ='B1 (Res) Branca OK'!N20 -> 0.0507 | O20: =ROUND(M20*N20,2) -> 11.59 | R20: =IF(AND($B$50<$F$2,$E$50<$F$2),R6,IF($B$50<$F$2,X6,U6)) -> 0.70086387 | S20: =D56*R20 -> 23.128508
B21: TUSD - Consumo Fora Ponta | C21: kWh | D21: 199 | E21: =IFERROR((ROUND(D21*K21,2)+ROUND(G21,2)+ROUND(J21,2))/ROUND(D21,4), 0) -> 0.51909548 | F21: =ROUND(D21*E21,2) -> 103.3 | G21: =((D21*K21)/(1-$N$19-$N$20))*($N$19+$N$20) -> 5.2898758 | H21: =ROUND((D21*K21)/(1-$N$19-$N$20)/(1-$I$19),8) -> 103.29569 | I21: =I19 -> 0.17 | J21: =H21*$I$19 -> 17.560268 | K21: =IF(AND($B$15<$F$2,$E$15<$F$2),C7,IF($B$15<$F$2,I7,F7)) -> 0.404249 | R21: =IF(AND($B$50<$F$2,$E$50<$F$2),R7,IF($B$50<$F$2,X7,U7)) -> 0.14017275 | S21: =D57*R21 -> 27.894378
B22: TE - Consumo Ponta | C22: kWh | D22: =D19 -> 33 | E22: =IFERROR((ROUND(D22*K22,2)+ROUND(G22,2)+ROUND(J22,2))/ROUND(D22,4), 0) -> 0.64 | F22: =ROUND(D22*E22,2) -> 21.12 | G22: =((D22*K22)/(1-$N$19-$N$20))*($N$19+$N$20) -> 1.0818108 | H22: =(D22*K22)/(1-$N$19-$N$20)/(1-$I$19) -> 21.124578 | J22: =H22*$I$19 -> 3.5911783 | K22: =IF(AND($B$15<$F$2,$E$15<$F$2),D6,IF($B$15<$F$2,J6,G6)) -> 0.498533 | R22: =IF(AND($B$50<$F$2,$E$50<$F$2),R8,IF($B$50<$F$2,X8,U8)) -> 0.42051836 | S22: =D58*R22 -> 5.8872571
B23: TE - Consumo Intermediário | C23: kWh | D23: =D20 -> 14 | E23: =IFERROR((ROUND(D23*K23,2)+ROUND(G23,2)+ROUND(J23,2))/ROUND(D23,4), 0) -> 0.40071429 | F23: =ROUND(D23*E23,2) -> 5.61 | G23: =((D23*K23)/(1-$N$19-$N$20))*($N$19+$N$20) -> 0.28760621 | H23: =(D23*K23)/(1-$N$19-$N$20)/(1-$I$19) -> 5.6161023 | J23: =H23*$I$19 -> 0.95473739 | K23: =IF(AND($B$15<$F$2,$E$15<$F$2),D8,IF($B$15<$F$2,J8,G8)) -> 0.31241133 | S23: =SUM(S20:S22) -> 56.910143
B24: TE - Consumo Fora Ponta | C24: kWh | D24: =D21 -> 199 | E24: =IFERROR((ROUND(D24*K24,2)+ROUND(G24,2)+ROUND(J24,2))/ROUND(D24,4), 0) -> 0.40115578 | F24: =ROUND(D24*E24,2) -> 79.83 | G24: =((D24*K24)/(1-$N$19-$N$20))*($N$19+$N$20) -> 4.0881169 | H24: =(D24*K24)/(1-$N$19-$N$20)/(1-$I$19) -> 79.828882 | J24: =H24*$I$19 -> 13.57091 | K24: =IF(AND($B$15<$F$2,$E$15<$F$2),D7,IF($B$15<$F$2,J7,G7)) -> 0.31241133
B25: Adicional BAM | C25: kWh | D25: =IF($K$13=M4,(($D$19+$D$20+$D$21)*($K$15)/($K$15+$L$15)),0)+IF($L$13=M4,(($D$19+$D$20+$D$21)*($L$15)/($K$15+$L$15)),0) -> 246 | E25: =IFERROR((ROUND(D25*K25,2)+ROUND(G25,2)+ROUND(J25,2))/ROUND(D25,4), 0) -> 0.024186992 | F25: =ROUND(D25*E25,2) -> 5.95 | G25: =((D25*K25)/(1-$N$19-$N$20))*($N$19+$N$20) -> 0.30492281 | H25: =(D25*K25)/(1-$N$19-$N$20)/(1-$I$19) -> 5.9542443 | J25: =H25*$I$19 -> 1.0122215 | K25: =N4 -> 0.01885
B26: Adicional BVM 1 | C26: kWh | D26: =IF($K$13=M5,(($D$19+$D$20+$D$21)*($K$15)/($K$15+$L$15)),0)+IF($L$13=M5,(($D$19+$D$20+$D$21)*($L$15)/($K$15+$L$15)),0) -> 0 | E26: =K26/(1-$N$19-$N$20)/(1-$I$19) -> 0.057306921 | F26: =ROUND(D26*E26,2) -> 0 | G26: =((D26*K26)/(1-$N$19-$N$20))*($N$19+$N$20) -> 0 | H26: =(D26*K26)/(1-$N$19-$N$20)/(1-$I$19) -> 0 | J26: =H26*$I$19 -> 0 | K26: =N5 -> 0.04463
B27: Adicional BVM 2 | C27: kWh | D27: =IF($K$13=M6,(($D$19+$D$20+$D$21)*($K$15)/($K$15+$L$15)),0)+IF($L$13=M6,(($D$19+$D$20+$D$21)*($L$15)/($K$15+$L$15)),0) -> 0 | E27: =K27/(1-$N$19-$N$20)/(1-$I$19) -> 0.10114421 | F27: =ROUND(D27*E27,2) -> 0 | G27: =((D27*K27)/(1-$N$19-$N$20))*($N$19+$N$20) -> 0 | H27: =(D27*K27)/(1-$N$19-$N$20)/(1-$I$19) -> 0 | J27: =H27*$I$19 -> 0 | K27: =N6 -> 0.07877
B28: Adicional Escassez | C28: kWh | D28: =IF($K$13=M7,(($D$19+$D$20+$D$21)*($K$15)/($K$15+$L$15)),0)+IF($L$13=M7,(($D$19+$D$20+$D$21)*($L$15)/($K$15+$L$15)),0) -> 0 | E28: =K28/(1-$N$19-$N$20)/(1-$I$19) -> 0.18233437 | F28: =ROUND(D28*E28,2) -> 0 | G28: =((D28*K28)/(1-$N$19-$N$20))*($N$19+$N$20) -> 0 | H28: =(D28*K28)/(1-$N$19-$N$20)/(1-$I$19) -> 0 | J28: =H28*$I$19 -> 0 | K28: =N7 -> 0.142
B29: Multas
B30: Juros
B31: Retenção PIS/PASEP | F31: -1.79
B32: Retenção CSLL | F32: -2.75
B33: Retenção IR | F33: -3.31
B34: Retenção COFINS | F34: -8.26
B35: Descontos
B36: CIP | F36: 64.32
B39: TOTAL | F39: =SUM(F19:F38) -> 323.65 | G39: =SUM(G19:G38) -> 14.106321 | H39: =SUM(H19:H38) -> 275.45491 | J39: =SUM(J19:J38) -> 46.827335
B41: Informativo Escassez | C41: =D19+D20+D21 -> 246 | D41: =IF(AND($B$15<$F$2,$E$15<$F$2),C9,IF($B$15<$F$2,I9,F9)) -> 0.00018620542 | E41: =IF(AND($B$15<$F$2,$E$15<$F$2),D9,IF($B$15<$F$2,J9,G9)) -> -0.002725567 | F41: =C41*(D41+E41) -> -0.62468294
H46: Fatura | L46: Vigência das Tarifas (troca Bandeira): | M46: =EOMONTH(B50,0)+1 -> 46235
B47: INSTALAÇÃO | C47: =C12 -> 475728 | H47: =E50 -> 46253 | K47: Altere a bandeira na célula abaixo
K48: =K13 -> BAM | L48: =L13 -> BAM
