Workbook
Name _Ref352134769: 'TABELA DE TARIFAS NOVAS'!$A$93

Sheet FIO B
B2: TUSD FIO B
B4: SUBGRUPO | C4: MODALIDADE | D4: CLASSE | E4: SUBCLASSE | F4: POSTO | G4: TARIFAS DE APLICAÇÃO
G5: TUSD FIO B (RTP 2025) | J5: TUSD FIO B (RTA 2026)
G6: R$/kW | H6: R$/MWh | J6: R$/kW | K6: R$/MWh
B7: B1 | C7: BRANCA | D7: RESIDENCIAL | E7: RESIDENCIAL | F7: P | G7: 0 | H7: 591.10909 | J7: 0 | K7: 606.53962
B8: B1 | C8: BRANCA | D8: RESIDENCIAL | E8: RESIDENCIAL | F8: INT | G8: 0 | H8: 354.6655 | J8: 0 | K8: 363.92381
B9: B1 | C9: BRANCA | D9: RESIDENCIAL | E9: RESIDENCIAL | F9: FP | G9: 0 | H9: 118.2218 | J9: 0 | K9: 121.3079
B10: B1 | C10: PRÉ-PAGAMENTO | D10: RESIDENCIAL | E10: RESIDENCIAL | F10: NA | G10: 0 | H10: 203.83072 | J10: 0 | K10: 209.15159
B11: B1 | C11: CONVENCIONAL | D11: RESIDENCIAL | E11: RESIDENCIAL | F11: NA | G11: 0 | H11: 203.83072 | J11: 0 | K11: 209.15159
B12: B1 | C12: PRÉ-PAGAMENTO | D12: RESIDENCIAL | E12: BAIXA RENDA | F12: NA | G12: 0 | H12: 203.83072 | J12: 0 | K12: 209.15159
B13: B1 | C13: CONVENCIONAL | D13: RESIDENCIAL | E13: BAIXA RENDA | F13: NA | G13: 0 | H13: 203.83072 | J13: 0 | K13: 209.15159
B14: B1 | C14: PRÉ-PAGAMENTO | D14: RESIDENCIAL | E14: RESIDENCIAL DESCONTO SOCIAL | F14: NA | G14: 0 | H14: 203.83072 | J14: 0 | K14: 209.15159
B15: B1 | C15: CONVENCIONAL | D15: RESIDENCIAL | E15: RESIDENCIAL DESCONTO SOCIAL | F15: NA | G15: 0 | H15: 203.83072 | J15: 0 | K15: 209.15159
B16: B2 | C16: BRANCA | D16: RURAL | E16: NÃO SE APLICA | F16: P | G16: 0 | H16: 693.02445 | J16: 0 | K16: 711.11541
B17: B2 | C17: BRANCA | D17: RURAL | E17: NÃO SE APLICA | F17: INT | G17: 0 | H17: 415.81471 | J17: 0 | K17: 426.66929
B18: B2 | C18: BRANCA | D18: RURAL | E18: NÃO SE APLICA | F18: FP | G18: 0 | H18: 138.60487 | J18: 0 | K18: 142.22306
... B39: B | C39: GERAÇÃO | D39: TIPO 02 | E39: NA | F39: NA | G39: 0 | H39: 11.690957 | J39: 0 | K39: 11.996142

Sheet TABELA DE TARIFAS ANTIGAS
A1: TABELA 1 – TARIFAS DE APLICAÇÃO E BASE ECONÔMICA PARA O GRUPO A.
A2: SUBGRUPO | B2: MODALIDADE | C2: UC | D2: POSTO | E2: TARIFAS DE APLICAÇÃO | J2: BASE ECONÔMICA | N2: Reajuste | O2: Dia | P2: Mês | Q2: Ano
E3: TUSD | G3: TE | J3: TUSD | L3: TE | N3: De | O3: 07 | P3: 08 | Q3: 2025
E4: R$/kW | F4: R$/MWh | G4: BVD – R$/MWh | H4: BAM – R$/MWh | I4: BVM – R$/MWh | J4: R$/kW | K4: R$/MWh | L4: R$/MWh | N4: Até | O4: 06 | P4: 08 | Q4: 2026
B5: AZUL | C5: NA | D5: P
A6: A1 (230 kV ou mais) | D6: FP
B7: AZUL APE | C7: NA | D7: P
D8: FP
A9: A2 (88 a 138kV) | B9: AZUL | C9: NA | D9: P
D10: FP
B11: AZUL APE | C11: NA | D11: P
D12: FP
B13: DISTRIBUIÇÃO | C13: ELFSM | D13: P
D14: FP
D15: NA
B16: GERAÇÃO | C16: UTE LASA | D16: NA
C17: UTE ALCON | D17: NA
C18: UTE SOL | D18: NA
C19: UHE MASCARENHAS - ENERGEST | D19: NA
C20: UHE SUICA | D20: NA
C21: PCH SAO JOAQUIM | D21: NA
C22: PCH SAO SIMAO | D22: NA
C23: PCH FRANCISCO GROSS | D23: NA
C24: PCH SAO PEDRO | D24: NA
C25: UTE LINHARES | D25: NA
C26: UTE ARCEL | D26: NA
C27: NOVO GERADOR | D27: NA
A28: A3 (69kV) | B28: AZUL | C28: NA | D28: P
D29: FP
B30: AZUL APE | C30: NA | D30: P
D31: FP
B32: DISTRIBUIÇÃO | D32: P
D33: FP
D34: NA
B35: GERAÇÃO | C35: NA | D35: NA
A36: A3a (30 a 44kV) | B36: AZUL | C36: NA | D36: P
D37: FP
B38: AZUL APE | C38: NA | D38: P
D39: FP
B40: VERDE | C40: NA | D40: NA
...

Sheet TABELA DE TARIFAS NOVAS
A1: TABELA 1 – TARIFAS DE APLICAÇÃO E BASE ECONÔMICA PARA O GRUPO A.
A2: SUBGRUPO | B2: MODALIDADE | C2: UC | D2: POSTO | E2: TARIFAS DE APLICAÇÃO | J2: BASE ECONÔMICA | N2: Reajuste | O2: Dia | P2: Mês | Q2: Ano
E3: TUSD | G3: TE | J3: TUSD | L3: TE | N3: De | O3: 07 | P3: 08 | Q3: 2026
E4: R$/kW | F4: R$/MWh | G4: BVD – R$/MWh | H4: BAM – R$/MWh | I4: BVM – R$/MWh | J4: R$/kW | K4: R$/MWh | L4: R$/MWh | N4: Até | O4: 31 | P4: 12 | Q4: 9999
B5: AZUL | C5: NA | D5: P
A6: A1 (230 kV ou mais) | D6: FP
B7: AZUL APE | C7: NA | D7: P
D8: FP
A9: A2 (88 a 138kV) | B9: AZUL | C9: NA | D9: P
D10: FP
B11: AZUL APE | C11: NA | D11: P
D12: FP
B13: DISTRIBUIÇÃO | C13: ELFSM | D13: P
D14: FP
D15: NA
B16: GERAÇÃO | C16: UTE LASA | D16: NA
C17: UTE ALCON | D17: NA
C18: UTE SOL | D18: NA
C19: UHE MASCARENHAS - ENERGEST | D19: NA
C20: UHE SUICA | D20: NA
C21: PCH SAO JOAQUIM | D21: NA
C22: PCH SAO SIMAO | D22: NA
C23: PCH FRANCISCO GROSS | D23: NA
C24: PCH SAO PEDRO | D24: NA
C25: UTE LINHARES | D25: NA
C26: UTE POVOACAO 1 | D26: NA
C27: UTE ARCEL | D27: NA
C28: UTE BIANCOGRES | D28: NA
C29: NOVO GERADOR | D29: NA
A30: A3 (69kV) | B30: AZUL | C30: NA | D30: P
D31: FP
B32: AZUL APE | C32: NA | D32: P
D33: FP
B34: DISTRIBUIÇÃO | D34: P
D35: FP
D36: NA
B37: GERAÇÃO | C37: NA | D37: NA
A38: A3a (30 a 44kV) | B38: AZUL | C38: NA | D38: P
D39: FP
B40: AZUL APE | C40: NA | D40: P
...

Sheet Fatura B1 (GD) OK
B2: B1 Res | E2: Vigência das Tarifas: | F2: 45695 | M2: Bandeira | N2: R$/kWh | O2: ANEEL em 29/06 | Q2: TUSD FIO B
M3: VERDE | N3: 0
B4: TARIFA | C4: TARIFA ANTIGA - REH 3370/2024 | F4: TARIFA NOVA - REH xxxx/2025 | I4: Tarifas Proporcionalizadas | M4: BAM | N4: =[1]BANDEIRA!$D$5 -> 0.01885 | Q4: TARIFA | R4: =C4 -> TARIFA ANTIGA - REH 3370/2024 | U4: =F4 -> TARIFA NOVA - REH xxxx/2025 | X4: Tarifas Proporcionalizadas
C5: Tusd | D5: TE | E5: TUSD + TE | F5: Tusd | G5: TE | H5: TUSD + TE | I5: Tusd | J5: TE | K5: TUSD + TE | M5: BVM1 | N5: =[1]BANDEIRA!$D$6 -> 0.04463 | R5: Tusd (R$/kWh) | U5: Tusd (R$/kWh) | X5: Tusd (R$/kWh)
B6: B1 | C6: ='TABELA DE TARIFAS ANTIGAS'!G71/1000 -> 0.46863 | D6: ='TABELA DE TARIFAS ANTIGAS'!H71/1000 -> 0.32068 | E6: =C6+D6 -> 0.78931 | F6: ='TABELA DE TARIFAS NOVAS'!G73/1000 -> 0.50632 | G6: ='TABELA DE TARIFAS NOVAS'!H73/1000 -> 0.33739 | H6: =F6+G6 -> 0.84371 | I6: =((C6*$C$14)+(F6*$D$14))/($D$14+$C$14) -> 0.48552552 | J6: =((D6*$C$14)+(G6*$D$14))/($D$14+$C$14) -> 0.32817069 | K6: =I6+J6 -> 0.81369621 | M6: BVM2 | N6: =[1]BANDEIRA!$D$7 -> 0.07877 | Q6: =B6 -> B1 | R6: ='[2]FIO B'!H11/1000 -> 0.18823431 | U6: ='[2]FIO B'!K11/1000 -> 0.20383072 | X6: =((R6*$C$14)+(U6*$D$14))/($D$14+$C$14) -> 0.19522581
B7: CDE Escassez Hídrica | C7: 0.00017567286 | D7: 0.0034297355 | E7: 0.0036054084 | F7: =T11 -> 0.00018774721 | G7: =U11 -> -0.0044031307 | H7: =F7+G7 -> -0.0042153835 | I7: =((C7*$C$14)+(F7*$D$14))/($D$14+$C$14) -> 0.0001810855 | J7: =((D7*$C$14)+(G7*$D$14))/($D$14+$C$14) -> -8.1549352e-05 | K7: =I7+J7 -> 9.953615e-05 | M7: Escassez Hídrica | N7: 0.142
B8: TE SCEE | G8: =G6*15% -> 0.0506085 | J8: =((D8*$C$14)+(G8*$D$14))/($D$14+$C$14) -> 0.022686569 | P8: CUSTO | R8: Part. TUSD (%) | S8: Part. TE (%) | T8: Tusd (R$/kWh) | U8: TE (R$/kWh)
P9: CDE CONTAS
H10: Fatura | L10: Vigência das Tarifas (troca Bandeira): | M10: =EOMONTH(B14,0)+1 -> 45689 | P10: CDE COVID | U10: 0
B11: INSTALAÇÃO | C11: 73278 | H11: =E14 -> 45707 | K11: Altere a bandeira na célula abaixo | P11: CDE ESCASSEZ HÍDRICA | T11: =0.187747214948319/1000 -> 0.00018774721 | U11: =-4.40313074144798/1000 -> -0.0044031307
K12: BVM1 | L12: BVM2
B13: Leitura Anterior | C13: Nº de dias tarifa Anterior | D13: Nº de dias tarifa Nova | E13: Leitura Atual | J13: Leitura Anterior | K13: Nº de dias tarifa Anterior | L13: Nº de dias tarifa Nova | M13: Leitura Atual
B14: 45678 | C14: =IF((F2-B14-1)<0,0,(F2-B14-1)) -> 16 | D14: =E14-F2+1 -> 13 | E14: 45707 | J14: =B14 -> 45678 | K14: =IF((M10-J14-1)<0,0,(M10-J14-1)) -> 10 | L14: =M14-M10+1 -> 19 | M14: =E14 -> 45707
B17: Perc. de Redução da Energia Injetada | E17: TUSD | F17: 1 | G17: TE | H17: 1 | M17: Documento Impressão | O17: 30006757412
B19: Descrição | C19: Unidade | D19: Quantidade | E19: Preço Unit (R$) com tributos | F19: Valor Total (R$) | G19: PIS/COFINS (R$) | H19: Base de Cálculo ICMS (R$) | I19: Alíquota ICMS (%) | J19: ICMS (R$) | K19: Preço Unit (R$) | L19: Tributos | M19: Base de Cálc (R$) | N19: Alíquota (%) | O19: Valor (R$)
R20: TUSD Fio B | S20: Receita Fio B
B21: TUSD - Consumo | C21: kWh | D21: 506 | E21: =(ROUND(D21*K21,2)+ROUND(G21,2)+ROUND(J21,2))/ROUND(D21,4) -> 0.60488142 | F21: =ROUND(D21*E21,2) -> 306.07 | G21: =((D21*K21)/(1-$N$21-$N$23))*($N$21+$N$23) -> 8.357706 | H21: =((D21*K21)/(1-$N$21-$N$23)/(1-$I$21)) -> 306.0646 | I21: 0.17 | J21: =(H21*$I$21) -> 52.030982 | K21: =IF(AND($B$14<$F$2,$E$14<$F$2),C6,IF($B$14<$F$2,I6,F6)) -> 0.48552552 | L21: PIS | M21: =D71 -> 460.78999 | N21: 0.0059 | O21: =ROUND(M21*N21,2) -> 2.72 | R21: =IF(AND($B$14<$F$2,$E$14<$F$2),R6,IF($B$14<$F$2,X6,U6)) -> 0.19522581 | S21: =D21*R21 -> 98.784258
B22: TE - Consumo | C22: kWh | D22: =D21 -> 506 | E22: =(ROUND(D22*K22,2)+ROUND(G22,2)+ROUND(J22,2))/ROUND(D22,4) -> 0.40883399 | F22: =ROUND(D22*E22,2) -> 206.87 | G22: =((D22*K22)/(1-$N$21-$N$23))*($N$21+$N$23) -> 5.6490422 | H22: =ROUND((D22*K22)/(1-$N$21-$N$23)/(1-$I$21),8) -> 206.87158 | J22: =ROUND(H22*$I$21,2) -> 35.17 | K22: =IF(AND($B$14<$F$2,$E$14<$F$2),D6,IF($B$14<$F$2,J6,G6)) -> 0.32817069 | L22: PIS Inj | M22: =D72 -> -326.02626 | N22: =N21 -> 0.0059 | O22: =ROUND(M22*N22,2) -> -1.92
B23: Adicional BAM | C23: kWh | D23: =IF($K$12=M4,($D$21*($K$14)/($L$14+$K$14)),0)+IF($L$12=M4,($D$21*($L$14)/($L$14+$K$14)),0) -> 0 | E23: =IFERROR((ROUND(D23*K23,2)+ROUND(G23,2)+ROUND(J23,2))/ROUND(D23,4), 0) -> 0 | F23: =ROUND(D23*E23,2) -> 0 | G23: =((D23*K23)/(1-$N$21-$N$23))*($N$21+$N$23) -> 0 | H23: =ROUND((D23*K23)/(1-$N$21-$N$23)/(1-$I$21),8) -> 0 | J23: =ROUND(H23*$I$21,2) -> 0 | K23: =N4 -> 0.01885 | L23: COFINS | M23: =M21 -> 460.78999 | N23: 0.027 | O23: =ROUND(M23*N23,2) -> 12.44
B24: Adicional BVM1 | C24: kWh | D24: =IF($K$12=M5,($D$21*($K$14)/($L$14+$K$14)),0)+IF($L$12=M5,($D$21*($L$14)/($L$14+$K$14)),0) -> 174.48276 | E24: =IFERROR((ROUND(D24*K24,2)+ROUND(G24,2)+ROUND(J24,2))/ROUND(D24,4), 0) -> 0.055592872 | F24: =ROUND(D24*E24,2) -> 9.7 | G24: =((D24*K24)/(1-$N$21-$N$23))*($N$21+$N$23) -> 0.2649134 | H24: =ROUND((D24*K24)/(1-$N$21-$N$23)/(1-$I$21),8) -> 9.7012999 | J24: =ROUND(H24*$I$21,2) -> 1.65 | K24: =N5 -> 0.04463 | L24: COFINS Inj | M24: =M22 -> -326.02626 | N24: =N23 -> 0.027 | O24: =ROUND(M24*N24,2) -> -8.8
B25: Adicional BVM2 | C25: kWh | D25: =IF($K$12=M6,($D$21*($K$14)/($L$14+$K$14)),0)+IF($L$12=M6,($D$21*($L$14)/($L$14+$K$14)),0) -> 331.51724 | E25: =IFERROR((ROUND(D25*K25,2)+ROUND(G25,2)+ROUND(J25,2))/ROUND(D25,4), 0) -> 0.098124622 | F25: =ROUND(D25*E25,2) -> 32.53 | G25: =((D25*K25)/(1-$N$21-$N$23))*($N$21+$N$23) -> 0.88836508 | H25: =ROUND((D25*K25)/(1-$N$21-$N$23)/(1-$I$21),8) -> 32.532504 | J25: =ROUND(H25*$I$21,2) -> 5.53 | K25: =N6 -> 0.07877
B26: Adicional EH | C26: kWh | D26: =IF($K$12=M7,($D$21*($K$14)/($L$14+$K$14)),0)+IF($L$12=M7,($D$21*($L$14)/($L$14+$K$14)),0) -> 0 | E26: =IFERROR((ROUND(D26*K26,2)+ROUND(G26,2)+ROUND(J26,2))/ROUND(D26,4), 0) -> 0 | F26: =ROUND(D26*E26,2) -> 0 | G26: =((D26*K26)/(1-$N$21-$N$23))*($N$21+$N$23) -> 0 | H26: =ROUND((D26*K26)/(1-$N$21-$N$23)/(1-$I$21),8) -> 0 | J26: =ROUND(H26*$I$21,2) -> 0 | K26: =N7 -> 0.142
B28: TUSD - Consumo inj | C28: kWh | D28: -358 | E28: =IFERROR((ROUND(D28*K28,2)+ROUND(G28,2)+ROUND(J28,2))/ROUND(D28,4),0) -> 0.50203911 | F28: =ROUND(D28*E28,2) -> -179.73 | G28: =((D28*K28)/(1-$N$22-$N$24))*($N$22+$N$24) -> -5.9131596 | H28: 0 | I28: 0 | J28: =H28*$I$21 -> 0 | K28: =K21 -> 0.48552552
B29: TE - Consumo inj | C29: kWh | D29: =D28 -> -358 | E29: =IFERROR((ROUND(D29*K29,2)+ROUND(G29,2)+ROUND(J29,2))/ROUND(D29,4),0) -> 0.40885475 | F29: =ROUND(D29*E29,2) -> -146.37 | G29: =((D29*K29)/(1-$N$22-$N$24))*($N$22+$N$24) -> -3.9967532 | H29: =ROUND((D29*K29)/(1-$N$22-$N$24)/(1-$I$21),8) -> -146.36369 | I29: =I21 -> 0.17 | J29: =H29*$I$21 -> -24.881827 | K29: =K22 -> 0.32817069
B30: Adicional BAM inj | C30: kWh | D30: =IF($K$12=M4,($D$28*($K$14)/($K$14+$L$14)),0)+IF($L$12=M4,($D$28*($L$14)/($K$14+$L$14)),0) -> 0 | E30: =IFERROR((ROUND(D30*K30,2)+ROUND(G30,2)+ROUND(J30,2))/ROUND(D30,4),0) -> 0 | F30: =ROUND(D30*E30,2) -> 0 | G30: =((D30*K30)/(1-$N$22-$N$24))*($N$22+$N$24) -> 0 | H30: =(D30*K30)/(1-$N$22-$N$24)/(1-$I$21) -> 0 | J30: =H30*$I$21 -> 0 | K30: =N4 -> 0.01885
B31: Adicional BVM1 inj | C31: kWh | D31: =IF($K$12=M5,($D$28*($K$14)/($K$14+$L$14)),0)+IF($L$12=M5,($D$28*($L$14)/($K$14+$L$14)),0) -> -123.44828 | E31: =IFERROR((ROUND(D31*K31,2)+ROUND(G31,2)+ROUND(J31,2))/ROUND(D31,4),0) -> 0.055650827 | F31: =ROUND(D31*E31,2) -> -6.87 | G31: =((D31*K31)/(1-$N$22-$N$24))*($N$22+$N$24) -> -0.18742885 | H31: =(D31*K31)/(1-$N$22-$N$24)/(1-$I$21) -> -6.8637655 | J31: =H31*$I$21 -> -1.1668401 | K31: =N5 -> 0.04463
B32: Adicional BVM2 inj | C32: kWh | D32: =IF($K$12=M6,($D$28*($K$14)/($K$14+$L$14)),0)+IF($L$12=M6,($D$28*($L$14)/($K$14+$L$14)),0) -> -234.55172 | E32: =IFERROR((ROUND(D32*K32,2)+ROUND(G32,2)+ROUND(J32,2))/ROUND(D32,4),0) -> 0.098144673 | F32: =ROUND(D32*E32,2) -> -23.02 | G32: =((D32*K32)/(1-$N$22-$N$24))*($N$22+$N$24) -> -0.62852707 | H32: =(D32*K32)/(1-$N$22-$N$24)/(1-$I$21) -> -23.017068 | J32: =H32*$I$21 -> -3.9129015 | K32: =N6 -> 0.07877
B33: Adicional EH inj | C33: kWh | D33: =IF($K$12=M7,($D$28*($K$14)/($K$14+$L$14)),0)+IF($L$12=M7,($D$28*($L$14)/($K$14+$L$14)),0) -> 0 | E33: =IFERROR((ROUND(D33*K33,2)+ROUND(G33,2)+ROUND(J33,2))/ROUND(D33,4),0) -> 0 | F33: =ROUND(D33*E33,2) -> 0 | G33: =((D33*K33)/(1-$N$22-$N$24))*($N$22+$N$24) -> 0 | H33: =(D33*K33)/(1-$N$22-$N$24)/(1-$I$21) -> 0 | J33: =H33*$I$21 -> 0 | K33: =N7 -> 0.142
B35: Multas
B36: Juros | F36: 3.08
B37: Bônus/Descontos
B38: Doações
B39: CIP | F39: 44.5
B42: TOTAL | F42: =SUM(F21:F41) -> 246.76 | G42: =SUM(G21:G41) -> 4.434158 | H42: =SUM(H21:H41) -> 378.92546 | J42: =SUM(J21:J41) -> 64.419413
B44: Informativo Escassez | C44: =(D21+D28) -> 148 | D44: =IF(AND($B$14<$F$2,$E$14<$F$2),C7,IF($B$14<$F$2,I7,F7)) -> 0.0001810855 | E44: =IF(AND($B$14<$F$2,$E$14<$F$2),D7,IF($B$14<$F$2,J7,G7)) -> -8.1549352e-05 | F44: =C44*(D44+E44) -> 0.01473135
B46: Fatura B1 Residencial
D47: Qtde | E47: TUSD | F47: TE | G47: TUSD + TE | H47: R$
B48: Fornecimento de Energia Elétrica | H48: =SUM(H50:H66)+SUM(H71:H76) -> 199.1798
B50: Energia Fornecida | D50: =D21 -> 506 | E50: =IF(AND($B$14<$F$2,$E$14<$F$2),C6,IF($B$14<$F$2,I6,F6)) -> 0.48552552 | F50: =IF(AND($B$14<$F$2,$E$14<$F$2),D6,IF($B$14<$F$2,J6,G6)) -> 0.32817069 | G50: =E50+F50 -> 0.81369621 | H50: =ROUND((D50*E50),2)+ROUND((D50*F50),2) -> 411.73
B52: Adicional BAM | D52: =IF($K$12=M4,(D50*(K14)/(K14+L14)),0)+IF($L$12=M4,(D50*(L14)/(K14+L14)),0) -> 0 | F52: =N4 -> 0.01885 | H52: =ROUND(D52*(E52+F52),2) -> 0
...

Sheet Fatura B1 BRe (GD)
B2: B1 Baixa renda | E2: Vigência das Tarifas: | F2: ='[3]Fatura B1 (GD)'!F2 -> 45511 | M2: Bandeira | N2: R$/kWh | O2: ANEEL em 29/06 | Q2: TUSD FIO B
M3: VERDE | N3: 0
B4: TARIFA R$ kWh | C4: TARIFA ANTIGA - REH 3091/2022 | F4: ='[3]Fatura B1 (GD)'!F4 -> TARIFA NOVA - REH xxxx/2024 | I4: Tarifas Proporcionalizadas | M4: BAM | N4: 0.01885 | Q4: TARIFA | R4: =C4 -> TARIFA ANTIGA - REH 3091/2022 | U4: =F4 -> TARIFA NOVA - REH xxxx/2024 | X4: Tarifas Proporcionalizadas
C5: Tusd | D5: TE | E5: TUSD + TE | F5: Tusd | G5: TE | H5: TUSD + TE | I5: Tusd | J5: TE | K5: TUSD + TE | M5: BVM1 | N5: 0.04463 | R5: Tusd (R$/kWh) | U5: Tusd (R$/kWh) | X5: Tusd (R$/kWh)
B6: Baixa renda | C6: 0.28337 | D6: 0.2988 | E6: 0.58217 | F6: 0.28935 | G6: 0.29334 | H6: 0.58269 | I6: =((C6*$C$14)+(F6*$D$14))/($D$14+$C$14) -> 0.28935 | J6: =((D6*$C$14)+(G6*$D$14))/($D$14+$C$14) -> 0.29334 | K6: =I6+J6 -> 0.58269 | M6: BVM2 | N6: 0.07877 | Q6: =B6 -> Baixa renda | R6: 0.17652 | U6: 0.061783268 | X6: 0.061783268
B7: CDE Escassez Hídrica | C7: =0.207830737658616/1000 -> 0.00020783074 | D7: =4.01792/1000 -> 0.00401792 | E7: =C7+D7 -> 0.0042257507 | F7: =T11 -> 0.00020783074 | G7: =U11 -> 0.00402 | H7: =F7+G7 -> 0.0042278307 | I7: =((C7*$C$14)+(F7*$D$14))/($D$14+$C$14) -> 0.00020783074 | J7: =((D7*$C$14)+(G7*$D$14))/($D$14+$C$14) -> 0.00402 | K7: =I7+J7 -> 0.0042278307
B8: TE SCEE | G8: =G6*15% -> 0.044001 | J8: =((D8*$C$14)+(G8*$D$14))/($D$14+$C$14) -> 0.044001 | M8: Escassez Hídrica | N8: 0.142 | P8: CUSTO | R8: Part. TUSD (%) | S8: Part. TE (%) | T8: Tusd (R$/kWh) | U8: TE (R$/kWh)
P9: CDE CONTAS
H10: Fatura | L10: Vigência das Tarifas (troca Bandeira): | M10: =EOMONTH(B14,0)+1 -> 45689 | P10: CDE COVID | U10: =5.61/1000 -> 0.00561
B11: INSTALAÇÃO | C11: 1041172 | H11: =E14 -> 45707 | K11: Altere a bandeira na célula abaixo | P11: CDE ESCASSEZ HÍDRICA | T11: =0.207830737658616/1000 -> 0.00020783074 | U11: =4.02/1000 -> 0.00402 | W11: prop
K12: ='Fatura B1 (GD) OK'!K12 -> BVM1 | L12: ='Fatura B1 (GD) OK'!L12 -> BVM2 | P12: 0 - 30 | Q12: 0.65 | U12: =$U$11*(1-Q12) -> 0.001407 | W12: =((T12*$C$14)+(U12*$D$14))/($D$14+$C$14) -> 0.001407
B13: Leitura Anterior | C13: Nº de dias tarifa Anterior | D13: Nº de dias tarifa Nova | E13: Leitura Atual | J13: Leitura Anterior | K13: Nº de dias tarifa Anterior | L13: Nº de dias tarifa Nova | M13: Leitura Atual | P13: 31- 100 | Q13: 0.4 | U13: =$U$11*(1-Q13) -> 0.002412 | W13: =((T13*$C$14)+(U13*$D$14))/($D$14+$C$14) -> 0.002412
B14: ='Fatura B1 (GD) OK'!B14 -> 45678 | C14: =IF((F2-B14-1)<0,0,(F2-B14-1)) -> 0 | D14: =E14-F2+1 -> 197 | E14: ='Fatura B1 (GD) OK'!E14 -> 45707 | J14: =B14 -> 45678 | K14: =IF((M10-J14-1)<0,0,(M10-J14-1)) -> 10 | L14: =M14-M10+1 -> 19 | M14: =E14 -> 45707 | P14: 101 - 220 | Q14: 0.1 | U14: =$U$11*(1-Q14) -> 0.003618 | W14: =((T14*$C$14)+(U14*$D$14))/($D$14+$C$14) -> 0.003618
P15: >220 | Q15: 0 | U15: =$U$11*(1-Q15) -> 0.00402 | W15: =((T15*$C$14)+(U15*$D$14))/($D$14+$C$14) -> 0.00402
B16: CONSUMO | D16: 537
B17: INJEÇÃO | D17: 221
B18: DIFERENÇA | D18: 316
B19: COMPENSAÇÃO | D19: =D16-D18 -> 221 | M19: Documento impressão: | O19: 241002228329
B21: Descrição | C21: Unidade | D21: Quantidade | E21: Preço Unit (R$) com tributos | F21: Valor Total (R$) | G21: PIS/COFINS (R$) | H21: Base de Cálculo ICMS (R$) | I21: Alíquota ICMS (%) | J21: ICMS (R$) | K21: Preço Unit (R$) | L21: Tributos | M21: Base de Cálc (R$) | N21: Alíquota (%) | O21: Valor (R$)
B23: Desconto Bx renda | D23: =-K168 -> -50.066645 | E23: 1 | F23: =D23*E23 -> -50.066645 | G23: 0 | H23: 0 | I23: 0 | K23: 1
B24: Valor Bx Renda | D24: =D23 -> -50.066645 | E24: =K24/(1-$N$25-$N$26)/(1-$I$24) -> 1.2458063 | F24: =-1*(F23-J24) -> 60.669545 | G24: 0 | H24: =ROUND((K168*K24)/(1-$N$25-$N$26)/(1-$I$24),2) -> 62.37 | I24: 0.17 | J24: =H24*$I$24 -> 10.6029 | K24: 1
A25: 0.65 | B25: TUSD - EAF 0 a 30 | C25: kWh | D25: =IF(D19>0,30,0) -> 30 | E25: =K25/(1-$N$25-$N$26)/(1-$I$24) -> 0.12616592 | F25: =ROUND(D25*E25,2) -> 3.78 | G25: =ROUND(((D25*K25)/(1-$N$25-$N$26))*($N$25+$N$26),2) -> 0.1 | H25: =ROUND((D25*K25)/(1-$N$25-$N$26)/(1-$I$24),2) -> 3.78 | J25: =H25*$I$24 -> 0.6426 | K25: =K28*(1-A25) -> 0.1012725 | L25: PIS | M25: =D138 -> 280.79826 | N25: ='Fatura B1 (GD) OK'!N21 -> 0.0059 | O25: =ROUND(M25*N25,2) -> 1.66
A26: 0.4 | B26: TUSD - EAF 31 a 100 | C26: kWh | D26: =IF(D19>30,IF(D19>100,70,D19-30),0) -> 70 | E26: =K26/(1-$N$25-$N$26)/(1-$I$24) -> 0.21628443 | F26: =ROUND(D26*E26,2) -> 15.14 | G26: =ROUND(((D26*K26)/(1-$N$25-$N$26))*($N$25+$N$26),2) -> 0.41 | H26: =ROUND((D26*K26)/(1-$N$25-$N$26)/(1-$I$24),2) -> 15.14 | J26: =H26*$I$24 -> 2.5738 | K26: =K28*(1-A26) -> 0.17361 | L26: COFINS | M26: =M25 -> 280.79826 | N26: ='Fatura B1 (GD) OK'!N23 -> 0.027 | O26: =ROUND(M26*N26,2) -> 7.58
A27: 0.1 | B27: TUSD - EAF 101 a 220 | C27: kWh | D27: =IF(D19>100,IF(D19>220,220-100,D19-100),0) -> 120 | E27: =K27/(1-$N$25-$N$26)/(1-$I$24) -> 0.32442665 | F27: =ROUND(D27*E27,2) -> 38.93 | G27: =ROUND(((D27*K27)/(1-$N$25-$N$26))*($N$25+$N$26),2) -> 1.06 | H27: =ROUND((D27*K27)/(1-$N$25-$N$26)/(1-$I$24),2) -> 38.93 | J27: =H27*$I$24 -> 6.6181 | K27: =K28*(1-A27) -> 0.260415
A28: 0 | B28: TUSD - EAF > 220 | C28: kWh | D28: =IF(D19>220,D19-220,0) -> 1 | E28: =K28/(1-$N$25-$N$26)/(1-$I$24) -> 0.36047405 | F28: =ROUND(D28*E28,2) -> 0.36 | G28: =ROUND(((D28*K28)/(1-$N$25-$N$26))*($N$25+$N$26),2) -> 0.01 | H28: =ROUND((D28*K28)/(1-$N$25-$N$26)/(1-$I$24),2) -> 0.36 | J28: =H28*$I$24 -> 0.0612 | K28: =IF(AND($B$13<$F$2,$E$13<$F$2),C6,IF($B$13<$F$2,I6,F6)) -> 0.28935
A29: 0.65 | B29: TUSD - EAFdc 0 a 30 | C29: kWh | D29: =IF(D18>0,30,0) -> 30 | E29: =K29/(1-$N$25-$N$26)/(1-$I$24) -> 0.12616592 | F29: =ROUND(D29*E29,2) -> 3.78 | G29: =ROUND(((D29*K29)/(1-$N$25-$N$26))*($N$25+$N$26),2) -> 0.1 | H29: =ROUND((D29*K29)/(1-$N$25-$N$26)/(1-$I$24),2) -> 3.78 | J29: =H29*$I$24 -> 0.6426 | K29: =K32*(1-A29) -> 0.1012725
A30: 0.4 | B30: TUSD - EAFdc 31 a 100 | C30: kWh | D30: =IF(D18>30,IF(D18>100,70,D18-30),0) -> 70 | E30: =K30/(1-$N$25-$N$26)/(1-$I$24) -> 0.21628443 | F30: =ROUND(D30*E30,2) -> 15.14 | G30: =ROUND(((D30*K30)/(1-$N$25-$N$26))*($N$25+$N$26),2) -> 0.41 | H30: =ROUND((D30*K30)/(1-$N$25-$N$26)/(1-$I$24),2) -> 15.14 | J30: =H30*$I$24 -> 2.5738 | K30: =K32*(1-A30) -> 0.17361
A31: 0.1 | B31: TUSD - EAFdc 101 a 220 | C31: kWh | D31: =IF(D18>100,IF(D18>220,220-100,D18-100),0) -> 120 | E31: =K31/(1-$N$25-$N$26)/(1-$I$24) -> 0.32442665 | F31: =ROUND(D31*E31,2) -> 38.93 | G31: =ROUND(((D31*K31)/(1-$N$25-$N$26))*($N$25+$N$26),2) -> 1.06 | H31: =ROUND((D31*K31)/(1-$N$25-$N$26)/(1-$I$24),2) -> 38.93 | J31: =H31*$I$24 -> 6.6181 | K31: =K32*(1-A31) -> 0.260415
A32: 0 | B32: TUSD - EAFdc > 220 | C32: kWh | D32: =IF(D18>220,D18-220,0) -> 96 | E32: =K32/(1-$N$25-$N$26)/(1-$I$24) -> 0.36047405 | F32: =ROUND(D32*E32,2) -> 34.61 | G32: =ROUND(((D32*K32)/(1-$N$25-$N$26))*($N$25+$N$26),2) -> 0.94 | H32: =ROUND((D32*K32)/(1-$N$25-$N$26)/(1-$I$24),2) -> 34.61 | J32: =H32*$I$24 -> 5.8837 | K32: =IF(AND($B$14<$F$2,$E$14<$F$2),C6,IF($B$14<$F$2,I6,F6)) -> 0.28935
B34: TE - EAF 0 a 30 | C34: kWh | D34: =D25 -> 30 | E34: =K34/(1-$N$25-$N$26)/(1-$I$24) -> 0.12790569 | F34: =ROUND(D34*E34,2) -> 3.84 | G34: =ROUND(((D34*K34)/(1-$N$25-$N$26))*($N$25+$N$26),2) -> 0.1 | H34: =ROUND((D34*K34)/(1-$N$25-$N$26)/(1-$I$24),2) -> 3.84 | J34: =H34*$I$24 -> 0.6528 | K34: =K37*(1-A25) -> 0.102669
B35: TE - EAF 31 a 100 | C35: kWh | D35: =D26 -> 70 | E35: =K35/(1-$N$25-$N$26)/(1-$I$24) -> 0.21926689 | F35: =ROUND(D35*E35,2) -> 15.35 | G35: =ROUND(((D35*K35)/(1-$N$25-$N$26))*($N$25+$N$26),2) -> 0.42 | H35: =ROUND((D35*K35)/(1-$N$25-$N$26)/(1-$I$24),2) -> 15.35 | J35: =H35*$I$24 -> 2.6095 | K35: =K37*(1-A26) -> 0.176004
B36: TE - EAF 101 a 220 | C36: kWh | D36: =D27 -> 120 | E36: =K36/(1-$N$25-$N$26)/(1-$I$24) -> 0.32890034 | F36: =ROUND(D36*E36,2) -> 39.47 | G36: =ROUND(((D36*K36)/(1-$N$25-$N$26))*($N$25+$N$26),2) -> 1.08 | H36: =ROUND((D36*K36)/(1-$N$25-$N$26)/(1-$I$24),2) -> 39.47 | J36: =H36*$I$24 -> 6.7099 | K36: =K37*(1-A27) -> 0.264006
B37: TE - EAF > 220 | C37: kWh | D37: =D28 -> 1 | E37: =K37/(1-$N$25-$N$26)/(1-$I$24) -> 0.36544482 | F37: =ROUND(D37*E37,2) -> 0.37 | G37: =ROUND(((D37*K37)/(1-$N$25-$N$26))*($N$25+$N$26),2) -> 0.01 | H37: =ROUND((D37*K37)/(1-$N$25-$N$26)/(1-$I$24),2) -> 0.37 | J37: =H37*$I$24 -> 0.0629 | K37: =IF(AND($B$14<$F$2,$E$14<$F$2),D6,IF($B$14<$F$2,J6,G6)) -> 0.29334
B38: TE - EAFdc 0 a 30 | C38: kWh | D38: =D29 -> 30 | E38: =K38/(1-$N$25-$N$26)/(1-$I$24) -> 0.12790569 | F38: =ROUND(D38*E38,2) -> 3.84 | G38: =ROUND(((D38*K38)/(1-$N$25-$N$26))*($N$25+$N$26),2) -> 0.1 | H38: =ROUND((D38*K38)/(1-$N$25-$N$26)/(1-$I$24),2) -> 3.84 | J38: =H38*$I$24 -> 0.6528 | K38: =K41*(1-A29) -> 0.102669
B39: TE - EAFdc 31 a 100 | C39: kWh | D39: =D30 -> 70 | E39: =K39/(1-$N$25-$N$26)/(1-$I$24) -> 0.21926689 | F39: =ROUND(D39*E39,2) -> 15.35 | G39: =ROUND(((D39*K39)/(1-$N$25-$N$26))*($N$25+$N$26),2) -> 0.42 | H39: =ROUND((D39*K39)/(1-$N$25-$N$26)/(1-$I$24),2) -> 15.35 | J39: =H39*$I$24 -> 2.6095 | K39: =K41*(1-A30) -> 0.176004
B40: TE - EAFdc 101 a 220 | C40: kWh | D40: =D31 -> 120 | E40: =K40/(1-$N$25-$N$26)/(1-$I$24) -> 0.32890034 | F40: =ROUND(D40*E40,2) -> 39.47 | G40: =ROUND(((D40*K40)/(1-$N$25-$N$26))*($N$25+$N$26),2) -> 1.08 | H40: =ROUND((D40*K40)/(1-$N$25-$N$26)/(1-$I$24),2) -> 39.47 | J40: =H40*$I$24 -> 6.7099 | K40: =K41*(1-A31) -> 0.264006
B41: TE - EAFdc > 220 | C41: kWh | D41: =D32 -> 96 | E41: =K41/(1-$N$25-$N$26)/(1-$I$24) -> 0.36544482 | F41: =ROUND(D41*E41,2) -> 35.08 | G41: =ROUND(((D41*K41)/(1-$N$25-$N$26))*($N$25+$N$26),2) -> 0.96 | H41: =ROUND((D41*K41)/(1-$N$25-$N$26)/(1-$I$24),2) -> 35.08 | J41: =H41*$I$24 -> 5.9636 | K41: =IF(AND($B$14<$F$2,$E$14<$F$2),D6,IF($B$14<$F$2,J6,G6)) -> 0.29334
B43: Adicional BAM | D43: =C175+C212 -> 0 | F43: =(O175+O212)/(1-$N$25-$N$26)/(1-$I$24) -> 0 | G43: =ROUND(((D43*K43)/(1-$N$25-$N$26))*($N$25+$N$26),2) -> 0 | H43: =F43 -> 0 | J43: =H43*$I$24 -> 0 | K43: =K175 -> 0.0065975
B44: Adicional BAM | D44: =C176+C213 -> 0 | F44: =(O176+O213)/(1-$N$25-$N$26)/(1-$I$24) -> 0 | G44: =ROUND(((D44*K44)/(1-$N$25-$N$26))*($N$25+$N$26),2) -> 0 | H44: =F44 -> 0 | J44: =H44*$I$24 -> 0 | K44: =K176 -> 0.01131
B45: Adicional BAM | D45: =C177+C214 -> 0 | F45: =(O177+O214)/(1-$N$25-$N$26)/(1-$I$24) -> 0 | G45: =ROUND(((D45*K45)/(1-$N$25-$N$26))*($N$25+$N$26),2) -> 0 | H45: =F45 -> 0 | J45: =H45*$I$24 -> 0 | K45: =K177 -> 0.016965
...

Sheet B1 Res (GD) Branca OK
B2: B1 Res TB | E2: Vigência das Tarifas: | F2: 46241 | H2: TARIFA BRANCA | M2: Bandeira | N2: R$/kWh | Q2: TUSD FIO B
M3: VERDE | N3: 0
B4: TARIFA | C4: ='Fatura B1 (GD) OK'!C4:E4 -> TARIFA ANTIGA - REH 3370/2024 | F4: ='Fatura B1 (GD) OK'!F4 -> TARIFA NOVA - REH xxxx/2025 | I4: Tarifas Proporcionalizadas | M4: BAM | N4: =[1]BANDEIRA!$D$5 -> 0.01885 | Q4: TARIFA | R4: =C4 -> TARIFA ANTIGA - REH 3370/2024 | U4: =F4 -> TARIFA NOVA - REH xxxx/2025 | X4: Tarifas Proporcionalizadas
C5: Tusd | D5: TE | E5: TUSD + TE | F5: Tusd | G5: TE | H5: TUSD + TE | I5: Tusd | J5: TE | K5: TUSD + TE | M5: BVM1 | N5: =[1]BANDEIRA!$D$6 -> 0.04463 | R5: Tusd (R$/kWh) | U5: Tusd (R$/kWh) | X5: Tusd (R$/kWh)
B6: B1 Ponta | C6: ='TABELA DE TARIFAS ANTIGAS'!G68/1000 -> 0.93761 | D6: ='TABELA DE TARIFAS ANTIGAS'!H68/1000 -> 0.48448 | E6: =C6+D6 -> 1.42209 | F6: ='TABELA DE TARIFAS NOVAS'!G70/1000 -> 0.99902 | G6: ='TABELA DE TARIFAS NOVAS'!H70/1000 -> 0.51691 | H6: =F6+G6 -> 1.51593 | I6: =((C6*$C$15)+(F6*$D$15))/($D$15+$C$15) -> 0.966268 | J6: =((D6*$C$15)+(G6*$D$15))/($D$15+$C$15) -> 0.499614 | K6: =I6+J6 -> 1.465882 | M6: BVM2 | N6: =[1]BANDEIRA!$D$7 -> 0.07877 | Q6: =B6 -> B1 Ponta | R6: ='FIO B'!H7/1000 -> 0.59110909 | U6: ='FIO B'!K7/1000 -> 0.60653962 | X6: =((R6*$C$15)+(U6*$D$15))/($D$15+$C$15) -> 0.59831
B7: B1 Fora Ponta | C7: ='TABELA DE TARIFAS ANTIGAS'!G70/1000 -> 0.36496 | D7: ='TABELA DE TARIFAS ANTIGAS'!H70/1000 -> 0.30579 | E7: =C7+D7 -> 0.67075 | F7: ='TABELA DE TARIFAS NOVAS'!G72/1000 -> 0.39741 | G7: ='TABELA DE TARIFAS NOVAS'!H72/1000 -> 0.32107 | H7: =F7+G7 -> 0.71848 | I7: =((C7*$C$15)+(F7*$D$15))/($D$15+$C$15) -> 0.38010333 | J7: =((D7*$C$15)+(G7*$D$15))/($D$15+$C$15) -> 0.31292067 | K7: =I7+J7 -> 0.693024 | M7: Escassez Hídrica | N7: 0.142 | Q7: =B7 -> B1 Fora Ponta | R7: ='FIO B'!H8/1000 -> 0.3546655 | U7: ='FIO B'!K8/1000 -> 0.36392381 | X7: =((R7*$C$15)+(U7*$D$15))/($D$15+$C$15) -> 0.35898604
B8: B1 Interm. | C8: ='TABELA DE TARIFAS ANTIGAS'!G69/1000 -> 0.65129 | D8: ='TABELA DE TARIFAS ANTIGAS'!H69/1000 -> 0.30579 | E8: =C8+D8 -> 0.95708 | F8: ='TABELA DE TARIFAS NOVAS'!G71/1000 -> 0.69821 | G8: ='TABELA DE TARIFAS NOVAS'!H71/1000 -> 0.32107 | H8: =F8+G8 -> 1.01928 | I8: =((C8*$C$15)+(F8*$D$15))/($D$15+$C$15) -> 0.673186 | J8: =((D8*$C$15)+(G8*$D$15))/($D$15+$C$15) -> 0.31292067 | K8: =I8+J8 -> 0.98610667 | Q8: =B8 -> B1 Interm. | R8: ='FIO B'!H9/1000 -> 0.1182218 | U8: ='FIO B'!K9/1000 -> 0.1213079 | X8: =((R8*$C$15)+(U8*$D$15))/($D$15+$C$15) -> 0.11966198
B9: CDE Escassez Hídrica | C9: 0.00018774721 | D9: -0.0044031307 | E9: 0.0036054084 | F9: =T13 -> 0.00018418923 | G9: =U13 -> -0.00053182975 | H9: =F9+G9 -> -0.00034764052 | I9: =((C9*$C$15)+(F9*$D$15))/($D$15+$C$15) -> 0.00018608682 | J9: =((D9*$C$15)+(G9*$D$15))/($D$15+$C$15) -> -0.0025965236 | K9: =I9+J9 -> -0.0024104368
P10: CUSTO | R10: Part. TUSD (%) | S10: Part. TE (%) | T10: Tusd (R$/kWh) | U10: TE (R$/kWh)
H11: Fatura | L11: Vigência das Tarifas (troca Bandeira): | M11: =EOMONTH(B15,0)+1 -> 46235 | P11: CDE CONTAS
B12: INSTALAÇÃO | C12: 160295767 | H12: =E15 -> 46254 | K12: Altere a bandeira na célula abaixo | P12: CDE COVID | U12: 0
K13: BAM | L13: BAM | P13: CDE ESCASSEZ HÍDRICA | T13: =0.184189231569235/1000 -> 0.00018418923 | U13: =-0.531829748712515/1000 -> -0.00053182975
B14: Leitura Anterior | C14: Nº de dias tarifa Anterior | D14: Nº de dias tarifa Nova | E14: Leitura Atual | J14: Leitura Anterior | K14: Nº de dias tarifa Anterior | L14: Nº de dias tarifa Nova | M14: Leitura Atual
B15: 46224 | C15: =IF((F2-B15-1)<0,0,(F2-B15-1)) -> 16 | D15: =E15-F2+1 -> 14 | E15: 46254 | J15: =B15 -> 46224 | K15: =IF((M11-J15-1)<0,0,(M11-J15-1)) -> 10 | L15: =M15-M11+1 -> 20 | M15: =E15 -> 46254 | P15: Documento impressão: | R15: 1025310400
B17: Descrição | C17: Unidade | D17: Quantidade | E17: Preço Unit (R$) com tributos | F17: Valor Total (R$) | G17: PIS/COFINS (R$) | H17: Base de Cálculo ICMS (R$) | I17: Alíquota ICMS (%) | J17: ICMS (R$) | K17: Preço Unit (R$) | L17: Tributos | M17: Base de Cálc (R$) | N17: Alíquota (%) | O17: Valor (R$)
B19: TUSD - Ponta | C19: kWh | D19: 139 | E19: =IFERROR((ROUND(D19*K19,2)+ROUND(G19,2)+ROUND(J19,2))/ROUND(D19,4), 0) -> 1.2407194 | F19: =ROUND(D19*E19,2) -> 172.46 | G19: =((D19*K19)/(1-$N$19-$N$21))*($N$19+$N$21) -> 8.8319346 | H19: =((D19*K19)/(1-$N$19-$N$21)/(1-$I$19)) -> 172.46167 | I19: 0.17 | J19: =(H19*$I$19) -> 29.318484 | K19: =E58 -> 0.966268 | L19: PIS | M19: =D78 -> 742.14004 | N19: 0.011 | O19: =ROUND(M19*N19,2) -> 8.16 | Q19: TUSD Fio B | R19: Receita Fio B
B20: TUSD - Intermediário | C20: kWh | D20: 293 | E20: =IFERROR((ROUND(D20*K20,2)+ROUND(G20,2)+ROUND(J20,2))/ROUND(D20,4), 0) -> 0.86440273 | F20: =ROUND(D20*E20,2) -> 253.27 | G20: =((D20*K20)/(1-$N$19-$N$21))*($N$19+$N$21) -> 12.970184 | H20: =((D20*K20)/(1-$N$19-$N$21)/(1-$I$19)) -> 253.2695 | I20: =I19 -> 0.17 | J20: =(H20*$I$19) -> 43.055814 | K20: =E60 -> 0.673186 | L20: PIS Inj | M20: =D79 -> -277.71502 | N20: =N19 -> 0.011 | O20: =ROUND(M20*N20,2) -> -3.05 | Q20: =IF(AND($B$15<$F$2,$E$15<$F$2),R6,IF($B$15<$F$2,X6,U6)) -> 0.59831 | R20: =D19*Q20 -> 83.165091
B21: TUSD - Fora Ponta | C21: kWh | D21: 280 | E21: =IFERROR((ROUND(D21*K21,2)+ROUND(G21,2)+ROUND(J21,2))/ROUND(D21,4), 0) -> 0.48807143 | F21: =ROUND(D21*E21,2) -> 136.66 | G21: =((D21*K21)/(1-$N$19-$N$21))*($N$19+$N$21) -> 6.9984708 | H21: =((D21*K21)/(1-$N$19-$N$21)/(1-$I$19)) -> 136.65952 | I21: =I19 -> 0.17 | J21: =(H21*$I$19) -> 23.232119 | K21: =E59 -> 0.38010333 | L21: COFINS | M21: =M19 -> 742.14004 | N21: 0.0507 | O21: =ROUND(M21*N21,2) -> 37.63 | Q21: =IF(AND($B$15<$F$2,$E$15<$F$2),R7,IF($B$15<$F$2,X7,U7)) -> 0.35898604 | R21: =D20*Q21 -> 105.18291
B22: TE - Ponta | C22: kWh | D22: =D19 -> 139 | E22: =IFERROR((ROUND(D22*K22,2)+ROUND(G22,2)+ROUND(J22,2))/ROUND(D22,4), 0) -> 0.64158273 | F22: =ROUND(D22*E22,2) -> 89.18 | G22: =((D22*K22)/(1-$N$19-$N$21))*($N$19+$N$21) -> 4.5665987 | H22: =ROUND((D22*K22)/(1-$N$19-$N$21)/(1-$I$19),8) -> 89.172223 | J22: =ROUND(H22*$I$19,2) -> 15.16 | K22: =F58 -> 0.499614 | L22: COFINS Inj | M22: =M20 -> -277.71502 | N22: =N21 -> 0.0507 | O22: =ROUND(M22*N22,2) -> -14.08 | Q22: =IF(AND($B$15<$F$2,$E$15<$F$2),R8,IF($B$15<$F$2,X8,U8)) -> 0.11966198 | R22: =D21*Q22 -> 33.505355
B23: TE - Intermediário | C23: kWh | D23: =D20 -> 293 | E23: =IFERROR((ROUND(D23*K23,2)+ROUND(G23,2)+ROUND(J23,2))/ROUND(D23,4), 0) -> 0.40180887 | F23: =ROUND(D23*E23,2) -> 117.73 | G23: =((D23*K23)/(1-$N$19-$N$21))*($N$19+$N$21) -> 6.0290004 | H23: =ROUND((D23*K23)/(1-$N$19-$N$21)/(1-$I$19),8) -> 117.72862 | J23: =ROUND(H23*$I$19,2) -> 20.01 | K23: =F60 -> 0.31292067 | R23: =SUM(R20:R22) -> 221.85336
B24: TE - Fora Ponta | C24: kWh | D24: =D21 -> 280 | E24: =IFERROR((ROUND(D24*K24,2)+ROUND(G24,2)+ROUND(J24,2))/ROUND(D24,4), 0) -> 0.40182143 | F24: =ROUND(D24*E24,2) -> 112.51 | G24: =((D24*K24)/(1-$N$19-$N$21))*($N$19+$N$21) -> 5.7615021 | H24: =ROUND((D24*K24)/(1-$N$19-$N$21)/(1-$I$19),8) -> 112.50517 | J24: =ROUND(H24*$I$19,2) -> 19.13 | K24: =F59 -> 0.31292067
B25: Adicional BAM | C25: kWh | D25: =IF($K$13=M4,(($D$19+$D$20+$D$21)*($K$15)/($K$15+$L$15)),0)+IF($L$13=M4,(($D$19+$D$20+$D$21)*($L$15)/($K$15+$L$15)),0) -> 712 | E25: =IFERROR((ROUND(D25*K25,2)+ROUND(G25,2)+ROUND(J25,2))/ROUND(D25,4), 0) -> 0.024199438 | F25: =ROUND(D25*E25,2) -> 17.23 | G25: =((D25*K25)/(1-$N$19-$N$21))*($N$19+$N$21) -> 0.88254081 | H25: =ROUND((D25*K25)/(1-$N$19-$N$21)/(1-$I$19),8) -> 17.233423 | J25: =ROUND(H25*$I$19,2) -> 2.93 | K25: =N4 -> 0.01885
B26: Adicional BVM1 | C26: kWh | D26: =IF($K$13=M5,(($D$19+$D$20+$D$21)*($K$15)/($K$15+$L$15)),0)+IF($L$13=M5,(($D$19+$D$20+$D$21)*($L$15)/($K$15+$L$15)),0) -> 0 | E26: =IFERROR((ROUND(D26*K26,2)+ROUND(G26,2)+ROUND(J26,2))/ROUND(D26,4), 0) -> 0 | F26: =ROUND(D26*E26,2) -> 0 | G26: =((D26*K26)/(1-$N$19-$N$21))*($N$19+$N$21) -> 0 | H26: =ROUND((D26*K26)/(1-$N$19-$N$21)/(1-$I$19),8) -> 0 | J26: =ROUND(H26*$I$19,2) -> 0 | K26: =N5 -> 0.04463
B27: Adicional BVM2 | C27: kWh | D27: =IF($K$13=M6,(($D$19+$D$20+$D$21)*($K$15)/($K$15+$L$15)),0)+IF($L$13=M6,(($D$19+$D$20+$D$21)*($L$15)/($K$15+$L$15)),0) -> 0 | E27: =IFERROR((ROUND(D27*K27,2)+ROUND(G27,2)+ROUND(J27,2))/ROUND(D27,4), 0) -> 0 | F27: =ROUND(D27*E27,2) -> 0 | G27: =((D27*K27)/(1-$N$19-$N$21))*($N$19+$N$21) -> 0 | H27: =ROUND((D27*K27)/(1-$N$19-$N$21)/(1-$I$19),8) -> 0 | J27: =ROUND(H27*$I$19,2) -> 0 | K27: =N6 -> 0.07877
B28: Adicional EH | C28: kWh | D28: =IF($K$13=M7,(($D$19+$D$20+$D$21)*($K$15)/($K$15+$L$15)),0)+IF($L$13=M7,(($D$19+$D$20+$D$21)*($L$15)/($K$15+$L$15)),0) -> 0 | E28: =IFERROR((ROUND(D28*K28,2)+ROUND(G28,2)+ROUND(J28,2))/ROUND(D28,4), 0) -> 0 | F28: =ROUND(D28*E28,2) -> 0 | G28: =((D28*K28)/(1-$N$19-$N$21))*($N$19+$N$21) -> 0 | H28: =ROUND((D28*K28)/(1-$N$19-$N$21)/(1-$I$19),8) -> 0 | J28: =ROUND(H28*$I$19,2) -> 0 | K28: =N7 -> 0.142 | R28: 56.925816
R29: 24.55085
B30: TUSD - Ponta inj | C30: kWh | D30: 0 | E30: =IFERROR((ROUND(D30*K30,2)+ROUND(G30,2)+ROUND(J30,2))/ROUND(D30,4),0) -> 0 | F30: =ROUND(D30*E30,2) -> 0 | G30: =((D30*K30)/(1-$N$19-$N$21))*($N$19+$N$21) -> 0 | H30: 0 | I30: 0 | J30: =H30*$I$25 -> 0 | K30: =K19 -> 0.966268 | R30: =SUM(R28:R29) -> 81.476667
B31: TUSD - Inermediário inj | C31: kWh | D31: -215 | E31: =IFERROR((ROUND(D31*K31,2)+ROUND(G31,2)+ROUND(J31,2))/ROUND(D31,4),0) -> 0.71744186 | F31: =ROUND(D31*E31,2) -> -154.25 | G31: =((D31*K31)/(1-$N$19-$N$21))*($N$19+$N$21) -> -9.5173707 | H31: 0 | I31: 0 | J31: =H31*$I$25 -> 0 | K31: =K20 -> 0.673186
B32: TUSD - Fora Ponta inj | C32: kWh | D32: -107 | E32: =IFERROR((ROUND(D32*K32,2)+ROUND(G32,2)+ROUND(J32,2))/ROUND(D32,4),0) -> 0.40504673 | F32: =ROUND(D32*E32,2) -> -43.34 | G32: =((D32*K32)/(1-$N$19-$N$21))*($N$19+$N$21) -> -2.6744156 | H32: 0 | I32: 0 | J32: =H32*$I$25 -> 0 | K32: =K21 -> 0.38010333
B33: TE - Ponta inj | C33: kWh | D33: =D30 -> 0 | E33: =IFERROR((ROUND(D33*K33,2)+ROUND(G33,2)+ROUND(J33,2))/ROUND(D33,4),0) -> 0 | F33: =ROUND(D33*E33,2) -> 0 | G33: =((D33*K33)/(1-$N$19-$N$21))*($N$19+$N$21) -> 0 | H33: =ROUND((D33*K33)/(1-$N$19-$N$21)/(1-$I$33),8) -> 0 | I33: =$I$19 -> 0.17 | J33: =H33*$I$33 -> 0 | K33: =K22 -> 0.499614
B34: TE - Intermediário inj | C34: kWh | D34: =D31 -> -215 | E34: =IFERROR((ROUND(D34*K34,2)+ROUND(G34,2)+ROUND(J34,2))/ROUND(D34,4),0) -> 0.40181395 | F34: =ROUND(D34*E34,2) -> -86.39 | G34: =((D34*K34)/(1-$N$19-$N$21))*($N$19+$N$21) -> -4.4240106 | H34: =ROUND((D34*K34)/(1-$N$19-$N$21)/(1-$I$33),8) -> -86.387896 | I34: =$I$19 -> 0.17 | J34: =H34*$I$33 -> -14.685942 | K34: =K23 -> 0.31292067
B35: TE - Fora Ponta inj | C35: kWh | D35: =D32 -> -107 | E35: =IFERROR((ROUND(D35*K35,2)+ROUND(G35,2)+ROUND(J35,2))/ROUND(D35,4),0) -> 0.4017757 | F35: =ROUND(D35*E35,2) -> -42.99 | G35: =((D35*K35)/(1-$N$19-$N$21))*($N$19+$N$21) -> -2.2017169 | H35: =ROUND((D35*K35)/(1-$N$19-$N$21)/(1-$I$33),8) -> -42.993046 | I35: =$I$19 -> 0.17 | J35: =H35*$I$33 -> -7.3088178 | K35: =K24 -> 0.31292067
B36: Adicional BAM inj | C36: kWh | D36: =IF($K$13=M4,(($D$30+$D$31+$D$32)*($K$15)/($K$15+$L$15)),0)+IF($L$13=M4,(($D$30+$D$31+$D$32)*($L$15)/($K$15+$L$15)),0) -> -322 | E36: =IFERROR((ROUND(D36*K36,2)+ROUND(G36,2)+ROUND(J36,2))/ROUND(D36,4),0) -> 0.024192547 | F36: =ROUND(D36*E36,2) -> -7.79 | G36: =((D36*K36)/(1-$N$19-$N$21))*($N$19+$N$21) -> -0.3991266 | H36: =(D36*K36)/(1-$N$19-$N$21)/(1-$I$33) -> -7.793767 | J36: =H36*$I$33 -> -1.3249404 | K36: =N4 -> 0.01885
B37: Adicional BVM1 inj | C37: kWh | D37: =IF($K$13=M5,(($D$30+$D$31+$D$32)*($K$15)/($K$15+$L$15)),0)+IF($L$13=M5,(($D$30+$D$31+$D$32)*($L$15)/($K$15+$L$15)),0) -> 0 | E37: =IFERROR((ROUND(D37*K37,2)+ROUND(G37,2)+ROUND(J37,2))/ROUND(D37,4),0) -> 0 | F37: =ROUND(D37*E37,2) -> 0 | G37: =((D37*K37)/(1-$N$19-$N$21))*($N$19+$N$21) -> 0 | H37: =(D37*K37)/(1-$N$19-$N$21)/(1-$I$33) -> 0 | J37: =H37*$I$33 -> 0 | K37: =N5 -> 0.04463
B38: Adicional BVM2 inj | C38: kWh | D38: =IF($K$13=M6,(($D$30+$D$31+$D$32)*($K$15)/($K$15+$L$15)),0)+IF($L$13=M6,(($D$30+$D$31+$D$32)*($L$15)/($K$15+$L$15)),0) -> 0 | E38: =IFERROR((ROUND(D38*K38,2)+ROUND(G38,2)+ROUND(J38,2))/ROUND(D38,4),0) -> 0 | F38: =ROUND(D38*E38,2) -> 0 | G38: =((D38*K38)/(1-$N$19-$N$21))*($N$19+$N$21) -> 0 | H38: =(D38*K38)/(1-$N$19-$N$21)/(1-$I$33) -> 0 | J38: =H38*$I$33 -> 0 | K38: =N6 -> 0.07877
B39: Adicional EH inj | C39: kWh | D39: =IF($K$13=M7,(($D$30+$D$31+$D$32)*($K$15)/($K$15+$L$15)),0)+IF($L$13=M7,(($D$30+$D$31+$D$32)*($L$15)/($K$15+$L$15)),0) -> 0 | E39: =IFERROR((ROUND(D39*K39,2)+ROUND(G39,2)+ROUND(J39,2))/ROUND(D39,4),0) -> 0 | F39: =ROUND(D39*E39,2) -> 0 | G39: =((D39*K39)/(1-$N$19-$N$21))*($N$19+$N$21) -> 0 | H39: =(D39*K39)/(1-$N$19-$N$21)/(1-$I$33) -> 0 | J39: =H39*$I$33 -> 0 | K39: =N7 -> 0.142
B41: Multas
B42: Juros
B43: Doações | F43: -12.85
B44: CIP
...

Sheet B3 GD Branca OK
B2: B3 TB | E2: Vigência das Tarifas: | F2: ='B1 Res (GD) Branca OK'!F2 -> 46241 | H2: TARIFA BRANCA | M2: Bandeira | N2: R$/kWh | Q2: TUSD FIO B
M3: VERDE | N3: ='[4]B1 (Res) Branca OK'!N3 -> 0
B4: TARIFA | C4: ='Fatura B1 (GD) OK'!C4:E4 -> TARIFA ANTIGA - REH 3370/2024 | F4: ='Fatura B1 (GD) OK'!F4 -> TARIFA NOVA - REH xxxx/2025 | I4: Tarifas Proporcionalizadas | M4: BAM | N4: ='[4]B1 (Res) Branca OK'!N4 -> 0.01885 | Q4: TARIFA | R4: =C4 -> TARIFA ANTIGA - REH 3370/2024 | U4: =F4 -> TARIFA NOVA - REH xxxx/2025 | X4: Tarifas Proporcionalizadas
C5: Tusd | D5: TE | E5: TUSD + TE | F5: Tusd | G5: TE | H5: TUSD + TE | I5: Tusd | J5: TE | K5: TUSD + TE | M5: BVM1 | N5: ='[4]B1 (Res) Branca OK'!N5 -> 0.04463 | R5: Tusd (R$/kWh) | U5: Tusd (R$/kWh) | X5: Tusd (R$/kWh)
B6: B3 Ponta | C6: ='TABELA DE TARIFAS ANTIGAS'!G86/1000 -> 1.06103 | D6: ='TABELA DE TARIFAS ANTIGAS'!H86/1000 -> 0.48448 | E6: =C6+D6 -> 1.54551 | F6: ='TABELA DE TARIFAS NOVAS'!G88/1000 -> 1.12867 | G6: ='TABELA DE TARIFAS NOVAS'!H88/1000 -> 0.51691 | H6: =F6+G6 -> 1.64558 | I6: =((C6*$C$15)+(F6*$D$15))/($D$15+$C$15) -> 1.0925953 | J6: =((D6*$C$15)+(G6*$D$15))/($D$15+$C$15) -> 0.499614 | K6: =I6+J6 -> 1.5922093 | M6: BVM2 | N6: ='[4]B1 (Res) Branca OK'!N6 -> 0.07877 | Q6: =B6 -> B3 Ponta | R6: ='FIO B'!H31/1000 -> 0.69302445 | U6: ='FIO B'!K31/1000 -> 0.71111541 | X6: =((R6*$C$15)+(U6*$D$15))/($D$15+$C$15) -> 0.7014669
B7: B3 Fora Ponta | C7: ='TABELA DE TARIFAS ANTIGAS'!G88/1000 -> 0.38965 | D7: ='TABELA DE TARIFAS ANTIGAS'!H88/1000 -> 0.30579 | E7: =C7+D7 -> 0.69544 | F7: ='TABELA DE TARIFAS NOVAS'!G90/1000 -> 0.42334 | G7: ='TABELA DE TARIFAS NOVAS'!H90/1000 -> 0.32107 | H7: =F7+G7 -> 0.74441 | I7: =((C7*$C$15)+(F7*$D$15))/($D$15+$C$15) -> 0.405372 | J7: =((D7*$C$15)+(G7*$D$15))/($D$15+$C$15) -> 0.31292067 | K7: =I7+J7 -> 0.71829267 | M7: Escassez Hídrica | N7: 0.142 | Q7: =B7 -> B3 Fora Ponta | R7: ='FIO B'!H32/1000 -> 0.41581471 | U7: ='FIO B'!K32/1000 -> 0.42666929 | X7: =((R7*$C$15)+(U7*$D$15))/($D$15+$C$15) -> 0.42088018
B8: B3 Interm. | C8: ='TABELA DE TARIFAS ANTIGAS'!G87/1000 -> 0.72534 | D8: ='TABELA DE TARIFAS ANTIGAS'!H87/1000 -> 0.30579 | E8: =C8+D8 -> 1.03113 | F8: ='TABELA DE TARIFAS NOVAS'!G89/1000 -> 0.77601 | G8: ='TABELA DE TARIFAS NOVAS'!H89/1000 -> 0.32107 | H8: =F8+G8 -> 1.09708 | I8: =((C8*$C$15)+(F8*$D$15))/($D$15+$C$15) -> 0.748986 | J8: =((D8*$C$15)+(G8*$D$15))/($D$15+$C$15) -> 0.31292067 | K8: =I8+J8 -> 1.0619067 | Q8: =B8 -> B3 Interm. | R8: ='FIO B'!H33/1000 -> 0.13860487 | U8: ='FIO B'!K33/1000 -> 0.14222306 | X8: =((R8*$C$15)+(U8*$D$15))/($D$15+$C$15) -> 0.14029336
B9: CDE Escassez Hídrica | C9: 0.00018774721 | D9: -0.0044031307 | E9: =SUM(C9+D9) -> -0.0042153835 | F9: =T13 -> 0.00018418923 | G9: =U13 -> -0.00053182975 | H9: =F9+G9 -> -0.00034764052 | I9: =((C9*$C$15)+(F9*$D$15))/($D$15+$C$15) -> 0.00018608682 | J9: =((D9*$C$15)+(G9*$D$15))/($D$15+$C$15) -> -0.0025965236 | K9: =I9+J9 -> -0.0024104368
P10: CUSTO | R10: Part. TUSD (%) | S10: Part. TE (%) | T10: Tusd (R$/kWh) | U10: TE (R$/kWh)
H11: Fatura | L11: Vigência das Tarifas (troca Bandeira): | M11: =EOMONTH(B15,0)+1 -> 46235 | P11: CDE CONTAS
B12: INSTALAÇÃO | C12: 588890 | H12: =E15 -> 46254 | K12: Altere a bandeira na célula abaixo | P12: CDE COVID | U12: 0
K13: BAM | L13: BAM | P13: CDE ESCASSEZ HÍDRICA | T13: ='B1 Res (GD) Branca OK'!T13 -> 0.00018418923 | U13: ='B1 Res (GD) Branca OK'!U13 -> -0.00053182975
B14: Leitura Anterior | C14: Nº de dias tarifa Anterior | D14: Nº de dias tarifa Nova | E14: Leitura Atual | J14: Leitura Anterior | K14: Nº de dias tarifa Anterior | L14: Nº de dias tarifa Nova | M14: Leitura Atual
B15: 46224 | C15: =IF((F2-B15-1)<0,0,(F2-B15-1)) -> 16 | D15: =E15-F2+1 -> 14 | E15: 46254 | J15: =B15 -> 46224 | K15: =IF((M11-J15-1)<0,0,(M11-J15-1)) -> 10 | L15: =M15-M11+1 -> 20 | M15: =E15 -> 46254
B18: Perc. de Redução da Energia Injetada | E18: TUSD | F18: 1 | G18: TE | H18: 1 | M18: Documento impressão: | O18: 1025310403
B20: Descrição | C20: Unidade | D20: Quantidade | E20: Preço Unit (R$) com tributos | F20: Valor Total (R$) | G20: PIS/COFINS (R$) | H20: Base de Cálculo ICMS (R$) | I20: Alíquota ICMS (%) | J20: ICMS (R$) | K20: Preço Unit (R$) | L20: Tributos | M20: Base de Cálc (R$) | N20: Alíquota (%) | O20: Valor (R$)
B22: TUSD - Ponta | C22: kWh | D22: 64 | E22: =IFERROR((ROUND(D22*K22,2)+ROUND(G22,2)+ROUND(J22,2))/ROUND(D22,4), 0) -> 1.4029688 | F22: =ROUND(D22*E22,2) -> 89.79 | G22: =((D22*K22)/(1-$N$22-$N$24))*($N$22+$N$24) -> 4.5981461 | H22: =((D22*K22)/(1-$N$22-$N$24)/(1-$I$22)) -> 89.78825 | I22: 0.17 | J22: =(H22*$I$22) -> 15.264002 | K22: =E60 -> 1.0925953 | L22: PIS | M22: =D80 -> 378.26921 | N22: ='B1 Res (GD) Branca OK'!N19 -> 0.011 | O22: =ROUND(M22*N22,2) -> 4.16 | Q22: TUSD Fio B | R22: Receita Fio B
B23: TUSD - Intermediário | C23: kWh | D23: 0 | E23: =IFERROR((ROUND(D23*K23,2)+ROUND(G23,2)+ROUND(J23,2))/ROUND(D23,4), 0) -> 0 | F23: =ROUND(D23*E23,2) -> 0 | G23: =((D23*K23)/(1-$N$22-$N$24))*($N$22+$N$24) -> 0 | H23: =((D23*K23)/(1-$N$22-$N$24)/(1-$I$22)) -> 0 | I23: =I22 -> 0.17 | J23: =(H23*$I$22) -> 0 | K23: =E62 -> 0.748986 | L23: PIS Inj | M23: =D83 -> -256.84749 | N23: =N22 -> 0.011 | O23: =ROUND(M23*N23,2) -> -2.83 | Q23: =IF(AND($B$15<$F$2,$E$15<$F$2),R6,IF($B$15<$F$2,X6,U6)) -> 0.7014669 | R23: =D60*Q23 -> 44.893882
B24: TUSD - Fora Ponta | C24: kWh | D24: 233 | E24: =IFERROR((ROUND(D24*K24,2)+ROUND(G24,2)+ROUND(J24,2))/ROUND(D24,4), 0) -> 0.52051502 | F24: =ROUND(D24*E24,2) -> 121.28 | G24: =((D24*K24)/(1-$N$22-$N$24))*($N$22+$N$24) -> 6.2108797 | H24: =((D24*K24)/(1-$N$22-$N$24)/(1-$I$22)) -> 121.28019 | I24: =I22 -> 0.17 | J24: =(H24*$I$22) -> 20.617632 | K24: =E61 -> 0.405372 | L24: COFINS | M24: =M22 -> 378.26921 | N24: ='B1 Res (GD) Branca OK'!N21 -> 0.0507 | O24: =ROUND(M24*N24,2) -> 19.18 | Q24: =IF(AND($B$15<$F$2,$E$15<$F$2),R7,IF($B$15<$F$2,X7,U7)) -> 0.42088018 | R24: =D61*Q24 -> 0
B25: TE - Ponta | C25: kWh | D25: =D22 -> 64 | E25: =IFERROR((ROUND(D25*K25,2)+ROUND(G25,2)+ROUND(J25,2))/ROUND(D25,4), 0) -> 0.6415625 | F25: =ROUND(D25*E25,2) -> 41.06 | G25: =((D25*K25)/(1-$N$22-$N$24))*($N$22+$N$24) -> 2.1026066 | H25: =ROUND((D25*K25)/(1-$N$23-$N$24)/(1-$I$22),8) -> 41.057714 | J25: =ROUND(H25*$I$22,2) -> 6.98 | K25: =F60 -> 0.499614 | L25: COFINS Inj | M25: =M23 -> -256.84749 | N25: =N24 -> 0.0507 | O25: =ROUND(M25*N25,2) -> -13.02 | Q25: =IF(AND($B$15<$F$2,$E$15<$F$2),R8,IF($B$15<$F$2,X8,U8)) -> 0.14029336 | R25: =D62*Q25 -> 32.688353
B26: TE - Intermediário | C26: kWh | D26: =D23 -> 0 | E26: =IFERROR((ROUND(D26*K26,2)+ROUND(G26,2)+ROUND(J26,2))/ROUND(D26,4), 0) -> 0 | F26: =ROUND(D26*E26,2) -> 0 | G26: =((D26*K26)/(1-$N$22-$N$24))*($N$22+$N$24) -> 0 | H26: =ROUND((D26*K26)/(1-$N$23-$N$24)/(1-$I$22),8) -> 0 | J26: =ROUND(H26*$I$22,2) -> 0 | K26: =F62 -> 0.31292067 | R26: =SUM(R23:R25) -> 77.582235
B27: TE - Fora Ponta | C27: kWh | D27: =D24 -> 233 | E27: =IFERROR((ROUND(D27*K27,2)+ROUND(G27,2)+ROUND(J27,2))/ROUND(D27,4), 0) -> 0.40180258 | F27: =ROUND(D27*E27,2) -> 93.62 | G27: =((D27*K27)/(1-$N$22-$N$24))*($N$22+$N$24) -> 4.7943928 | H27: =ROUND((D27*K27)/(1-$N$23-$N$24)/(1-$I$22),8) -> 93.620371 | J27: =ROUND(H27*$I$22,2) -> 15.92 | K27: =F61 -> 0.31292067
B28: Adicional BAM | C28: kWh | D28: =IF($K$13=M4,(($D$22+$D$23+$D$24)*($K$15)/($K$15+$L$15)),0)+IF($L$13=M4,(($D$22+$D$23+$D$24)*($L$15)/($K$15+$L$15)),0) -> 297 | E28: =IFERROR((ROUND(D28*K28,2)+ROUND(G28,2)+ROUND(J28,2))/ROUND(D28,4), 0) -> 0.024208754 | F28: =ROUND(D28*E28,2) -> 7.19 | G28: =((D28*K28)/(1-$N$22-$N$24))*($N$22+$N$24) -> 0.36813851 | H28: =ROUND((D28*K28)/(1-$N$22-$N$24)/(1-$I$22),8) -> 7.1886609 | J28: =ROUND(H28*$I$22,2) -> 1.22 | K28: =N4 -> 0.01885
B29: Adicional BVM1 | C29: kWh | D29: =IF($K$13=M5,(($D$22+$D$23+$D$24)*($K$15)/($K$15+$L$15)),0)+IF($L$13=M5,(($D$22+$D$23+$D$24)*($L$15)/($K$15+$L$15)),0) -> 0 | E29: =IFERROR((ROUND(D29*K29,2)+ROUND(G29,2)+ROUND(J29,2))/ROUND(D29,4), 0) -> 0 | F29: =ROUND(D29*E29,2) -> 0 | G29: =((D29*K29)/(1-$N$22-$N$24))*($N$22+$N$24) -> 0 | H29: =ROUND((D29*K29)/(1-$N$22-$N$24)/(1-$I$22),8) -> 0 | J29: =ROUND(H29*$I$22,2) -> 0 | K29: =N5 -> 0.04463
B30: Adicional BVM2 | C30: kWh | D30: =IF($K$13=M6,(($D$22+$D$23+$D$24)*($K$15)/($K$15+$L$15)),0)+IF($L$13=M6,(($D$22+$D$23+$D$24)*($L$15)/($K$15+$L$15)),0) -> 0 | E30: =IFERROR((ROUND(D30*K30,2)+ROUND(G30,2)+ROUND(J30,2))/ROUND(D30,4), 0) -> 0 | F30: =ROUND(D30*E30,2) -> 0 | G30: =((D30*K30)/(1-$N$22-$N$24))*($N$22+$N$24) -> 0 | H30: =ROUND((D30*K30)/(1-$N$22-$N$24)/(1-$I$22),8) -> 0 | J30: =ROUND(H30*$I$22,2) -> 0 | K30: =N6 -> 0.07877
B31: Adicional EH | C31: kWh | D31: =IF($K$13=M7,(($D$22+$D$23+$D$24)*($K$15)/($K$15+$L$15)),0)+IF($L$13=M7,(($D$22+$D$23+$D$24)*($L$15)/($K$15+$L$15)),0) -> 0 | E31: =IFERROR((ROUND(D31*K31,2)+ROUND(G31,2)+ROUND(J31,2))/ROUND(D31,4), 0) -> 0 | F31: =ROUND(D31*E31,2) -> 0 | G31: =((D31*K31)/(1-$N$22-$N$24))*($N$22+$N$24) -> 0 | H31: =ROUND((D31*K31)/(1-$N$22-$N$24)/(1-$I$22),8) -> 0 | J31: =ROUND(H31*$I$22,2) -> 0 | K31: =N7 -> 0.142
B33: TUSD - Ponta inj | C33: kWh | D33: -52.9735 | E33: =IFERROR((ROUND(D33*K33,2)+ROUND(G33,2)+ROUND(J33,2))/ROUND(D33,4),0) -> 1.1645445 | F33: =ROUND(D33*E33,2) -> -61.69 | G33: =((D33*K33)/(1-$N$23-$N$25))*($N$23+$N$25) -> -3.8059358 | H33: 0 | I33: 0 | J33: =H33*$I$33 -> 0 | K33: =K22 -> 1.0925953
B34: TUSD - Intermediário inj | C34: kWh | D34: 0 | E34: =IFERROR((ROUND(D34*K34,2)+ROUND(G34,2)+ROUND(J34,2))/ROUND(D34,4),0) -> 0 | F34: =ROUND(D34*E34,2) -> 0 | G34: =((D34*K34)/(1-$N$23-$N$25))*($N$23+$N$25) -> 0 | H34: 0 | I34: 0 | J34: =H34*$I$33 -> 0 | K34: =K23 -> 0.748986
B35: TUSD - Fora Ponta inj | C35: kWh | D35: -144.0207 | E35: =IFERROR((ROUND(D35*K35,2)+ROUND(G35,2)+ROUND(J35,2))/ROUND(D35,4),0) -> 0.43202123 | F35: =ROUND(D35*E35,2) -> -62.22 | G35: =((D35*K35)/(1-$N$23-$N$25))*($N$23+$N$25) -> -3.8390354 | H35: 0 | I35: 0 | J35: =H35*$I$33 -> 0 | K35: =K24 -> 0.405372
B36: TE - Ponta inj | C36: kWh | D36: =D33 -> -52.9735 | E36: =IFERROR((ROUND(D36*K36,2)+ROUND(G36,2)+ROUND(J36,2))/ROUND(D36,4),0) -> 0.64164158 | F36: =ROUND(D36*E36,2) -> -33.99 | G36: =((D36*K36)/(1-$N$23-$N$25))*($N$23+$N$25) -> -1.7403505 | H36: =ROUND((D36*K36)/(1-$N$23-$N$25)/(1-$I$36),8) -> -33.983919 | I36: 0.17 | J36: =H36*$I$36 -> -5.7772662 | K36: =K25 -> 0.499614
B37: TE - Intermediário inj | C37: kWh | D37: =D34 -> 0 | E37: =IFERROR((ROUND(D37*K37,2)+ROUND(G37,2)+ROUND(J37,2))/ROUND(D37,4),0) -> 0 | F37: =ROUND(D37*E37,2) -> 0 | G37: =((D37*K37)/(1-$N$23-$N$25))*($N$23+$N$25) -> 0 | H37: =ROUND((D37*K37)/(1-$N$23-$N$25)/(1-$I$36),8) -> 0 | I37: =I36 -> 0.17 | J37: =H37*$I$36 -> 0 | K37: =K26 -> 0.31292067
B38: TE - Fora Ponta inj | C38: kWh | D38: =D35 -> -144.0207 | E38: =IFERROR((ROUND(D38*K38,2)+ROUND(G38,2)+ROUND(J38,2))/ROUND(D38,4),0) -> 0.40181724 | F38: =ROUND(D38*E38,2) -> -57.87 | G38: =((D38*K38)/(1-$N$23-$N$25))*($N$23+$N$25) -> -2.9634842 | H38: =ROUND((D38*K38)/(1-$N$23-$N$25)/(1-$I$36),8) -> -57.868118 | I38: =I36 -> 0.17 | J38: =H38*$I$36 -> -9.83758 | K38: =K27 -> 0.31292067
B39: Adicional BAM inj | C39: kWh | D39: =IF($K$13=M4,(($D$33+$D$34+$D$35)*($K$15)/($K$15+$L$15)),0)+IF($L$13=M4,(($D$33+$D$34+$D$35)*($L$15)/($K$15+$L$15)),0) -> -196.9942 | E39: =IFERROR((ROUND(D39*K39,2)+ROUND(G39,2)+ROUND(J39,2))/ROUND(D39,4),0) -> 0.024163148 | F39: =ROUND(D39*E39,2) -> -4.76 | G39: =((D39*K39)/(1-$N$23-$N$25))*($N$23+$N$25) -> -0.24417896 | H39: =(D39*K39)/(1-$N$23-$N$25)/(1-$I$36) -> -4.7680959 | J39: =H39*$I$36 -> -0.81057631 | K39: =N4 -> 0.01885
B40: Adicional BVM1 inj | C40: kWh | D40: =IF($K$13=M5,(($D$33+$D$34+$D$35)*($K$15)/($K$15+$L$15)),0)+IF($L$13=M5,(($D$33+$D$34+$D$35)*($L$15)/($K$15+$L$15)),0) -> 0 | E40: =IFERROR((ROUND(D40*K40,2)+ROUND(G40,2)+ROUND(J40,2))/ROUND(D40,4),0) -> 0 | F40: =ROUND(D40*E40,2) -> 0 | G40: =((D40*K40)/(1-$N$23-$N$25))*($N$23+$N$25) -> 0 | H40: =(D40*K40)/(1-$N$23-$N$25)/(1-$I$36) -> 0 | J40: =H40*$I$36 -> 0 | K40: =N5 -> 0.04463
B41: Adicional BVM2 inj | C41: kWh | D41: =IF($K$13=M6,(($D$33+$D$34+$D$35)*($K$15)/($K$15+$L$15)),0)+IF($L$13=M6,(($D$33+$D$34+$D$35)*($L$15)/($K$15+$L$15)),0) -> 0 | E41: =IFERROR((ROUND(D41*K41,2)+ROUND(G41,2)+ROUND(J41,2))/ROUND(D41,4),0) -> 0 | F41: =ROUND(D41*E41,2) -> 0 | G41: =((D41*K41)/(1-$N$23-$N$25))*($N$23+$N$25) -> 0 | H41: =(D41*K41)/(1-$N$23-$N$25)/(1-$I$36) -> 0 | J41: =H41*$I$36 -> 0 | K41: =N6 -> 0.07877
B42: Adicional EH inj | C42: kWh | E42: =IFERROR((ROUND(D42*K42,2)+ROUND(G42,2)+ROUND(J42,2))/ROUND(D42,4),0) -> 0 | F42: =ROUND(D42*E42,2) -> 0 | G42: =((D42*K42)/(1-$N$23-$N$25))*($N$23+$N$25) -> 0 | H42: =(D42*K42)/(1-$N$23-$N$25)/(1-$I$36) -> 0 | J42: =H42*$I$36 -> 0 | K42: =N7 -> 0.142
B44: Multas
B45: Juros
B46: Bônus/Descontos
B47: Doações
...

Sheet B2 GD Branca OK
B2: B2 TB | E2: Vigência das Tarifas: | F2: ='B1 Res (GD) Branca OK'!F2 -> 46241 | H2: TARIFA BRANCA | M2: Bandeira | N2: R$/kWh | Q2: TUSD FIO B
M3: VERDE | N3: ='[4]B1 (Res) Branca OK'!N3 -> 0
B4: TARIFA | C4: ='Fatura B1 (GD) OK'!C4:E4 -> TARIFA ANTIGA - REH 3370/2024 | F4: ='Fatura B1 (GD) OK'!F4 -> TARIFA NOVA - REH xxxx/2025 | I4: Tarifas Proporcionalizadas | M4: BAM | N4: ='[4]B1 (Res) Branca OK'!N4 -> 0.01885 | Q4: TARIFA | R4: =C4 -> TARIFA ANTIGA - REH 3370/2024 | U4: =F4 -> TARIFA NOVA - REH xxxx/2025 | X4: Tarifas Proporcionalizadas
C5: Tusd | D5: TE | E5: TUSD + TE | F5: Tusd | G5: TE | H5: TUSD + TE | I5: Tusd | J5: TE | K5: TUSD + TE | M5: BVM1 | N5: ='[4]B1 (Res) Branca OK'!N5 -> 0.04463 | R5: Tusd (R$/kWh) | U5: Tusd (R$/kWh) | X5: Tusd (R$/kWh)
B6: B2 Ponta | C6: ='TABELA DE TARIFAS ANTIGAS'!G74/1000 -> 1.06103 | D6: ='TABELA DE TARIFAS ANTIGAS'!H74/1000 -> 0.48448 | E6: =C6+D6 -> 1.54551 | F6: ='TABELA DE TARIFAS NOVAS'!G76/1000 -> 1.12867 | G6: ='TABELA DE TARIFAS NOVAS'!H76/1000 -> 0.51691 | H6: =F6+G6 -> 1.64558 | I6: =((C6*$C$15)+(F6*$D$15))/($D$15+$C$15) -> 1.0715987 | J6: =((D6*$C$15)+(G6*$D$15))/($D$15+$C$15) -> 0.48954719 | K6: =I6+J6 -> 1.5611459 | M6: BVM2 | N6: ='[4]B1 (Res) Branca OK'!N6 -> 0.07877 | Q6: =B6 -> B2 Ponta | R6: ='FIO B'!H16/1000 -> 0.69302445 | U6: ='FIO B'!K16/1000 -> 0.71111541 | X6: =((R6*$C$15)+(U6*$D$15))/($D$15+$C$15) -> 0.69585117
B7: B2 Fora Ponta | C7: ='TABELA DE TARIFAS ANTIGAS'!G76/1000 -> 0.38965 | D7: ='TABELA DE TARIFAS ANTIGAS'!H76/1000 -> 0.30579 | E7: =C7+D7 -> 0.69544 | F7: ='TABELA DE TARIFAS NOVAS'!G78/1000 -> 0.42334 | G7: ='TABELA DE TARIFAS NOVAS'!H78/1000 -> 0.32107 | H7: =F7+G7 -> 0.74441 | I7: =((C7*$C$15)+(F7*$D$15))/($D$15+$C$15) -> 0.39491406 | J7: =((D7*$C$15)+(G7*$D$15))/($D$15+$C$15) -> 0.3081775 | K7: =I7+J7 -> 0.70309156 | M7: Escassez Hídrica | N7: 0.142 | Q7: =B7 -> B2 Fora Ponta | R7: ='FIO B'!H17/1000 -> 0.41581471 | U7: ='FIO B'!K17/1000 -> 0.42666929 | X7: =((R7*$C$15)+(U7*$D$15))/($D$15+$C$15) -> 0.41751074
B8: B2 Interm. | C8: ='TABELA DE TARIFAS ANTIGAS'!G75/1000 -> 0.72534 | D8: ='TABELA DE TARIFAS ANTIGAS'!H75/1000 -> 0.30579 | E8: =C8+D8 -> 1.03113 | F8: ='TABELA DE TARIFAS NOVAS'!G77/1000 -> 0.77601 | G8: ='TABELA DE TARIFAS NOVAS'!H77/1000 -> 0.32107 | H8: =F8+G8 -> 1.09708 | I8: =((C8*$C$15)+(F8*$D$15))/($D$15+$C$15) -> 0.73325719 | J8: =((D8*$C$15)+(G8*$D$15))/($D$15+$C$15) -> 0.3081775 | K8: =I8+J8 -> 1.0414347 | Q8: =B8 -> B2 Interm. | R8: ='FIO B'!H18/1000 -> 0.13860487 | U8: ='FIO B'!K18/1000 -> 0.14222306 | X8: =((R8*$C$15)+(U8*$D$15))/($D$15+$C$15) -> 0.13917021
B9: CDE Escassez Hídrica | C9: 0.00018774721 | D9: -0.0044031307 | E9: =SUM(C9+D9) -> -0.0042153835 | F9: =T13 -> 0.00018418923 | G9: =U13 -> -0.00053182975 | H9: =F9+G9 -> -0.00034764052 | I9: =((C9*$C$15)+(F9*$D$15))/($D$15+$C$15) -> 0.00018719128 | J9: =((D9*$C$15)+(G9*$D$15))/($D$15+$C$15) -> -0.00379824 | K9: =I9+J9 -> -0.0036110487
P10: CUSTO | R10: Part. TUSD (%) | S10: Part. TE (%) | T10: Tusd (R$/kWh) | U10: TE (R$/kWh)
H11: Fatura | L11: Vigência das Tarifas (troca Bandeira): | M11: =EOMONTH(B15,0)+1 -> 46235 | P11: CDE CONTAS
B12: INSTALAÇÃO | C12: 584185 | H12: =E15 -> 46245 | K12: Altere a bandeira na célula abaixo | P12: CDE COVID | U12: 0
K13: BAM | L13: BAM | P13: CDE ESCASSEZ HÍDRICA | T13: ='B1 Res (GD) Branca OK'!T13 -> 0.00018418923 | U13: ='B1 Res (GD) Branca OK'!U13 -> -0.00053182975
B14: Leitura Anterior | C14: Nº de dias tarifa Anterior | D14: Nº de dias tarifa Nova | E14: Leitura Atual | J14: Leitura Anterior | K14: Nº de dias tarifa Anterior | L14: Nº de dias tarifa Nova | M14: Leitura Atual
B15: 46213 | C15: =IF((F2-B15-1)<0,0,(F2-B15-1)) -> 27 | D15: =E15-F2+1 -> 5 | E15: 46245 | J15: =B15 -> 46213 | K15: =IF((M11-J15-1)<0,0,(M11-J15-1)) -> 21 | L15: =M15-M11+1 -> 11 | M15: =E15 -> 46245
Q16: instalações
Q17: 584185
B18: Perc. de Redução da Energia Injetada | E18: TUSD | F18: 1 | G18: TE | H18: 1 | M18: Documento impressão: | O18: 1025310408 | Q18: 160671516
Q19: 645437
B20: Descrição | C20: Unidade | D20: Quantidade | E20: Preço Unit (R$) com tributos | F20: Valor Total (R$) | G20: PIS/COFINS (R$) | H20: Base de Cálculo ICMS (R$) | I20: Alíquota ICMS (%) | J20: ICMS (R$) | K20: Preço Unit (R$) | L20: Tributos | M20: Base de Cálc (R$) | N20: Alíquota (%) | O20: Valor (R$)
B22: TUSD - Ponta | C22: kWh | D22: 204 | E22: =IFERROR((ROUND(D22*K22,2)+ROUND(G22,2)+ROUND(J22,2))/ROUND(D22,4), 0) -> 1.1896569 | F22: =ROUND(D22*E22,2) -> 242.69 | G22: =((D22*K22)/(1-$N$22-$N$24))*($N$22+$N$24) -> 14.374932 | H22: =(IF($I$22=12%,(D22*K22)/(1-$N$22-$N$24)/(1-$C$93)/$F$93*$C$93,(D22*K22)/(1-$N$22-$N$24)/(1-$I$22))) -> 80.896207 | I22: 0.12 | J22: =(H22*$I$22) -> 9.7075449 | K22: =E60 -> 1.0715987 | L22: PIS | M22: =D80 -> 805.69114 | N22: ='B1 Res (GD) Branca OK'!N19 -> 0.011 | O22: =ROUND(M22*N22,2) -> 8.86 | R22: 60.906708
B23: TUSD - Intermediário | C23: kWh | D23: 0 | E23: =IFERROR((ROUND(D23*K23,2)+ROUND(G23,2)+ROUND(J23,2))/ROUND(D23,4), 0) -> 0 | F23: =ROUND(D23*E23,2) -> 0 | G23: =((D23*K23)/(1-$N$22-$N$24))*($N$22+$N$24) -> 0 | H23: =(IF($I$22=12%,(D23*K23)/(1-$N$22-$N$24)/(1-$C$93)/$F$93*$C$93,(D23*K23)/(1-$N$22-$N$24)/(1-$I$22))) -> 0 | I23: =I22 -> 0.12 | J23: =(H23*$I$22) -> 0 | K23: =E62 -> 0.73325719 | L23: PIS Inj | M23: =D81 -> -691.49526 | N23: =N22 -> 0.011 | O23: =ROUND(M23*N23,2) -> -7.61 | R23: 23.773292
B24: TUSD - Fora Ponta | C24: kWh | D24: 409 | E24: =IFERROR((ROUND(D24*K24,2)+ROUND(G24,2)+ROUND(J24,2))/ROUND(D24,4), 0) -> 0.43841076 | F24: =ROUND(D24*E24,2) -> 179.31 | G24: =((D24*K24)/(1-$N$22-$N$24))*($N$22+$N$24) -> 10.621096 | H24: =(IF($I$22=12%,(D24*K24)/(1-$N$22-$N$24)/(1-$C$93)/$F$93*$C$93,(D24*K24)/(1-$N$22-$N$24)/(1-$I$22))) -> 59.771163 | I24: =I22 -> 0.12 | J24: =(H24*$I$22) -> 7.1725395 | K24: =E61 -> 0.39491406 | L24: COFINS | M24: =D82 -> 805.69114 | N24: ='B1 Res (GD) Branca OK'!N21 -> 0.0507 | O24: =ROUND(M24*N24,2) -> 40.85
B25: TE - Ponta | C25: kWh | D25: =D22 -> 204 | E25: =IFERROR((ROUND(D25*K25,2)+ROUND(G25,2)+ROUND(J25,2))/ROUND(D25,4), 0) -> 0.54348039 | F25: =ROUND(D25*E25,2) -> 110.87 | G25: =((D25*K25)/(1-$N$22-$N$24))*($N$22+$N$24) -> 6.5670175 | H25: =(IF($I$22=12%,(D25*K25)/(1-$N$22-$N$24)/(1-$C$93)/$F$93*$C$93,(D25*K25)/(1-$N$22-$N$24)/(1-$I$22))) -> 36.956474 | J25: =(H25*$I$22) -> 4.4347768 | K25: =F60 -> 0.48954719 | L25: COFINS Inj | M25: =D83 -> -691.49526 | N25: =N24 -> 0.0507 | O25: =ROUND(M25*N25,2) -> -35.06
B26: TE - Intermediário | C26: kWh | D26: =D23 -> 0 | E26: =IFERROR((ROUND(D26*K26,2)+ROUND(G26,2)+ROUND(J26,2))/ROUND(D26,4), 0) -> 0 | F26: =ROUND(D26*E26,2) -> 0 | G26: =((D26*K26)/(1-$N$22-$N$24))*($N$22+$N$24) -> 0 | H26: =(IF($I$22=12%,(D26*K26)/(1-$N$22-$N$24)/(1-$C$93)/$F$93*$C$93,(D26*K26)/(1-$N$22-$N$24)/(1-$I$22))) -> 0 | J26: =(H26*$I$22) -> 0 | K26: =F62 -> 0.3081775
B27: TE - Fora Ponta | C27: kWh | D27: =D24 -> 409 | E27: =IFERROR((ROUND(D27*K27,2)+ROUND(G27,2)+ROUND(J27,2))/ROUND(D27,4), 0) -> 0.34212714 | F27: =ROUND(D27*E27,2) -> 139.93 | G27: =((D27*K27)/(1-$N$22-$N$24))*($N$22+$N$24) -> 8.2883424 | H27: =(IF($I$22=12%,(D27*K27)/(1-$N$22-$N$24)/(1-$C$93)/$F$93*$C$93,(D27*K27)/(1-$N$22-$N$24)/(1-$I$22))) -> 46.643382 | J27: =(H27*$I$22) -> 5.5972058 | K27: =F61 -> 0.3081775
B28: Adicional BAM | C28: kWh | D28: =IF($K$13=M4,(($D$22+$D$23+$D$24)*($K$15)/($K$15+$L$15)),0)+IF($L$13=M4,(($D$22+$D$23+$D$24)*($L$15)/($K$15+$L$15)),0) -> 613 | E28: =IFERROR((ROUND(D28*K28,2)+ROUND(G28,2)+ROUND(J28,2))/ROUND(D28,4), 0) -> 0.020929853 | F28: =ROUND(D28*E28,2) -> 12.83 | G28: =((D28*K28)/(1-$N$22-$N$24))*($N$22+$N$24) -> 0.75982797 | H28: =(IF($I$22=12%,(D28*K28)/(1-$N$22-$N$24)/(1-$C$93)/$F$93*$C$93,(D28*K28)/(1-$N$22-$N$24)/(1-$I$22))) -> 4.2759993 | J28: =ROUND(H28*$I$22,2) -> 0.51 | K28: =N4 -> 0.01885
B29: Adicional BVM1 | C29: kWh | D29: =IF($K$13=M5,(($D$22+$D$23+$D$24)*($K$15)/($K$15+$L$15)),0)+IF($L$13=M5,(($D$22+$D$23+$D$24)*($L$15)/($K$15+$L$15)),0) -> 0 | E29: =IFERROR((ROUND(D29*K29,2)+ROUND(G29,2)+ROUND(J29,2))/ROUND(D29,4), 0) -> 0 | F29: =ROUND(D29*E29,2) -> 0 | G29: =((D29*K29)/(1-$N$22-$N$24))*($N$22+$N$24) -> 0 | H29: =(IF($I$22=12%,(D29*K29)/(1-$N$22-$N$24)/(1-$C$93)/$F$93*$C$93,(D29*K29)/(1-$N$22-$N$24)/(1-$I$22))) -> 0 | J29: =ROUND(H29*$I$22,2) -> 0 | K29: =N5 -> 0.04463
B30: Adicional BVM2 | C30: kWh | D30: =IF($K$13=M6,(($D$22+$D$23+$D$24)*($K$15)/($K$15+$L$15)),0)+IF($L$13=M6,(($D$22+$D$23+$D$24)*($L$15)/($K$15+$L$15)),0) -> 0 | E30: =IFERROR((ROUND(D30*K30,2)+ROUND(G30,2)+ROUND(J30,2))/ROUND(D30,4), 0) -> 0 | F30: =ROUND(D30*E30,2) -> 0 | G30: =((D30*K30)/(1-$N$22-$N$24))*($N$22+$N$24) -> 0 | H30: =(IF($I$22=12%,(D30*K30)/(1-$N$22-$N$24)/(1-$C$93)/$F$93*$C$93,(D30*K30)/(1-$N$22-$N$24)/(1-$I$22))) -> 0 | J30: =ROUND(H30*$I$22,2) -> 0 | K30: =N6 -> 0.07877 | R30: TUSD Fio B | S30: Receita Fio B
B31: Adicional EH | C31: kWh | D31: =IF($K$13=M7,(($D$22+$D$23+$D$24)*($K$15)/($K$15+$L$15)),0)+IF($L$13=M7,(($D$22+$D$23+$D$24)*($L$15)/($K$15+$L$15)),0) -> 0 | E31: =IFERROR((ROUND(D31*K31,2)+ROUND(G31,2)+ROUND(J31,2))/ROUND(D31,4), 0) -> 0 | F31: =ROUND(D31*E31,2) -> 0 | G31: =((D31*K31)/(1-$N$22-$N$24))*($N$22+$N$24) -> 0 | H31: =(IF($I$22=12%,(D31*K31)/(1-$N$22-$N$24)/(1-$C$93)/$F$93*$C$93,(D31*K31)/(1-$N$22-$N$24)/(1-$I$22))) -> 0 | J31: =ROUND(H31*$I$22,2) -> 0 | K31: =N7 -> 0.142 | R31: =IF(AND($B$15<$F$2,$E$15<$F$2),R6,IF($B$15<$F$2,X6,U6)) -> 0.69585117 | S31: =D60*R31 -> 141.95364
R32: =IF(AND($B$15<$F$2,$E$15<$F$2),R7,IF($B$15<$F$2,X7,U7)) -> 0.41751074 | S32: =D61*R32 -> 0
