Workbook

Sheet Fatura B1 (GD I)
B2: B1 Res | E2: Vigência das Tarifas: | F2: 45145 | I2: GDI | M2: Bandeira | N2: R$/kWh | O2: ANEEL em 29/06 | Q2: TUSD FIO B
M3: VERDE | N3: 0
B4: TARIFA | C4: TARIFA ANTIGA - REH 3091/2022 | F4: TARIFA NOVA - REH XXXX/2023 | I4: Tarifas Proporcionalizadas | M4: BAM | N4: 0.02989 | Q4: TARIFA | R4: =C4 -> TARIFA ANTIGA - REH 3091/2022 | U4: =F4 -> TARIFA NOVA - REH XXXX/2023 | X4: Tarifas Proporcionalizadas
C5: Tusd | D5: TE | E5: TUSD + TE | F5: Tusd | G5: TE | H5: TUSD + TE | I5: Tusd | J5: TE | K5: TUSD + TE | M5: BVM1 | N5: 0.065 | R5: Tusd (R$/kWh) | U5: Tusd (R$/kWh) | X5: Tusd (R$/kWh)
B6: B1 | C6: 0.39681 | D6: 0.27703 | E6: =C6+D6 -> 0.67384 | F6: 0.39681 | G6: 0.27703 | H6: =F6+G6 -> 0.67384 | I6: =((C6*$C$14)+(F6*$D$14))/($D$14+$C$14) -> 0.39681 | J6: =((D6*$C$14)+(G6*$D$14))/($D$14+$C$14) -> 0.27703 | K6: =I6+J6 -> 0.67384 | M6: BVM2 | N6: 0.09795 | Q6: =B6 -> B1 | R6: ='[2]FIO B'!H11/1000 -> 0.19205 | U6: ='[2]FIO B'!K11/1000 -> 0.17652 | X6: =((R6*$C$14)+(U6*$D$14))/($D$14+$C$14) -> 0.18503645
B7: CDE Escassez Hídrica | F7: =T11 -> 0.00020011 | G7: =U11 -> 0.00402681 | H7: =F7+G7 -> 0.00422692 | I7: =((C7*$C$14)+(F7*$D$14))/($D$14+$C$14) -> 9.0372258e-05 | J7: =((D7*$C$14)+(G7*$D$14))/($D$14+$C$14) -> 0.0018185594 | K7: =I7+J7 -> 0.0019089316
B8: TE SCEE | G8: =G6*15% -> 0.0415545 | J8: =((D8*$C$14)+(G8*$D$14))/($D$14+$C$14) -> 0.018766548 | M8: Escassez Hídrica | N8: 0.142 | P8: CUSTO | T8: Tusd (R$/kWh) | U8: TE (R$/kWh)
P9: CDE CONTAS
H10: Fatura | L10: Vigência das Tarifas (troca Bandeira): | M10: =EOMONTH(B14,0)+1 -> 45139 | P10: CDE COVID
B11: INSTALAÇÃO | C11: 1182321 | H11: =E14 -> 45158 | K11: Altere a bandeira na célula abaixo | P11: CDE ESCASSEZ HÍDRICA | T11: 0.00020011 | U11: 0.00402681
K12: BAM | L12: BVM2
B13: Leitura Anterior | C13: Nº de dias tarifa Anterior | D13: Nº de dias tarifa Nova | E13: Leitura Atual | J13: Leitura Anterior | K13: Nº de dias tarifa Anterior | L13: Nº de dias tarifa Nova | M13: Leitura Atual
B14: 45127 | C14: =IF((F2-B14-1)<0,0,(F2-B14-1)) -> 17 | D14: =E14-F2+1 -> 14 | E14: 45158 | J14: =B14 -> 45127 | K14: =IF((M10-J14-1)<0,0,(M10-J14-1)) -> 11 | L14: =M14-M10+1 -> 20 | M14: =E14 -> 45158
B17: Perc. de Redução da Energia Injetada | E17: TUSD | F17: 1 | G17: TE | H17: 1
B19: Fatura B1 Residencial
D20: Qtde | E20: TUSD | F20: TE | G20: TUSD + TE | H20: R$
B21: Fornecimento de Energia Elétrica | H21: =SUM(H23:H39)+SUM(H44:H49) -> 254.92055
B23: Energia Fornecida | D23: 2000 | E23: =IF(AND($B$14<$F$2,$E$14<$F$2),C6,IF($B$14<$F$2,I6,F6)) -> 0.39681 | F23: =IF(AND($B$14<$F$2,$E$14<$F$2),D6,IF($B$14<$F$2,J6,G6)) -> 0.27703 | G23: =E23+F23 -> 0.67384 | H23: =ROUND((D23*E23),2)+ROUND((D23*F23),2) -> 1347.68
B25: Adicional BAM | D25: =IF($K$12=M4,(D23*(K14)/(K14+L14)),0)+IF($L$12=M4,(D23*(L14)/(K14+L14)),0) -> 709.67742 | F25: =N4 -> 0.02989 | H25: =ROUND(D25*(E25+F25),2) -> 21.21
B26: Adicional BVM 1 | D26: =IF($K$12=M5,(D23*(K14)/(K14+L14)),0)+IF($L$12=M5,(D23*(L14)/(K14+L14)),0) -> 0 | F26: =N5 -> 0.065 | H26: =ROUND(D26*(E26+F26),2) -> 0
B27: Adicional BVM 2 | D27: =IF($K$12=M6,(D23*(K14)/(K14+L14)),0)+IF($L$12=M6,(D23*(L14)/(K14+L14)),0) -> 1290.3226 | F27: =N6 -> 0.09795 | H27: =ROUND(D27*(E27+F27),2) -> 126.39
B28: Adicional Escassez Hídrica | D28: =IF($K$12=M8,(D23*(K14)/(K14+L14)),0)+IF($L$12=M8,(D23*(L14)/(K14+L14)),0) -> 0 | F28: =N8 -> 0.142 | H28: =ROUND(D28*(E28+F28),2) -> 0
B30: Energia Injetada | D30: -1900.0009 | E30: =E23*F17 -> 0.39681 | F30: =F23 -> 0.27703 | G30: =E30+F30 -> 0.67384 | H30: =ROUND((D30*E30),2)+ROUND((D30*F30),2) -> -1280.3
B32: Adicional BAM | D32: =IF($K$12=M4,(D30*(K14)/(K14+L14)),0)+IF($L$12=M4,(D30*(L14)/(K14+L14)),0) -> -674.19385 | F32: =F25 -> 0.02989 | H32: =ROUND(D32*(E32+F32),2) -> -20.15
B33: Adicional BVM 1 | D33: =IF($K$12=M5,(D30*(K14)/(K14+L14)),0)+IF($L$12=M5,(D30*(L14)/(K14+L14)),0) -> 0 | F33: =F26 -> 0.065 | H33: =ROUND(D33*(E33+F33),2) -> 0
B34: Adicional BVM 2 | D34: =IF($K$12=M6,(D30*(K14)/(K14+L14)),0)+IF($L$12=M6,(D30*(L14)/(K14+L14)),0) -> -1225.807 | F34: =F27 -> 0.09795 | H34: =ROUND(D34*(E34+F34),2) -> -120.07
B35: Adicional Escassez Hídrica | D35: =IF($K$12=M8,(D30*(K14)/(K14+L14)),0)+IF($L$12=M8,(D30*(L14)/(K14+L14)),0) -> 0 | F35: =F28 -> 0.142 | H35: =ROUND(D35*(E35+F35),2) -> 0
H41: =SUM(H23:H40) -> 74.76
D43: Base de Cálculo
B44: PIS | D44: =(H23+H25+H26+H27+H28)/(1-E44-E46) -> 1559.0449 | E44: 0.0073 | H44: =D44*E44 -> 11.381028
B45: PIS Eneg Inj | D45: =(H30+H32+H33+H34+H35+H37+H39)/(1-E44-E46) -> -1481.0969 | E45: =E44 -> 0.0073 | H45: =D45*E45 -> -10.812007
B46: COFINS | D46: =D44 -> 1559.0449 | E46: 0.0336 | H46: =D46*E46 -> 52.38391
B47: COFINS Eneg Inj | D47: =D45 -> -1481.0969 | E47: =E46 -> 0.0336 | H47: =D47*E47 -> -49.764855
B48: ICMS | D48: =D44/(1-E48) -> 1878.3674 | E48: 0.17 | H48: =D48*E48 -> 319.32246
B49: ICMS Eneg Inj | D49: =((D30*F30)+(H32+H33+H34+H35)+(D37*F37)+(D39*F39))/(1-E45-E47)/(1-E49) -> -837.35284 | E49: =E48 -> 0.17 | H49: =D49*E49 -> -142.34998
B51: Informativo Escassez Hídrica | D51: =D23+D30 -> 99.999137 | E51: =IF(AND($B$13<$F$2,$E$13<$F$2),C7,IF($B$13<$F$2,I7,F7)) -> 0.00020011 | F51: =IF(AND($B$13<$F$2,$E$13<$F$2),D7,IF($B$13<$F$2,J7,G7)) -> 0.00402681 | H51: =D51*(E51+F51) -> 0.42268835

Sheet FIO B
B2: TUSD FIO B
B4: SUBGRUPO | C4: MODALIDADE | D4: CLASSE | E4: SUBCLASSE | F4: POSTO | G4: TARIFAS DE APLICAÇÃO
G5: TUSD FIO B (RTP 2025) | J5: TUSD FIO B (RTA 2026)
G6: R$/kW | H6: R$/MWh | J6: R$/kW | K6: R$/MWh
B7: B1 | C7: BRANCA | D7: RESIDENCIAL | E7: RESIDENCIAL | F7: P | G7: 0 | H7: 591.10909 | J7: 0 | K7: 606.53962
B8: B1 | C8: BRANCA | D8: RESIDENCIAL | E8: RESIDENCIAL | F8: INT | G8: 0 | H8: 354.6655 | J8: 0 | K8: 363.92381
B9: B1 | C9: BRANCA | D9: RESIDENCIAL | E9: RESIDENCIAL | F9: FP | G9: 0 | H9: 118.2218 | J9: 0 | K9: 121.3079
B10: B1 | C10: PRÉ-PAGAMENTO | D10: RESIDENCIAL | E10: RESIDENCIAL | F10: NA | G10: 0 | H10: 203.83072 | J10: 0 | K10: 209.15159
B11: B1 | C11: CONVENCIONAL | D11: RESIDENCIAL | E11: RESIDENCIAL | F11: NA | G11: 0 | H11: 203.83072 | J11: 0 | K11: 209.15159
B12: B1 | C12: PRÉ-PAGAMENTO | D12: RESIDENCIAL | E12: BAIXA RENDA | F12: NA | G12: 0 | H12: 203.83072 | J12: 0 | K12: 209.15159
B13: B1 | C13: CONVENCIONAL | D13: RESIDENCIAL | E13: BAIXA RENDA | F13: NA | G13: 0 | H13: 203.83072 | J13: 0 | K13: 209.15159
B14: B1 | C14: PRÉ-PAGAMENTO | D14: RESIDENCIAL | E14: RESIDENCIAL DESCONTO SOCIAL | F14: NA | G14: 0 | H14: 203.83072 | J14: 0 | K14: 209.15159
B15: B1 | C15: CONVENCIONAL | D15: RESIDENCIAL | E15: RESIDENCIAL DESCONTO SOCIAL | F15: NA | G15: 0 | H15: 203.83072 | J15: 0 | K15: 209.15159
B16: B2 | C16: BRANCA | D16: RURAL | E16: NÃO SE APLICA | F16: P | G16: 0 | H16: 693.02445 | J16: 0 | K16: 711.11541
B17: B2 | C17: BRANCA | D17: RURAL | E17: NÃO SE APLICA | F17: INT | G17: 0 | H17: 415.81471 | J17: 0 | K17: 426.66929
B18: B2 | C18: BRANCA | D18: RURAL | E18: NÃO SE APLICA | F18: FP | G18: 0 | H18: 138.60487 | J18: 0 | K18: 142.22306
... B39: B | C39: GERAÇÃO | D39: TIPO 02 | E39: NA | F39: NA | G39: 0 | H39: 11.690957 | J39: 0 | K39: 11.996142

Sheet TABELA DE TARIFAS ANTIGAS
A1: TABELA 1 – TARIFAS DE APLICAÇÃO E BASE ECONÔMICA PARA O GRUPO A.
A2: SUBGRUPO | B2: MODALIDADE | C2: UC | D2: POSTO | E2: TARIFAS DE APLICAÇÃO | J2: BASE ECONÔMICA | N2: Reajuste | O2: Dia | P2: Mês | Q2: Ano
E3: TUSD | G3: TE | J3: TUSD | L3: TE | N3: De | O3: 07 | P3: 08 | Q3: 2025
E4: R$/kW | F4: R$/MWh | G4: BVD – R$/MWh | H4: BAM – R$/MWh | I4: BVM – R$/MWh | J4: R$/kW | K4: R$/MWh | L4: R$/MWh | N4: Até | O4: 06 | P4: 08 | Q4: 2026
B5: AZUL | C5: NA | D5: P
A6: A1 (230 kV ou mais) | D6: FP
B7: AZUL APE | C7: NA | D7: P
D8: FP
A9: A2 (88 a 138kV) | B9: AZUL | C9: NA | D9: P
D10: FP
B11: AZUL APE | C11: NA | D11: P
D12: FP
B13: DISTRIBUIÇÃO | C13: ELFSM | D13: P
D14: FP
D15: NA
B16: GERAÇÃO | C16: UTE LASA | D16: NA
C17: UTE ALCON | D17: NA
C18: UTE SOL | D18: NA
C19: UHE MASCARENHAS - ENERGEST | D19: NA
C20: UHE SUICA | D20: NA
C21: PCH SAO JOAQUIM | D21: NA
C22: PCH SAO SIMAO | D22: NA
C23: PCH FRANCISCO GROSS | D23: NA
C24: PCH SAO PEDRO | D24: NA
C25: UTE LINHARES | D25: NA
C26: UTE ARCEL | D26: NA
C27: NOVO GERADOR | D27: NA
A28: A3 (69kV) | B28: AZUL | C28: NA | D28: P
D29: FP
B30: AZUL APE | C30: NA | D30: P
D31: FP
B32: DISTRIBUIÇÃO | D32: P
D33: FP
D34: NA
B35: GERAÇÃO | C35: NA | D35: NA
A36: A3a (30 a 44kV) | B36: AZUL | C36: NA | D36: P
D37: FP
B38: AZUL APE | C38: NA | D38: P
D39: FP
B40: VERDE | C40: NA | D40: NA
...

Sheet TABELA DE TARIFAS NOVAS
A1: TABELA 1 – TARIFAS DE APLICAÇÃO E BASE ECONÔMICA PARA O GRUPO A.
A2: SUBGRUPO | B2: MODALIDADE | C2: UC | D2: POSTO | E2: TARIFAS DE APLICAÇÃO | J2: BASE ECONÔMICA | N2: Reajuste | O2: Dia | P2: Mês | Q2: Ano
E3: TUSD | G3: TE | J3: TUSD | L3: TE | N3: De | O3: 07 | P3: 08 | Q3: 2026
E4: R$/kW | F4: R$/MWh | G4: BVD – R$/MWh | H4: BAM – R$/MWh | I4: BVM – R$/MWh | J4: R$/kW | K4: R$/MWh | L4: R$/MWh | N4: Até | O4: 31 | P4: 12 | Q4: 9999
B5: AZUL | C5: NA | D5: P
A6: A1 (230 kV ou mais) | D6: FP
B7: AZUL APE | C7: NA | D7: P
D8: FP
A9: A2 (88 a 138kV) | B9: AZUL | C9: NA | D9: P
D10: FP
B11: AZUL APE | C11: NA | D11: P
D12: FP
B13: DISTRIBUIÇÃO | C13: ELFSM | D13: P
D14: FP
D15: NA
B16: GERAÇÃO | C16: UTE LASA | D16: NA
C17: UTE ALCON | D17: NA
C18: UTE SOL | D18: NA
C19: UHE MASCARENHAS - ENERGEST | D19: NA
C20: UHE SUICA | D20: NA
C21: PCH SAO JOAQUIM | D21: NA
C22: PCH SAO SIMAO | D22: NA
C23: PCH FRANCISCO GROSS | D23: NA
C24: PCH SAO PEDRO | D24: NA
C25: UTE LINHARES | D25: NA
C26: UTE POVOACAO 1 | D26: NA
C27: UTE ARCEL | D27: NA
C28: UTE BIANCOGRES | D28: NA
C29: NOVO GERADOR | D29: NA
A30: A3 (69kV) | B30: AZUL | C30: NA | D30: P
D31: FP
B32: AZUL APE | C32: NA | D32: P
D33: FP
B34: DISTRIBUIÇÃO | D34: P
D35: FP
D36: NA
B37: GERAÇÃO | C37: NA | D37: NA
A38: A3a (30 a 44kV) | B38: AZUL | C38: NA | D38: P
D39: FP
B40: AZUL APE | C40: NA | D40: P
...

Sheet Fatura B1 (GD II) OK
B2: B1 Res | E2: Vigência das Tarifas: | F2: 46241 | G2: 2025: | H2: 45658 | M2: Bandeira | N2: R$/kWh | O2: ANEEL em 29/06 | Q2: TUSD FIO B
M3: VERDE | N3: 0
B4: TARIFA | C4: TARIFA ANTIGA - REH 3370/2024 | F4: TARIFA NOVA - REH xxxx/2025 | I4: Tarifas Proporcionalizadas | M4: BAM | N4: =[3]BANDEIRA!$D$5 -> 0.01885 | Q4: TARIFA | R4: =C4 -> TARIFA ANTIGA - REH 3370/2024 | U4: =F4 -> TARIFA NOVA - REH xxxx/2025 | X4: Tarifas Proporcionalizadas
C5: Tusd | D5: TE | E5: TUSD + TE | F5: Tusd | G5: TE | H5: TUSD + TE | I5: Tusd | J5: TE | K5: TUSD + TE | M5: BVM1 | N5: =[3]BANDEIRA!$D$6 -> 0.04463 | R5: Tusd (R$/kWh) | U5: Tusd (R$/kWh) | X5: Tusd (R$/kWh)
B6: B1 | C6: ='TABELA DE TARIFAS ANTIGAS'!G71/1000 -> 0.46863 | D6: ='TABELA DE TARIFAS ANTIGAS'!H71/1000 -> 0.32068 | E6: =C6+D6 -> 0.78931 | F6: ='TABELA DE TARIFAS NOVAS'!G73/1000 -> 0.50632 | G6: ='TABELA DE TARIFAS NOVAS'!H73/1000 -> 0.33739 | H6: =F6+G6 -> 0.84371 | I6: =((C6*$C$14)+(F6*$D$14))/($D$14+$C$14) -> 0.49100844 | J6: =((D6*$C$14)+(G6*$D$14))/($D$14+$C$14) -> 0.33060156 | K6: =I6+J6 -> 0.82161 | M6: BVM2 | N6: =[3]BANDEIRA!$D$7 -> 0.07877 | Q6: =B6 -> B1 | R6: ='FIO B'!H11/1000 -> 0.20383072 | U6: ='FIO B'!K11/1000 -> 0.20915159 | X6: =((R6*$C$14)+(U6*$D$14))/($D$14+$C$14) -> 0.20698999
B7: CDE Escassez Hídrica | C7: 0.00018774721 | D7: -0.0044031307 | E7: 0.0036054084 | F7: =T11 -> 0.00018418923 | G7: =U11 -> -0.00053182975 | H7: =F7+G7 -> -0.00034764052 | I7: =((C7*$C$14)+(F7*$D$14))/($D$14+$C$14) -> 0.00018563466 | J7: =((D7*$C$14)+(G7*$D$14))/($D$14+$C$14) -> -0.0021045458 | K7: =I7+J7 -> -0.0019189111
B8: TE SCEE | G8: =G6*15% -> 0.0506085 | J8: =((D8*$C$14)+(G8*$D$14))/($D$14+$C$14) -> 0.030048797 | M8: Escassez Hídrica | N8: 0.142 | P8: CUSTO | R8: Part. TUSD (%) | S8: Part. TE (%) | T8: Tusd (R$/kWh) | U8: TE (R$/kWh)
P9: CDE CONTAS
H10: Fatura | L10: Vigência das Tarifas (troca Bandeira): | M10: =EOMONTH(B14,0)+1 -> 46235 | P10: CDE COVID | U10: 0
B11: INSTALAÇÃO | C11: 1280804 | H11: =E14 -> 46259 | K11: Altere a bandeira na célula abaixo | P11: CDE ESCASSEZ HÍDRICA | T11: =0.184189231569235/1000 -> 0.00018418923 | U11: =-0.531829748712515/1000 -> -0.00053182975
K12: BAM | L12: BAM
B13: Leitura Anterior | C13: Nº de dias tarifa Anterior | D13: Nº de dias tarifa Nova | E13: Leitura Atual | J13: Leitura Anterior | K13: Nº de dias tarifa Anterior | L13: Nº de dias tarifa Nova | M13: Leitura Atual
B14: 46227 | C14: =IF((F2-B14-1)<0,0,(F2-B14-1)) -> 13 | D14: =E14-F2+1 -> 19 | E14: 46259 | J14: =B14 -> 46227 | K14: =IF((M10-J14-1)<0,0,(M10-J14-1)) -> 7 | L14: =M14-M10+1 -> 25 | M14: =E14 -> 46259 | O14: Documento Impressão | Q14: 1025310412
B16: Descrição | C16: Unidade | D16: Quantidade | E16: Preço Unit (R$) com tributos | F16: Valor Total (R$) | G16: PIS/COFINS (R$) | H16: Base de Cálculo ICMS (R$) | I16: Alíquota ICMS (%) | J16: ICMS (R$) | K16: Preço Unit (R$) | L16: Tributos | M16: Base de Cálc (R$) | N16: Alíquota (%) | O16: Valor (R$) | P16: não está contabilizando injetada
R17: TUSD Fio B | S17: Receita Fio B
B18: TUSD - Consumo | C18: kWh | D18: 149 | E18: =(ROUND(D18*K18,2)+ROUND(G18,2)+ROUND(J18,2))/ROUND(D18,4) -> 0.6304698 | F18: =ROUND(D18*E18,2) -> 93.94 | G18: =((D18*K18)/(1-$N$18-$N$20))*($N$18+$N$20) -> 4.8108152 | H18: =((D18*K18)/(1-$N$18-$N$20)/(1-$I$18)) -> 93.941051 | I18: 0.17 | J18: =(H18*$I$18) -> 15.969979 | K18: =IF(AND($B$14<$F$2,$E$14<$F$2),C6,IF($B$14<$F$2,I6,F6)) -> 0.49100844 | L18: PIS | M18: =D71 -> 133.46478 | N18: 0.011 | O18: =ROUND(M18*N18,2) -> 1.47 | R18: =IF(AND($B$14<$F$2,$E$14<$F$2),R6,IF($B$14<$F$2,X6,U6)) -> 0.20698999 | S18: =D18*R18 -> 30.841508
B19: TE - Consumo | C19: kWh | D19: =D18 -> 149 | E19: =(ROUND(D19*K19,2)+ROUND(G19,2)+ROUND(J19,2))/ROUND(D19,4) -> 0.42449664 | F19: =ROUND(D19*E19,2) -> 63.25 | G19: =((D19*K19)/(1-$N$18-$N$20))*($N$18+$N$20) -> 3.2391765 | H19: =ROUND((D19*K19)/(1-$N$18-$N$20)/(1-$I$18),8) -> 63.251578 | J19: =(H19*$I$18) -> 10.752768 | K19: =IF(AND($B$14<$F$2,$E$14<$F$2),D6,IF($B$14<$F$2,J6,G6)) -> 0.33060156 | L19: PIS Inj | M19: =D72 -> -43.887882 | N19: =N18 -> 0.011 | O19: =ROUND(M19*N19,2) -> -0.48
B20: Adicional BAM | C20: kWh | D20: =IF($K$12=M4,($D$18*($K$14)/($L$14+$K$14)),0)+IF($L$12=M4,($D$18*($L$14)/($L$14+$K$14)),0) -> 149 | E20: =IFERROR((ROUND(D20*K20,2)+ROUND(G20,2)+ROUND(J20,2))/ROUND(D20,4), 0) -> 0.024161074 | F20: =ROUND(D20*E20,2) -> 3.6 | G20: =((D20*K20)/(1-$N$18-$N$20))*($N$18+$N$20) -> 0.18468902 | H20: =ROUND((D20*K20)/(1-$N$18-$N$20)/(1-$I$18),8) -> 3.6064326 | J20: =(H20*$I$18) -> 0.61309353 | K20: =N4 -> 0.01885 | L20: COFINS | M20: =M18 -> 133.46478 | N20: 0.0507 | O20: =ROUND(M20*N20,2) -> 6.77
B21: Adicional BVM1 | C21: kWh | D21: =IF($K$12=M5,($D$18*($K$14)/($L$14+$K$14)),0)+IF($L$12=M5,($D$18*($L$14)/($L$14+$K$14)),0) -> 0 | E21: =IFERROR((ROUND(D21*K21,2)+ROUND(G21,2)+ROUND(J21,2))/ROUND(D21,4), 0) -> 0 | F21: =ROUND(D21*E21,2) -> 0 | G21: =((D21*K21)/(1-$N$18-$N$20))*($N$18+$N$20) -> 0 | H21: =ROUND((D21*K21)/(1-$N$18-$N$20)/(1-$I$18),8) -> 0 | J21: =(H21*$I$18) -> 0 | K21: =N5 -> 0.04463 | L21: COFINS Inj | M21: =M19 -> -43.887882 | N21: =N20 -> 0.0507 | O21: =ROUND(M21*N21,2) -> -2.23
B22: Adicional BVM2 | C22: kWh | D22: =IF($K$12=M6,($D$18*($K$14)/($L$14+$K$14)),0)+IF($L$12=M6,($D$18*($L$14)/($L$14+$K$14)),0) -> 0 | E22: =IFERROR((ROUND(D22*K22,2)+ROUND(G22,2)+ROUND(J22,2))/ROUND(D22,4), 0) -> 0 | F22: =ROUND(D22*E22,2) -> 0 | G22: =((D22*K22)/(1-$N$18-$N$20))*($N$18+$N$20) -> 0 | H22: =ROUND((D22*K22)/(1-$N$18-$N$20)/(1-$I$18),8) -> 0 | J22: =(H22*$I$18) -> 0 | K22: =N6 -> 0.07877
B23: Adicional EH | C23: kWh | D23: =IF($K$12=M8,($D$18*($K$14)/($L$14+$K$14)),0)+IF($L$12=M8,($D$18*($L$14)/($L$14+$K$14)),0) -> 0 | E23: =IFERROR((ROUND(D23*K23,2)+ROUND(G23,2)+ROUND(J23,2))/ROUND(D23,4), 0) -> 0 | F23: =ROUND(D23*E23,2) -> 0 | G23: =((D23*K23)/(1-$N$18-$N$20))*($N$18+$N$20) -> 0 | H23: =ROUND((D23*K23)/(1-$N$18-$N$20)/(1-$I$18),8) -> 0 | J23: =(H23*$I$18) -> 0 | K23: =N8 -> 0.142
B25: TUSD - Consumo inj | C25: kWh | D25: -57.503 | E25: =IFERROR((ROUND(D25*K25,2)+ROUND(G25,2)+ROUND(J25,2))/ROUND(D25,4),0) -> 0.39093613 | F25: =ROUND(D25*E25,2) -> -22.48 | G25: =((D25*K25)/(1-$N$19-$N$21))*($N$19+$N$21) -> -1.3865931 | H25: 0 | I25: 0 | J25: =H25*$I$25 -> 0 | K25: =E57 -> 0.36670351
B26: TE - Consumo inj | C26: kWh | D26: =D25 -> -57.503 | E26: =IFERROR((ROUND(D26*K26,2)+ROUND(G26,2)+ROUND(J26,2))/ROUND(D26,4),0) -> 0.42449959 | F26: =ROUND(D26*E26,2) -> -24.41 | G26: =((D26*K26)/(1-$N$19-$N$21))*($N$19+$N$21) -> -1.250083 | H26: =ROUND((D26*K26)/(1-$N$19-$N$21)/(1-$I$26),8) -> -24.410439 | I26: =I18 -> 0.17 | J26: =H26*$I$26 -> -4.1497747 | K26: =F57 -> 0.33060156
B27: Adicional BAM inj | C27: kWh | D27: =IF($K$12=M4,($D$25*($K$14)/($K$14+$L$14)),0)+IF($L$12=M4,($D$25*($L$14)/($K$14+$L$14)),0) -> -57.503 | E27: =IFERROR((ROUND(D27*K27,2)+ROUND(G27,2)+ROUND(J27,2))/ROUND(D27,4),0) -> 0.024172652 | F27: =ROUND(D27*E27,2) -> -1.39 | G27: =((D27*K27)/(1-$N$19-$N$21))*($N$19+$N$21) -> -0.071276326 | H27: =ROUND((D27*K27)/(1-$N$19-$N$21)/(1-$I$26),8) -> -1.3918167 | J27: =H27*$I$26 -> -0.23660884 | K27: =N4 -> 0.01885
B28: Adicional BVM1 inj | C28: kWh | D28: =IF($K$12=M5,($D$25*($K$14)/($K$14+$L$14)),0)+IF($L$12=M5,($D$25*($L$14)/($K$14+$L$14)),0) -> 0 | E28: =IFERROR((ROUND(D28*K28,2)+ROUND(G28,2)+ROUND(J28,2))/ROUND(D28,4),0) -> 0 | F28: =ROUND(D28*E28,2) -> 0 | G28: =((D28*K28)/(1-$N$19-$N$21))*($N$19+$N$21) -> 0 | H28: =ROUND((D28*K28)/(1-$N$19-$N$21)/(1-$I$26),8) -> 0 | J28: =H28*$I$26 -> 0 | K28: =N5 -> 0.04463
B29: Adicional BVM2 inj | C29: kWh | D29: =IF($K$12=M6,($D$25*($K$14)/($K$14+$L$14)),0)+IF($L$12=M6,($D$25*($L$14)/($K$14+$L$14)),0) -> 0 | E29: =IFERROR((ROUND(D29*K29,2)+ROUND(G29,2)+ROUND(J29,2))/ROUND(D29,4),0) -> 0 | F29: =ROUND(D29*E29,2) -> 0 | G29: =((D29*K29)/(1-$N$19-$N$21))*($N$19+$N$21) -> 0 | H29: =ROUND((D29*K29)/(1-$N$19-$N$21)/(1-$I$26),8) -> 0 | J29: =H29*$I$26 -> 0 | K29: =N6 -> 0.07877
B30: Adicional EH inj | C30: kWh | D30: =IF($K$12=M7,($D$25*($K$14)/($K$14+$L$14)),0)+IF($L$12=M7,($D$25*($L$14)/($K$14+$L$14)),0) -> 0 | E30: =IFERROR((ROUND(D30*K30,2)+ROUND(G30,2)+ROUND(J30,2))/ROUND(D30,4),0) -> 0 | F30: =ROUND(D30*E30,2) -> 0 | G30: =((D30*K30)/(1-$N$19-$N$21))*($N$19+$N$21) -> 0 | H30: =ROUND((D30*K30)/(1-$N$19-$N$21)/(1-$I$26),8) -> 0 | J30: =H30*$I$26 -> 0 | K30: =N8 -> 0.142
B32: Multas
B33: Juros
B34: Doações
B35: Bônus/Descontos | F35: -7.07
B36: CIP | F36: 40.37
B38: TOTAL | F38: =SUM(F18:F37) -> 145.81 | G38: =SUM(G18:G37) -> 5.5267283 | H38: =SUM(H18:H37) -> 134.99681 | J38: =SUM(J18:J37) -> 22.949457
B40: Informativo Escassez Hídrica | D40: =D18 -> 149 | E40: =IF(AND($B$14<$F$2,$E$14<$F$2),C7,IF($B$14<$F$2,I7,F7)) -> 0.00018563466 | F40: =IF(AND($B$14<$F$2,$E$14<$F$2),D7,IF($B$14<$F$2,J7,G7)) -> -0.0021045458 | G40: =D40*(E40+F40) -> -0.28591776
D41: =D25 -> -57.503 | E41: =IF(AND($B$14<$F$2,$E$14<$F$2),C7*$F$44,IF($B$14<$F$2,(((I7*F44)*C14)+((I7*F45)*D14))/(C14+D14),I7*$F$45)) -> 0.00013863893 | F41: =IF(AND($B$14<$F$2,$E$14<$F$2),D7,IF($B$14<$F$2,J7,G7)) -> -0.0021045458 | G41: =D41*(E41+F41) -> 0.11304554
G42: =SUM(G40:G41) -> -0.17287221
B44: Perc. de Redução da Energia Injetada | E44: TUSD | F44: 0.739 | G44: TE | H44: 1 | I44: A partir de 01/01/2026
E45: TUSD | F45: 0.7522 | G45: TE | H45: 1 | I45: A partir de 07/08/2026
B46: Fatura B1 Residencial
D47: Qtde | E47: TUSD | F47: TE | G47: TUSD + TE | H47: R$
...

Sheet Fatura B2 (GD II) OK
B2: B2 | E2: Vigência das Tarifas: | F2: ='Fatura B1 (GD II) OK'!F2 -> 46241 | G2: 2025: | H2: 45658 | M2: Bandeira | N2: R$/kWh | O2: ANEEL em 29/06 | Q2: TUSD FIO B
M3: VERDE | N3: 0
B4: TARIFA | C4: ='Fatura B1 (GD II) OK'!C4:E4 -> TARIFA ANTIGA - REH 3370/2024 | F4: ='Fatura B1 (GD II) OK'!F4:H4 -> TARIFA NOVA - REH xxxx/2025 | I4: Tarifas Proporcionalizadas | M4: BAM | N4: ='[1]Fatura B1 (Res) OK'!$N$4 -> 0.01885 | Q4: TARIFA | R4: =C4 -> TARIFA ANTIGA - REH 3370/2024 | U4: =F4 -> TARIFA NOVA - REH xxxx/2025 | X4: Tarifas Proporcionalizadas
C5: Tusd | D5: TE | E5: TUSD + TE | F5: Tusd | G5: TE | H5: TUSD + TE | I5: Tusd | J5: TE | K5: TUSD + TE | M5: BVM1 | N5: ='[1]Fatura B1 (Res) OK'!$N$5 -> 0.04463 | R5: Tusd (R$/kWh) | U5: Tusd (R$/kWh) | X5: Tusd (R$/kWh)
B6: B2 | C6: ='TABELA DE TARIFAS ANTIGAS'!G77/1000 -> 0.46863 | D6: ='TABELA DE TARIFAS ANTIGAS'!H77/1000 -> 0.32068 | E6: =C6+D6 -> 0.78931 | F6: ='TABELA DE TARIFAS NOVAS'!G79/1000 -> 0.50632 | G6: ='TABELA DE TARIFAS NOVAS'!H79/1000 -> 0.33739 | H6: =F6+G6 -> 0.84371 | I6: =((C6*$C$14)+(F6*$D$14))/($D$14+$C$14) -> 0.48621867 | J6: =((D6*$C$14)+(G6*$D$14))/($D$14+$C$14) -> 0.328478 | K6: =I6+J6 -> 0.81469667 | M6: BVM2 | N6: ='[1]Fatura B1 (Res) OK'!$N$6 -> 0.07877 | Q6: =B6 -> B2 | R6: ='FIO B'!H20/1000 -> 0.20383072 | U6: ='FIO B'!K20/1000 -> 0.20915159 | X6: =((R6*$C$14)+(U6*$D$14))/($D$14+$C$14) -> 0.20631379
B7: B1 | C7: ='TABELA DE TARIFAS ANTIGAS'!G71/1000 -> 0.46863 | D7: ='TABELA DE TARIFAS ANTIGAS'!H71/1000 -> 0.32068 | E7: =C7+D7 -> 0.78931 | F7: ='TABELA DE TARIFAS NOVAS'!G73/1000 -> 0.50632 | G7: ='TABELA DE TARIFAS NOVAS'!H73/1000 -> 0.33739 | H7: =F7+G7 -> 0.84371 | I7: =((C7*$C$14)+(F7*$D$14))/($D$14+$C$14) -> 0.48621867 | J7: =((D7*$C$14)+(G7*$D$14))/($D$14+$C$14) -> 0.328478 | K7: =I7+J7 -> 0.81469667
B8: CDE Escassez Hídrica | C8: 0.00018774721 | D8: -0.0044031307 | E8: 0.0036054084 | F8: =T11 -> 0.00018418923 | G8: =U11 -> -0.00053182975 | H8: =F8+G8 -> -0.00034764052 | I8: =((C8*$C$14)+(F8*$D$14))/($D$14+$C$14) -> 0.00018608682 | J8: =((D8*$C$14)+(G8*$D$14))/($D$14+$C$14) -> -0.0025965236 | K8: =I8+J8 -> -0.0024104368 | M8: Escassez Hídrica | N8: 0.142 | P8: CUSTO | R8: Part. TUSD (%) | S8: Part. TE (%) | T8: Tusd (R$/kWh) | U8: TE (R$/kWh)
P9: CDE CONTAS
H10: Fatura | L10: Vigência das Tarifas (troca Bandeira): | M10: =EOMONTH(B14,0)+1 -> 46235 | P10: CDE COVID | U10: 0
B11: INSTALAÇÃO | C11: 1687996 | H11: =E14 -> 46254 | K11: Altere a bandeira na célula abaixo | P11: CDE ESCASSEZ HÍDRICA | T11: ='Fatura B1 (GD II) OK'!T11 -> 0.00018418923 | U11: ='Fatura B1 (GD II) OK'!U11 -> -0.00053182975
K12: ='Fatura B1 (GD II) OK'!K12 -> BAM | L12: ='Fatura B1 (GD II) OK'!L12 -> BAM
B13: Leitura Anterior | C13: Nº de dias tarifa Anterior | D13: Nº de dias tarifa Nova | E13: Leitura Atual | J13: Leitura Anterior | K13: Nº de dias tarifa Anterior | L13: Nº de dias tarifa Nova | M13: Leitura Atual
B14: 46224 | C14: =IF((F2-B14-1)<0,0,(F2-B14-1)) -> 16 | D14: =E14-F2+1 -> 14 | E14: 46254 | J14: =B14 -> 46224 | K14: =IF((M10-J14-1)<0,0,(M10-J14-1)) -> 10 | L14: =M14-M10+1 -> 20 | M14: =E14 -> 46254 | O14: Documento Impressão | Q14: 1025310490
B16: Descrição | C16: Unidade | D16: Quantidade | E16: Preço Unit (R$) com tributos | F16: Valor Total (R$) | G16: PIS/COFINS (R$) | H16: Base de Cálculo ICMS (R$) | I16: Alíquota ICMS (%) | J16: ICMS (R$) | K16: Preço Unit (R$) | L16: Tributos | M16: Base de Cálc (R$) | N16: Alíquota (%) | O16: Valor (R$) | P16: não está contabilizando injetada
R17: TUSD Fio B | S17: Receita Fio B
B18: TUSD - Consumo | C18: kWh | D18: 297 | E18: =(ROUND(D18*K18,2)+ROUND(G18,2)+ROUND(J18,2))/ROUND(D18,4) -> 0.62434343 | F18: =ROUND(D18*E18,2) -> 185.43 | G18: =((D18*K18)/(1-$N$18-$N$20))*($N$18+$N$20) -> 9.4957993 | H18: =(IF($I$18=12%,(D18*K18)/(1-$N$18-$N$20)/(1-$C$48)/$F$48*$C$48,(D18*K18)/(1-$N$18-$N$20)/(1-$I$18))) -> 185.42499 | I18: 0.17 | J18: =(H18*$I$18) -> 31.522249 | K18: =IF(AND($B$14<$F$2,$E$14<$F$2),C6,IF($B$14<$F$2,I6,F6)) -> 0.48621867 | L18: PIS | M18: =D82 -> 263.84952 | N18: ='Fatura B1 (GD II) OK'!N18 -> 0.011 | O18: =ROUND(M18*N18,2) -> 2.9 | R18: =IF(AND($B$14<$F$2,$E$14<$F$2),R6,IF($B$14<$F$2,X6,U6)) -> 0.20631379 | S18: =D18*R18 -> 61.275197
B19: TE - Consumo | C19: kWh | D19: =D18 -> 297 | E19: =(ROUND(D19*K19,2)+ROUND(G19,2)+ROUND(J19,2))/ROUND(D19,4) -> 0.42181818 | F19: =ROUND(D19*E19,2) -> 125.28 | G19: =((D19*K19)/(1-$N$18-$N$20))*($N$18+$N$20) -> 6.4151407 | H19: =(IF($I$18=12%,(D19*K19)/(1-$N$18-$N$20)/(1-$C$48)/$F$48*$C$48,(D19*K19)/(1-$N$18-$N$20)/(1-$I$18))) -> 125.2688 | J19: =(H19*$I$18) -> 21.295697 | K19: =IF(AND($B$14<$F$2,$E$14<$F$2),D6,IF($B$14<$F$2,J6,G6)) -> 0.328478 | L19: PIS Inj | M19: =D83 -> -218.66141 | N19: =N18 -> 0.011 | O19: =ROUND(M19*N19,2) -> -2.41
B20: Adicional BAM | C20: kWh | D20: =IF($K$12=M4,($D$18*($K$14)/($K$14+$L$14)),0)+IF($L$12=M4,($D$18*($L$14)/($K$14+$L$14)),0) -> 297 | E20: =IFERROR((ROUND(D20*K20,2)+ROUND(G20,2)+ROUND(J20,2))/ROUND(D20,4), 0) -> 0.024208754 | F20: =ROUND(D20*E20,2) -> 7.19 | G20: =((D20*K20)/(1-$N$18-$N$20))*($N$18+$N$20) -> 0.36813851 | H20: =(IF($I$18=12%,(D20*K20)/(1-$N$18-$N$20)/(1-$C$48)/$F$48*$C$48,(D20*K20)/(1-$N$18-$N$20)/(1-$I$18))) -> 7.1886609 | J20: =(H20*$I$18) -> 1.2220723 | K20: =N4 -> 0.01885 | L20: COFINS | M20: =M18 -> 263.84952 | N20: ='Fatura B1 (GD II) OK'!N20 -> 0.0507 | O20: =ROUND(M20*N20,2) -> 13.38
B21: Adicional BVM1 | C21: kWh | D21: =IF($K$12=M5,($D$18*($K$14)/($K$14+$L$14)),0)+IF($L$12=M5,($D$18*($L$14)/($K$14+$L$14)),0) -> 0 | E21: =IFERROR((ROUND(D21*K21,2)+ROUND(G21,2)+ROUND(J21,2))/ROUND(D21,4), 0) -> 0 | F21: =ROUND(D21*E21,2) -> 0 | G21: =((D21*K21)/(1-$N$18-$N$20))*($N$18+$N$20) -> 0 | H21: =(IF($I$18=12%,(D21*K21)/(1-$N$18-$N$20)/(1-$C$48)/$F$48*$C$48,(D21*K21)/(1-$N$18-$N$20)/(1-$I$18))) -> 0 | J21: =(H21*$I$18) -> 0 | K21: =N5 -> 0.04463 | L21: COFINS Inj | M21: =M19 -> -218.66141 | N21: =N20 -> 0.0507 | O21: =ROUND(M21*N21,2) -> -11.09
B22: Adicional BVM2 | C22: kWh | D22: =IF($K$12=M6,($D$18*($K$14)/($K$14+$L$14)),0)+IF($L$12=M6,($D$18*($L$14)/($K$14+$L$14)),0) -> 0 | E22: =IFERROR((ROUND(D22*K22,2)+ROUND(G22,2)+ROUND(J22,2))/ROUND(D22,4), 0) -> 0 | F22: =ROUND(D22*E22,2) -> 0 | G22: =((D22*K22)/(1-$N$18-$N$20))*($N$18+$N$20) -> 0 | H22: =(IF($I$18=12%,(D22*K22)/(1-$N$18-$N$20)/(1-$C$48)/$F$48*$C$48,(D22*K22)/(1-$N$18-$N$20)/(1-$I$18))) -> 0 | J22: =(H22*$I$18) -> 0 | K22: =N6 -> 0.07877
B23: Adicional EH | C23: kWh | D23: =IF($K$12=M8,($D$18*($K$14)/($K$14+$L$14)),0)+IF($L$12=M8,($D$18*($L$14)/($K$14+$L$14)),0) -> 0 | E23: =IFERROR((ROUND(D23*K23,2)+ROUND(G23,2)+ROUND(J23,2))/ROUND(D23,4), 0) -> 0 | F23: =ROUND(D23*E23,2) -> 0 | G23: =((D23*K23)/(1-$N$18-$N$20))*($N$18+$N$20) -> 0 | H23: =(IF($I$18=12%,(D23*K23)/(1-$N$18-$N$20)/(1-$C$48)/$F$48*$C$48,(D23*K23)/(1-$N$18-$N$20)/(1-$I$18))) -> 0 | J23: =(H23*$I$18) -> 0 | K23: =N8 -> 0.142
B25: TUSD - Consumo inj | C25: kWh | D25: -297 | E25: =IFERROR((ROUND(D25*K25,2)+ROUND(G25,2)+ROUND(J25,2))/ROUND(D25,4), 0) -> 0.38616162 | F25: =ROUND(D25*E25,2) -> -114.69 | G25: =((D25*K25)/(1-$N$19-$N$21))*($N$19+$N$21) -> -7.0758898 | H25: 0 | I25: 0 | J25: =H25*$I$21 -> 0 | K25: =E68 -> 0.3623107
B26: TE - Consumo inj | C26: kWh | D26: =D25 -> -297 | E26: =IFERROR((ROUND(D26*K26,2)+ROUND(G26,2)+ROUND(J26,2))/ROUND(D26,4), 0) -> 0.42181818 | F26: =ROUND(D26*E26,2) -> -125.28 | G26: =((D26*K26)/(1-$N$19-$N$21))*($N$19+$N$21) -> -6.4151407 | H26: =(IF($I$26=12%,(D26*K26)/(1-$N$19-$N$21)/(1-$C$48)/$F$48*$C$48,(D26*K26)/(1-$N$19-$N$21)/(1-$I$26))) -> -125.2688 | I26: =I18 -> 0.17 | J26: =H26*$I$26 -> -21.295697 | K26: =F68 -> 0.328478
B27: Adicional BAM inj | C27: kWh | D27: =IF($K$12=M4,($D$25*($K$14)/($K$14+$L$14)),0)+IF($L$12=M4,($D$25*($L$14)/($K$14+$L$14)),0) -> -297 | E27: =IFERROR((ROUND(D27*K27,2)+ROUND(G27,2)+ROUND(J27,2))/ROUND(D27,4), 0) -> 0.024208754 | F27: =ROUND(D27*E27,2) -> -7.19 | G27: =((D27*K27)/(1-$N$19-$N$21))*($N$19+$N$21) -> -0.36813851 | H27: =(IF($I$26=12%,(D27*K27)/(1-$N$19-$N$21)/(1-$C$48)/$F$48*$C$48,(D27*K27)/(1-$N$19-$N$21)/(1-$I$26))) -> -7.1886609 | J27: =H27*$I$26 -> -1.2220723 | K27: =K20 -> 0.01885
B28: Adicional BVM1 inj | C28: kWh | D28: =IF($K$12=M5,($D$25*($K$14)/($K$14+$L$14)),0)+IF($L$12=M5,($D$25*($L$14)/($K$14+$L$14)),0) -> 0 | E28: =IFERROR((ROUND(D28*K28,2)+ROUND(G28,2)+ROUND(J28,2))/ROUND(D28,4), 0) -> 0 | F28: =ROUND(D28*E28,2) -> 0 | G28: =((D28*K28)/(1-$N$19-$N$21))*($N$19+$N$21) -> 0 | H28: =(IF($I$26=12%,(D28*K28)/(1-$N$19-$N$21)/(1-$C$48)/$F$48*$C$48,(D28*K28)/(1-$N$19-$N$21)/(1-$I$26))) -> 0 | J28: =H28*$I$26 -> 0 | K28: =K21 -> 0.04463
B29: Adicional BVM2 inj | C29: kWh | D29: =IF($K$12=M6,($D$25*($K$14)/($K$14+$L$14)),0)+IF($L$12=M6,($D$25*($L$14)/($K$14+$L$14)),0) -> 0 | E29: =IFERROR((ROUND(D29*K29,2)+ROUND(G29,2)+ROUND(J29,2))/ROUND(D29,4), 0) -> 0 | F29: =ROUND(D29*E29,2) -> 0 | G29: =((D29*K29)/(1-$N$19-$N$21))*($N$19+$N$21) -> 0 | H29: =(IF($I$26=12%,(D29*K29)/(1-$N$19-$N$21)/(1-$C$48)/$F$48*$C$48,(D29*K29)/(1-$N$19-$N$21)/(1-$I$26))) -> 0 | J29: =H29*$I$26 -> 0 | K29: =K22 -> 0.07877
B30: Adicional EH inj | C30: kWh | D30: =IF($K$12=M8,($D$25*($K$14)/($K$14+$L$14)),0)+IF($L$12=M8,($D$25*($L$14)/($K$14+$L$14)),0) -> 0 | E30: =IFERROR((ROUND(D30*K30,2)+ROUND(G30,2)+ROUND(J30,2))/ROUND(D30,4), 0) -> 0 | F30: =ROUND(D30*E30,2) -> 0 | G30: =((D30*K30)/(1-$N$19-$N$21))*($N$19+$N$21) -> 0 | H30: =(IF($I$26=12%,(D30*K30)/(1-$N$19-$N$21)/(1-$C$48)/$F$48*$C$48,(D30*K30)/(1-$N$19-$N$21)/(1-$I$26))) -> 0 | J30: =H30*$I$26 -> 0 | K30: =K23 -> 0.142
B32: Multas
B33: Juros
B34: Doações | F34: -0.67
B35: Bônus/Descontos
B36: CIP
B38: TOTAL | F38: =SUM(F18:F37) -> 70.07 | G38: =SUM(G18:G37) -> 2.4199095 | H38: =SUM(H18:H37) -> 185.42499 | J38: =SUM(J18:J37) -> 31.522249
B40: Informativo Escassez | C40: =D18 -> 297 | D40: =IF(AND($B$14<$F$2,$E$14<$F$2),C8,IF($B$14<$F$2,I8,F8)) -> 0.00018608682 | E40: =IF(AND($B$14<$F$2,$E$14<$F$2),D8,IF($B$14<$F$2,J8,G8)) -> -0.0025965236 | F40: =C40*(D40+E40) -> -0.71589973
C41: =D25 -> -297 | D41: =IF(AND($B$14<$F$2,$E$14<$F$2),C8*$F$55,IF($B$14<$F$2,(((I8*F55)*C14)+((I8*F56)*D14))/(C14+D14),I8*$F$56)) -> 0.00013866446 | E41: =IF(AND($B$14<$F$2,$E$14<$F$2),D8,IF($B$14<$F$2,J8,G8)) -> -0.0025965236 | F41: =C41*(D41+E41) -> 0.72998417
F42: =SUM(F40:F41) -> 0.014084443
B44: Se for base reduzida: (célula I18 = 12%)
D45: Com tributos
B46: PIS | C46: =N18 -> 0.011 | D46: =((D18*K18)+(D19*K19)+(D20*K20)+(D21*K21)+(D22*K22)+(D23*K23))/(1-$N$21-$N$23) -> 260.78517 | E46: x | F46: =C46 -> 0.011 | G46: =D46*F46 -> 2.8686368
B47: COFINS | C47: =N20 -> 0.0507 | D47: =D46 -> 260.78517 | E47: x | F47: =C47 -> 0.0507 | G47: =D47*F47 -> 13.221808
...

Sheet Fatura B3 (GD II) OK
B2: B3 | E2: Vigência das Tarifas: | F2: ='Fatura B1 (GD II) OK'!F2 -> 46241 | G2: 2025: | H2: 45658 | M2: Bandeira | N2: R$/kWh | O2: ANEEL em 29/06 | Q2: TUSD FIO B
M3: VERDE | N3: 0
B4: TARIFA R$ kWh | C4: ='Fatura B1 (GD II) OK'!C4:E4 -> TARIFA ANTIGA - REH 3370/2024 | F4: ='Fatura B1 (GD II) OK'!F4:H4 -> TARIFA NOVA - REH xxxx/2025 | I4: Tarifas Proporcionalizadas | M4: BAM | N4: =[3]BANDEIRA!$D$5 -> 0.01885 | Q4: TARIFA | R4: =C4 -> TARIFA ANTIGA - REH 3370/2024 | U4: =F4 -> TARIFA NOVA - REH xxxx/2025 | X4: Tarifas Proporcionalizadas
C5: Tusd | D5: TE | E5: TUSD + TE | F5: Tusd | G5: TE | H5: TUSD + TE | I5: Tusd | J5: TE | K5: TUSD + TE | M5: BVM1 | N5: =[3]BANDEIRA!$D$6 -> 0.04463 | R5: Tusd (R$/kWh) | U5: Tusd (R$/kWh) | X5: Tusd (R$/kWh)
B6: B3 | C6: ='TABELA DE TARIFAS ANTIGAS'!G89/1000 -> 0.46863 | D6: ='TABELA DE TARIFAS ANTIGAS'!H89/1000 -> 0.32068 | E6: =C6+D6 -> 0.78931 | F6: ='TABELA DE TARIFAS NOVAS'!G91/1000 -> 0.50632 | G6: ='TABELA DE TARIFAS NOVAS'!H91/1000 -> 0.33739 | H6: =F6+G6 -> 0.84371 | I6: =((C6*$C$14)+(F6*$D$14))/($D$14+$C$14) -> 0.47742433 | J6: =((D6*$C$14)+(G6*$D$14))/($D$14+$C$14) -> 0.324579 | K6: =I6+J6 -> 0.80200333 | M6: BVM2 | N6: =[3]BANDEIRA!$D$7 -> 0.07877 | Q6: =B6 -> B3 | R6: ='FIO B'!H35/1000 -> 0.20383072 | U6: ='FIO B'!K35/1000 -> 0.20915159 | X6: =((R6*$C$14)+(U6*$D$14))/($D$14+$C$14) -> 0.20507226
B7: CDE Escassez Hídrica | C7: 0.00018774721 | D7: -0.0044031307 | E7: 0.0036054084 | F7: =T11 -> 0.00018418923 | G7: =U11 -> -0.00053182975 | H7: =F7+G7 -> -0.00034764052 | I7: =((C7*$C$14)+(F7*$D$14))/($D$14+$C$14) -> 0.00018691702 | J7: =((D7*$C$14)+(G7*$D$14))/($D$14+$C$14) -> -0.0034998272 | K7: =I7+J7 -> -0.0033129102
B8: TE SCEE | G8: =G6*15% -> 0.0506085 | J8: =((D8*$C$14)+(G8*$D$14))/($D$14+$C$14) -> 0.01180865 | M8: Escassez Hídrica | N8: 0.142 | P8: CUSTO | R8: Part. TUSD (%) | S8: Part. TE (%) | T8: Tusd (R$/kWh) | U8: TE (R$/kWh)
P9: CDE CONTAS
H10: Fatura | L10: Vigência das Tarifas (troca Bandeira): | M10: =EOMONTH(B14,0)+1 -> 46235 | P10: CDE COVID | U10: 0
B11: INSTALAÇÃO | C11: 160392975 | H11: =E14 -> 46247 | K11: Altere a bandeira na célula abaixo | P11: CDE ESCASSEZ HÍDRICA | T11: ='Fatura B1 (GD II) OK'!T11 -> 0.00018418923 | U11: ='Fatura B1 (GD II) OK'!U11 -> -0.00053182975
K12: ='Fatura B1 (GD II) OK'!K12 -> BAM | L12: ='Fatura B1 (GD II) OK'!L12 -> BAM
B13: Leitura Anterior | C13: Nº de dias tarifa Anterior | D13: Nº de dias tarifa Nova | E13: Leitura Atual | J13: Leitura Anterior | K13: Nº de dias tarifa Anterior | L13: Nº de dias tarifa Nova | M13: Leitura Atual
B14: 46217 | C14: =IF((F2-B14-1)<0,0,(F2-B14-1)) -> 23 | D14: =E14-F2+1 -> 7 | E14: 46247 | J14: =B14 -> 46217 | K14: =IF((M10-J14-1)<0,0,(M10-J14-1)) -> 17 | L14: =M14-M10+1 -> 13 | M14: =E14 -> 46247 | O14: Documento Impressão | Q14: 1025310638
B16: Descrição | C16: Unidade | D16: Quantidade | E16: Preço Unit (R$) com tributos | F16: Valor Total (R$) | G16: PIS/COFINS (R$) | H16: Base de Cálculo ICMS (R$) | I16: Alíquota ICMS (%) | J16: ICMS (R$) | K16: Preço Unit (R$) | L16: Tributos | M16: Base de Cálc (R$) | N16: Alíquota (%) | O16: Valor (R$) | P16: não está contabilizando injetada
R17: TUSD Fio B | S17: Receita Fio B
B18: TUSD - Consumo | C18: kWh | D18: 1078 | E18: =(ROUND(D18*K18,2)+ROUND(G18,2)+ROUND(J18,2))/ROUND(D18,4) -> 0.61302412 | F18: =ROUND(D18*E18,2) -> 660.84 | G18: =((D18*K18)/(1-$N$18-$N$20))*($N$18+$N$20) -> 33.842837 | H18: =((D18*K18)/(1-$N$18-$N$20)/(1-$I$18)) -> 660.85093 | I18: 0.17 | J18: =(H18*$I$18) -> 112.34466 | K18: =IF(AND($B$14<$F$2,$E$14<$F$2),C6,IF($B$14<$F$2,I6,F6)) -> 0.47742433 | L18: PIS | M18: =D76 -> 943.06725 | N18: ='Fatura B1 (GD II) OK'!N18 -> 0.011 | O18: =ROUND(M18*N18,2) -> 10.37 | R18: =IF(AND($B$14<$F$2,$E$14<$F$2),R6,IF($B$14<$F$2,X6,U6)) -> 0.20507226 | S18: =D18*R18 -> 221.06789
B19: TE - Consumo | C19: kWh | D19: =D18 -> 1078 | E19: =(ROUND(D19*K19,2)+ROUND(G19,2)+ROUND(J19,2))/ROUND(D19,4) -> 0.41678108 | F19: =ROUND(D19*E19,2) -> 449.29 | G19: =((D19*K19)/(1-$N$18-$N$20))*($N$18+$N$20) -> 23.008199 | H19: =((D19*K19)/(1-$N$18-$N$20)/(1-$I$18)) -> 449.28236 | J19: =(H19*$I$18) -> 76.378002 | K19: =IF(AND($B$14<$F$2,$E$14<$F$2),D6,IF($B$14<$F$2,J6,G6)) -> 0.324579 | L19: PIS Inj | M19: =D77 -> -2297.7726 | N19: =N18 -> 0.011 | O19: =ROUND(M19*N19,2) -> -25.28
B20: Adicional BAM | C20: kWh | D20: =IF($K$12=M4,($D$18*($K$14)/($K$14+$L$14)),0)+IF($L$12=M4,($D$18*($L$14)/($K$14+$L$14)),0) -> 1078 | E20: =IFERROR((ROUND(D20*K20,2)+ROUND(G20,2)+ROUND(J20,2))/ROUND(D20,4), 0) -> 0.024211503 | F20: =ROUND(D20*E20,2) -> 26.1 | G20: =((D20*K20)/(1-$N$18-$N$20))*($N$18+$N$20) -> 1.3362064 | H20: =((D20*K20)/(1-$N$18-$N$20)/(1-$I$18)) -> 26.092176 | J20: =(H20*$I$18) -> 4.43567 | K20: =N4 -> 0.01885 | L20: COFINS | M20: =M18 -> 943.06725 | N20: ='Fatura B1 (GD II) OK'!N20 -> 0.0507 | O20: =ROUND(M20*N20,2) -> 47.81
B21: Adicional BVM1 | C21: kWh | D21: =IF($K$12=M5,($D$18*($K$14)/($K$14+$L$14)),0)+IF($L$12=M5,($D$18*($L$14)/($K$14+$L$14)),0) -> 0 | E21: =IFERROR((ROUND(D21*K21,2)+ROUND(G21,2)+ROUND(J21,2))/ROUND(D21,4), 0) -> 0 | F21: =ROUND(D21*E21,2) -> 0 | G21: =((D21*K21)/(1-$N$18-$N$20))*($N$18+$N$20) -> 0 | H21: =((D21*K21)/(1-$N$18-$N$20)/(1-$I$18)) -> 0 | J21: =(H21*$I$18) -> 0 | K21: =N5 -> 0.04463 | L21: COFINS Inj | M21: =M19 -> -2297.7726 | N21: =N20 -> 0.0507 | O21: =ROUND(M21*N21,2) -> -116.5
B22: Adicional BVM2 | C22: kWh | D22: =IF($K$12=M6,($D$18*($K$14)/($K$14+$L$14)),0)+IF($L$12=M6,($D$18*($L$14)/($K$14+$L$14)),0) -> 0 | E22: =IFERROR((ROUND(D22*K22,2)+ROUND(G22,2)+ROUND(J22,2))/ROUND(D22,4), 0) -> 0 | F22: =ROUND(D22*E22,2) -> 0 | G22: =((D22*K22)/(1-$N$18-$N$20))*($N$18+$N$20) -> 0 | H22: =((D22*K22)/(1-$N$18-$N$20)/(1-$I$18)) -> 0 | J22: =(H22*$I$18) -> 0 | K22: =N6 -> 0.07877
B23: Adicional EH | C23: kWh | D23: =IF($K$12=M7,($D$18*($K$14)/($K$14+$L$14)),0)+IF($L$12=M7,($D$18*($L$14)/($K$14+$L$14)),0) -> 0 | E23: =IFERROR((ROUND(D23*K23,2)+ROUND(G23,2)+ROUND(J23,2))/ROUND(D23,4), 0) -> 0 | F23: =ROUND(D23*E23,2) -> 0 | G23: =((D23*K23)/(1-$N$18-$N$20))*($N$18+$N$20) -> 0 | H23: =((D23*K23)/(1-$N$18-$N$20)/(1-$I$18)) -> 0 | J23: =(H23*$I$18) -> 0 | K23: =N8 -> 0.142
B25: TUSD - Consumo inj | C25: kWh | D25: -1078 | E25: =IFERROR((ROUND(D25*K25,2)+ROUND(G25,2)+ROUND(J25,2))/ROUND(D25,4),0) -> 0.37757885 | F25: =ROUND(D25*E25,2) -> -407.03 | G25: =((D25*K25)/(1-$N$19-$N$21))*($N$19+$N$21) -> -25.114092 | H25: 0 | I25: 0 | J25: =H25*$I$21 -> 0 | K25: =E62 -> 0.35428705
B26: TE - Consumo inj | C26: kWh | D26: =D25 -> -1078 | E26: =IFERROR((ROUND(D26*K26,2)+ROUND(G26,2)+ROUND(J26,2))/ROUND(D26,4),0) -> 0.41678108 | F26: =ROUND(D26*E26,2) -> -449.29 | G26: =((D26*K26)/(1-$N$19-$N$21))*($N$19+$N$21) -> -23.008199 | H26: =ROUND((D26*K26)/(1-$N$19-$N$21)/(1-$I$26),8) -> -449.28236 | I26: =I18 -> 0.17 | J26: =H26*$I$26 -> -76.378002 | K26: =F62 -> 0.324579
B27: Adicional BAM inj | C27: kWh | D27: =IF($K$12=M4,($D$25*($K$14)/($K$14+$L$14)),0)+IF($L$12=M4,($D$25*($L$14)/($K$14+$L$14)),0) -> -1078 | E27: =IFERROR((ROUND(D27*K27,2)+ROUND(G27,2)+ROUND(J27,2))/ROUND(D27,4),0) -> 0.024211503 | F27: =ROUND(D27*E27,2) -> -26.1 | G27: =((D27*K27)/(1-$N$19-$N$21))*($N$19+$N$21) -> -1.3362064 | H27: =ROUND((D27*K27)/(1-$N$19-$N$21)/(1-$I$26),8) -> -26.092176 | J27: =H27*$I$26 -> -4.43567 | K27: =K20 -> 0.01885
B28: Adicional BVM1 inj | C28: kWh | D28: =IF($K$12=M5,($D$25*($K$14)/($K$14+$L$14)),0)+IF($L$12=M5,($D$25*($L$14)/($K$14+$L$14)),0) -> 0 | E28: =IFERROR((ROUND(D28*K28,2)+ROUND(G28,2)+ROUND(J28,2))/ROUND(D28,4),0) -> 0 | F28: =ROUND(D28*E28,2) -> 0 | G28: =((D28*K28)/(1-$N$19-$N$21))*($N$19+$N$21) -> 0 | H28: =ROUND((D28*K28)/(1-$N$19-$N$21)/(1-$I$26),8) -> 0 | J28: =H28*$I$26 -> 0 | K28: =K21 -> 0.04463
B29: Adicional BVM2 inj | C29: kWh | D29: =IF($K$12=M6,($D$25*($K$14)/($K$14+$L$14)),0)+IF($L$12=M6,($D$25*($L$14)/($K$14+$L$14)),0) -> 0 | E29: =IFERROR((ROUND(D29*K29,2)+ROUND(G29,2)+ROUND(J29,2))/ROUND(D29,4),0) -> 0 | F29: =ROUND(D29*E29,2) -> 0 | G29: =((D29*K29)/(1-$N$19-$N$21))*($N$19+$N$21) -> 0 | H29: =ROUND((D29*K29)/(1-$N$19-$N$21)/(1-$I$26),8) -> 0 | J29: =H29*$I$26 -> 0 | K29: =K22 -> 0.07877
B30: Adicional EH inj | C30: kWh | D30: =IF($K$12=M8,($D$25*($K$14)/($K$14+$L$14)),0)+IF($L$12=M8,($D$25*($L$14)/($K$14+$L$14)),0) -> 0 | E30: =IFERROR((ROUND(D30*K30,2)+ROUND(G30,2)+ROUND(J30,2))/ROUND(D30,4),0) -> 0 | F30: =ROUND(D30*E30,2) -> 0 | G30: =((D30*K30)/(1-$N$19-$N$21))*($N$19+$N$21) -> 0 | H30: =ROUND((D30*K30)/(1-$N$19-$N$21)/(1-$I$26),8) -> 0 | J30: =H30*$I$26 -> 0 | K30: =K23 -> 0.142
B32: Multas | F32: 0.43
B33: Juros
B34: Doações | F34: 2.94
B35: Bônus/Descontos
B36: CIP | F36: 77.47
B38: TOTAL | F38: =SUM(F18:F37) -> 334.65 | G38: =SUM(G18:G37) -> 8.7287445 | H38: =SUM(H18:H37) -> 660.85093 | J38: =SUM(J18:J37) -> 112.34466
B40: Informativo Escassez Hídrica | D40: =D18 -> 1078 | E40: =IF(AND($B$14<$F$2,$E$14<$F$2),C7,IF($B$14<$F$2,I7,F7)) -> 0.00018691702 | F40: =IF(AND($B$14<$F$2,$E$14<$F$2),D7,IF($B$14<$F$2,J7,G7)) -> -0.0034998272 | G40: =D40*(E40+F40) -> -3.5713171
D41: =D25 -> -1078 | E41: =IF(AND($B$14<$F$2,$E$14<$F$2),C7*$F$49,IF($B$14<$F$2,(((I7*F49)*C14)+((I7*F50)*D14))/(C14+D14),I7*$F$50)) -> 0.00013870738 | F41: =IF(AND($B$14<$F$2,$E$14<$F$2),D7,IF($B$14<$F$2,J7,G7)) -> -0.0034998272 | G41: =D41*(E41+F41) -> 3.6232871
G42: =SUM(G40:G41) -> 0.051969989
B49: Perc. de Redução da Energia Injetada | E49: TUSD | F49: 0.739 | G49: TE | H49: 1 | I49: ='Fatura B1 (GD II) OK'!I44 -> A partir de 01/01/2026 | K49: =C6*F49 -> 0.34631757 | L49: =(K49*C14)/(C14+D14) -> 0.26551014
E50: TUSD | F50: 0.7522 | G50: TE | H50: 1 | I50: ='Fatura B1 (GD II) OK'!I45 -> A partir de 07/08/2026 | K50: =F6*F50 -> 0.3808539 | L50: =(K50*D14)/(C14+D14) -> 0.088865911
B51: Fatura B1 Residencial
D52: Qtde | E52: TUSD | F52: TE | G52: TUSD + TE | H52: R$
...

Sheet Fatura B2 IRRIG (GD II) OK
B2: B2 | E2: Vigência das Tarifas: | F2: ='Fatura B1 (GD II) OK'!F2 -> 46241 | G2: 2025: | H2: 45658 | M2: Bandeira | N2: R$/kWh | O2: ANEEL em 29/06 | Q2: TUSD FIO B
M3: VERDE | N3: 0
B4: TARIFA | C4: ='Fatura B1 (GD II) OK'!C4:E4 -> TARIFA ANTIGA - REH 3370/2024 | F4: ='Fatura B1 (GD II) OK'!F4:H4 -> TARIFA NOVA - REH xxxx/2025 | I4: Tarifas Proporcionalizadas | M4: BAM | N4: ='[1]Fatura B1 (Res) OK'!$N$4 -> 0.01885 | Q4: TARIFA | R4: =C4 -> TARIFA ANTIGA - REH 3370/2024 | U4: =F4 -> TARIFA NOVA - REH xxxx/2025 | X4: Tarifas Proporcionalizadas
C5: Tusd | D5: TE | E5: TUSD + TE | F5: Tusd | G5: TE | H5: TUSD + TE | I5: Tusd | J5: TE | K5: TUSD + TE | M5: BVM1 | N5: ='[1]Fatura B1 (Res) OK'!$N$5 -> 0.04463 | R5: Tusd (R$/kWh) | U5: Tusd (R$/kWh) | X5: Tusd (R$/kWh)
B6: B2 | C6: ='TABELA DE TARIFAS ANTIGAS'!G77/1000 -> 0.46863 | D6: ='TABELA DE TARIFAS ANTIGAS'!H77/1000 -> 0.32068 | E6: =C6+D6 -> 0.78931 | F6: ='TABELA DE TARIFAS NOVAS'!G79/1000 -> 0.50632 | G6: ='TABELA DE TARIFAS NOVAS'!H79/1000 -> 0.33739 | H6: =F6+G6 -> 0.84371 | I6: =((C6*$C$14)+(F6*$D$14))/($D$14+$C$14) -> 0.48621867 | J6: =((D6*$C$14)+(G6*$D$14))/($D$14+$C$14) -> 0.328478 | K6: =I6+J6 -> 0.81469667 | M6: BVM2 | N6: ='[1]Fatura B1 (Res) OK'!$N$6 -> 0.07877 | Q6: =B6 -> B2 | R6: ='FIO B'!H20/1000 -> 0.20383072 | U6: ='FIO B'!K20/1000 -> 0.20915159 | X6: =((R6*$C$14)+(U6*$D$14))/($D$14+$C$14) -> 0.20631379
B7: CDE Escassez Hídrica | C7: 0.00018774721 | D7: -0.0044031307 | E7: 0.0036054084 | F7: =T11 -> 0.00018418923 | G7: =U11 -> -0.00053182975 | H7: =F7+G7 -> -0.00034764052 | I7: =((C7*$C$14)+(F7*$D$14))/($D$14+$C$14) -> 0.00018608682 | J7: =((D7*$C$14)+(G7*$D$14))/($D$14+$C$14) -> -0.0025965236 | K7: =I7+J7 -> -0.0024104368
B8: TE SCEE | G8: =G6*15% -> 0.0506085 | J8: =((D8*$C$14)+(G8*$D$14))/($D$14+$C$14) -> 0.0236173 | M8: Escassez Hídrica | N8: 0.142 | P8: CUSTO | R8: Part. TUSD (%) | S8: Part. TE (%) | T8: Tusd (R$/kWh) | U8: TE (R$/kWh)
P9: CDE CONTAS
H10: Fatura | L10: Vigência das Tarifas (troca Bandeira): | M10: =EOMONTH(B14,0)+1 -> 46235 | P10: CDE COVID | U10: 0
B11: INSTALAÇÃO | C11: 160846277 | H11: =E14 -> 46254 | K11: Altere a bandeira na célula abaixo | P11: CDE ESCASSEZ HÍDRICA | T11: ='Fatura B1 (GD II) OK'!T11 -> 0.00018418923 | U11: ='Fatura B1 (GD II) OK'!U11 -> -0.00053182975
K12: ='Fatura B1 (GD II) OK'!K12 -> BAM | L12: ='Fatura B1 (GD II) OK'!L12 -> BAM
B13: Leitura Anterior | C13: Nº de dias tarifa Anterior | D13: Nº de dias tarifa Nova | E13: Leitura Atual | J13: Leitura Anterior | K13: Nº de dias tarifa Anterior | L13: Nº de dias tarifa Nova | M13: Leitura Atual
B14: 46224 | C14: =IF((F2-B14-1)<0,0,(F2-B14-1)) -> 16 | D14: =E14-F2+1 -> 14 | E14: 46254 | J14: =B14 -> 46224 | K14: =IF((M10-J14-1)<0,0,(M10-J14-1)) -> 10 | L14: =M14-M10+1 -> 20 | M14: =E14 -> 46254 | O14: Documento Impressão | Q14: 1025310493
N15: desconto: | O15: 0.6
B16: Descrição | C16: Unidade | D16: Quantidade | E16: Preço Unit (R$) com tributos | F16: Valor Total (R$) | G16: PIS/COFINS (R$) | H16: Base de Cálculo ICMS (R$) | I16: Alíquota ICMS (%) | J16: ICMS (R$) | K16: Preço Unit (R$) | L16: Tributos | M16: Base de Cálc (R$) | N16: Alíquota (%) | O16: Valor (R$) | P16: não está contabilizando injetada
R17: TUSD Fio B | S17: Receita Fio B
B18: TUSD - Ativo | C18: kWh | D18: 6812 | E18: =IFERROR((ROUND(D18*K18,2)+ROUND(G18,2)+ROUND(J18,2))/ROUND(D18,4), 0) -> 0.53978274 | F18: =ROUND(D18*E18,2) -> 3677 | G18: =((D18*K18)/(1-$N$18-$N$20))*($N$18+$N$20) -> 217.79591 | H18: =(IF($I$18=12%,(D18*K18)/(1-$N$18-$N$20)/(1-$C$124)/$F$124*$C$124,(D18*K18)/(1-$N$18-$N$20)/(1-$I$18))) -> 1225.6658 | I18: 0.12 | J18: =(H18*$I$18) -> 147.07989 | K18: =IF(AND($B$14<$F$2,$E$14<$F$2),C6,IF($B$14<$F$2,I6,F6)) -> 0.48621867 | L18: PIS | M18: =D112 -> 6219.222 | N18: ='Fatura B1 (GD II) OK'!N18 -> 0.011 | O18: =ROUND(M18*N18,2) -> 68.41 | R18: =IF(AND($B$14<$F$2,$E$14<$F$2),R6,IF($B$14<$F$2,X6,U6)) -> 0.20631379 | S18: =D18*R18 -> 1405.4096
B19: TUSD - Consumo Reservado | C19: kWh | D19: 472 | E19: =IFERROR((ROUND(D19*K19,2)+ROUND(G19,2)+ROUND(J19,2))/ROUND(D19,4), 0) -> 0.2159322 | F19: =ROUND(D19*E19,2) -> 101.92 | G19: =((D19*K19)/(1-$N$18-$N$20))*($N$18+$N$20) -> 6.0363869 | H19: =(IF($I$18=12%,(D19*K19)/(1-$N$18-$N$20)/(1-$C$124)/$F$124*$C$124,(D19*K19)/(1-$N$18-$N$20)/(1-$I$18))) -> 33.970302 | I19: =I18 -> 0.12 | J19: =(H19*$I$18) -> 4.0764363 | K19: =(K18+(K18*(-$H$57))) -> 0.19448747 | L19: PIS Inj | M19: =D113 -> -0.75668763 | N19: =N18 -> 0.011 | O19: =ROUND(M19*N19,2) -> -0.01 | R19: =IF(AND($B$14<$F$2,$E$14<$F$2),R6,IF($B$14<$F$2,X6,U6)) -> 0.20631379 | S19: =D19*R19 -> 97.380111
B20: TE - Consumo | C20: kWh | D20: =D18 -> 6812 | E20: =IFERROR((ROUND(D20*K20,2)+ROUND(G20,2)+ROUND(J20,2))/ROUND(D20,4), 0) -> 0.36466383 | F20: =ROUND(D20*E20,2) -> 2484.09 | G20: =((D20*K20)/(1-$N$18-$N$20))*($N$18+$N$20) -> 147.13784 | H20: =(IF($I$18=12%,(D20*K20)/(1-$N$18-$N$20)/(1-$C$124)/$F$124*$C$124,(D20*K20)/(1-$N$18-$N$20)/(1-$I$18))) -> 828.03124 | J20: =(H20*$I$18) -> 99.363749 | K20: =IF(AND($B$14<$F$2,$E$14<$F$2),D6,IF($B$14<$F$2,J6,G6)) -> 0.328478 | L20: COFINS | M20: =M18 -> 6219.222 | N20: ='Fatura B1 (GD II) OK'!N20 -> 0.0507 | O20: =ROUND(M20*N20,2) -> 315.31 | S20: =-S19*60% -> -58.428067
B21: TE - Consumo Reservado | C21: kWh | D21: =D19 -> 472 | E21: =IFERROR((ROUND(D21*K21,2)+ROUND(G21,2)+ROUND(J21,2))/ROUND(D21,4), 0) -> 0.14586864 | F21: =ROUND(D21*E21,2) -> 68.85 | G21: =((D21*K21)/(1-$N$18-$N$20))*($N$18+$N$20) -> 4.0780423 | H21: =(IF($I$18=12%,(D21*K21)/(1-$N$18-$N$20)/(1-$C$124)/$F$124*$C$124,(D21*K21)/(1-$N$18-$N$20)/(1-$I$18))) -> 22.949545 | J21: =(H21*$I$18) -> 2.7539454 | K21: =ROUND(K20+(K20*(-$H$57)),8) -> 0.1313912 | L21: COFINS Inj | M21: =M19 -> -0.75668763 | N21: =N20 -> 0.0507 | O21: =ROUND(M21*N21,2) -> -0.04 | S21: =SUM(S18:S20) -> 1444.3616
B22: Adicional BAM | C22: kWh | D22: =IF($K$12=M4,(($D$18+$D$19)*($K$14)/($K$14+$L$14)),0)+IF($L$12=M4,(($D$18+$D$19)*($L$14)/($K$14+$L$14)),0) -> 7284 | E22: =IFERROR((ROUND(D22*K22,2)+ROUND(G22,2)+ROUND(J22,2))/ROUND(D22,4), 0) -> 0.020113948 | F22: =ROUND(D22*E22,2) -> 146.51 | G22: =((D22*K22)/(1-$N$18-$N$20))*($N$18+$N$20) -> 8.6776569 | H22: =(IF($I$18=12%,(D22*K22)/(1-$N$18-$N$20)/(1-$C$124)/$F$124*$C$124,(D22*K22)/(1-$N$18-$N$20)/(1-$I$18))) -> 48.834284 | J22: =(H22*$I$18) -> 5.860114 | K22: =J63 -> 0.018117117 | Q22: 838840 | R22: massa
B23: Adicional BVM1 | C23: kWh | D23: =IF($K$12=M5,(($D$18+$D$19)*($K$14)/($K$14+$L$14)),0)+IF($L$12=M5,(($D$18+$D$19)*($L$14)/($K$14+$L$14)),0) -> 0 | E23: =IFERROR((ROUND(D23*K23,2)+ROUND(G23,2)+ROUND(J23,2))/ROUND(D23,4), 0) -> 0 | F23: =ROUND(D23*E23,2) -> 0 | G23: =((D23*K23)/(1-$N$18-$N$20))*($N$18+$N$20) -> 0 | H23: =(IF($I$18=12%,(D23*K23)/(1-$N$18-$N$20)/(1-$C$124)/$F$124*$C$124,(D23*K23)/(1-$N$18-$N$20)/(1-$I$18))) -> 0 | J23: =(H23*$I$18) -> 0 | K23: =J64 -> 0
B24: Adicional BVM2 | C24: kWh | D24: =IF($K$12=M6,(($D$18+$D$19)*($K$14)/($K$14+$L$14)),0)+IF($L$12=M6,(($D$18+$D$19)*($L$14)/($K$14+$L$14)),0) -> 0 | E24: =IFERROR((ROUND(D24*K24,2)+ROUND(G24,2)+ROUND(J24,2))/ROUND(D24,4), 0) -> 0 | F24: =ROUND(D24*E24,2) -> 0 | G24: =((D24*K24)/(1-$N$18-$N$20))*($N$18+$N$20) -> 0 | H24: =(IF($I$18=12%,(D24*K24)/(1-$N$18-$N$20)/(1-$C$124)/$F$124*$C$124,(D24*K24)/(1-$N$18-$N$20)/(1-$I$18))) -> 0 | J24: =(H24*$I$18) -> 0 | K24: =J65 -> 0
B25: Adicional EH | C25: kWh | D25: =IF($K$12=M7,(($D$18+$D$19)*($K$14)/($K$14+$L$14)),0)+IF($L$12=M7,(($D$18+$D$19)*($L$14)/($K$14+$L$14)),0) -> 0 | E25: =IFERROR((ROUND(D25*K25,2)+ROUND(G25,2)+ROUND(J25,2))/ROUND(D25,4), 0) -> 0 | F25: =ROUND(D25*E25,2) -> 0 | G25: =((D25*K25)/(1-$N$18-$N$20))*($N$18+$N$20) -> 0 | H25: =(IF($I$18=12%,(D25*K25)/(1-$N$18-$N$20)/(1-$C$124)/$F$124*$C$124,(D25*K25)/(1-$N$18-$N$20)/(1-$I$18))) -> 0 | J25: =(H25*$I$18) -> 0 | K25: =J66 -> 0
B27: TUSD - Consumo inj Reservado | C27: kWh | D27: 0 | E27: =IFERROR((ROUND(D27*K27,2)+ROUND(G27,2)+ROUND(J27,2))/ROUND(D27,4), 0) -> 0 | F27: =ROUND(D27*E27,2) -> 0 | G27: =((D27*K27)/(1-$N$19-$N$21))*($N$19+$N$21) -> 0 | H27: 0 | I27: 0 | J27: =H27*$I$21 -> 0 | K27: =(K28+(K28*(-$H$57))) -> 0.14492428
B28: TUSD - Consumo inj | C28: kWh | D28: -1 | E28: =IFERROR((ROUND(D28*K28,2)+ROUND(G28,2)+ROUND(J28,2))/ROUND(D28,4), 0) -> 0.38 | F28: =ROUND(D28*E28,2) -> -0.38 | G28: =((D28*K28)/(1-$N$19-$N$21))*($N$19+$N$21) -> -0.023824545 | H28: 0 | I28: 0 | J28: =H28*$I$21 -> 0 | K28: =E81 -> 0.3623107
B29: TE - Consumo inj Reservado | C29: kWh | D29: =D27 -> 0 | E29: =IFERROR((ROUND(D29*K29,2)+ROUND(G29,2)+ROUND(J29,2))/ROUND(D29,4), 0) -> 0 | F29: =ROUND(D29*E29,2) -> 0 | G29: =((D29*K29)/(1-$N$19-$N$21))*($N$19+$N$21) -> 0 | H29: =(IF($I$29=12%,(D29*K29)/(1-$N$19-$N$21)/(1-$C$130)/$F$130*$C$130,(D29*K29)/(1-$N$19-$N$21)/(1-$I$29))) -> 0 | I29: =I18 -> 0.12 | J29: =H29*$I$29 -> 0 | K29: =K30+(K30*(-$H$57)) -> 0.1313912
B30: TE - Consumo inj | C30: kWh | D30: =D28 -> -1 | E30: =IFERROR((ROUND(D30*K30,2)+ROUND(G30,2)+ROUND(J30,2))/ROUND(D30,4), 0) -> 0.36 | F30: =ROUND(D30*E30,2) -> -0.36 | G30: =((D30*K30)/(1-$N$19-$N$21))*($N$19+$N$21) -> -0.0215998 | H30: =(IF($I$29=12%,(D30*K30)/(1-$N$19-$N$21)/(1-$C$130)/$F$130*$C$130,(D30*K30)/(1-$N$19-$N$21)/(1-$I$29))) -> -0.12155479 | I30: =I19 -> 0.12 | J30: =H30*$I$29 -> -0.014586575 | K30: =K20 -> 0.328478
B31: Adicional BAM inj | C31: kWh | D31: =IF($K$12=M4,(($D$27+$D$28)*($K$14)/($K$14+$L$14)),0)+IF($L$12=M4,(($D$27+$D$28)*($L$14)/($K$14+$L$14)),0) -> -1 | E31: =IFERROR((ROUND(D31*K31,2)+ROUND(G31,2)+ROUND(J31,2))/ROUND(D31,4), 0) -> 0.02 | F31: =ROUND(D31*E31,2) -> -0.02 | G31: =((D31*K31)/(1-$N$19-$N$21))*($N$19+$N$21) -> -0.0012395236 | H31: =(IF($I$29=12%,(D31*K31)/(1-$N$19-$N$21)/(1-$C$130)/$F$130*$C$130,(D31*K31)/(1-$N$19-$N$21)/(1-$I$29))) -> -0.006975529 | J31: =H31*$I$29 -> -0.00083706348 | K31: =J84 -> 0.01885
B32: Adicional BVM1 inj | C32: kWh | D32: =IF($K$12=M5,(($D$27+$D$28)*($K$14)/($K$14+$L$14)),0)+IF($L$12=M5,(($D$27+$D$28)*($L$14)/($K$14+$L$14)),0) -> 0 | E32: =IFERROR((ROUND(D32*K32,2)+ROUND(G32,2)+ROUND(J32,2))/ROUND(D32,4), 0) -> 0 | F32: =ROUND(D32*E32,2) -> 0 | G32: =((D32*K32)/(1-$N$19-$N$21))*($N$19+$N$21) -> 0 | H32: =(IF($I$29=12%,(D32*K32)/(1-$N$19-$N$21)/(1-$C$130)/$F$130*$C$130,(D32*K32)/(1-$N$19-$N$21)/(1-$I$29))) -> 0 | J32: =H32*$I$29 -> 0 | K32: =J85 -> 0
B33: Adicional BVM2 inj | C33: kWh | D33: =IF($K$12=M6,(($D$27+$D$28)*($K$14)/($K$14+$L$14)),0)+IF($L$12=M6,(($D$27+$D$28)*($L$14)/($K$14+$L$14)),0) -> 0 | E33: =IFERROR((ROUND(D33*K33,2)+ROUND(G33,2)+ROUND(J33,2))/ROUND(D33,4), 0) -> 0 | F33: =ROUND(D33*E33,2) -> 0 | G33: =((D33*K33)/(1-$N$19-$N$21))*($N$19+$N$21) -> 0 | H33: =(IF($I$29=12%,(D33*K33)/(1-$N$19-$N$21)/(1-$C$130)/$F$130*$C$130,(D33*K33)/(1-$N$19-$N$21)/(1-$I$29))) -> 0 | J33: =H33*$I$29 -> 0 | K33: =J86 -> 0
B34: Adicional EH inj | C34: kWh | D34: =IF($K$12=M7,(($D$27+$D$28)*($K$14)/($K$14+$L$14)),0)+IF($L$12=M7,(($D$27+$D$28)*($L$14)/($K$14+$L$14)),0) -> 0 | E34: =IFERROR((ROUND(D34*K34,2)+ROUND(G34,2)+ROUND(J34,2))/ROUND(D34,4), 0) -> 0 | F34: =ROUND(D34*E34,2) -> 0 | G34: =((D34*K34)/(1-$N$19-$N$21))*($N$19+$N$21) -> 0 | H34: =(IF($I$29=12%,(D34*K34)/(1-$N$19-$N$21)/(1-$C$130)/$F$130*$C$130,(D34*K34)/(1-$N$19-$N$21)/(1-$I$29))) -> 0 | J34: =H34*$I$29 -> 0 | K34: =J87 -> 0
B36: Multas
B37: Juros | F37: -0.33
B38: Doações
B39: Bônus/Descontos
B40: CIP
B42: TOTAL | F42: =SUM(F18:F41) -> 6477.28 | G42: =SUM(G18:G41) -> 383.67917 | H42: =SUM(H18:H41) -> 2159.3226 | J42: =SUM(J18:J41) -> 259.11872
B44: Informativo Escassez | C44: =D18 -> 6812 | D44: =IF(AND($B$14<$F$2,$E$14<$F$2),C7,IF($B$14<$F$2,I7,F7)) -> 0.00018608682 | E44: =IF(AND($B$14<$F$2,$E$14<$F$2),D7,IF($B$14<$F$2,J7,G7)) -> -0.0025965236 | F44: =C44*(D44+E44) -> -16.419895 | G44: Incorreto no SAP
C45: =D19 -> 472 | D45: =IF(AND($B$14<$F$2,$E$14<$F$2),C7,IF($B$14<$F$2,I7,F7)) -> 0.00018608682 | E45: =IF(AND($B$14<$F$2,$E$14<$F$2),D7,IF($B$14<$F$2,J7,G7)) -> -0.0025965236 | F45: =C45*(D45+E45) -> -1.1377262
...

Sheet Fatura B2 IRRIG (GD II) OK (2)
B2: B2 | E2: Vigência das Tarifas: | F2: ='Fatura B1 (GD II) OK'!F2 -> 46241 | G2: 2025: | H2: 45658 | M2: Bandeira | N2: R$/kWh | O2: ANEEL em 29/06 | Q2: TUSD FIO B
M3: VERDE | N3: 0
B4: TARIFA | C4: ='Fatura B1 (GD II) OK'!C4:E4 -> TARIFA ANTIGA - REH 3370/2024 | F4: ='Fatura B1 (GD II) OK'!F4:H4 -> TARIFA NOVA - REH xxxx/2025 | I4: Tarifas Proporcionalizadas | M4: BAM | N4: ='[1]Fatura B1 (Res) OK'!$N$4 -> 0.01885 | Q4: TARIFA | R4: =C4 -> TARIFA ANTIGA - REH 3370/2024 | U4: =F4 -> TARIFA NOVA - REH xxxx/2025 | X4: Tarifas Proporcionalizadas
C5: Tusd | D5: TE | E5: TUSD + TE | F5: Tusd | G5: TE | H5: TUSD + TE | I5: Tusd | J5: TE | K5: TUSD + TE | M5: BVM1 | N5: ='[1]Fatura B1 (Res) OK'!$N$5 -> 0.04463 | R5: Tusd (R$/kWh) | U5: Tusd (R$/kWh) | X5: Tusd (R$/kWh)
B6: B2 | C6: ='TABELA DE TARIFAS ANTIGAS'!G77/1000 -> 0.46863 | D6: ='TABELA DE TARIFAS ANTIGAS'!H77/1000 -> 0.32068 | E6: =C6+D6 -> 0.78931 | F6: ='TABELA DE TARIFAS NOVAS'!G79/1000 -> 0.50632 | G6: ='TABELA DE TARIFAS NOVAS'!H79/1000 -> 0.33739 | H6: =F6+G6 -> 0.84371 | I6: =((C6*$C$14)+(F6*$D$14))/($D$14+$C$14) -> 0.47451906 | J6: =((D6*$C$14)+(G6*$D$14))/($D$14+$C$14) -> 0.32329094 | K6: =I6+J6 -> 0.79781 | M6: BVM2 | N6: ='[1]Fatura B1 (Res) OK'!$N$6 -> 0.07877 | Q6: =B6 -> B2 | R6: ='FIO B'!H20/1000 -> 0.20383072 | U6: ='FIO B'!K20/1000 -> 0.20915159 | X6: =((R6*$C$14)+(U6*$D$14))/($D$14+$C$14) -> 0.20466211
B7: CDE Escassez Hídrica | C7: 0.00018774721 | D7: -0.0044031307 | E7: 0.0036054084 | F7: =T11 -> 0.00018418923 | G7: =U11 -> -0.00053182975 | H7: =F7+G7 -> -0.00034764052 | I7: =((C7*$C$14)+(F7*$D$14))/($D$14+$C$14) -> 0.00018719128 | J7: =((D7*$C$14)+(G7*$D$14))/($D$14+$C$14) -> -0.00379824 | K7: =I7+J7 -> -0.0036110487
B8: TE SCEE | G8: =G6*15% -> 0.0506085 | J8: =((D8*$C$14)+(G8*$D$14))/($D$14+$C$14) -> 0.0079075781 | M8: Escassez Hídrica | N8: 0.142 | P8: CUSTO | R8: Part. TUSD (%) | S8: Part. TE (%) | T8: Tusd (R$/kWh) | U8: TE (R$/kWh)
P9: CDE CONTAS
H10: Fatura | L10: Vigência das Tarifas (troca Bandeira): | M10: =EOMONTH(B14,0)+1 -> 46235 | P10: CDE COVID | U10: 0
B11: INSTALAÇÃO | C11: 838840 | H11: =E14 -> 46245 | K11: Altere a bandeira na célula abaixo | P11: CDE ESCASSEZ HÍDRICA | T11: ='Fatura B1 (GD II) OK'!T11 -> 0.00018418923 | U11: ='Fatura B1 (GD II) OK'!U11 -> -0.00053182975
K12: ='Fatura B1 (GD II) OK'!K12 -> BAM | L12: ='Fatura B1 (GD II) OK'!L12 -> BAM
B13: Leitura Anterior | C13: Nº de dias tarifa Anterior | D13: Nº de dias tarifa Nova | E13: Leitura Atual | J13: Leitura Anterior | K13: Nº de dias tarifa Anterior | L13: Nº de dias tarifa Nova | M13: Leitura Atual
B14: 46213 | C14: =IF((F2-B14-1)<0,0,(F2-B14-1)) -> 27 | D14: =E14-F2+1 -> 5 | E14: 46245 | J14: =B14 -> 46213 | K14: =IF((M10-J14-1)<0,0,(M10-J14-1)) -> 21 | L14: =M14-M10+1 -> 11 | M14: =E14 -> 46245 | O14: Documento Impressão | Q14: 1025310494
N15: desconto: | O15: 0.6
B16: Descrição | C16: Unidade | D16: Quantidade | E16: Preço Unit (R$) com tributos | F16: Valor Total (R$) | G16: PIS/COFINS (R$) | H16: Base de Cálculo ICMS (R$) | I16: Alíquota ICMS (%) | J16: ICMS (R$) | K16: Preço Unit (R$) | L16: Tributos | M16: Base de Cálc (R$) | N16: Alíquota (%) | O16: Valor (R$) | P16: não está contabilizando injetada
R17: TUSD Fio B | S17: Receita Fio B
B18: TUSD - Ativo | C18: kWh | D18: 4480 | E18: =IFERROR((ROUND(D18*K18,2)+ROUND(G18,2)+ROUND(J18,2))/ROUND(D18,4), 0) -> 0.6093058 | F18: =ROUND(D18*E18,2) -> 2729.69 | G18: =((D18*K18)/(1-$N$18-$N$20))*($N$18+$N$20) -> 139.78968 | H18: =(IF($I$18=12%,(D18*K18)/(1-$N$18-$N$20)/(1-$C$124)/$F$124*$C$124,(D18*K18)/(1-$N$18-$N$20)/(1-$I$18))) -> 2729.6808 | I18: 0.17 | J18: =(H18*$I$18) -> 464.04574 | K18: =IF(AND($B$14<$F$2,$E$14<$F$2),C6,IF($B$14<$F$2,I6,F6)) -> 0.47451906 | L18: PIS | M18: =D112 -> 4957.5786 | N18: ='Fatura B1 (GD II) OK'!N18 -> 0.011 | O18: =ROUND(M18*N18,2) -> 54.53 | R18: =IF(AND($B$14<$F$2,$E$14<$F$2),R6,IF($B$14<$F$2,X6,U6)) -> 0.20466211 | S18: =D18*R18 -> 916.88624
B19: TUSD - Consumo Reservado | C19: kWh | D19: 3040 | E19: =IFERROR((ROUND(D19*K19,2)+ROUND(G19,2)+ROUND(J19,2))/ROUND(D19,4), 0) -> 0.24372368 | F19: =ROUND(D19*E19,2) -> 740.92 | G19: =((D19*K19)/(1-$N$18-$N$20))*($N$18+$N$20) -> 37.942914 | H19: =(IF($I$18=12%,(D19*K19)/(1-$N$18-$N$20)/(1-$C$124)/$F$124*$C$124,(D19*K19)/(1-$N$18-$N$20)/(1-$I$18))) -> 740.91337 | I19: =I18 -> 0.17 | J19: =(H19*$I$18) -> 125.95527 | K19: =(K18+(K18*(-$H$57))) -> 0.18980762 | L19: PIS Inj | M19: =D113 -> -3135.0954 | N19: =N18 -> 0.011 | O19: =ROUND(M19*N19,2) -> -34.49 | R19: =IF(AND($B$14<$F$2,$E$14<$F$2),R6,IF($B$14<$F$2,X6,U6)) -> 0.20466211 | S19: =D19*R19 -> 622.17281
B20: TE - Consumo | C20: kWh | D20: =D18 -> 4480 | E20: =IFERROR((ROUND(D20*K20,2)+ROUND(G20,2)+ROUND(J20,2))/ROUND(D20,4), 0) -> 0.41512054 | F20: =ROUND(D20*E20,2) -> 1859.74 | G20: =((D20*K20)/(1-$N$18-$N$20))*($N$18+$N$20) -> 95.239036 | H20: =(IF($I$18=12%,(D20*K20)/(1-$N$18-$N$20)/(1-$C$124)/$F$124*$C$124,(D20*K20)/(1-$N$18-$N$20)/(1-$I$18))) -> 1859.7379 | J20: =(H20*$I$18) -> 316.15544 | K20: =IF(AND($B$14<$F$2,$E$14<$F$2),D6,IF($B$14<$F$2,J6,G6)) -> 0.32329094 | L20: COFINS | M20: =M18 -> 4957.5786 | N20: ='Fatura B1 (GD II) OK'!N20 -> 0.0507 | O20: =ROUND(M20*N20,2) -> 251.35 | S20: =-S19*60% -> -373.30368
B21: TE - Consumo Reservado | C21: kWh | D21: =D19 -> 3040 | E21: =IFERROR((ROUND(D21*K21,2)+ROUND(G21,2)+ROUND(J21,2))/ROUND(D21,4), 0) -> 0.16604605 | F21: =ROUND(D21*E21,2) -> 504.78 | G21: =((D21*K21)/(1-$N$18-$N$20))*($N$18+$N$20) -> 25.850597 | H21: =(IF($I$18=12%,(D21*K21)/(1-$N$18-$N$20)/(1-$C$124)/$F$124*$C$124,(D21*K21)/(1-$N$18-$N$20)/(1-$I$18))) -> 504.78601 | J21: =(H21*$I$18) -> 85.813622 | K21: =ROUND(K20+(K20*(-$H$57)),8) -> 0.12931638 | L21: COFINS Inj | M21: =M19 -> -3135.0954 | N21: =N20 -> 0.0507 | O21: =ROUND(M21*N21,2) -> -158.95 | S21: =SUM(S18:S20) -> 1165.7554
B22: Adicional BAM | C22: kWh | D22: =IF($K$12=M4,(($D$18+$D$19)*($K$14)/($K$14+$L$14)),0)+IF($L$12=M4,(($D$18+$D$19)*($L$14)/($K$14+$L$14)),0) -> 7520 | E22: =IFERROR((ROUND(D22*K22,2)+ROUND(G22,2)+ROUND(J22,2))/ROUND(D22,4), 0) -> 0.018333777 | F22: =ROUND(D22*E22,2) -> 137.87 | G22: =((D22*K22)/(1-$N$18-$N$20))*($N$18+$N$20) -> 7.0603265 | H22: =(IF($I$18=12%,(D22*K22)/(1-$N$18-$N$20)/(1-$C$124)/$F$124*$C$124,(D22*K22)/(1-$N$18-$N$20)/(1-$I$18))) -> 137.86738 | J22: =(H22*$I$18) -> 23.437455 | K22: =J63 -> 0.014277872 | Q22: 838840 | R22: massa
B23: Adicional BVM1 | C23: kWh | D23: =IF($K$12=M5,(($D$18+$D$19)*($K$14)/($K$14+$L$14)),0)+IF($L$12=M5,(($D$18+$D$19)*($L$14)/($K$14+$L$14)),0) -> 0 | E23: =IFERROR((ROUND(D23*K23,2)+ROUND(G23,2)+ROUND(J23,2))/ROUND(D23,4), 0) -> 0 | F23: =ROUND(D23*E23,2) -> 0 | G23: =((D23*K23)/(1-$N$18-$N$20))*($N$18+$N$20) -> 0 | H23: =(IF($I$18=12%,(D23*K23)/(1-$N$18-$N$20)/(1-$C$124)/$F$124*$C$124,(D23*K23)/(1-$N$18-$N$20)/(1-$I$18))) -> 0 | J23: =(H23*$I$18) -> 0 | K23: =J64 -> 0
B24: Adicional BVM2 | C24: kWh | D24: =IF($K$12=M6,(($D$18+$D$19)*($K$14)/($K$14+$L$14)),0)+IF($L$12=M6,(($D$18+$D$19)*($L$14)/($K$14+$L$14)),0) -> 0 | E24: =IFERROR((ROUND(D24*K24,2)+ROUND(G24,2)+ROUND(J24,2))/ROUND(D24,4), 0) -> 0 | F24: =ROUND(D24*E24,2) -> 0 | G24: =((D24*K24)/(1-$N$18-$N$20))*($N$18+$N$20) -> 0 | H24: =(IF($I$18=12%,(D24*K24)/(1-$N$18-$N$20)/(1-$C$124)/$F$124*$C$124,(D24*K24)/(1-$N$18-$N$20)/(1-$I$18))) -> 0 | J24: =(H24*$I$18) -> 0 | K24: =J65 -> 0
B25: Adicional EH | C25: kWh | D25: =IF($K$12=M7,(($D$18+$D$19)*($K$14)/($K$14+$L$14)),0)+IF($L$12=M7,(($D$18+$D$19)*($L$14)/($K$14+$L$14)),0) -> 0 | E25: =IFERROR((ROUND(D25*K25,2)+ROUND(G25,2)+ROUND(J25,2))/ROUND(D25,4), 0) -> 0 | F25: =ROUND(D25*E25,2) -> 0 | G25: =((D25*K25)/(1-$N$18-$N$20))*($N$18+$N$20) -> 0 | H25: =(IF($I$18=12%,(D25*K25)/(1-$N$18-$N$20)/(1-$C$124)/$F$124*$C$124,(D25*K25)/(1-$N$18-$N$20)/(1-$I$18))) -> 0 | J25: =(H25*$I$18) -> 0 | K25: =J66 -> 0
